2024-11-28 17:12:20,123 - app - INFO - Database connection pool created successfully.
2024-11-28 17:13:40,370 - app - INFO - Database connection pool created successfully.
2024-11-28 17:15:00,550 - app - INFO - Database connection pool created successfully.
2024-11-28 17:15:03,495 - app - INFO - Database connection pool created successfully.
2024-11-28 17:16:01,191 - app - INFO - Database connection pool created successfully.
2024-11-28 17:18:25,875 - app - INFO - Database connection pool created successfully.
2024-11-28 17:19:14,236 - app - INFO - Database connection pool created successfully.
2024-11-28 17:19:33,082 - app - INFO - Database connection pool created successfully.
2024-11-28 17:19:52,088 - app - INFO - Database connection pool created successfully.
2024-11-28 17:20:24,199 - app - INFO - Database connection pool created successfully.
2024-11-28 17:20:58,383 - app - INFO - Database connection pool created successfully.
2024-11-28 17:21:32,063 - app - INFO - Database connection pool created successfully.
2024-11-28 17:22:07,571 - app - INFO - Database connection pool created successfully.
2024-11-28 17:22:17,328 - app - INFO - Database connection pool created successfully.
2024-11-28 17:22:33,027 - app - INFO - Database connection pool created successfully.
2024-11-28 17:22:38,620 - app - INFO - Database connection pool created successfully.
2024-11-28 17:23:37,348 - app - INFO - Database connection pool created successfully.
2024-11-28 17:23:49,401 - app - INFO - Database connection pool created successfully.
2024-11-28 17:24:11,819 - app - INFO - Database connection pool created successfully.
2024-11-28 17:24:21,352 - app - INFO - Database connection pool created successfully.
2024-11-28 17:24:43,013 - app - INFO - Database connection pool created successfully.
2024-11-28 17:24:59,710 - app - INFO - Database connection pool created successfully.
2024-11-28 17:25:25,057 - app - INFO - Database connection pool created successfully.
2024-11-28 17:25:40,770 - app - INFO - Database connection pool created successfully.
2024-11-28 17:27:02,939 - app - INFO - Database connection pool created successfully.
2024-11-28 17:27:44,788 - app - INFO - Database connection pool created successfully.
2024-11-28 17:33:09,029 - app - INFO - Database connection pool created successfully.
2024-11-28 17:33:09,192 - app - INFO - Database connection pool created successfully.
2024-11-28 17:35:06,393 - app - INFO - Database connection pool created successfully.
2024-11-28 17:35:06,555 - app - INFO - Database connection pool created successfully.
2024-11-28 17:35:40,418 - app - INFO - Database connection pool created successfully.
2024-11-28 17:35:40,640 - app - INFO - Database connection pool created successfully.
2024-11-28 17:46:46,059 - app - INFO - Database connection pool created successfully.
2024-11-28 17:46:46,255 - app - INFO - Database connection pool created successfully.
2024-11-28 17:46:55,270 - app - ERROR - Error fetching properties: cannot access local variable 'cursor' where it is not associated with a value
2024-11-28 17:47:08,233 - app - ERROR - Authentication error: cannot access local variable 'cursor' where it is not associated with a value
2024-11-28 17:47:09,082 - app - ERROR - Authentication error: cannot access local variable 'cursor' where it is not associated with a value
2024-11-28 17:47:29,430 - app - ERROR - Login error: cannot access local variable 'cursor' where it is not associated with a value
2024-11-28 17:47:41,286 - app - ERROR - Login error: cannot access local variable 'cursor' where it is not associated with a value
2024-11-28 17:48:33,461 - app - INFO - Database connection pool created successfully.
2024-11-28 17:48:33,658 - app - INFO - Database connection pool created successfully.
2024-11-28 17:48:40,250 - app - ERROR - Login error: cannot access local variable 'cursor' where it is not associated with a value
2024-11-28 17:48:52,674 - app - ERROR - Login error: cannot access local variable 'cursor' where it is not associated with a value
2024-11-28 17:54:55,574 - app - INFO - Database connection pool created successfully.
2024-11-28 17:54:55,793 - app - INFO - Database connection pool created successfully.
2024-11-28 17:55:05,062 - app - ERROR - Login error: cannot access local variable 'cursor' where it is not associated with a value
2024-11-28 17:55:49,287 - app - INFO - Database connection pool created successfully.
2024-11-28 17:55:49,601 - app - INFO - Database connection pool created successfully.
2024-11-28 17:55:56,777 - app - INFO - Database connection pool created successfully.
2024-11-28 17:55:56,977 - app - INFO - Database connection pool created successfully.
2024-11-28 17:56:44,849 - app - INFO - Database connection pool created successfully.
2024-11-28 17:56:45,062 - app - INFO - Database connection pool created successfully.
2024-11-28 17:56:54,300 - app - ERROR - Login error: cannot access local variable 'cursor' where it is not associated with a value
2024-11-28 17:57:07,967 - app - ERROR - Login error: cannot access local variable 'cursor' where it is not associated with a value
2024-11-28 17:58:21,515 - app - INFO - Database connection pool created successfully.
2024-11-28 17:58:21,754 - app - INFO - Database connection pool created successfully.
2024-11-28 17:58:35,291 - app - ERROR - Login error: cannot access local variable 'cursor' where it is not associated with a value
2024-11-28 17:58:46,106 - app - INFO - Database connection pool created successfully.
2024-11-28 17:58:46,323 - app - INFO - Database connection pool created successfully.
2024-11-28 17:58:47,239 - app - ERROR - Error fetching properties: cannot access local variable 'cursor' where it is not associated with a value
2024-11-28 17:58:48,739 - app - ERROR - Error fetching properties: cannot access local variable 'cursor' where it is not associated with a value
2024-11-28 17:59:06,351 - app - ERROR - Login error: cannot access local variable 'cursor' where it is not associated with a value
2024-11-28 17:59:25,376 - app - INFO - Database connection pool created successfully.
2024-11-28 17:59:25,651 - app - INFO - Database connection pool created successfully.
2024-11-28 17:59:27,209 - app - ERROR - Login error: cannot access local variable 'cursor' where it is not associated with a value
2024-11-28 18:00:44,468 - app - INFO - Database connection pool created successfully.
2024-11-28 18:01:17,396 - app - INFO - Database connection pool created successfully.
2024-11-28 18:01:17,605 - app - INFO - Database connection pool created successfully.
2024-11-28 18:01:26,181 - app - ERROR - Login error: cannot access local variable 'cursor' where it is not associated with a value
2024-11-28 18:01:34,322 - app - ERROR - Login error: cannot access local variable 'cursor' where it is not associated with a value
2024-11-28 18:01:52,623 - app - ERROR - Login error: cannot access local variable 'cursor' where it is not associated with a value
2024-11-28 18:03:31,308 - app - INFO - Database connection pool created successfully.
2024-11-28 18:03:31,486 - app - INFO - Database connection pool created successfully.
2024-11-28 18:03:34,851 - app - ERROR - Login error: cannot access local variable 'cursor' where it is not associated with a value
2024-11-28 18:03:43,975 - app - ERROR - Login error: cannot access local variable 'cursor' where it is not associated with a value
2024-11-28 18:03:48,160 - app - ERROR - Login error: cannot access local variable 'cursor' where it is not associated with a value
2024-11-28 18:03:50,764 - app - ERROR - Login error: cannot access local variable 'cursor' where it is not associated with a value
2024-11-28 18:04:33,495 - app - INFO - Database connection pool created successfully.
2024-11-28 18:04:33,700 - app - INFO - Database connection pool created successfully.
2024-11-28 18:05:35,188 - app - INFO - Database connection pool created successfully.
2024-11-28 18:05:35,508 - app - INFO - Database connection pool created successfully.
2024-11-28 18:05:43,679 - app - ERROR - Login error: cannot access local variable 'cursor' where it is not associated with a value
2024-11-28 18:08:05,799 - app - INFO - Database connection pool created successfully.
2024-11-28 18:08:05,965 - app - INFO - Database connection pool created successfully.
2024-11-28 18:08:16,681 - app - ERROR - Login error: cannot access local variable 'cursor' where it is not associated with a value
2024-11-28 19:30:37,919 - app - INFO - Database connection pool created successfully.
2024-11-28 19:30:37,984 - app - INFO - Database connection pool created successfully.
2024-11-28 19:30:42,878 - app - ERROR - Login error: cannot access local variable 'cursor' where it is not associated with a value
2024-11-28 19:30:50,816 - app - ERROR - Login error: cannot access local variable 'cursor' where it is not associated with a value
2024-11-28 19:31:08,027 - app - ERROR - Login error: cannot access local variable 'cursor' where it is not associated with a value
2024-11-28 19:33:14,679 - app - INFO - Database connection pool created successfully.
2024-11-28 19:33:14,728 - app - INFO - Database connection pool created successfully.
2024-11-28 19:33:19,154 - app - INFO - Successful login for user: admin
2024-11-28 19:33:19,157 - app - ERROR - Authentication error: '_GeneratorContextManager' object has no attribute 'cursor'
2024-11-28 19:33:21,572 - app - ERROR - Authentication error: '_GeneratorContextManager' object has no attribute 'cursor'
2024-11-28 19:33:21,862 - app - ERROR - Authentication error: '_GeneratorContextManager' object has no attribute 'cursor'
2024-11-28 19:33:24,205 - app - ERROR - Authentication error: '_GeneratorContextManager' object has no attribute 'cursor'
2024-11-28 19:33:24,571 - app - ERROR - Authentication error: '_GeneratorContextManager' object has no attribute 'cursor'
2024-11-28 19:34:31,376 - app - INFO - Database connection pool created successfully.
2024-11-28 19:34:31,420 - app - INFO - Database connection pool created successfully.
2024-11-28 19:34:51,425 - app - INFO - Database connection pool created successfully.
2024-11-28 19:34:51,473 - app - INFO - Database connection pool created successfully.
2024-11-28 19:35:15,833 - app - INFO - Database connection pool created successfully.
2024-11-28 19:35:15,879 - app - INFO - Database connection pool created successfully.
2024-11-28 19:35:19,332 - app - ERROR - Authentication error: '_GeneratorContextManager' object has no attribute 'cursor'
2024-11-28 19:35:21,995 - app - ERROR - Authentication error: '_GeneratorContextManager' object has no attribute 'cursor'
2024-11-28 19:35:22,703 - app - ERROR - Authentication error: '_GeneratorContextManager' object has no attribute 'cursor'
2024-11-28 19:35:30,231 - app - INFO - Database connection pool created successfully.
2024-11-28 19:35:30,273 - app - INFO - Database connection pool created successfully.
2024-11-28 19:37:22,190 - app - INFO - Database connection pool created successfully.
2024-11-28 19:37:22,236 - app - INFO - Database connection pool created successfully.
2024-11-28 19:37:23,699 - app - ERROR - Authentication error: '_GeneratorContextManager' object has no attribute 'cursor'
2024-11-28 19:37:24,966 - app - ERROR - Authentication error: '_GeneratorContextManager' object has no attribute 'cursor'
2024-11-28 19:37:25,621 - app - ERROR - Authentication error: '_GeneratorContextManager' object has no attribute 'cursor'
2024-11-28 19:38:22,063 - app - INFO - Database connection pool created successfully.
2024-11-28 19:38:22,108 - app - INFO - Database connection pool created successfully.
2024-11-28 19:38:24,986 - app - ERROR - Authentication error: '_GeneratorContextManager' object has no attribute 'cursor'
2024-11-28 19:38:26,267 - app - ERROR - Authentication error: '_GeneratorContextManager' object has no attribute 'cursor'
2024-11-28 19:38:26,988 - app - ERROR - Authentication error: '_GeneratorContextManager' object has no attribute 'cursor'
2024-11-28 19:40:18,796 - app - INFO - Database connection pool created successfully.
2024-11-28 19:40:18,841 - app - INFO - Database connection pool created successfully.
2024-11-28 19:40:22,611 - app - ERROR - Authentication error: '_GeneratorContextManager' object has no attribute 'cursor'
2024-11-28 19:40:24,369 - app - ERROR - Authentication error: '_GeneratorContextManager' object has no attribute 'cursor'
2024-11-28 19:40:25,094 - app - ERROR - Authentication error: '_GeneratorContextManager' object has no attribute 'cursor'
2024-11-28 19:40:27,105 - app - ERROR - Authentication error: '_GeneratorContextManager' object has no attribute 'cursor'
2024-11-28 19:40:33,492 - app - ERROR - Error fetching properties: cannot access local variable 'cursor' where it is not associated with a value
2024-11-28 19:40:49,951 - app - ERROR - Login error: '_GeneratorContextManager' object has no attribute 'cursor'
2024-11-28 19:41:53,163 - app - INFO - Database connection pool created successfully.
2024-11-28 19:41:53,226 - app - INFO - Database connection pool created successfully.
2024-11-28 19:42:02,539 - app - ERROR - Authentication error: '_GeneratorContextManager' object has no attribute 'cursor'
2024-11-28 19:42:03,666 - app - ERROR - Authentication error: '_GeneratorContextManager' object has no attribute 'cursor'
2024-11-28 19:42:05,958 - app - ERROR - Authentication error: '_GeneratorContextManager' object has no attribute 'cursor'
2024-11-28 19:42:06,708 - app - ERROR - Authentication error: '_GeneratorContextManager' object has no attribute 'cursor'
2024-11-28 19:42:10,101 - app - INFO - Successful login for user: admin
2024-11-28 19:42:10,105 - app - ERROR - Authentication error: '_GeneratorContextManager' object has no attribute 'cursor'
2024-11-28 19:42:12,241 - app - ERROR - Authentication error: '_GeneratorContextManager' object has no attribute 'cursor'
2024-11-28 19:42:12,988 - app - ERROR - Authentication error: '_GeneratorContextManager' object has no attribute 'cursor'
2024-11-28 19:43:17,064 - app - INFO - Database connection pool created successfully.
2024-11-28 19:43:17,107 - app - INFO - Database connection pool created successfully.
2024-11-28 19:43:20,344 - app - INFO - Database connection pool created successfully.
2024-11-28 19:43:20,383 - app - INFO - Database connection pool created successfully.
2024-11-28 19:43:22,000 - app - ERROR - Authentication error: '_GeneratorContextManager' object has no attribute 'cursor'
2024-11-28 19:43:23,515 - app - ERROR - Authentication error: '_GeneratorContextManager' object has no attribute 'cursor'
2024-11-28 19:43:24,231 - app - ERROR - Authentication error: '_GeneratorContextManager' object has no attribute 'cursor'
2024-11-28 19:43:28,272 - app - ERROR - Error fetching properties: cannot access local variable 'cursor' where it is not associated with a value
2024-11-28 19:43:45,605 - app - ERROR - Login error: cannot access local variable 'cursor' where it is not associated with a value
2024-11-28 21:21:03,667 - app - ERROR - Authentication error: '_GeneratorContextManager' object has no attribute 'cursor'
2024-11-28 21:21:04,453 - app - ERROR - Authentication error: '_GeneratorContextManager' object has no attribute 'cursor'
2024-11-28 21:21:58,408 - app - INFO - Database connection pool created successfully.
2024-11-28 21:21:58,475 - app - INFO - Database connection pool created successfully.
2024-11-28 21:22:12,541 - app - INFO - Database connection pool created successfully.
2024-11-28 21:22:12,607 - app - INFO - Database connection pool created successfully.
2024-11-28 21:26:44,961 - app - INFO - Database connection pool created successfully.
2024-11-28 21:29:31,505 - app - INFO - Database connection pool created successfully.
2024-11-28 21:29:39,248 - app - INFO - Database connection pool created successfully.
2024-11-28 21:29:53,551 - app - ERROR - Authentication error: '_GeneratorContextManager' object has no attribute 'cursor'
2024-11-28 21:29:55,512 - app - ERROR - Authentication error: '_GeneratorContextManager' object has no attribute 'cursor'
2024-11-28 21:29:56,252 - app - ERROR - Authentication error: '_GeneratorContextManager' object has no attribute 'cursor'
2024-11-28 21:33:56,694 - app - INFO - Database connection pool created successfully.
2024-11-28 21:34:45,403 - app - INFO - Database connection pool created successfully.
2024-11-28 21:35:30,168 - app - INFO - Database connection pool created successfully.
2024-11-28 21:35:34,172 - app - ERROR - Dashboard error: 1305 (42000): PROCEDURE real_estate.get_all_properties does not exist
Traceback (most recent call last):
  File "/home/tygilman/School/CS3200/real-estate-htmx-fastapi/.venv/lib/python3.12/site-packages/mysql/connector/connection_cext.py", line 706, in cmd_query
    self._cmysql.query(
_mysql_connector.MySQLInterfaceError: PROCEDURE real_estate.get_all_properties does not exist

The above exception was the direct cause of the following exception:

Traceback (most recent call last):
  File "/home/tygilman/School/CS3200/real-estate-htmx-fastapi/app/routes/admin.py", line 43, in admin_dashboard
    context["properties"] = execute_procedure(conn, 'get_all_properties')
                            ^^^^^^^^^^^^^^^^^^^^^^^^^^^^^^^^^^^^^^^^^^^^^
  File "/home/tygilman/School/CS3200/real-estate-htmx-fastapi/app/core/database.py", line 48, in execute_procedure
    cursor.callproc(procedure_name, params)
  File "/home/tygilman/School/CS3200/real-estate-htmx-fastapi/.venv/lib/python3.12/site-packages/mysql/connector/cursor_cext.py", line 566, in callproc
    result = self._connection.cmd_query(
             ^^^^^^^^^^^^^^^^^^^^^^^^^^^
  File "/home/tygilman/School/CS3200/real-estate-htmx-fastapi/.venv/lib/python3.12/site-packages/mysql/connector/opentelemetry/context_propagation.py", line 97, in wrapper
    return method(cnx, *args, **kwargs)
           ^^^^^^^^^^^^^^^^^^^^^^^^^^^^
  File "/home/tygilman/School/CS3200/real-estate-htmx-fastapi/.venv/lib/python3.12/site-packages/mysql/connector/connection_cext.py", line 714, in cmd_query
    raise get_mysql_exception(
mysql.connector.errors.ProgrammingError: 1305 (42000): PROCEDURE real_estate.get_all_properties does not exist
2024-11-28 21:35:35,070 - app - ERROR - Dashboard error: 1305 (42000): PROCEDURE real_estate.get_all_properties does not exist
Traceback (most recent call last):
  File "/home/tygilman/School/CS3200/real-estate-htmx-fastapi/.venv/lib/python3.12/site-packages/mysql/connector/connection_cext.py", line 706, in cmd_query
    self._cmysql.query(
_mysql_connector.MySQLInterfaceError: PROCEDURE real_estate.get_all_properties does not exist

The above exception was the direct cause of the following exception:

Traceback (most recent call last):
  File "/home/tygilman/School/CS3200/real-estate-htmx-fastapi/app/routes/admin.py", line 43, in admin_dashboard
    context["properties"] = execute_procedure(conn, 'get_all_properties')
                            ^^^^^^^^^^^^^^^^^^^^^^^^^^^^^^^^^^^^^^^^^^^^^
  File "/home/tygilman/School/CS3200/real-estate-htmx-fastapi/app/core/database.py", line 48, in execute_procedure
    cursor.callproc(procedure_name, params)
  File "/home/tygilman/School/CS3200/real-estate-htmx-fastapi/.venv/lib/python3.12/site-packages/mysql/connector/cursor_cext.py", line 566, in callproc
    result = self._connection.cmd_query(
             ^^^^^^^^^^^^^^^^^^^^^^^^^^^
  File "/home/tygilman/School/CS3200/real-estate-htmx-fastapi/.venv/lib/python3.12/site-packages/mysql/connector/opentelemetry/context_propagation.py", line 97, in wrapper
    return method(cnx, *args, **kwargs)
           ^^^^^^^^^^^^^^^^^^^^^^^^^^^^
  File "/home/tygilman/School/CS3200/real-estate-htmx-fastapi/.venv/lib/python3.12/site-packages/mysql/connector/connection_cext.py", line 714, in cmd_query
    raise get_mysql_exception(
mysql.connector.errors.ProgrammingError: 1305 (42000): PROCEDURE real_estate.get_all_properties does not exist
2024-11-28 21:38:07,384 - app - INFO - Database connection pool created successfully.
2024-11-28 21:38:10,054 - app - ERROR - Authentication error: 1305 (42000): PROCEDURE real_estate.get_or_create_admin_role does not exist
2024-11-28 21:38:13,074 - app - ERROR - Authentication error: 1305 (42000): PROCEDURE real_estate.get_or_create_admin_role does not exist
2024-11-28 21:38:13,769 - app - ERROR - Authentication error: 1305 (42000): PROCEDURE real_estate.get_or_create_admin_role does not exist
2024-11-28 21:39:25,796 - app - INFO - Database connection pool created successfully.
2024-11-28 21:39:32,638 - app - ERROR - Error fetching properties: 1305 (42000): PROCEDURE real_estate.get_all_properties_with_details does not exist
2024-11-28 21:39:38,314 - app - ERROR - Dashboard error: 1305 (42000): PROCEDURE real_estate.get_admin_dashboard_stats does not exist
Traceback (most recent call last):
  File "/home/tygilman/School/CS3200/real-estate-htmx-fastapi/.venv/lib/python3.12/site-packages/mysql/connector/connection_cext.py", line 706, in cmd_query
    self._cmysql.query(
_mysql_connector.MySQLInterfaceError: PROCEDURE real_estate.get_admin_dashboard_stats does not exist

The above exception was the direct cause of the following exception:

Traceback (most recent call last):
  File "/home/tygilman/School/CS3200/real-estate-htmx-fastapi/app/routes/admin.py", line 38, in admin_dashboard
    dashboard_stats = execute_procedure(conn, 'get_admin_dashboard_stats')
                      ^^^^^^^^^^^^^^^^^^^^^^^^^^^^^^^^^^^^^^^^^^^^^^^^^^^^
  File "/home/tygilman/School/CS3200/real-estate-htmx-fastapi/app/core/database.py", line 48, in execute_procedure
    cursor.callproc(procedure_name, params)
  File "/home/tygilman/School/CS3200/real-estate-htmx-fastapi/.venv/lib/python3.12/site-packages/mysql/connector/cursor_cext.py", line 566, in callproc
    result = self._connection.cmd_query(
             ^^^^^^^^^^^^^^^^^^^^^^^^^^^
  File "/home/tygilman/School/CS3200/real-estate-htmx-fastapi/.venv/lib/python3.12/site-packages/mysql/connector/opentelemetry/context_propagation.py", line 97, in wrapper
    return method(cnx, *args, **kwargs)
           ^^^^^^^^^^^^^^^^^^^^^^^^^^^^
  File "/home/tygilman/School/CS3200/real-estate-htmx-fastapi/.venv/lib/python3.12/site-packages/mysql/connector/connection_cext.py", line 714, in cmd_query
    raise get_mysql_exception(
mysql.connector.errors.ProgrammingError: 1305 (42000): PROCEDURE real_estate.get_admin_dashboard_stats does not exist
2024-11-28 21:39:38,562 - app - ERROR - Dashboard error: 1305 (42000): PROCEDURE real_estate.get_admin_dashboard_stats does not exist
Traceback (most recent call last):
  File "/home/tygilman/School/CS3200/real-estate-htmx-fastapi/.venv/lib/python3.12/site-packages/mysql/connector/connection_cext.py", line 706, in cmd_query
    self._cmysql.query(
_mysql_connector.MySQLInterfaceError: PROCEDURE real_estate.get_admin_dashboard_stats does not exist

The above exception was the direct cause of the following exception:

Traceback (most recent call last):
  File "/home/tygilman/School/CS3200/real-estate-htmx-fastapi/app/routes/admin.py", line 38, in admin_dashboard
    dashboard_stats = execute_procedure(conn, 'get_admin_dashboard_stats')
                      ^^^^^^^^^^^^^^^^^^^^^^^^^^^^^^^^^^^^^^^^^^^^^^^^^^^^
  File "/home/tygilman/School/CS3200/real-estate-htmx-fastapi/app/core/database.py", line 48, in execute_procedure
    cursor.callproc(procedure_name, params)
  File "/home/tygilman/School/CS3200/real-estate-htmx-fastapi/.venv/lib/python3.12/site-packages/mysql/connector/cursor_cext.py", line 566, in callproc
    result = self._connection.cmd_query(
             ^^^^^^^^^^^^^^^^^^^^^^^^^^^
  File "/home/tygilman/School/CS3200/real-estate-htmx-fastapi/.venv/lib/python3.12/site-packages/mysql/connector/opentelemetry/context_propagation.py", line 97, in wrapper
    return method(cnx, *args, **kwargs)
           ^^^^^^^^^^^^^^^^^^^^^^^^^^^^
  File "/home/tygilman/School/CS3200/real-estate-htmx-fastapi/.venv/lib/python3.12/site-packages/mysql/connector/connection_cext.py", line 714, in cmd_query
    raise get_mysql_exception(
mysql.connector.errors.ProgrammingError: 1305 (42000): PROCEDURE real_estate.get_admin_dashboard_stats does not exist
2024-11-28 21:40:38,153 - app - INFO - Database connection pool created successfully.
2024-11-28 21:40:45,404 - app - ERROR - Dashboard error: 1305 (42000): PROCEDURE real_estate.get_all_agents does not exist
Traceback (most recent call last):
  File "/home/tygilman/School/CS3200/real-estate-htmx-fastapi/.venv/lib/python3.12/site-packages/mysql/connector/connection_cext.py", line 706, in cmd_query
    self._cmysql.query(
_mysql_connector.MySQLInterfaceError: PROCEDURE real_estate.get_all_agents does not exist

The above exception was the direct cause of the following exception:

Traceback (most recent call last):
  File "/home/tygilman/School/CS3200/real-estate-htmx-fastapi/app/routes/admin.py", line 44, in admin_dashboard
    context["agents"] = execute_procedure(conn, 'get_all_agents')
                        ^^^^^^^^^^^^^^^^^^^^^^^^^^^^^^^^^^^^^^^^^
  File "/home/tygilman/School/CS3200/real-estate-htmx-fastapi/app/core/database.py", line 48, in execute_procedure
    cursor.callproc(procedure_name, params)
  File "/home/tygilman/School/CS3200/real-estate-htmx-fastapi/.venv/lib/python3.12/site-packages/mysql/connector/cursor_cext.py", line 566, in callproc
    result = self._connection.cmd_query(
             ^^^^^^^^^^^^^^^^^^^^^^^^^^^
  File "/home/tygilman/School/CS3200/real-estate-htmx-fastapi/.venv/lib/python3.12/site-packages/mysql/connector/opentelemetry/context_propagation.py", line 97, in wrapper
    return method(cnx, *args, **kwargs)
           ^^^^^^^^^^^^^^^^^^^^^^^^^^^^
  File "/home/tygilman/School/CS3200/real-estate-htmx-fastapi/.venv/lib/python3.12/site-packages/mysql/connector/connection_cext.py", line 714, in cmd_query
    raise get_mysql_exception(
mysql.connector.errors.ProgrammingError: 1305 (42000): PROCEDURE real_estate.get_all_agents does not exist
2024-11-28 21:40:47,287 - app - ERROR - Dashboard error: 1305 (42000): PROCEDURE real_estate.get_all_agents does not exist
Traceback (most recent call last):
  File "/home/tygilman/School/CS3200/real-estate-htmx-fastapi/.venv/lib/python3.12/site-packages/mysql/connector/connection_cext.py", line 706, in cmd_query
    self._cmysql.query(
_mysql_connector.MySQLInterfaceError: PROCEDURE real_estate.get_all_agents does not exist

The above exception was the direct cause of the following exception:

Traceback (most recent call last):
  File "/home/tygilman/School/CS3200/real-estate-htmx-fastapi/app/routes/admin.py", line 44, in admin_dashboard
    context["agents"] = execute_procedure(conn, 'get_all_agents')
                        ^^^^^^^^^^^^^^^^^^^^^^^^^^^^^^^^^^^^^^^^^
  File "/home/tygilman/School/CS3200/real-estate-htmx-fastapi/app/core/database.py", line 48, in execute_procedure
    cursor.callproc(procedure_name, params)
  File "/home/tygilman/School/CS3200/real-estate-htmx-fastapi/.venv/lib/python3.12/site-packages/mysql/connector/cursor_cext.py", line 566, in callproc
    result = self._connection.cmd_query(
             ^^^^^^^^^^^^^^^^^^^^^^^^^^^
  File "/home/tygilman/School/CS3200/real-estate-htmx-fastapi/.venv/lib/python3.12/site-packages/mysql/connector/opentelemetry/context_propagation.py", line 97, in wrapper
    return method(cnx, *args, **kwargs)
           ^^^^^^^^^^^^^^^^^^^^^^^^^^^^
  File "/home/tygilman/School/CS3200/real-estate-htmx-fastapi/.venv/lib/python3.12/site-packages/mysql/connector/connection_cext.py", line 714, in cmd_query
    raise get_mysql_exception(
mysql.connector.errors.ProgrammingError: 1305 (42000): PROCEDURE real_estate.get_all_agents does not exist
2024-11-28 21:40:48,645 - app - ERROR - Dashboard error: 1305 (42000): PROCEDURE real_estate.get_all_agents does not exist
Traceback (most recent call last):
  File "/home/tygilman/School/CS3200/real-estate-htmx-fastapi/.venv/lib/python3.12/site-packages/mysql/connector/connection_cext.py", line 706, in cmd_query
    self._cmysql.query(
_mysql_connector.MySQLInterfaceError: PROCEDURE real_estate.get_all_agents does not exist

The above exception was the direct cause of the following exception:

Traceback (most recent call last):
  File "/home/tygilman/School/CS3200/real-estate-htmx-fastapi/app/routes/admin.py", line 44, in admin_dashboard
    context["agents"] = execute_procedure(conn, 'get_all_agents')
                        ^^^^^^^^^^^^^^^^^^^^^^^^^^^^^^^^^^^^^^^^^
  File "/home/tygilman/School/CS3200/real-estate-htmx-fastapi/app/core/database.py", line 48, in execute_procedure
    cursor.callproc(procedure_name, params)
  File "/home/tygilman/School/CS3200/real-estate-htmx-fastapi/.venv/lib/python3.12/site-packages/mysql/connector/cursor_cext.py", line 566, in callproc
    result = self._connection.cmd_query(
             ^^^^^^^^^^^^^^^^^^^^^^^^^^^
  File "/home/tygilman/School/CS3200/real-estate-htmx-fastapi/.venv/lib/python3.12/site-packages/mysql/connector/opentelemetry/context_propagation.py", line 97, in wrapper
    return method(cnx, *args, **kwargs)
           ^^^^^^^^^^^^^^^^^^^^^^^^^^^^
  File "/home/tygilman/School/CS3200/real-estate-htmx-fastapi/.venv/lib/python3.12/site-packages/mysql/connector/connection_cext.py", line 714, in cmd_query
    raise get_mysql_exception(
mysql.connector.errors.ProgrammingError: 1305 (42000): PROCEDURE real_estate.get_all_agents does not exist
2024-11-28 21:41:30,129 - app - INFO - Database connection pool created successfully.
2024-11-28 21:41:43,101 - app - INFO - User logged out: admin
2024-11-28 21:41:43,111 - app - ERROR - Error fetching properties: 1305 (42000): PROCEDURE real_estate.get_all_properties_with_details does not exist
2024-11-28 21:41:47,025 - app - ERROR - Authentication error: 
2024-11-28 21:41:47,792 - app - ERROR - Authentication error: 
2024-11-28 21:42:01,915 - app - INFO - Successful login for user: admin
2024-11-28 21:46:54,443 - app - INFO - Database connection pool created successfully.
2024-11-28 21:46:56,992 - app - ERROR - Failed to create agent: 1305 (42000): PROCEDURE real_estate.create_agent does not exist
Traceback (most recent call last):
  File "/home/tygilman/School/CS3200/real-estate-htmx-fastapi/.venv/lib/python3.12/site-packages/mysql/connector/connection_cext.py", line 706, in cmd_query
    self._cmysql.query(
_mysql_connector.MySQLInterfaceError: PROCEDURE real_estate.create_agent does not exist

The above exception was the direct cause of the following exception:

Traceback (most recent call last):
  File "/home/tygilman/School/CS3200/real-estate-htmx-fastapi/app/routes/admin.py", line 129, in create_agent
    execute_procedure(
  File "/home/tygilman/School/CS3200/real-estate-htmx-fastapi/app/core/database.py", line 48, in execute_procedure
    cursor.callproc(procedure_name, params)
  File "/home/tygilman/School/CS3200/real-estate-htmx-fastapi/.venv/lib/python3.12/site-packages/mysql/connector/cursor_cext.py", line 566, in callproc
    result = self._connection.cmd_query(
             ^^^^^^^^^^^^^^^^^^^^^^^^^^^
  File "/home/tygilman/School/CS3200/real-estate-htmx-fastapi/.venv/lib/python3.12/site-packages/mysql/connector/opentelemetry/context_propagation.py", line 97, in wrapper
    return method(cnx, *args, **kwargs)
           ^^^^^^^^^^^^^^^^^^^^^^^^^^^^
  File "/home/tygilman/School/CS3200/real-estate-htmx-fastapi/.venv/lib/python3.12/site-packages/mysql/connector/connection_cext.py", line 714, in cmd_query
    raise get_mysql_exception(
mysql.connector.errors.ProgrammingError: 1305 (42000): PROCEDURE real_estate.create_agent does not exist
2024-11-28 22:47:57,575 - app - INFO - Database connection pool created successfully.
2024-11-28 22:58:25,071 - app - ERROR - Error fetching properties: 1305 (42000): PROCEDURE real_estate.get_all_properties_with_details does not exist
2024-11-30 16:06:26,841 - app - ERROR - Error fetching properties: 1305 (42000): PROCEDURE real_estate.get_all_properties_with_details does not exist
2024-11-30 16:06:37,992 - app - ERROR - Error fetching properties: 1305 (42000): PROCEDURE real_estate.get_all_properties_with_details does not exist
2024-11-30 16:27:06,342 - app - INFO - Database connection pool created successfully.
2024-11-30 16:27:13,146 - app - INFO - Database connection pool created successfully.
2024-11-30 16:27:37,733 - app - ERROR - Failed to create client: 1146 (42S02): Table 'real_estate.Clients' doesn't exist
Traceback (most recent call last):
  File "/home/tygilman/School/CS3200/real-estate-htmx-fastapi/.venv/lib/python3.12/site-packages/mysql/connector/connection_cext.py", line 706, in cmd_query
    self._cmysql.query(
_mysql_connector.MySQLInterfaceError: Table 'real_estate.Clients' doesn't exist

The above exception was the direct cause of the following exception:

Traceback (most recent call last):
  File "/home/tygilman/School/CS3200/real-estate-htmx-fastapi/app/routes/admin.py", line 88, in create_client
    execute_procedure(
  File "/home/tygilman/School/CS3200/real-estate-htmx-fastapi/app/core/database.py", line 48, in execute_procedure
    cursor.callproc(procedure_name, params)
  File "/home/tygilman/School/CS3200/real-estate-htmx-fastapi/.venv/lib/python3.12/site-packages/mysql/connector/cursor_cext.py", line 566, in callproc
    result = self._connection.cmd_query(
             ^^^^^^^^^^^^^^^^^^^^^^^^^^^
  File "/home/tygilman/School/CS3200/real-estate-htmx-fastapi/.venv/lib/python3.12/site-packages/mysql/connector/opentelemetry/context_propagation.py", line 97, in wrapper
    return method(cnx, *args, **kwargs)
           ^^^^^^^^^^^^^^^^^^^^^^^^^^^^
  File "/home/tygilman/School/CS3200/real-estate-htmx-fastapi/.venv/lib/python3.12/site-packages/mysql/connector/connection_cext.py", line 714, in cmd_query
    raise get_mysql_exception(
mysql.connector.errors.ProgrammingError: 1146 (42S02): Table 'real_estate.Clients' doesn't exist
2024-11-30 16:31:03,667 - app - INFO - Database connection pool created successfully.
2024-11-30 16:33:33,975 - app - INFO - Database connection pool created successfully.
2024-11-30 16:35:48,360 - app - ERROR - Failed to create client: 'None' has no attribute 'split'
Traceback (most recent call last):
  File "/home/tygilman/School/CS3200/real-estate-htmx-fastapi/app/routes/admin.py", line 98, in create_client
    return templates.TemplateResponse(
           ^^^^^^^^^^^^^^^^^^^^^^^^^^^
  File "/home/tygilman/School/CS3200/real-estate-htmx-fastapi/.venv/lib/python3.12/site-packages/starlette/templating.py", line 113, in TemplateResponse
    return _TemplateResponse(
           ^^^^^^^^^^^^^^^^^^
  File "/home/tygilman/School/CS3200/real-estate-htmx-fastapi/.venv/lib/python3.12/site-packages/starlette/templating.py", line 39, in __init__
    content = template.render(context)
              ^^^^^^^^^^^^^^^^^^^^^^^^
  File "/home/tygilman/School/CS3200/real-estate-htmx-fastapi/.venv/lib/python3.12/site-packages/jinja2/environment.py", line 1301, in render
    self.environment.handle_exception()
  File "/home/tygilman/School/CS3200/real-estate-htmx-fastapi/.venv/lib/python3.12/site-packages/jinja2/environment.py", line 936, in handle_exception
    raise rewrite_traceback_stack(source=source)
  File "app/templates/admin/clients/table_row.html", line 22, in top-level template code
    {% for role in client.roles.split(',') if client.roles %}
    ^^^^^^^^^^^^^^^^^^^^^^^^^
  File "/home/tygilman/School/CS3200/real-estate-htmx-fastapi/.venv/lib/python3.12/site-packages/jinja2/utils.py", line 83, in from_obj
    if hasattr(obj, "jinja_pass_arg"):
       ^^^^^^^^^^^^^^^^^^^^^^^^^^^^^^
jinja2.exceptions.UndefinedError: 'None' has no attribute 'split'
2024-11-30 16:35:51,212 - app - ERROR - Failed to create client: 'None' has no attribute 'split'
Traceback (most recent call last):
  File "/home/tygilman/School/CS3200/real-estate-htmx-fastapi/app/routes/admin.py", line 98, in create_client
    return templates.TemplateResponse(
           ^^^^^^^^^^^^^^^^^^^^^^^^^^^
  File "/home/tygilman/School/CS3200/real-estate-htmx-fastapi/.venv/lib/python3.12/site-packages/starlette/templating.py", line 113, in TemplateResponse
    return _TemplateResponse(
           ^^^^^^^^^^^^^^^^^^
  File "/home/tygilman/School/CS3200/real-estate-htmx-fastapi/.venv/lib/python3.12/site-packages/starlette/templating.py", line 39, in __init__
    content = template.render(context)
              ^^^^^^^^^^^^^^^^^^^^^^^^
  File "/home/tygilman/School/CS3200/real-estate-htmx-fastapi/.venv/lib/python3.12/site-packages/jinja2/environment.py", line 1301, in render
    self.environment.handle_exception()
  File "/home/tygilman/School/CS3200/real-estate-htmx-fastapi/.venv/lib/python3.12/site-packages/jinja2/environment.py", line 936, in handle_exception
    raise rewrite_traceback_stack(source=source)
  File "app/templates/admin/clients/table_row.html", line 22, in top-level template code
    {% for role in client.roles.split(',') if client.roles %}
    ^^^^^^^^^^^^^^^^^^^^^^^^^
  File "/home/tygilman/School/CS3200/real-estate-htmx-fastapi/.venv/lib/python3.12/site-packages/jinja2/utils.py", line 83, in from_obj
    if hasattr(obj, "jinja_pass_arg"):
       ^^^^^^^^^^^^^^^^^^^^^^^^^^^^^^
jinja2.exceptions.UndefinedError: 'None' has no attribute 'split'
2024-11-30 16:38:03,659 - app - INFO - Database connection pool created successfully.
2024-11-30 16:38:06,095 - app - ERROR - Dashboard error: No test named 'contains'.
Traceback (most recent call last):
  File "/home/tygilman/School/CS3200/real-estate-htmx-fastapi/app/routes/admin.py", line 49, in admin_dashboard
    return templates.TemplateResponse("admin/dashboard.html", context)
           ^^^^^^^^^^^^^^^^^^^^^^^^^^^^^^^^^^^^^^^^^^^^^^^^^^^^^^^^^^^
  File "/home/tygilman/School/CS3200/real-estate-htmx-fastapi/.venv/lib/python3.12/site-packages/starlette/templating.py", line 113, in TemplateResponse
    return _TemplateResponse(
           ^^^^^^^^^^^^^^^^^^
  File "/home/tygilman/School/CS3200/real-estate-htmx-fastapi/.venv/lib/python3.12/site-packages/starlette/templating.py", line 39, in __init__
    content = template.render(context)
              ^^^^^^^^^^^^^^^^^^^^^^^^
  File "/home/tygilman/School/CS3200/real-estate-htmx-fastapi/.venv/lib/python3.12/site-packages/jinja2/environment.py", line 1301, in render
    self.environment.handle_exception()
  File "/home/tygilman/School/CS3200/real-estate-htmx-fastapi/.venv/lib/python3.12/site-packages/jinja2/environment.py", line 936, in handle_exception
    raise rewrite_traceback_stack(source=source)
  File "app/templates/admin/dashboard.html", line 1, in top-level template code
    {% extends "admin/admin_base.html" %}
    ^^^^^^^^^^^^^^^^^^^^^^^^^
  File "app/templates/admin/admin_base.html", line 1, in top-level template code
    {% extends "base.html" %}
  File "app/templates/base.html", line 26, in top-level template code
    {% block content %}{% endblock %}
    ^^^^^^^^^^^^^^^^^^^^^^^^^
  File "app/templates/admin/dashboard.html", line 23, in block 'content'
    </div>{% include "admin/clients/table.html" %}
    ^^^^^^^^^^^^^^^^^^^^^^^^^
  File "app/templates/admin/clients/table.html", line 10, in top-level template code
    {{ clients|selectattr('roles', 'contains', 'SELLER')|list|length }}
    ^^^^^^^^^^^^^^^^^^^^^^^^^
  File "/home/tygilman/School/CS3200/real-estate-htmx-fastapi/.venv/lib/python3.12/site-packages/jinja2/async_utils.py", line 45, in wrapper
    return normal_func(*args, **kwargs)
           ^^^^^^^^^^^^^^^^^^^^^^^^^^^^
  File "/home/tygilman/School/CS3200/real-estate-htmx-fastapi/.venv/lib/python3.12/site-packages/jinja2/filters.py", line 1324, in sync_do_list
    return list(value)
           ^^^^^^^^^^^
  File "/home/tygilman/School/CS3200/real-estate-htmx-fastapi/.venv/lib/python3.12/site-packages/jinja2/filters.py", line 1765, in select_or_reject
    if func(item):
       ^^^^^^^^^^
  File "/home/tygilman/School/CS3200/real-estate-htmx-fastapi/.venv/lib/python3.12/site-packages/jinja2/filters.py", line 1750, in <lambda>
    return lambda item: modfunc(func(transfunc(item)))
                                ^^^^^^^^^^^^^^^^^^^^^
  File "/home/tygilman/School/CS3200/real-estate-htmx-fastapi/.venv/lib/python3.12/site-packages/jinja2/filters.py", line 1745, in func
    return context.environment.call_test(name, item, args, kwargs)
           ^^^^^^^^^^^^^^^^^^^^^^^^^^^^^^^^^^^^^^^^^^^^^^^^^^^^^^^
  File "/home/tygilman/School/CS3200/real-estate-htmx-fastapi/.venv/lib/python3.12/site-packages/jinja2/environment.py", line 589, in call_test
    return self._filter_test_common(
           ^^^^^^^^^^^^^^^^^^^^^^^^^
  File "/home/tygilman/School/CS3200/real-estate-htmx-fastapi/.venv/lib/python3.12/site-packages/jinja2/environment.py", line 521, in _filter_test_common
    raise TemplateRuntimeError(msg)
jinja2.exceptions.TemplateRuntimeError: No test named 'contains'.
2024-11-30 16:38:06,922 - app - ERROR - Dashboard error: No test named 'contains'.
Traceback (most recent call last):
  File "/home/tygilman/School/CS3200/real-estate-htmx-fastapi/app/routes/admin.py", line 49, in admin_dashboard
    return templates.TemplateResponse("admin/dashboard.html", context)
           ^^^^^^^^^^^^^^^^^^^^^^^^^^^^^^^^^^^^^^^^^^^^^^^^^^^^^^^^^^^
  File "/home/tygilman/School/CS3200/real-estate-htmx-fastapi/.venv/lib/python3.12/site-packages/starlette/templating.py", line 113, in TemplateResponse
    return _TemplateResponse(
           ^^^^^^^^^^^^^^^^^^
  File "/home/tygilman/School/CS3200/real-estate-htmx-fastapi/.venv/lib/python3.12/site-packages/starlette/templating.py", line 39, in __init__
    content = template.render(context)
              ^^^^^^^^^^^^^^^^^^^^^^^^
  File "/home/tygilman/School/CS3200/real-estate-htmx-fastapi/.venv/lib/python3.12/site-packages/jinja2/environment.py", line 1301, in render
    self.environment.handle_exception()
  File "/home/tygilman/School/CS3200/real-estate-htmx-fastapi/.venv/lib/python3.12/site-packages/jinja2/environment.py", line 936, in handle_exception
    raise rewrite_traceback_stack(source=source)
  File "app/templates/admin/dashboard.html", line 1, in top-level template code
    {% extends "admin/admin_base.html" %}
    ^^^^^^^^^^^^^^^^^^^^^^^^^
  File "app/templates/admin/admin_base.html", line 1, in top-level template code
    {% extends "base.html" %}
  File "app/templates/base.html", line 26, in top-level template code
    {% block content %}{% endblock %}
    ^^^^^^^^^^^^^^^^^^^^^^^^^
  File "app/templates/admin/dashboard.html", line 23, in block 'content'
    </div>{% include "admin/clients/table.html" %}
    ^^^^^^^^^^^^^^^^^^^^^^^^^
  File "app/templates/admin/clients/table.html", line 10, in top-level template code
    {{ clients|selectattr('roles', 'contains', 'SELLER')|list|length }}
    ^^^^^^^^^^^^^^^^^^^^^^^^^
  File "/home/tygilman/School/CS3200/real-estate-htmx-fastapi/.venv/lib/python3.12/site-packages/jinja2/async_utils.py", line 45, in wrapper
    return normal_func(*args, **kwargs)
           ^^^^^^^^^^^^^^^^^^^^^^^^^^^^
  File "/home/tygilman/School/CS3200/real-estate-htmx-fastapi/.venv/lib/python3.12/site-packages/jinja2/filters.py", line 1324, in sync_do_list
    return list(value)
           ^^^^^^^^^^^
  File "/home/tygilman/School/CS3200/real-estate-htmx-fastapi/.venv/lib/python3.12/site-packages/jinja2/filters.py", line 1765, in select_or_reject
    if func(item):
       ^^^^^^^^^^
  File "/home/tygilman/School/CS3200/real-estate-htmx-fastapi/.venv/lib/python3.12/site-packages/jinja2/filters.py", line 1750, in <lambda>
    return lambda item: modfunc(func(transfunc(item)))
                                ^^^^^^^^^^^^^^^^^^^^^
  File "/home/tygilman/School/CS3200/real-estate-htmx-fastapi/.venv/lib/python3.12/site-packages/jinja2/filters.py", line 1745, in func
    return context.environment.call_test(name, item, args, kwargs)
           ^^^^^^^^^^^^^^^^^^^^^^^^^^^^^^^^^^^^^^^^^^^^^^^^^^^^^^^
  File "/home/tygilman/School/CS3200/real-estate-htmx-fastapi/.venv/lib/python3.12/site-packages/jinja2/environment.py", line 589, in call_test
    return self._filter_test_common(
           ^^^^^^^^^^^^^^^^^^^^^^^^^
  File "/home/tygilman/School/CS3200/real-estate-htmx-fastapi/.venv/lib/python3.12/site-packages/jinja2/environment.py", line 521, in _filter_test_common
    raise TemplateRuntimeError(msg)
jinja2.exceptions.TemplateRuntimeError: No test named 'contains'.
2024-11-30 16:38:08,227 - app - ERROR - Dashboard error: No test named 'contains'.
Traceback (most recent call last):
  File "/home/tygilman/School/CS3200/real-estate-htmx-fastapi/app/routes/admin.py", line 49, in admin_dashboard
    return templates.TemplateResponse("admin/dashboard.html", context)
           ^^^^^^^^^^^^^^^^^^^^^^^^^^^^^^^^^^^^^^^^^^^^^^^^^^^^^^^^^^^
  File "/home/tygilman/School/CS3200/real-estate-htmx-fastapi/.venv/lib/python3.12/site-packages/starlette/templating.py", line 113, in TemplateResponse
    return _TemplateResponse(
           ^^^^^^^^^^^^^^^^^^
  File "/home/tygilman/School/CS3200/real-estate-htmx-fastapi/.venv/lib/python3.12/site-packages/starlette/templating.py", line 39, in __init__
    content = template.render(context)
              ^^^^^^^^^^^^^^^^^^^^^^^^
  File "/home/tygilman/School/CS3200/real-estate-htmx-fastapi/.venv/lib/python3.12/site-packages/jinja2/environment.py", line 1301, in render
    self.environment.handle_exception()
  File "/home/tygilman/School/CS3200/real-estate-htmx-fastapi/.venv/lib/python3.12/site-packages/jinja2/environment.py", line 936, in handle_exception
    raise rewrite_traceback_stack(source=source)
  File "app/templates/admin/dashboard.html", line 1, in top-level template code
    {% extends "admin/admin_base.html" %}
    ^^^^^^^^^^^^^^^^^^^^^^^^^
  File "app/templates/admin/admin_base.html", line 1, in top-level template code
    {% extends "base.html" %}
  File "app/templates/base.html", line 26, in top-level template code
    {% block content %}{% endblock %}
    ^^^^^^^^^^^^^^^^^^^^^^^^^
  File "app/templates/admin/dashboard.html", line 23, in block 'content'
    </div>{% include "admin/clients/table.html" %}
    ^^^^^^^^^^^^^^^^^^^^^^^^^
  File "app/templates/admin/clients/table.html", line 10, in top-level template code
    {{ clients|selectattr('roles', 'contains', 'SELLER')|list|length }}
    ^^^^^^^^^^^^^^^^^^^^^^^^^
  File "/home/tygilman/School/CS3200/real-estate-htmx-fastapi/.venv/lib/python3.12/site-packages/jinja2/async_utils.py", line 45, in wrapper
    return normal_func(*args, **kwargs)
           ^^^^^^^^^^^^^^^^^^^^^^^^^^^^
  File "/home/tygilman/School/CS3200/real-estate-htmx-fastapi/.venv/lib/python3.12/site-packages/jinja2/filters.py", line 1324, in sync_do_list
    return list(value)
           ^^^^^^^^^^^
  File "/home/tygilman/School/CS3200/real-estate-htmx-fastapi/.venv/lib/python3.12/site-packages/jinja2/filters.py", line 1765, in select_or_reject
    if func(item):
       ^^^^^^^^^^
  File "/home/tygilman/School/CS3200/real-estate-htmx-fastapi/.venv/lib/python3.12/site-packages/jinja2/filters.py", line 1750, in <lambda>
    return lambda item: modfunc(func(transfunc(item)))
                                ^^^^^^^^^^^^^^^^^^^^^
  File "/home/tygilman/School/CS3200/real-estate-htmx-fastapi/.venv/lib/python3.12/site-packages/jinja2/filters.py", line 1745, in func
    return context.environment.call_test(name, item, args, kwargs)
           ^^^^^^^^^^^^^^^^^^^^^^^^^^^^^^^^^^^^^^^^^^^^^^^^^^^^^^^
  File "/home/tygilman/School/CS3200/real-estate-htmx-fastapi/.venv/lib/python3.12/site-packages/jinja2/environment.py", line 589, in call_test
    return self._filter_test_common(
           ^^^^^^^^^^^^^^^^^^^^^^^^^
  File "/home/tygilman/School/CS3200/real-estate-htmx-fastapi/.venv/lib/python3.12/site-packages/jinja2/environment.py", line 521, in _filter_test_common
    raise TemplateRuntimeError(msg)
jinja2.exceptions.TemplateRuntimeError: No test named 'contains'.
2024-11-30 16:40:05,120 - app - ERROR - Failed to create agent: 1305 (42000): PROCEDURE real_estate.create_agent does not exist
Traceback (most recent call last):
  File "/home/tygilman/School/CS3200/real-estate-htmx-fastapi/.venv/lib/python3.12/site-packages/mysql/connector/connection_cext.py", line 706, in cmd_query
    self._cmysql.query(
_mysql_connector.MySQLInterfaceError: PROCEDURE real_estate.create_agent does not exist

The above exception was the direct cause of the following exception:

Traceback (most recent call last):
  File "/home/tygilman/School/CS3200/real-estate-htmx-fastapi/app/routes/admin.py", line 273, in create_agent
    execute_procedure(
  File "/home/tygilman/School/CS3200/real-estate-htmx-fastapi/app/core/database.py", line 48, in execute_procedure
    cursor.callproc(procedure_name, params)
  File "/home/tygilman/School/CS3200/real-estate-htmx-fastapi/.venv/lib/python3.12/site-packages/mysql/connector/cursor_cext.py", line 566, in callproc
    result = self._connection.cmd_query(
             ^^^^^^^^^^^^^^^^^^^^^^^^^^^
  File "/home/tygilman/School/CS3200/real-estate-htmx-fastapi/.venv/lib/python3.12/site-packages/mysql/connector/opentelemetry/context_propagation.py", line 97, in wrapper
    return method(cnx, *args, **kwargs)
           ^^^^^^^^^^^^^^^^^^^^^^^^^^^^
  File "/home/tygilman/School/CS3200/real-estate-htmx-fastapi/.venv/lib/python3.12/site-packages/mysql/connector/connection_cext.py", line 714, in cmd_query
    raise get_mysql_exception(
mysql.connector.errors.ProgrammingError: 1305 (42000): PROCEDURE real_estate.create_agent does not exist
2024-11-30 16:40:05,766 - app - ERROR - Failed to create agent: 1305 (42000): PROCEDURE real_estate.create_agent does not exist
Traceback (most recent call last):
  File "/home/tygilman/School/CS3200/real-estate-htmx-fastapi/.venv/lib/python3.12/site-packages/mysql/connector/connection_cext.py", line 706, in cmd_query
    self._cmysql.query(
_mysql_connector.MySQLInterfaceError: PROCEDURE real_estate.create_agent does not exist

The above exception was the direct cause of the following exception:

Traceback (most recent call last):
  File "/home/tygilman/School/CS3200/real-estate-htmx-fastapi/app/routes/admin.py", line 273, in create_agent
    execute_procedure(
  File "/home/tygilman/School/CS3200/real-estate-htmx-fastapi/app/core/database.py", line 48, in execute_procedure
    cursor.callproc(procedure_name, params)
  File "/home/tygilman/School/CS3200/real-estate-htmx-fastapi/.venv/lib/python3.12/site-packages/mysql/connector/cursor_cext.py", line 566, in callproc
    result = self._connection.cmd_query(
             ^^^^^^^^^^^^^^^^^^^^^^^^^^^
  File "/home/tygilman/School/CS3200/real-estate-htmx-fastapi/.venv/lib/python3.12/site-packages/mysql/connector/opentelemetry/context_propagation.py", line 97, in wrapper
    return method(cnx, *args, **kwargs)
           ^^^^^^^^^^^^^^^^^^^^^^^^^^^^
  File "/home/tygilman/School/CS3200/real-estate-htmx-fastapi/.venv/lib/python3.12/site-packages/mysql/connector/connection_cext.py", line 714, in cmd_query
    raise get_mysql_exception(
mysql.connector.errors.ProgrammingError: 1305 (42000): PROCEDURE real_estate.create_agent does not exist
2024-11-30 16:40:08,206 - app - ERROR - Failed to create agent: 1305 (42000): PROCEDURE real_estate.create_agent does not exist
Traceback (most recent call last):
  File "/home/tygilman/School/CS3200/real-estate-htmx-fastapi/.venv/lib/python3.12/site-packages/mysql/connector/connection_cext.py", line 706, in cmd_query
    self._cmysql.query(
_mysql_connector.MySQLInterfaceError: PROCEDURE real_estate.create_agent does not exist

The above exception was the direct cause of the following exception:

Traceback (most recent call last):
  File "/home/tygilman/School/CS3200/real-estate-htmx-fastapi/app/routes/admin.py", line 273, in create_agent
    execute_procedure(
  File "/home/tygilman/School/CS3200/real-estate-htmx-fastapi/app/core/database.py", line 48, in execute_procedure
    cursor.callproc(procedure_name, params)
  File "/home/tygilman/School/CS3200/real-estate-htmx-fastapi/.venv/lib/python3.12/site-packages/mysql/connector/cursor_cext.py", line 566, in callproc
    result = self._connection.cmd_query(
             ^^^^^^^^^^^^^^^^^^^^^^^^^^^
  File "/home/tygilman/School/CS3200/real-estate-htmx-fastapi/.venv/lib/python3.12/site-packages/mysql/connector/opentelemetry/context_propagation.py", line 97, in wrapper
    return method(cnx, *args, **kwargs)
           ^^^^^^^^^^^^^^^^^^^^^^^^^^^^
  File "/home/tygilman/School/CS3200/real-estate-htmx-fastapi/.venv/lib/python3.12/site-packages/mysql/connector/connection_cext.py", line 714, in cmd_query
    raise get_mysql_exception(
mysql.connector.errors.ProgrammingError: 1305 (42000): PROCEDURE real_estate.create_agent does not exist
2024-11-30 16:40:08,438 - app - ERROR - Failed to create agent: 1305 (42000): PROCEDURE real_estate.create_agent does not exist
Traceback (most recent call last):
  File "/home/tygilman/School/CS3200/real-estate-htmx-fastapi/.venv/lib/python3.12/site-packages/mysql/connector/connection_cext.py", line 706, in cmd_query
    self._cmysql.query(
_mysql_connector.MySQLInterfaceError: PROCEDURE real_estate.create_agent does not exist

The above exception was the direct cause of the following exception:

Traceback (most recent call last):
  File "/home/tygilman/School/CS3200/real-estate-htmx-fastapi/app/routes/admin.py", line 273, in create_agent
    execute_procedure(
  File "/home/tygilman/School/CS3200/real-estate-htmx-fastapi/app/core/database.py", line 48, in execute_procedure
    cursor.callproc(procedure_name, params)
  File "/home/tygilman/School/CS3200/real-estate-htmx-fastapi/.venv/lib/python3.12/site-packages/mysql/connector/cursor_cext.py", line 566, in callproc
    result = self._connection.cmd_query(
             ^^^^^^^^^^^^^^^^^^^^^^^^^^^
  File "/home/tygilman/School/CS3200/real-estate-htmx-fastapi/.venv/lib/python3.12/site-packages/mysql/connector/opentelemetry/context_propagation.py", line 97, in wrapper
    return method(cnx, *args, **kwargs)
           ^^^^^^^^^^^^^^^^^^^^^^^^^^^^
  File "/home/tygilman/School/CS3200/real-estate-htmx-fastapi/.venv/lib/python3.12/site-packages/mysql/connector/connection_cext.py", line 714, in cmd_query
    raise get_mysql_exception(
mysql.connector.errors.ProgrammingError: 1305 (42000): PROCEDURE real_estate.create_agent does not exist
2024-11-30 16:40:09,307 - app - ERROR - Failed to create agent: 1305 (42000): PROCEDURE real_estate.create_agent does not exist
Traceback (most recent call last):
  File "/home/tygilman/School/CS3200/real-estate-htmx-fastapi/.venv/lib/python3.12/site-packages/mysql/connector/connection_cext.py", line 706, in cmd_query
    self._cmysql.query(
_mysql_connector.MySQLInterfaceError: PROCEDURE real_estate.create_agent does not exist

The above exception was the direct cause of the following exception:

Traceback (most recent call last):
  File "/home/tygilman/School/CS3200/real-estate-htmx-fastapi/app/routes/admin.py", line 273, in create_agent
    execute_procedure(
  File "/home/tygilman/School/CS3200/real-estate-htmx-fastapi/app/core/database.py", line 48, in execute_procedure
    cursor.callproc(procedure_name, params)
  File "/home/tygilman/School/CS3200/real-estate-htmx-fastapi/.venv/lib/python3.12/site-packages/mysql/connector/cursor_cext.py", line 566, in callproc
    result = self._connection.cmd_query(
             ^^^^^^^^^^^^^^^^^^^^^^^^^^^
  File "/home/tygilman/School/CS3200/real-estate-htmx-fastapi/.venv/lib/python3.12/site-packages/mysql/connector/opentelemetry/context_propagation.py", line 97, in wrapper
    return method(cnx, *args, **kwargs)
           ^^^^^^^^^^^^^^^^^^^^^^^^^^^^
  File "/home/tygilman/School/CS3200/real-estate-htmx-fastapi/.venv/lib/python3.12/site-packages/mysql/connector/connection_cext.py", line 714, in cmd_query
    raise get_mysql_exception(
mysql.connector.errors.ProgrammingError: 1305 (42000): PROCEDURE real_estate.create_agent does not exist
2024-11-30 16:41:36,438 - app - INFO - Database connection pool created successfully.
2024-11-30 16:41:39,331 - app - ERROR - Authentication error: 1305 (42000): PROCEDURE real_estate.get_or_create_admin_role does not exist
2024-11-30 16:41:40,278 - app - ERROR - Authentication error: 1305 (42000): PROCEDURE real_estate.get_or_create_admin_role does not exist
2024-11-30 16:41:42,759 - app - ERROR - Authentication error: 1305 (42000): PROCEDURE real_estate.get_or_create_admin_role does not exist
2024-11-30 16:41:43,479 - app - ERROR - Authentication error: 1305 (42000): PROCEDURE real_estate.get_or_create_admin_role does not exist
2024-11-30 16:42:10,534 - app - INFO - Database connection pool created successfully.
2024-11-30 16:42:11,986 - app - ERROR - Authentication error: 1305 (42000): PROCEDURE real_estate.get_or_create_admin_role does not exist
2024-11-30 16:42:14,590 - app - ERROR - Authentication error: 1305 (42000): PROCEDURE real_estate.get_or_create_admin_role does not exist
2024-11-30 16:42:15,507 - app - ERROR - Authentication error: 1305 (42000): PROCEDURE real_estate.get_or_create_admin_role does not exist
2024-11-30 16:43:38,564 - app - INFO - Database connection pool created successfully.
2024-11-30 16:43:40,144 - app - ERROR - Authentication error: 1305 (42000): PROCEDURE real_estate.get_or_create_admin_role does not exist
2024-11-30 16:47:24,028 - app - INFO - Database connection pool created successfully.
2024-11-30 16:47:29,282 - app - ERROR - Authentication error: 1305 (42000): PROCEDURE real_estate.get_or_create_admin_role does not exist
2024-11-30 16:47:31,606 - app - ERROR - Authentication error: 1305 (42000): PROCEDURE real_estate.get_or_create_admin_role does not exist
2024-11-30 16:49:32,275 - app - INFO - Database connection pool created successfully.
2024-11-30 16:49:38,983 - app - ERROR - Authentication error: 1305 (42000): PROCEDURE real_estate.get_or_create_admin_role does not exist
2024-11-30 16:50:49,630 - app - INFO - Database connection pool created successfully.
2024-11-30 16:50:52,522 - app - ERROR - Authentication error: 1305 (42000): PROCEDURE real_estate.get_or_create_admin_role does not exist
2024-11-30 16:50:55,458 - app - ERROR - Error fetching properties: 1305 (42000): PROCEDURE real_estate.get_all_properties_with_details does not exist
2024-11-30 16:51:11,246 - app - WARNING - Authentication failed for user admin: Invalid credentials
2024-11-30 16:51:18,993 - app - ERROR - Database error during authentication: 1305 (42000): PROCEDURE real_estate.get_or_create_admin_role does not exist
2024-11-30 16:51:18,993 - app - WARNING - Authentication failed for user admin: System error occurred
2024-11-30 16:51:39,933 - app - ERROR - Database error during authentication: 1305 (42000): PROCEDURE real_estate.get_or_create_admin_role does not exist
2024-11-30 16:51:39,933 - app - WARNING - Authentication failed for user admin: System error occurred
2024-11-30 16:54:14,490 - app - INFO - Database connection pool created successfully.
2024-11-30 16:54:16,557 - app - ERROR - Authentication error: 1305 (42000): PROCEDURE real_estate.get_or_create_admin_role does not exist
2024-11-30 16:54:17,827 - app - ERROR - Authentication error: 1305 (42000): PROCEDURE real_estate.get_or_create_admin_role does not exist
2024-11-30 17:55:20,418 - app - INFO - Database connection pool created successfully.
2024-11-30 17:55:24,962 - app - ERROR - Error fetching properties: 1305 (42000): PROCEDURE real_estate.get_all_properties_with_details does not exist
2024-11-30 17:55:30,182 - app - ERROR - Authentication error: 1305 (42000): PROCEDURE real_estate.get_or_create_admin_role does not exist
2024-11-30 17:55:31,047 - app - ERROR - Authentication error: 1305 (42000): PROCEDURE real_estate.get_or_create_admin_role does not exist
2024-11-30 17:55:32,286 - app - ERROR - Authentication error: 1305 (42000): PROCEDURE real_estate.get_or_create_admin_role does not exist
2024-11-30 17:55:32,795 - app - ERROR - Authentication error: 1305 (42000): PROCEDURE real_estate.get_or_create_admin_role does not exist
2024-11-30 17:57:02,412 - app - INFO - Database connection pool created successfully.
2024-11-30 17:57:06,191 - app - ERROR - Authentication error: 1305 (42000): PROCEDURE real_estate.get_or_create_admin_role does not exist
2024-11-30 17:57:06,632 - app - ERROR - Authentication error: 1305 (42000): PROCEDURE real_estate.get_or_create_admin_role does not exist
2024-11-30 17:59:40,697 - app - INFO - Database connection pool created successfully.
2024-11-30 18:04:59,846 - app - INFO - Database connection pool created successfully.
2024-11-30 18:05:05,530 - app - ERROR - Authentication error: 1305 (42000): PROCEDURE real_estate.get_or_create_admin_role does not exist
2024-11-30 18:05:07,456 - app - ERROR - Authentication error: 1305 (42000): PROCEDURE real_estate.get_or_create_admin_role does not exist
2024-11-30 18:05:08,458 - app - ERROR - Authentication error: 1305 (42000): PROCEDURE real_estate.get_or_create_admin_role does not exist
2024-11-30 18:05:14,846 - app - ERROR - Error fetching properties: 1305 (42000): PROCEDURE real_estate.get_all_properties_with_details does not exist
2024-11-30 18:05:26,332 - app - ERROR - Database error during authentication: 1305 (42000): PROCEDURE real_estate.get_or_create_admin_role does not exist
2024-11-30 18:05:26,333 - app - WARNING - Authentication failed for user admin: System error occurred
2024-11-30 18:08:32,049 - app - INFO - Database connection pool created successfully.
2024-11-30 18:18:05,494 - app - INFO - Database connection pool created successfully.
2024-11-30 18:18:10,339 - app - ERROR - Dashboard error: 1305 (42000): PROCEDURE real_estate.get_all_clients does not exist
Traceback (most recent call last):
  File "/home/tygilman/School/CS3200/real-estate-htmx-fastapi/.venv/lib/python3.12/site-packages/mysql/connector/connection_cext.py", line 706, in cmd_query
    self._cmysql.query(
_mysql_connector.MySQLInterfaceError: PROCEDURE real_estate.get_all_clients does not exist

The above exception was the direct cause of the following exception:

Traceback (most recent call last):
  File "/home/tygilman/School/CS3200/real-estate-htmx-fastapi/app/routes/admin.py", line 24, in admin_dashboard
    clients = execute_procedure(conn, 'get_all_clients')
              ^^^^^^^^^^^^^^^^^^^^^^^^^^^^^^^^^^^^^^^^^^
  File "/home/tygilman/School/CS3200/real-estate-htmx-fastapi/app/core/database.py", line 48, in execute_procedure
    cursor.callproc(procedure_name, params)
  File "/home/tygilman/School/CS3200/real-estate-htmx-fastapi/.venv/lib/python3.12/site-packages/mysql/connector/cursor_cext.py", line 566, in callproc
    result = self._connection.cmd_query(
             ^^^^^^^^^^^^^^^^^^^^^^^^^^^
  File "/home/tygilman/School/CS3200/real-estate-htmx-fastapi/.venv/lib/python3.12/site-packages/mysql/connector/opentelemetry/context_propagation.py", line 97, in wrapper
    return method(cnx, *args, **kwargs)
           ^^^^^^^^^^^^^^^^^^^^^^^^^^^^
  File "/home/tygilman/School/CS3200/real-estate-htmx-fastapi/.venv/lib/python3.12/site-packages/mysql/connector/connection_cext.py", line 714, in cmd_query
    raise get_mysql_exception(
mysql.connector.errors.ProgrammingError: 1305 (42000): PROCEDURE real_estate.get_all_clients does not exist
2024-11-30 18:41:12,883 - app - INFO - Database connection pool created successfully.
2024-11-30 18:41:15,223 - app - ERROR - Dashboard error: 1305 (42000): PROCEDURE real_estate.get_all_clients does not exist
Traceback (most recent call last):
  File "/home/tygilman/School/CS3200/real-estate-htmx-fastapi/.venv/lib/python3.12/site-packages/mysql/connector/connection_cext.py", line 706, in cmd_query
    self._cmysql.query(
_mysql_connector.MySQLInterfaceError: PROCEDURE real_estate.get_all_clients does not exist

The above exception was the direct cause of the following exception:

Traceback (most recent call last):
  File "/home/tygilman/School/CS3200/real-estate-htmx-fastapi/app/routes/admin.py", line 24, in admin_dashboard
    clients = execute_procedure(conn, 'get_all_clients')
              ^^^^^^^^^^^^^^^^^^^^^^^^^^^^^^^^^^^^^^^^^^
  File "/home/tygilman/School/CS3200/real-estate-htmx-fastapi/app/core/database.py", line 48, in execute_procedure
    cursor.callproc(procedure_name, params)
  File "/home/tygilman/School/CS3200/real-estate-htmx-fastapi/.venv/lib/python3.12/site-packages/mysql/connector/cursor_cext.py", line 566, in callproc
    result = self._connection.cmd_query(
             ^^^^^^^^^^^^^^^^^^^^^^^^^^^
  File "/home/tygilman/School/CS3200/real-estate-htmx-fastapi/.venv/lib/python3.12/site-packages/mysql/connector/opentelemetry/context_propagation.py", line 97, in wrapper
    return method(cnx, *args, **kwargs)
           ^^^^^^^^^^^^^^^^^^^^^^^^^^^^
  File "/home/tygilman/School/CS3200/real-estate-htmx-fastapi/.venv/lib/python3.12/site-packages/mysql/connector/connection_cext.py", line 714, in cmd_query
    raise get_mysql_exception(
mysql.connector.errors.ProgrammingError: 1305 (42000): PROCEDURE real_estate.get_all_clients does not exist
2024-11-30 18:41:18,831 - app - ERROR - Dashboard error: 1305 (42000): PROCEDURE real_estate.get_all_clients does not exist
Traceback (most recent call last):
  File "/home/tygilman/School/CS3200/real-estate-htmx-fastapi/.venv/lib/python3.12/site-packages/mysql/connector/connection_cext.py", line 706, in cmd_query
    self._cmysql.query(
_mysql_connector.MySQLInterfaceError: PROCEDURE real_estate.get_all_clients does not exist

The above exception was the direct cause of the following exception:

Traceback (most recent call last):
  File "/home/tygilman/School/CS3200/real-estate-htmx-fastapi/app/routes/admin.py", line 24, in admin_dashboard
    clients = execute_procedure(conn, 'get_all_clients')
              ^^^^^^^^^^^^^^^^^^^^^^^^^^^^^^^^^^^^^^^^^^
  File "/home/tygilman/School/CS3200/real-estate-htmx-fastapi/app/core/database.py", line 48, in execute_procedure
    cursor.callproc(procedure_name, params)
  File "/home/tygilman/School/CS3200/real-estate-htmx-fastapi/.venv/lib/python3.12/site-packages/mysql/connector/cursor_cext.py", line 566, in callproc
    result = self._connection.cmd_query(
             ^^^^^^^^^^^^^^^^^^^^^^^^^^^
  File "/home/tygilman/School/CS3200/real-estate-htmx-fastapi/.venv/lib/python3.12/site-packages/mysql/connector/opentelemetry/context_propagation.py", line 97, in wrapper
    return method(cnx, *args, **kwargs)
           ^^^^^^^^^^^^^^^^^^^^^^^^^^^^
  File "/home/tygilman/School/CS3200/real-estate-htmx-fastapi/.venv/lib/python3.12/site-packages/mysql/connector/connection_cext.py", line 714, in cmd_query
    raise get_mysql_exception(
mysql.connector.errors.ProgrammingError: 1305 (42000): PROCEDURE real_estate.get_all_clients does not exist
2024-11-30 18:41:19,456 - app - ERROR - Dashboard error: 1305 (42000): PROCEDURE real_estate.get_all_clients does not exist
Traceback (most recent call last):
  File "/home/tygilman/School/CS3200/real-estate-htmx-fastapi/.venv/lib/python3.12/site-packages/mysql/connector/connection_cext.py", line 706, in cmd_query
    self._cmysql.query(
_mysql_connector.MySQLInterfaceError: PROCEDURE real_estate.get_all_clients does not exist

The above exception was the direct cause of the following exception:

Traceback (most recent call last):
  File "/home/tygilman/School/CS3200/real-estate-htmx-fastapi/app/routes/admin.py", line 24, in admin_dashboard
    clients = execute_procedure(conn, 'get_all_clients')
              ^^^^^^^^^^^^^^^^^^^^^^^^^^^^^^^^^^^^^^^^^^
  File "/home/tygilman/School/CS3200/real-estate-htmx-fastapi/app/core/database.py", line 48, in execute_procedure
    cursor.callproc(procedure_name, params)
  File "/home/tygilman/School/CS3200/real-estate-htmx-fastapi/.venv/lib/python3.12/site-packages/mysql/connector/cursor_cext.py", line 566, in callproc
    result = self._connection.cmd_query(
             ^^^^^^^^^^^^^^^^^^^^^^^^^^^
  File "/home/tygilman/School/CS3200/real-estate-htmx-fastapi/.venv/lib/python3.12/site-packages/mysql/connector/opentelemetry/context_propagation.py", line 97, in wrapper
    return method(cnx, *args, **kwargs)
           ^^^^^^^^^^^^^^^^^^^^^^^^^^^^
  File "/home/tygilman/School/CS3200/real-estate-htmx-fastapi/.venv/lib/python3.12/site-packages/mysql/connector/connection_cext.py", line 714, in cmd_query
    raise get_mysql_exception(
mysql.connector.errors.ProgrammingError: 1305 (42000): PROCEDURE real_estate.get_all_clients does not exist
2024-11-30 18:45:00,528 - app - INFO - Database connection pool created successfully.
2024-11-30 18:45:03,513 - app - ERROR - Dashboard error: 1054 (42S22): Unknown column 'last_modified' in 'field list'
Traceback (most recent call last):
  File "/home/tygilman/School/CS3200/real-estate-htmx-fastapi/.venv/lib/python3.12/site-packages/mysql/connector/connection_cext.py", line 706, in cmd_query
    self._cmysql.query(
_mysql_connector.MySQLInterfaceError: Unknown column 'last_modified' in 'field list'

The above exception was the direct cause of the following exception:

Traceback (most recent call last):
  File "/home/tygilman/School/CS3200/real-estate-htmx-fastapi/app/routes/admin.py", line 24, in admin_dashboard
    clients = execute_procedure(conn, 'get_all_clients')
              ^^^^^^^^^^^^^^^^^^^^^^^^^^^^^^^^^^^^^^^^^^
  File "/home/tygilman/School/CS3200/real-estate-htmx-fastapi/app/core/database.py", line 48, in execute_procedure
    cursor.callproc(procedure_name, params)
  File "/home/tygilman/School/CS3200/real-estate-htmx-fastapi/.venv/lib/python3.12/site-packages/mysql/connector/cursor_cext.py", line 566, in callproc
    result = self._connection.cmd_query(
             ^^^^^^^^^^^^^^^^^^^^^^^^^^^
  File "/home/tygilman/School/CS3200/real-estate-htmx-fastapi/.venv/lib/python3.12/site-packages/mysql/connector/opentelemetry/context_propagation.py", line 97, in wrapper
    return method(cnx, *args, **kwargs)
           ^^^^^^^^^^^^^^^^^^^^^^^^^^^^
  File "/home/tygilman/School/CS3200/real-estate-htmx-fastapi/.venv/lib/python3.12/site-packages/mysql/connector/connection_cext.py", line 714, in cmd_query
    raise get_mysql_exception(
mysql.connector.errors.ProgrammingError: 1054 (42S22): Unknown column 'last_modified' in 'field list'
2024-11-30 18:47:23,102 - app - INFO - Database connection pool created successfully.
2024-11-30 18:47:25,209 - app - ERROR - Dashboard error: 1305 (42000): PROCEDURE real_estate.get_all_clients does not exist
Traceback (most recent call last):
  File "/home/tygilman/School/CS3200/real-estate-htmx-fastapi/.venv/lib/python3.12/site-packages/mysql/connector/connection_cext.py", line 706, in cmd_query
    self._cmysql.query(
_mysql_connector.MySQLInterfaceError: PROCEDURE real_estate.get_all_clients does not exist

The above exception was the direct cause of the following exception:

Traceback (most recent call last):
  File "/home/tygilman/School/CS3200/real-estate-htmx-fastapi/app/routes/admin.py", line 24, in admin_dashboard
    clients = execute_procedure(conn, 'get_all_clients')
              ^^^^^^^^^^^^^^^^^^^^^^^^^^^^^^^^^^^^^^^^^^
  File "/home/tygilman/School/CS3200/real-estate-htmx-fastapi/app/core/database.py", line 48, in execute_procedure
    cursor.callproc(procedure_name, params)
  File "/home/tygilman/School/CS3200/real-estate-htmx-fastapi/.venv/lib/python3.12/site-packages/mysql/connector/cursor_cext.py", line 566, in callproc
    result = self._connection.cmd_query(
             ^^^^^^^^^^^^^^^^^^^^^^^^^^^
  File "/home/tygilman/School/CS3200/real-estate-htmx-fastapi/.venv/lib/python3.12/site-packages/mysql/connector/opentelemetry/context_propagation.py", line 97, in wrapper
    return method(cnx, *args, **kwargs)
           ^^^^^^^^^^^^^^^^^^^^^^^^^^^^
  File "/home/tygilman/School/CS3200/real-estate-htmx-fastapi/.venv/lib/python3.12/site-packages/mysql/connector/connection_cext.py", line 714, in cmd_query
    raise get_mysql_exception(
mysql.connector.errors.ProgrammingError: 1305 (42000): PROCEDURE real_estate.get_all_clients does not exist
2024-11-30 18:47:26,745 - app - ERROR - Dashboard error: 1305 (42000): PROCEDURE real_estate.get_all_clients does not exist
Traceback (most recent call last):
  File "/home/tygilman/School/CS3200/real-estate-htmx-fastapi/.venv/lib/python3.12/site-packages/mysql/connector/connection_cext.py", line 706, in cmd_query
    self._cmysql.query(
_mysql_connector.MySQLInterfaceError: PROCEDURE real_estate.get_all_clients does not exist

The above exception was the direct cause of the following exception:

Traceback (most recent call last):
  File "/home/tygilman/School/CS3200/real-estate-htmx-fastapi/app/routes/admin.py", line 24, in admin_dashboard
    clients = execute_procedure(conn, 'get_all_clients')
              ^^^^^^^^^^^^^^^^^^^^^^^^^^^^^^^^^^^^^^^^^^
  File "/home/tygilman/School/CS3200/real-estate-htmx-fastapi/app/core/database.py", line 48, in execute_procedure
    cursor.callproc(procedure_name, params)
  File "/home/tygilman/School/CS3200/real-estate-htmx-fastapi/.venv/lib/python3.12/site-packages/mysql/connector/cursor_cext.py", line 566, in callproc
    result = self._connection.cmd_query(
             ^^^^^^^^^^^^^^^^^^^^^^^^^^^
  File "/home/tygilman/School/CS3200/real-estate-htmx-fastapi/.venv/lib/python3.12/site-packages/mysql/connector/opentelemetry/context_propagation.py", line 97, in wrapper
    return method(cnx, *args, **kwargs)
           ^^^^^^^^^^^^^^^^^^^^^^^^^^^^
  File "/home/tygilman/School/CS3200/real-estate-htmx-fastapi/.venv/lib/python3.12/site-packages/mysql/connector/connection_cext.py", line 714, in cmd_query
    raise get_mysql_exception(
mysql.connector.errors.ProgrammingError: 1305 (42000): PROCEDURE real_estate.get_all_clients does not exist
2024-11-30 18:47:27,020 - app - ERROR - Dashboard error: 1305 (42000): PROCEDURE real_estate.get_all_clients does not exist
Traceback (most recent call last):
  File "/home/tygilman/School/CS3200/real-estate-htmx-fastapi/.venv/lib/python3.12/site-packages/mysql/connector/connection_cext.py", line 706, in cmd_query
    self._cmysql.query(
_mysql_connector.MySQLInterfaceError: PROCEDURE real_estate.get_all_clients does not exist

The above exception was the direct cause of the following exception:

Traceback (most recent call last):
  File "/home/tygilman/School/CS3200/real-estate-htmx-fastapi/app/routes/admin.py", line 24, in admin_dashboard
    clients = execute_procedure(conn, 'get_all_clients')
              ^^^^^^^^^^^^^^^^^^^^^^^^^^^^^^^^^^^^^^^^^^
  File "/home/tygilman/School/CS3200/real-estate-htmx-fastapi/app/core/database.py", line 48, in execute_procedure
    cursor.callproc(procedure_name, params)
  File "/home/tygilman/School/CS3200/real-estate-htmx-fastapi/.venv/lib/python3.12/site-packages/mysql/connector/cursor_cext.py", line 566, in callproc
    result = self._connection.cmd_query(
             ^^^^^^^^^^^^^^^^^^^^^^^^^^^
  File "/home/tygilman/School/CS3200/real-estate-htmx-fastapi/.venv/lib/python3.12/site-packages/mysql/connector/opentelemetry/context_propagation.py", line 97, in wrapper
    return method(cnx, *args, **kwargs)
           ^^^^^^^^^^^^^^^^^^^^^^^^^^^^
  File "/home/tygilman/School/CS3200/real-estate-htmx-fastapi/.venv/lib/python3.12/site-packages/mysql/connector/connection_cext.py", line 714, in cmd_query
    raise get_mysql_exception(
mysql.connector.errors.ProgrammingError: 1305 (42000): PROCEDURE real_estate.get_all_clients does not exist
2024-11-30 18:48:44,185 - app - INFO - Database connection pool created successfully.
2024-11-30 18:48:46,419 - app - ERROR - Dashboard error: 1305 (42000): PROCEDURE real_estate.get_all_clients does not exist
Traceback (most recent call last):
  File "/home/tygilman/School/CS3200/real-estate-htmx-fastapi/.venv/lib/python3.12/site-packages/mysql/connector/connection_cext.py", line 706, in cmd_query
    self._cmysql.query(
_mysql_connector.MySQLInterfaceError: PROCEDURE real_estate.get_all_clients does not exist

The above exception was the direct cause of the following exception:

Traceback (most recent call last):
  File "/home/tygilman/School/CS3200/real-estate-htmx-fastapi/app/routes/admin.py", line 24, in admin_dashboard
    clients = execute_procedure(conn, 'get_all_clients')
              ^^^^^^^^^^^^^^^^^^^^^^^^^^^^^^^^^^^^^^^^^^
  File "/home/tygilman/School/CS3200/real-estate-htmx-fastapi/app/core/database.py", line 48, in execute_procedure
    cursor.callproc(procedure_name, params)
  File "/home/tygilman/School/CS3200/real-estate-htmx-fastapi/.venv/lib/python3.12/site-packages/mysql/connector/cursor_cext.py", line 566, in callproc
    result = self._connection.cmd_query(
             ^^^^^^^^^^^^^^^^^^^^^^^^^^^
  File "/home/tygilman/School/CS3200/real-estate-htmx-fastapi/.venv/lib/python3.12/site-packages/mysql/connector/opentelemetry/context_propagation.py", line 97, in wrapper
    return method(cnx, *args, **kwargs)
           ^^^^^^^^^^^^^^^^^^^^^^^^^^^^
  File "/home/tygilman/School/CS3200/real-estate-htmx-fastapi/.venv/lib/python3.12/site-packages/mysql/connector/connection_cext.py", line 714, in cmd_query
    raise get_mysql_exception(
mysql.connector.errors.ProgrammingError: 1305 (42000): PROCEDURE real_estate.get_all_clients does not exist
2024-11-30 18:51:07,070 - app - INFO - Database connection pool created successfully.
2024-11-30 18:51:12,650 - app - INFO - Database connection pool created successfully.
2024-11-30 18:51:14,445 - app - ERROR - Dashboard error: 1305 (42000): PROCEDURE real_estate.get_all_clients does not exist
Traceback (most recent call last):
  File "/home/tygilman/School/CS3200/real-estate-htmx-fastapi/.venv/lib/python3.12/site-packages/mysql/connector/connection_cext.py", line 706, in cmd_query
    self._cmysql.query(
_mysql_connector.MySQLInterfaceError: PROCEDURE real_estate.get_all_clients does not exist

The above exception was the direct cause of the following exception:

Traceback (most recent call last):
  File "/home/tygilman/School/CS3200/real-estate-htmx-fastapi/app/routes/admin.py", line 24, in admin_dashboard
    clients = execute_procedure(conn, 'get_all_clients')
              ^^^^^^^^^^^^^^^^^^^^^^^^^^^^^^^^^^^^^^^^^^
  File "/home/tygilman/School/CS3200/real-estate-htmx-fastapi/app/core/database.py", line 48, in execute_procedure
    cursor.callproc(procedure_name, params)
  File "/home/tygilman/School/CS3200/real-estate-htmx-fastapi/.venv/lib/python3.12/site-packages/mysql/connector/cursor_cext.py", line 566, in callproc
    result = self._connection.cmd_query(
             ^^^^^^^^^^^^^^^^^^^^^^^^^^^
  File "/home/tygilman/School/CS3200/real-estate-htmx-fastapi/.venv/lib/python3.12/site-packages/mysql/connector/opentelemetry/context_propagation.py", line 97, in wrapper
    return method(cnx, *args, **kwargs)
           ^^^^^^^^^^^^^^^^^^^^^^^^^^^^
  File "/home/tygilman/School/CS3200/real-estate-htmx-fastapi/.venv/lib/python3.12/site-packages/mysql/connector/connection_cext.py", line 714, in cmd_query
    raise get_mysql_exception(
mysql.connector.errors.ProgrammingError: 1305 (42000): PROCEDURE real_estate.get_all_clients does not exist
2024-11-30 18:51:15,240 - app - ERROR - Dashboard error: 1305 (42000): PROCEDURE real_estate.get_all_clients does not exist
Traceback (most recent call last):
  File "/home/tygilman/School/CS3200/real-estate-htmx-fastapi/.venv/lib/python3.12/site-packages/mysql/connector/connection_cext.py", line 706, in cmd_query
    self._cmysql.query(
_mysql_connector.MySQLInterfaceError: PROCEDURE real_estate.get_all_clients does not exist

The above exception was the direct cause of the following exception:

Traceback (most recent call last):
  File "/home/tygilman/School/CS3200/real-estate-htmx-fastapi/app/routes/admin.py", line 24, in admin_dashboard
    clients = execute_procedure(conn, 'get_all_clients')
              ^^^^^^^^^^^^^^^^^^^^^^^^^^^^^^^^^^^^^^^^^^
  File "/home/tygilman/School/CS3200/real-estate-htmx-fastapi/app/core/database.py", line 48, in execute_procedure
    cursor.callproc(procedure_name, params)
  File "/home/tygilman/School/CS3200/real-estate-htmx-fastapi/.venv/lib/python3.12/site-packages/mysql/connector/cursor_cext.py", line 566, in callproc
    result = self._connection.cmd_query(
             ^^^^^^^^^^^^^^^^^^^^^^^^^^^
  File "/home/tygilman/School/CS3200/real-estate-htmx-fastapi/.venv/lib/python3.12/site-packages/mysql/connector/opentelemetry/context_propagation.py", line 97, in wrapper
    return method(cnx, *args, **kwargs)
           ^^^^^^^^^^^^^^^^^^^^^^^^^^^^
  File "/home/tygilman/School/CS3200/real-estate-htmx-fastapi/.venv/lib/python3.12/site-packages/mysql/connector/connection_cext.py", line 714, in cmd_query
    raise get_mysql_exception(
mysql.connector.errors.ProgrammingError: 1305 (42000): PROCEDURE real_estate.get_all_clients does not exist
2024-11-30 18:53:45,643 - app - INFO - Database connection pool created successfully.
2024-11-30 18:53:46,370 - app - ERROR - Dashboard error: 1305 (42000): PROCEDURE real_estate.get_all_clients does not exist
Traceback (most recent call last):
  File "/home/tygilman/School/CS3200/real-estate-htmx-fastapi/.venv/lib/python3.12/site-packages/mysql/connector/connection_cext.py", line 706, in cmd_query
    self._cmysql.query(
_mysql_connector.MySQLInterfaceError: PROCEDURE real_estate.get_all_clients does not exist

The above exception was the direct cause of the following exception:

Traceback (most recent call last):
  File "/home/tygilman/School/CS3200/real-estate-htmx-fastapi/app/routes/admin.py", line 24, in admin_dashboard
    clients = execute_procedure(conn, 'get_all_clients')
              ^^^^^^^^^^^^^^^^^^^^^^^^^^^^^^^^^^^^^^^^^^
  File "/home/tygilman/School/CS3200/real-estate-htmx-fastapi/app/core/database.py", line 48, in execute_procedure
    cursor.callproc(procedure_name, params)
  File "/home/tygilman/School/CS3200/real-estate-htmx-fastapi/.venv/lib/python3.12/site-packages/mysql/connector/cursor_cext.py", line 566, in callproc
    result = self._connection.cmd_query(
             ^^^^^^^^^^^^^^^^^^^^^^^^^^^
  File "/home/tygilman/School/CS3200/real-estate-htmx-fastapi/.venv/lib/python3.12/site-packages/mysql/connector/opentelemetry/context_propagation.py", line 97, in wrapper
    return method(cnx, *args, **kwargs)
           ^^^^^^^^^^^^^^^^^^^^^^^^^^^^
  File "/home/tygilman/School/CS3200/real-estate-htmx-fastapi/.venv/lib/python3.12/site-packages/mysql/connector/connection_cext.py", line 714, in cmd_query
    raise get_mysql_exception(
mysql.connector.errors.ProgrammingError: 1305 (42000): PROCEDURE real_estate.get_all_clients does not exist
2024-11-30 18:58:09,394 - app - INFO - Database connection pool created successfully.
2024-11-30 18:58:10,090 - app - ERROR - Dashboard error: 1305 (42000): PROCEDURE real_estate.get_admin_dashboard_stats does not exist
Traceback (most recent call last):
  File "/home/tygilman/School/CS3200/real-estate-htmx-fastapi/.venv/lib/python3.12/site-packages/mysql/connector/connection_cext.py", line 706, in cmd_query
    self._cmysql.query(
_mysql_connector.MySQLInterfaceError: PROCEDURE real_estate.get_admin_dashboard_stats does not exist

The above exception was the direct cause of the following exception:

Traceback (most recent call last):
  File "/home/tygilman/School/CS3200/real-estate-htmx-fastapi/app/routes/admin.py", line 41, in admin_dashboard
    dashboard_stats = execute_procedure(conn, 'get_admin_dashboard_stats')
                      ^^^^^^^^^^^^^^^^^^^^^^^^^^^^^^^^^^^^^^^^^^^^^^^^^^^^
  File "/home/tygilman/School/CS3200/real-estate-htmx-fastapi/app/core/database.py", line 48, in execute_procedure
    cursor.callproc(procedure_name, params)
  File "/home/tygilman/School/CS3200/real-estate-htmx-fastapi/.venv/lib/python3.12/site-packages/mysql/connector/cursor_cext.py", line 566, in callproc
    result = self._connection.cmd_query(
             ^^^^^^^^^^^^^^^^^^^^^^^^^^^
  File "/home/tygilman/School/CS3200/real-estate-htmx-fastapi/.venv/lib/python3.12/site-packages/mysql/connector/opentelemetry/context_propagation.py", line 97, in wrapper
    return method(cnx, *args, **kwargs)
           ^^^^^^^^^^^^^^^^^^^^^^^^^^^^
  File "/home/tygilman/School/CS3200/real-estate-htmx-fastapi/.venv/lib/python3.12/site-packages/mysql/connector/connection_cext.py", line 714, in cmd_query
    raise get_mysql_exception(
mysql.connector.errors.ProgrammingError: 1305 (42000): PROCEDURE real_estate.get_admin_dashboard_stats does not exist
2024-11-30 18:59:19,050 - app - INFO - Database connection pool created successfully.
2024-11-30 18:59:20,998 - app - ERROR - Dashboard error: 1146 (42S02): Table 'real_estate.Users' doesn't exist
Traceback (most recent call last):
  File "/home/tygilman/School/CS3200/real-estate-htmx-fastapi/.venv/lib/python3.12/site-packages/mysql/connector/connection_cext.py", line 706, in cmd_query
    self._cmysql.query(
_mysql_connector.MySQLInterfaceError: Table 'real_estate.Users' doesn't exist

The above exception was the direct cause of the following exception:

Traceback (most recent call last):
  File "/home/tygilman/School/CS3200/real-estate-htmx-fastapi/app/routes/admin.py", line 41, in admin_dashboard
    dashboard_stats = execute_procedure(conn, 'get_admin_dashboard_stats')
                      ^^^^^^^^^^^^^^^^^^^^^^^^^^^^^^^^^^^^^^^^^^^^^^^^^^^^
  File "/home/tygilman/School/CS3200/real-estate-htmx-fastapi/app/core/database.py", line 48, in execute_procedure
    cursor.callproc(procedure_name, params)
  File "/home/tygilman/School/CS3200/real-estate-htmx-fastapi/.venv/lib/python3.12/site-packages/mysql/connector/cursor_cext.py", line 566, in callproc
    result = self._connection.cmd_query(
             ^^^^^^^^^^^^^^^^^^^^^^^^^^^
  File "/home/tygilman/School/CS3200/real-estate-htmx-fastapi/.venv/lib/python3.12/site-packages/mysql/connector/opentelemetry/context_propagation.py", line 97, in wrapper
    return method(cnx, *args, **kwargs)
           ^^^^^^^^^^^^^^^^^^^^^^^^^^^^
  File "/home/tygilman/School/CS3200/real-estate-htmx-fastapi/.venv/lib/python3.12/site-packages/mysql/connector/connection_cext.py", line 714, in cmd_query
    raise get_mysql_exception(
mysql.connector.errors.ProgrammingError: 1146 (42S02): Table 'real_estate.Users' doesn't exist
2024-11-30 18:59:22,630 - app - ERROR - Dashboard error: 1146 (42S02): Table 'real_estate.Users' doesn't exist
Traceback (most recent call last):
  File "/home/tygilman/School/CS3200/real-estate-htmx-fastapi/.venv/lib/python3.12/site-packages/mysql/connector/connection_cext.py", line 706, in cmd_query
    self._cmysql.query(
_mysql_connector.MySQLInterfaceError: Table 'real_estate.Users' doesn't exist

The above exception was the direct cause of the following exception:

Traceback (most recent call last):
  File "/home/tygilman/School/CS3200/real-estate-htmx-fastapi/app/routes/admin.py", line 41, in admin_dashboard
    dashboard_stats = execute_procedure(conn, 'get_admin_dashboard_stats')
                      ^^^^^^^^^^^^^^^^^^^^^^^^^^^^^^^^^^^^^^^^^^^^^^^^^^^^
  File "/home/tygilman/School/CS3200/real-estate-htmx-fastapi/app/core/database.py", line 48, in execute_procedure
    cursor.callproc(procedure_name, params)
  File "/home/tygilman/School/CS3200/real-estate-htmx-fastapi/.venv/lib/python3.12/site-packages/mysql/connector/cursor_cext.py", line 566, in callproc
    result = self._connection.cmd_query(
             ^^^^^^^^^^^^^^^^^^^^^^^^^^^
  File "/home/tygilman/School/CS3200/real-estate-htmx-fastapi/.venv/lib/python3.12/site-packages/mysql/connector/opentelemetry/context_propagation.py", line 97, in wrapper
    return method(cnx, *args, **kwargs)
           ^^^^^^^^^^^^^^^^^^^^^^^^^^^^
  File "/home/tygilman/School/CS3200/real-estate-htmx-fastapi/.venv/lib/python3.12/site-packages/mysql/connector/connection_cext.py", line 714, in cmd_query
    raise get_mysql_exception(
mysql.connector.errors.ProgrammingError: 1146 (42S02): Table 'real_estate.Users' doesn't exist
2024-11-30 19:00:08,079 - app - INFO - Database connection pool created successfully.
2024-11-30 19:00:09,967 - app - ERROR - Dashboard error: 1146 (42S02): Table 'real_estate.Users' doesn't exist
Traceback (most recent call last):
  File "/home/tygilman/School/CS3200/real-estate-htmx-fastapi/.venv/lib/python3.12/site-packages/mysql/connector/connection_cext.py", line 706, in cmd_query
    self._cmysql.query(
_mysql_connector.MySQLInterfaceError: Table 'real_estate.Users' doesn't exist

The above exception was the direct cause of the following exception:

Traceback (most recent call last):
  File "/home/tygilman/School/CS3200/real-estate-htmx-fastapi/app/routes/admin.py", line 41, in admin_dashboard
    dashboard_stats = execute_procedure(conn, 'get_admin_dashboard_stats')
                      ^^^^^^^^^^^^^^^^^^^^^^^^^^^^^^^^^^^^^^^^^^^^^^^^^^^^
  File "/home/tygilman/School/CS3200/real-estate-htmx-fastapi/app/core/database.py", line 48, in execute_procedure
    cursor.callproc(procedure_name, params)
  File "/home/tygilman/School/CS3200/real-estate-htmx-fastapi/.venv/lib/python3.12/site-packages/mysql/connector/cursor_cext.py", line 566, in callproc
    result = self._connection.cmd_query(
             ^^^^^^^^^^^^^^^^^^^^^^^^^^^
  File "/home/tygilman/School/CS3200/real-estate-htmx-fastapi/.venv/lib/python3.12/site-packages/mysql/connector/opentelemetry/context_propagation.py", line 97, in wrapper
    return method(cnx, *args, **kwargs)
           ^^^^^^^^^^^^^^^^^^^^^^^^^^^^
  File "/home/tygilman/School/CS3200/real-estate-htmx-fastapi/.venv/lib/python3.12/site-packages/mysql/connector/connection_cext.py", line 714, in cmd_query
    raise get_mysql_exception(
mysql.connector.errors.ProgrammingError: 1146 (42S02): Table 'real_estate.Users' doesn't exist
2024-11-30 19:01:44,608 - app - INFO - Database connection pool created successfully.
2024-11-30 19:01:51,713 - app - INFO - Database connection pool created successfully.
2024-11-30 19:01:53,423 - app - ERROR - Dashboard error: 1146 (42S02): Table 'real_estate.Properties' doesn't exist
Traceback (most recent call last):
  File "/home/tygilman/School/CS3200/real-estate-htmx-fastapi/.venv/lib/python3.12/site-packages/mysql/connector/connection_cext.py", line 706, in cmd_query
    self._cmysql.query(
_mysql_connector.MySQLInterfaceError: Table 'real_estate.Properties' doesn't exist

The above exception was the direct cause of the following exception:

Traceback (most recent call last):
  File "/home/tygilman/School/CS3200/real-estate-htmx-fastapi/app/routes/admin.py", line 41, in admin_dashboard
    dashboard_stats = execute_procedure(conn, 'get_admin_dashboard_stats')
                      ^^^^^^^^^^^^^^^^^^^^^^^^^^^^^^^^^^^^^^^^^^^^^^^^^^^^
  File "/home/tygilman/School/CS3200/real-estate-htmx-fastapi/app/core/database.py", line 48, in execute_procedure
    cursor.callproc(procedure_name, params)
  File "/home/tygilman/School/CS3200/real-estate-htmx-fastapi/.venv/lib/python3.12/site-packages/mysql/connector/cursor_cext.py", line 566, in callproc
    result = self._connection.cmd_query(
             ^^^^^^^^^^^^^^^^^^^^^^^^^^^
  File "/home/tygilman/School/CS3200/real-estate-htmx-fastapi/.venv/lib/python3.12/site-packages/mysql/connector/opentelemetry/context_propagation.py", line 97, in wrapper
    return method(cnx, *args, **kwargs)
           ^^^^^^^^^^^^^^^^^^^^^^^^^^^^
  File "/home/tygilman/School/CS3200/real-estate-htmx-fastapi/.venv/lib/python3.12/site-packages/mysql/connector/connection_cext.py", line 714, in cmd_query
    raise get_mysql_exception(
mysql.connector.errors.ProgrammingError: 1146 (42S02): Table 'real_estate.Properties' doesn't exist
2024-11-30 19:01:56,241 - app - ERROR - Dashboard error: 1146 (42S02): Table 'real_estate.Properties' doesn't exist
Traceback (most recent call last):
  File "/home/tygilman/School/CS3200/real-estate-htmx-fastapi/.venv/lib/python3.12/site-packages/mysql/connector/connection_cext.py", line 706, in cmd_query
    self._cmysql.query(
_mysql_connector.MySQLInterfaceError: Table 'real_estate.Properties' doesn't exist

The above exception was the direct cause of the following exception:

Traceback (most recent call last):
  File "/home/tygilman/School/CS3200/real-estate-htmx-fastapi/app/routes/admin.py", line 41, in admin_dashboard
    dashboard_stats = execute_procedure(conn, 'get_admin_dashboard_stats')
                      ^^^^^^^^^^^^^^^^^^^^^^^^^^^^^^^^^^^^^^^^^^^^^^^^^^^^
  File "/home/tygilman/School/CS3200/real-estate-htmx-fastapi/app/core/database.py", line 48, in execute_procedure
    cursor.callproc(procedure_name, params)
  File "/home/tygilman/School/CS3200/real-estate-htmx-fastapi/.venv/lib/python3.12/site-packages/mysql/connector/cursor_cext.py", line 566, in callproc
    result = self._connection.cmd_query(
             ^^^^^^^^^^^^^^^^^^^^^^^^^^^
  File "/home/tygilman/School/CS3200/real-estate-htmx-fastapi/.venv/lib/python3.12/site-packages/mysql/connector/opentelemetry/context_propagation.py", line 97, in wrapper
    return method(cnx, *args, **kwargs)
           ^^^^^^^^^^^^^^^^^^^^^^^^^^^^
  File "/home/tygilman/School/CS3200/real-estate-htmx-fastapi/.venv/lib/python3.12/site-packages/mysql/connector/connection_cext.py", line 714, in cmd_query
    raise get_mysql_exception(
mysql.connector.errors.ProgrammingError: 1146 (42S02): Table 'real_estate.Properties' doesn't exist
2024-11-30 19:03:48,016 - app - INFO - Database connection pool created successfully.
2024-11-30 19:03:51,319 - app - ERROR - Authentication error: 1146 (42S02): Table 'real_estate.UserRole' doesn't exist
2024-11-30 19:05:25,238 - app - INFO - Database connection pool created successfully.
2024-11-30 19:05:27,245 - app - ERROR - Dashboard error: 1146 (42S02): Table 'real_estate.Properties' doesn't exist
Traceback (most recent call last):
  File "/home/tygilman/School/CS3200/real-estate-htmx-fastapi/.venv/lib/python3.12/site-packages/mysql/connector/connection_cext.py", line 706, in cmd_query
    self._cmysql.query(
_mysql_connector.MySQLInterfaceError: Table 'real_estate.Properties' doesn't exist

The above exception was the direct cause of the following exception:

Traceback (most recent call last):
  File "/home/tygilman/School/CS3200/real-estate-htmx-fastapi/app/routes/admin.py", line 41, in admin_dashboard
    dashboard_stats = execute_procedure(conn, 'get_admin_dashboard_stats')
                      ^^^^^^^^^^^^^^^^^^^^^^^^^^^^^^^^^^^^^^^^^^^^^^^^^^^^
  File "/home/tygilman/School/CS3200/real-estate-htmx-fastapi/app/core/database.py", line 48, in execute_procedure
    cursor.callproc(procedure_name, params)
  File "/home/tygilman/School/CS3200/real-estate-htmx-fastapi/.venv/lib/python3.12/site-packages/mysql/connector/cursor_cext.py", line 566, in callproc
    result = self._connection.cmd_query(
             ^^^^^^^^^^^^^^^^^^^^^^^^^^^
  File "/home/tygilman/School/CS3200/real-estate-htmx-fastapi/.venv/lib/python3.12/site-packages/mysql/connector/opentelemetry/context_propagation.py", line 97, in wrapper
    return method(cnx, *args, **kwargs)
           ^^^^^^^^^^^^^^^^^^^^^^^^^^^^
  File "/home/tygilman/School/CS3200/real-estate-htmx-fastapi/.venv/lib/python3.12/site-packages/mysql/connector/connection_cext.py", line 714, in cmd_query
    raise get_mysql_exception(
mysql.connector.errors.ProgrammingError: 1146 (42S02): Table 'real_estate.Properties' doesn't exist
2024-11-30 19:05:30,562 - app - ERROR - Dashboard error: 1146 (42S02): Table 'real_estate.Properties' doesn't exist
Traceback (most recent call last):
  File "/home/tygilman/School/CS3200/real-estate-htmx-fastapi/.venv/lib/python3.12/site-packages/mysql/connector/connection_cext.py", line 706, in cmd_query
    self._cmysql.query(
_mysql_connector.MySQLInterfaceError: Table 'real_estate.Properties' doesn't exist

The above exception was the direct cause of the following exception:

Traceback (most recent call last):
  File "/home/tygilman/School/CS3200/real-estate-htmx-fastapi/app/routes/admin.py", line 41, in admin_dashboard
    dashboard_stats = execute_procedure(conn, 'get_admin_dashboard_stats')
                      ^^^^^^^^^^^^^^^^^^^^^^^^^^^^^^^^^^^^^^^^^^^^^^^^^^^^
  File "/home/tygilman/School/CS3200/real-estate-htmx-fastapi/app/core/database.py", line 48, in execute_procedure
    cursor.callproc(procedure_name, params)
  File "/home/tygilman/School/CS3200/real-estate-htmx-fastapi/.venv/lib/python3.12/site-packages/mysql/connector/cursor_cext.py", line 566, in callproc
    result = self._connection.cmd_query(
             ^^^^^^^^^^^^^^^^^^^^^^^^^^^
  File "/home/tygilman/School/CS3200/real-estate-htmx-fastapi/.venv/lib/python3.12/site-packages/mysql/connector/opentelemetry/context_propagation.py", line 97, in wrapper
    return method(cnx, *args, **kwargs)
           ^^^^^^^^^^^^^^^^^^^^^^^^^^^^
  File "/home/tygilman/School/CS3200/real-estate-htmx-fastapi/.venv/lib/python3.12/site-packages/mysql/connector/connection_cext.py", line 714, in cmd_query
    raise get_mysql_exception(
mysql.connector.errors.ProgrammingError: 1146 (42S02): Table 'real_estate.Properties' doesn't exist
2024-11-30 19:10:43,939 - app - INFO - Database connection pool created successfully.
2024-11-30 19:10:44,443 - app - ERROR - Dashboard error: 1305 (42000): PROCEDURE real_estate.get_all_clients does not exist
Traceback (most recent call last):
  File "/home/tygilman/School/CS3200/real-estate-htmx-fastapi/.venv/lib/python3.12/site-packages/mysql/connector/connection_cext.py", line 706, in cmd_query
    self._cmysql.query(
_mysql_connector.MySQLInterfaceError: PROCEDURE real_estate.get_all_clients does not exist

The above exception was the direct cause of the following exception:

Traceback (most recent call last):
  File "/home/tygilman/School/CS3200/real-estate-htmx-fastapi/app/routes/admin.py", line 24, in admin_dashboard
    clients = execute_procedure(conn, 'get_all_clients')
              ^^^^^^^^^^^^^^^^^^^^^^^^^^^^^^^^^^^^^^^^^^
  File "/home/tygilman/School/CS3200/real-estate-htmx-fastapi/app/core/database.py", line 48, in execute_procedure
    cursor.callproc(procedure_name, params)
  File "/home/tygilman/School/CS3200/real-estate-htmx-fastapi/.venv/lib/python3.12/site-packages/mysql/connector/cursor_cext.py", line 566, in callproc
    result = self._connection.cmd_query(
             ^^^^^^^^^^^^^^^^^^^^^^^^^^^
  File "/home/tygilman/School/CS3200/real-estate-htmx-fastapi/.venv/lib/python3.12/site-packages/mysql/connector/opentelemetry/context_propagation.py", line 97, in wrapper
    return method(cnx, *args, **kwargs)
           ^^^^^^^^^^^^^^^^^^^^^^^^^^^^
  File "/home/tygilman/School/CS3200/real-estate-htmx-fastapi/.venv/lib/python3.12/site-packages/mysql/connector/connection_cext.py", line 714, in cmd_query
    raise get_mysql_exception(
mysql.connector.errors.ProgrammingError: 1305 (42000): PROCEDURE real_estate.get_all_clients does not exist
2024-11-30 19:10:46,177 - app - ERROR - Dashboard error: 1305 (42000): PROCEDURE real_estate.get_all_clients does not exist
Traceback (most recent call last):
  File "/home/tygilman/School/CS3200/real-estate-htmx-fastapi/.venv/lib/python3.12/site-packages/mysql/connector/connection_cext.py", line 706, in cmd_query
    self._cmysql.query(
_mysql_connector.MySQLInterfaceError: PROCEDURE real_estate.get_all_clients does not exist

The above exception was the direct cause of the following exception:

Traceback (most recent call last):
  File "/home/tygilman/School/CS3200/real-estate-htmx-fastapi/app/routes/admin.py", line 24, in admin_dashboard
    clients = execute_procedure(conn, 'get_all_clients')
              ^^^^^^^^^^^^^^^^^^^^^^^^^^^^^^^^^^^^^^^^^^
  File "/home/tygilman/School/CS3200/real-estate-htmx-fastapi/app/core/database.py", line 48, in execute_procedure
    cursor.callproc(procedure_name, params)
  File "/home/tygilman/School/CS3200/real-estate-htmx-fastapi/.venv/lib/python3.12/site-packages/mysql/connector/cursor_cext.py", line 566, in callproc
    result = self._connection.cmd_query(
             ^^^^^^^^^^^^^^^^^^^^^^^^^^^
  File "/home/tygilman/School/CS3200/real-estate-htmx-fastapi/.venv/lib/python3.12/site-packages/mysql/connector/opentelemetry/context_propagation.py", line 97, in wrapper
    return method(cnx, *args, **kwargs)
           ^^^^^^^^^^^^^^^^^^^^^^^^^^^^
  File "/home/tygilman/School/CS3200/real-estate-htmx-fastapi/.venv/lib/python3.12/site-packages/mysql/connector/connection_cext.py", line 714, in cmd_query
    raise get_mysql_exception(
mysql.connector.errors.ProgrammingError: 1305 (42000): PROCEDURE real_estate.get_all_clients does not exist
2024-11-30 19:14:31,153 - app - INFO - Database connection pool created successfully.
2024-11-30 19:14:32,734 - app - ERROR - Dashboard error: 1146 (42S02): Table 'real_estate.Properties' doesn't exist
Traceback (most recent call last):
  File "/home/tygilman/School/CS3200/real-estate-htmx-fastapi/.venv/lib/python3.12/site-packages/mysql/connector/connection_cext.py", line 706, in cmd_query
    self._cmysql.query(
_mysql_connector.MySQLInterfaceError: Table 'real_estate.Properties' doesn't exist

The above exception was the direct cause of the following exception:

Traceback (most recent call last):
  File "/home/tygilman/School/CS3200/real-estate-htmx-fastapi/app/routes/admin.py", line 41, in admin_dashboard
    dashboard_stats = execute_procedure(conn, 'get_admin_dashboard_stats')
                      ^^^^^^^^^^^^^^^^^^^^^^^^^^^^^^^^^^^^^^^^^^^^^^^^^^^^
  File "/home/tygilman/School/CS3200/real-estate-htmx-fastapi/app/core/database.py", line 48, in execute_procedure
    cursor.callproc(procedure_name, params)
  File "/home/tygilman/School/CS3200/real-estate-htmx-fastapi/.venv/lib/python3.12/site-packages/mysql/connector/cursor_cext.py", line 566, in callproc
    result = self._connection.cmd_query(
             ^^^^^^^^^^^^^^^^^^^^^^^^^^^
  File "/home/tygilman/School/CS3200/real-estate-htmx-fastapi/.venv/lib/python3.12/site-packages/mysql/connector/opentelemetry/context_propagation.py", line 97, in wrapper
    return method(cnx, *args, **kwargs)
           ^^^^^^^^^^^^^^^^^^^^^^^^^^^^
  File "/home/tygilman/School/CS3200/real-estate-htmx-fastapi/.venv/lib/python3.12/site-packages/mysql/connector/connection_cext.py", line 714, in cmd_query
    raise get_mysql_exception(
mysql.connector.errors.ProgrammingError: 1146 (42S02): Table 'real_estate.Properties' doesn't exist
2024-11-30 19:14:34,004 - app - ERROR - Dashboard error: 1146 (42S02): Table 'real_estate.Properties' doesn't exist
Traceback (most recent call last):
  File "/home/tygilman/School/CS3200/real-estate-htmx-fastapi/.venv/lib/python3.12/site-packages/mysql/connector/connection_cext.py", line 706, in cmd_query
    self._cmysql.query(
_mysql_connector.MySQLInterfaceError: Table 'real_estate.Properties' doesn't exist

The above exception was the direct cause of the following exception:

Traceback (most recent call last):
  File "/home/tygilman/School/CS3200/real-estate-htmx-fastapi/app/routes/admin.py", line 41, in admin_dashboard
    dashboard_stats = execute_procedure(conn, 'get_admin_dashboard_stats')
                      ^^^^^^^^^^^^^^^^^^^^^^^^^^^^^^^^^^^^^^^^^^^^^^^^^^^^
  File "/home/tygilman/School/CS3200/real-estate-htmx-fastapi/app/core/database.py", line 48, in execute_procedure
    cursor.callproc(procedure_name, params)
  File "/home/tygilman/School/CS3200/real-estate-htmx-fastapi/.venv/lib/python3.12/site-packages/mysql/connector/cursor_cext.py", line 566, in callproc
    result = self._connection.cmd_query(
             ^^^^^^^^^^^^^^^^^^^^^^^^^^^
  File "/home/tygilman/School/CS3200/real-estate-htmx-fastapi/.venv/lib/python3.12/site-packages/mysql/connector/opentelemetry/context_propagation.py", line 97, in wrapper
    return method(cnx, *args, **kwargs)
           ^^^^^^^^^^^^^^^^^^^^^^^^^^^^
  File "/home/tygilman/School/CS3200/real-estate-htmx-fastapi/.venv/lib/python3.12/site-packages/mysql/connector/connection_cext.py", line 714, in cmd_query
    raise get_mysql_exception(
mysql.connector.errors.ProgrammingError: 1146 (42S02): Table 'real_estate.Properties' doesn't exist
2024-11-30 19:14:34,865 - app - ERROR - Dashboard error: 1146 (42S02): Table 'real_estate.Properties' doesn't exist
Traceback (most recent call last):
  File "/home/tygilman/School/CS3200/real-estate-htmx-fastapi/.venv/lib/python3.12/site-packages/mysql/connector/connection_cext.py", line 706, in cmd_query
    self._cmysql.query(
_mysql_connector.MySQLInterfaceError: Table 'real_estate.Properties' doesn't exist

The above exception was the direct cause of the following exception:

Traceback (most recent call last):
  File "/home/tygilman/School/CS3200/real-estate-htmx-fastapi/app/routes/admin.py", line 41, in admin_dashboard
    dashboard_stats = execute_procedure(conn, 'get_admin_dashboard_stats')
                      ^^^^^^^^^^^^^^^^^^^^^^^^^^^^^^^^^^^^^^^^^^^^^^^^^^^^
  File "/home/tygilman/School/CS3200/real-estate-htmx-fastapi/app/core/database.py", line 48, in execute_procedure
    cursor.callproc(procedure_name, params)
  File "/home/tygilman/School/CS3200/real-estate-htmx-fastapi/.venv/lib/python3.12/site-packages/mysql/connector/cursor_cext.py", line 566, in callproc
    result = self._connection.cmd_query(
             ^^^^^^^^^^^^^^^^^^^^^^^^^^^
  File "/home/tygilman/School/CS3200/real-estate-htmx-fastapi/.venv/lib/python3.12/site-packages/mysql/connector/opentelemetry/context_propagation.py", line 97, in wrapper
    return method(cnx, *args, **kwargs)
           ^^^^^^^^^^^^^^^^^^^^^^^^^^^^
  File "/home/tygilman/School/CS3200/real-estate-htmx-fastapi/.venv/lib/python3.12/site-packages/mysql/connector/connection_cext.py", line 714, in cmd_query
    raise get_mysql_exception(
mysql.connector.errors.ProgrammingError: 1146 (42S02): Table 'real_estate.Properties' doesn't exist
2024-11-30 19:14:35,770 - app - ERROR - Dashboard error: 1146 (42S02): Table 'real_estate.Properties' doesn't exist
Traceback (most recent call last):
  File "/home/tygilman/School/CS3200/real-estate-htmx-fastapi/.venv/lib/python3.12/site-packages/mysql/connector/connection_cext.py", line 706, in cmd_query
    self._cmysql.query(
_mysql_connector.MySQLInterfaceError: Table 'real_estate.Properties' doesn't exist

The above exception was the direct cause of the following exception:

Traceback (most recent call last):
  File "/home/tygilman/School/CS3200/real-estate-htmx-fastapi/app/routes/admin.py", line 41, in admin_dashboard
    dashboard_stats = execute_procedure(conn, 'get_admin_dashboard_stats')
                      ^^^^^^^^^^^^^^^^^^^^^^^^^^^^^^^^^^^^^^^^^^^^^^^^^^^^
  File "/home/tygilman/School/CS3200/real-estate-htmx-fastapi/app/core/database.py", line 48, in execute_procedure
    cursor.callproc(procedure_name, params)
  File "/home/tygilman/School/CS3200/real-estate-htmx-fastapi/.venv/lib/python3.12/site-packages/mysql/connector/cursor_cext.py", line 566, in callproc
    result = self._connection.cmd_query(
             ^^^^^^^^^^^^^^^^^^^^^^^^^^^
  File "/home/tygilman/School/CS3200/real-estate-htmx-fastapi/.venv/lib/python3.12/site-packages/mysql/connector/opentelemetry/context_propagation.py", line 97, in wrapper
    return method(cnx, *args, **kwargs)
           ^^^^^^^^^^^^^^^^^^^^^^^^^^^^
  File "/home/tygilman/School/CS3200/real-estate-htmx-fastapi/.venv/lib/python3.12/site-packages/mysql/connector/connection_cext.py", line 714, in cmd_query
    raise get_mysql_exception(
mysql.connector.errors.ProgrammingError: 1146 (42S02): Table 'real_estate.Properties' doesn't exist
2024-11-30 19:14:55,094 - app - INFO - Database connection pool created successfully.
2024-11-30 19:14:59,887 - app - ERROR - Dashboard error: 1146 (42S02): Table 'real_estate.Properties' doesn't exist
Traceback (most recent call last):
  File "/home/tygilman/School/CS3200/real-estate-htmx-fastapi/.venv/lib/python3.12/site-packages/mysql/connector/connection_cext.py", line 706, in cmd_query
    self._cmysql.query(
_mysql_connector.MySQLInterfaceError: Table 'real_estate.Properties' doesn't exist

The above exception was the direct cause of the following exception:

Traceback (most recent call last):
  File "/home/tygilman/School/CS3200/real-estate-htmx-fastapi/app/routes/admin.py", line 41, in admin_dashboard
    dashboard_stats = execute_procedure(conn, 'get_admin_dashboard_stats')
                      ^^^^^^^^^^^^^^^^^^^^^^^^^^^^^^^^^^^^^^^^^^^^^^^^^^^^
  File "/home/tygilman/School/CS3200/real-estate-htmx-fastapi/app/core/database.py", line 48, in execute_procedure
    cursor.callproc(procedure_name, params)
  File "/home/tygilman/School/CS3200/real-estate-htmx-fastapi/.venv/lib/python3.12/site-packages/mysql/connector/cursor_cext.py", line 566, in callproc
    result = self._connection.cmd_query(
             ^^^^^^^^^^^^^^^^^^^^^^^^^^^
  File "/home/tygilman/School/CS3200/real-estate-htmx-fastapi/.venv/lib/python3.12/site-packages/mysql/connector/opentelemetry/context_propagation.py", line 97, in wrapper
    return method(cnx, *args, **kwargs)
           ^^^^^^^^^^^^^^^^^^^^^^^^^^^^
  File "/home/tygilman/School/CS3200/real-estate-htmx-fastapi/.venv/lib/python3.12/site-packages/mysql/connector/connection_cext.py", line 714, in cmd_query
    raise get_mysql_exception(
mysql.connector.errors.ProgrammingError: 1146 (42S02): Table 'real_estate.Properties' doesn't exist
2024-11-30 19:16:29,784 - app - INFO - Database connection pool created successfully.
2024-11-30 19:16:32,061 - app - ERROR - Dashboard error: 1146 (42S02): Table 'real_estate.Transactions' doesn't exist
Traceback (most recent call last):
  File "/home/tygilman/School/CS3200/real-estate-htmx-fastapi/.venv/lib/python3.12/site-packages/mysql/connector/connection_cext.py", line 706, in cmd_query
    self._cmysql.query(
_mysql_connector.MySQLInterfaceError: Table 'real_estate.Transactions' doesn't exist

The above exception was the direct cause of the following exception:

Traceback (most recent call last):
  File "/home/tygilman/School/CS3200/real-estate-htmx-fastapi/app/routes/admin.py", line 41, in admin_dashboard
    dashboard_stats = execute_procedure(conn, 'get_admin_dashboard_stats')
                      ^^^^^^^^^^^^^^^^^^^^^^^^^^^^^^^^^^^^^^^^^^^^^^^^^^^^
  File "/home/tygilman/School/CS3200/real-estate-htmx-fastapi/app/core/database.py", line 48, in execute_procedure
    cursor.callproc(procedure_name, params)
  File "/home/tygilman/School/CS3200/real-estate-htmx-fastapi/.venv/lib/python3.12/site-packages/mysql/connector/cursor_cext.py", line 566, in callproc
    result = self._connection.cmd_query(
             ^^^^^^^^^^^^^^^^^^^^^^^^^^^
  File "/home/tygilman/School/CS3200/real-estate-htmx-fastapi/.venv/lib/python3.12/site-packages/mysql/connector/opentelemetry/context_propagation.py", line 97, in wrapper
    return method(cnx, *args, **kwargs)
           ^^^^^^^^^^^^^^^^^^^^^^^^^^^^
  File "/home/tygilman/School/CS3200/real-estate-htmx-fastapi/.venv/lib/python3.12/site-packages/mysql/connector/connection_cext.py", line 714, in cmd_query
    raise get_mysql_exception(
mysql.connector.errors.ProgrammingError: 1146 (42S02): Table 'real_estate.Transactions' doesn't exist
2024-11-30 19:16:34,402 - app - ERROR - Dashboard error: 1146 (42S02): Table 'real_estate.Transactions' doesn't exist
Traceback (most recent call last):
  File "/home/tygilman/School/CS3200/real-estate-htmx-fastapi/.venv/lib/python3.12/site-packages/mysql/connector/connection_cext.py", line 706, in cmd_query
    self._cmysql.query(
_mysql_connector.MySQLInterfaceError: Table 'real_estate.Transactions' doesn't exist

The above exception was the direct cause of the following exception:

Traceback (most recent call last):
  File "/home/tygilman/School/CS3200/real-estate-htmx-fastapi/app/routes/admin.py", line 41, in admin_dashboard
    dashboard_stats = execute_procedure(conn, 'get_admin_dashboard_stats')
                      ^^^^^^^^^^^^^^^^^^^^^^^^^^^^^^^^^^^^^^^^^^^^^^^^^^^^
  File "/home/tygilman/School/CS3200/real-estate-htmx-fastapi/app/core/database.py", line 48, in execute_procedure
    cursor.callproc(procedure_name, params)
  File "/home/tygilman/School/CS3200/real-estate-htmx-fastapi/.venv/lib/python3.12/site-packages/mysql/connector/cursor_cext.py", line 566, in callproc
    result = self._connection.cmd_query(
             ^^^^^^^^^^^^^^^^^^^^^^^^^^^
  File "/home/tygilman/School/CS3200/real-estate-htmx-fastapi/.venv/lib/python3.12/site-packages/mysql/connector/opentelemetry/context_propagation.py", line 97, in wrapper
    return method(cnx, *args, **kwargs)
           ^^^^^^^^^^^^^^^^^^^^^^^^^^^^
  File "/home/tygilman/School/CS3200/real-estate-htmx-fastapi/.venv/lib/python3.12/site-packages/mysql/connector/connection_cext.py", line 714, in cmd_query
    raise get_mysql_exception(
mysql.connector.errors.ProgrammingError: 1146 (42S02): Table 'real_estate.Transactions' doesn't exist
2024-11-30 19:17:19,629 - app - INFO - Database connection pool created successfully.
2024-11-30 19:17:20,387 - app - ERROR - Dashboard error: 1146 (42S02): Table 'real_estate.Transactions' doesn't exist
Traceback (most recent call last):
  File "/home/tygilman/School/CS3200/real-estate-htmx-fastapi/.venv/lib/python3.12/site-packages/mysql/connector/connection_cext.py", line 706, in cmd_query
    self._cmysql.query(
_mysql_connector.MySQLInterfaceError: Table 'real_estate.Transactions' doesn't exist

The above exception was the direct cause of the following exception:

Traceback (most recent call last):
  File "/home/tygilman/School/CS3200/real-estate-htmx-fastapi/app/routes/admin.py", line 41, in admin_dashboard
    dashboard_stats = execute_procedure(conn, 'get_admin_dashboard_stats')
                      ^^^^^^^^^^^^^^^^^^^^^^^^^^^^^^^^^^^^^^^^^^^^^^^^^^^^
  File "/home/tygilman/School/CS3200/real-estate-htmx-fastapi/app/core/database.py", line 48, in execute_procedure
    cursor.callproc(procedure_name, params)
  File "/home/tygilman/School/CS3200/real-estate-htmx-fastapi/.venv/lib/python3.12/site-packages/mysql/connector/cursor_cext.py", line 566, in callproc
    result = self._connection.cmd_query(
             ^^^^^^^^^^^^^^^^^^^^^^^^^^^
  File "/home/tygilman/School/CS3200/real-estate-htmx-fastapi/.venv/lib/python3.12/site-packages/mysql/connector/opentelemetry/context_propagation.py", line 97, in wrapper
    return method(cnx, *args, **kwargs)
           ^^^^^^^^^^^^^^^^^^^^^^^^^^^^
  File "/home/tygilman/School/CS3200/real-estate-htmx-fastapi/.venv/lib/python3.12/site-packages/mysql/connector/connection_cext.py", line 714, in cmd_query
    raise get_mysql_exception(
mysql.connector.errors.ProgrammingError: 1146 (42S02): Table 'real_estate.Transactions' doesn't exist
2024-11-30 19:17:22,383 - app - ERROR - Dashboard error: 1146 (42S02): Table 'real_estate.Transactions' doesn't exist
Traceback (most recent call last):
  File "/home/tygilman/School/CS3200/real-estate-htmx-fastapi/.venv/lib/python3.12/site-packages/mysql/connector/connection_cext.py", line 706, in cmd_query
    self._cmysql.query(
_mysql_connector.MySQLInterfaceError: Table 'real_estate.Transactions' doesn't exist

The above exception was the direct cause of the following exception:

Traceback (most recent call last):
  File "/home/tygilman/School/CS3200/real-estate-htmx-fastapi/app/routes/admin.py", line 41, in admin_dashboard
    dashboard_stats = execute_procedure(conn, 'get_admin_dashboard_stats')
                      ^^^^^^^^^^^^^^^^^^^^^^^^^^^^^^^^^^^^^^^^^^^^^^^^^^^^
  File "/home/tygilman/School/CS3200/real-estate-htmx-fastapi/app/core/database.py", line 48, in execute_procedure
    cursor.callproc(procedure_name, params)
  File "/home/tygilman/School/CS3200/real-estate-htmx-fastapi/.venv/lib/python3.12/site-packages/mysql/connector/cursor_cext.py", line 566, in callproc
    result = self._connection.cmd_query(
             ^^^^^^^^^^^^^^^^^^^^^^^^^^^
  File "/home/tygilman/School/CS3200/real-estate-htmx-fastapi/.venv/lib/python3.12/site-packages/mysql/connector/opentelemetry/context_propagation.py", line 97, in wrapper
    return method(cnx, *args, **kwargs)
           ^^^^^^^^^^^^^^^^^^^^^^^^^^^^
  File "/home/tygilman/School/CS3200/real-estate-htmx-fastapi/.venv/lib/python3.12/site-packages/mysql/connector/connection_cext.py", line 714, in cmd_query
    raise get_mysql_exception(
mysql.connector.errors.ProgrammingError: 1146 (42S02): Table 'real_estate.Transactions' doesn't exist
2024-11-30 19:17:45,891 - app - INFO - Database connection pool created successfully.
2024-11-30 19:17:47,305 - app - ERROR - Dashboard error: 1146 (42S02): Table 'real_estate.Agents' doesn't exist
Traceback (most recent call last):
  File "/home/tygilman/School/CS3200/real-estate-htmx-fastapi/.venv/lib/python3.12/site-packages/mysql/connector/connection_cext.py", line 706, in cmd_query
    self._cmysql.query(
_mysql_connector.MySQLInterfaceError: Table 'real_estate.Agents' doesn't exist

The above exception was the direct cause of the following exception:

Traceback (most recent call last):
  File "/home/tygilman/School/CS3200/real-estate-htmx-fastapi/app/routes/admin.py", line 41, in admin_dashboard
    dashboard_stats = execute_procedure(conn, 'get_admin_dashboard_stats')
                      ^^^^^^^^^^^^^^^^^^^^^^^^^^^^^^^^^^^^^^^^^^^^^^^^^^^^
  File "/home/tygilman/School/CS3200/real-estate-htmx-fastapi/app/core/database.py", line 48, in execute_procedure
    cursor.callproc(procedure_name, params)
  File "/home/tygilman/School/CS3200/real-estate-htmx-fastapi/.venv/lib/python3.12/site-packages/mysql/connector/cursor_cext.py", line 566, in callproc
    result = self._connection.cmd_query(
             ^^^^^^^^^^^^^^^^^^^^^^^^^^^
  File "/home/tygilman/School/CS3200/real-estate-htmx-fastapi/.venv/lib/python3.12/site-packages/mysql/connector/opentelemetry/context_propagation.py", line 97, in wrapper
    return method(cnx, *args, **kwargs)
           ^^^^^^^^^^^^^^^^^^^^^^^^^^^^
  File "/home/tygilman/School/CS3200/real-estate-htmx-fastapi/.venv/lib/python3.12/site-packages/mysql/connector/connection_cext.py", line 714, in cmd_query
    raise get_mysql_exception(
mysql.connector.errors.ProgrammingError: 1146 (42S02): Table 'real_estate.Agents' doesn't exist
2024-11-30 19:18:27,660 - app - INFO - Database connection pool created successfully.
2024-11-30 19:18:29,518 - app - ERROR - Dashboard error: 1305 (42000): PROCEDURE real_estate.get_all_properties does not exist
Traceback (most recent call last):
  File "/home/tygilman/School/CS3200/real-estate-htmx-fastapi/.venv/lib/python3.12/site-packages/mysql/connector/connection_cext.py", line 706, in cmd_query
    self._cmysql.query(
_mysql_connector.MySQLInterfaceError: PROCEDURE real_estate.get_all_properties does not exist

The above exception was the direct cause of the following exception:

Traceback (most recent call last):
  File "/home/tygilman/School/CS3200/real-estate-htmx-fastapi/app/routes/admin.py", line 46, in admin_dashboard
    context["properties"] = execute_procedure(conn, 'get_all_properties')
                            ^^^^^^^^^^^^^^^^^^^^^^^^^^^^^^^^^^^^^^^^^^^^^
  File "/home/tygilman/School/CS3200/real-estate-htmx-fastapi/app/core/database.py", line 48, in execute_procedure
    cursor.callproc(procedure_name, params)
  File "/home/tygilman/School/CS3200/real-estate-htmx-fastapi/.venv/lib/python3.12/site-packages/mysql/connector/cursor_cext.py", line 566, in callproc
    result = self._connection.cmd_query(
             ^^^^^^^^^^^^^^^^^^^^^^^^^^^
  File "/home/tygilman/School/CS3200/real-estate-htmx-fastapi/.venv/lib/python3.12/site-packages/mysql/connector/opentelemetry/context_propagation.py", line 97, in wrapper
    return method(cnx, *args, **kwargs)
           ^^^^^^^^^^^^^^^^^^^^^^^^^^^^
  File "/home/tygilman/School/CS3200/real-estate-htmx-fastapi/.venv/lib/python3.12/site-packages/mysql/connector/connection_cext.py", line 714, in cmd_query
    raise get_mysql_exception(
mysql.connector.errors.ProgrammingError: 1305 (42000): PROCEDURE real_estate.get_all_properties does not exist
2024-11-30 19:20:04,563 - app - INFO - Database connection pool created successfully.
2024-11-30 19:20:06,237 - app - ERROR - Dashboard error: 1318 (42000): Incorrect number of arguments for PROCEDURE real_estate.get_all_agents; expected 4, got 0
Traceback (most recent call last):
  File "/home/tygilman/School/CS3200/real-estate-htmx-fastapi/.venv/lib/python3.12/site-packages/mysql/connector/connection_cext.py", line 706, in cmd_query
    self._cmysql.query(
_mysql_connector.MySQLInterfaceError: Incorrect number of arguments for PROCEDURE real_estate.get_all_agents; expected 4, got 0

The above exception was the direct cause of the following exception:

Traceback (most recent call last):
  File "/home/tygilman/School/CS3200/real-estate-htmx-fastapi/app/routes/admin.py", line 47, in admin_dashboard
    context["agents"] = execute_procedure(conn, 'get_all_agents')
                        ^^^^^^^^^^^^^^^^^^^^^^^^^^^^^^^^^^^^^^^^^
  File "/home/tygilman/School/CS3200/real-estate-htmx-fastapi/app/core/database.py", line 48, in execute_procedure
    cursor.callproc(procedure_name, params)
  File "/home/tygilman/School/CS3200/real-estate-htmx-fastapi/.venv/lib/python3.12/site-packages/mysql/connector/cursor_cext.py", line 566, in callproc
    result = self._connection.cmd_query(
             ^^^^^^^^^^^^^^^^^^^^^^^^^^^
  File "/home/tygilman/School/CS3200/real-estate-htmx-fastapi/.venv/lib/python3.12/site-packages/mysql/connector/opentelemetry/context_propagation.py", line 97, in wrapper
    return method(cnx, *args, **kwargs)
           ^^^^^^^^^^^^^^^^^^^^^^^^^^^^
  File "/home/tygilman/School/CS3200/real-estate-htmx-fastapi/.venv/lib/python3.12/site-packages/mysql/connector/connection_cext.py", line 714, in cmd_query
    raise get_mysql_exception(
mysql.connector.errors.ProgrammingError: 1318 (42000): Incorrect number of arguments for PROCEDURE real_estate.get_all_agents; expected 4, got 0
2024-11-30 19:21:46,708 - app - INFO - Database connection pool created successfully.
2024-11-30 19:21:49,847 - app - ERROR - Dashboard error: 1146 (42S02): Table 'real_estate.Agents' doesn't exist
Traceback (most recent call last):
  File "/home/tygilman/School/CS3200/real-estate-htmx-fastapi/.venv/lib/python3.12/site-packages/mysql/connector/connection_cext.py", line 706, in cmd_query
    self._cmysql.query(
_mysql_connector.MySQLInterfaceError: Table 'real_estate.Agents' doesn't exist

The above exception was the direct cause of the following exception:

Traceback (most recent call last):
  File "/home/tygilman/School/CS3200/real-estate-htmx-fastapi/app/routes/admin.py", line 47, in admin_dashboard
    context["agents"] = execute_procedure(conn, 'get_all_agents')
                        ^^^^^^^^^^^^^^^^^^^^^^^^^^^^^^^^^^^^^^^^^
  File "/home/tygilman/School/CS3200/real-estate-htmx-fastapi/app/core/database.py", line 48, in execute_procedure
    cursor.callproc(procedure_name, params)
  File "/home/tygilman/School/CS3200/real-estate-htmx-fastapi/.venv/lib/python3.12/site-packages/mysql/connector/cursor_cext.py", line 566, in callproc
    result = self._connection.cmd_query(
             ^^^^^^^^^^^^^^^^^^^^^^^^^^^
  File "/home/tygilman/School/CS3200/real-estate-htmx-fastapi/.venv/lib/python3.12/site-packages/mysql/connector/opentelemetry/context_propagation.py", line 97, in wrapper
    return method(cnx, *args, **kwargs)
           ^^^^^^^^^^^^^^^^^^^^^^^^^^^^
  File "/home/tygilman/School/CS3200/real-estate-htmx-fastapi/.venv/lib/python3.12/site-packages/mysql/connector/connection_cext.py", line 714, in cmd_query
    raise get_mysql_exception(
mysql.connector.errors.ProgrammingError: 1146 (42S02): Table 'real_estate.Agents' doesn't exist
2024-11-30 19:22:12,153 - app - INFO - Database connection pool created successfully.
2024-11-30 19:22:15,506 - app - ERROR - Dashboard error: 1054 (42S22): Unknown column 'email' in 'field list'
Traceback (most recent call last):
  File "/home/tygilman/School/CS3200/real-estate-htmx-fastapi/.venv/lib/python3.12/site-packages/mysql/connector/connection_cext.py", line 706, in cmd_query
    self._cmysql.query(
_mysql_connector.MySQLInterfaceError: Unknown column 'email' in 'field list'

The above exception was the direct cause of the following exception:

Traceback (most recent call last):
  File "/home/tygilman/School/CS3200/real-estate-htmx-fastapi/app/routes/admin.py", line 47, in admin_dashboard
    context["agents"] = execute_procedure(conn, 'get_all_agents')
                        ^^^^^^^^^^^^^^^^^^^^^^^^^^^^^^^^^^^^^^^^^
  File "/home/tygilman/School/CS3200/real-estate-htmx-fastapi/app/core/database.py", line 48, in execute_procedure
    cursor.callproc(procedure_name, params)
  File "/home/tygilman/School/CS3200/real-estate-htmx-fastapi/.venv/lib/python3.12/site-packages/mysql/connector/cursor_cext.py", line 566, in callproc
    result = self._connection.cmd_query(
             ^^^^^^^^^^^^^^^^^^^^^^^^^^^
  File "/home/tygilman/School/CS3200/real-estate-htmx-fastapi/.venv/lib/python3.12/site-packages/mysql/connector/opentelemetry/context_propagation.py", line 97, in wrapper
    return method(cnx, *args, **kwargs)
           ^^^^^^^^^^^^^^^^^^^^^^^^^^^^
  File "/home/tygilman/School/CS3200/real-estate-htmx-fastapi/.venv/lib/python3.12/site-packages/mysql/connector/connection_cext.py", line 714, in cmd_query
    raise get_mysql_exception(
mysql.connector.errors.ProgrammingError: 1054 (42S22): Unknown column 'email' in 'field list'
2024-11-30 19:22:17,833 - app - ERROR - Dashboard error: 1054 (42S22): Unknown column 'email' in 'field list'
Traceback (most recent call last):
  File "/home/tygilman/School/CS3200/real-estate-htmx-fastapi/.venv/lib/python3.12/site-packages/mysql/connector/connection_cext.py", line 706, in cmd_query
    self._cmysql.query(
_mysql_connector.MySQLInterfaceError: Unknown column 'email' in 'field list'

The above exception was the direct cause of the following exception:

Traceback (most recent call last):
  File "/home/tygilman/School/CS3200/real-estate-htmx-fastapi/app/routes/admin.py", line 47, in admin_dashboard
    context["agents"] = execute_procedure(conn, 'get_all_agents')
                        ^^^^^^^^^^^^^^^^^^^^^^^^^^^^^^^^^^^^^^^^^
  File "/home/tygilman/School/CS3200/real-estate-htmx-fastapi/app/core/database.py", line 48, in execute_procedure
    cursor.callproc(procedure_name, params)
  File "/home/tygilman/School/CS3200/real-estate-htmx-fastapi/.venv/lib/python3.12/site-packages/mysql/connector/cursor_cext.py", line 566, in callproc
    result = self._connection.cmd_query(
             ^^^^^^^^^^^^^^^^^^^^^^^^^^^
  File "/home/tygilman/School/CS3200/real-estate-htmx-fastapi/.venv/lib/python3.12/site-packages/mysql/connector/opentelemetry/context_propagation.py", line 97, in wrapper
    return method(cnx, *args, **kwargs)
           ^^^^^^^^^^^^^^^^^^^^^^^^^^^^
  File "/home/tygilman/School/CS3200/real-estate-htmx-fastapi/.venv/lib/python3.12/site-packages/mysql/connector/connection_cext.py", line 714, in cmd_query
    raise get_mysql_exception(
mysql.connector.errors.ProgrammingError: 1054 (42S22): Unknown column 'email' in 'field list'
2024-11-30 19:25:57,951 - app - INFO - Database connection pool created successfully.
2024-11-30 19:26:21,506 - app - ERROR - Failed to create client: 1054 (42S22): Unknown column 'last_modified' in 'field list'
Traceback (most recent call last):
  File "/home/tygilman/School/CS3200/real-estate-htmx-fastapi/.venv/lib/python3.12/site-packages/mysql/connector/connection_cext.py", line 706, in cmd_query
    self._cmysql.query(
_mysql_connector.MySQLInterfaceError: Unknown column 'last_modified' in 'field list'

The above exception was the direct cause of the following exception:

Traceback (most recent call last):
  File "/home/tygilman/School/CS3200/real-estate-htmx-fastapi/app/routes/admin.py", line 92, in create_client
    execute_procedure(
  File "/home/tygilman/School/CS3200/real-estate-htmx-fastapi/app/core/database.py", line 48, in execute_procedure
    cursor.callproc(procedure_name, params)
  File "/home/tygilman/School/CS3200/real-estate-htmx-fastapi/.venv/lib/python3.12/site-packages/mysql/connector/cursor_cext.py", line 566, in callproc
    result = self._connection.cmd_query(
             ^^^^^^^^^^^^^^^^^^^^^^^^^^^
  File "/home/tygilman/School/CS3200/real-estate-htmx-fastapi/.venv/lib/python3.12/site-packages/mysql/connector/opentelemetry/context_propagation.py", line 97, in wrapper
    return method(cnx, *args, **kwargs)
           ^^^^^^^^^^^^^^^^^^^^^^^^^^^^
  File "/home/tygilman/School/CS3200/real-estate-htmx-fastapi/.venv/lib/python3.12/site-packages/mysql/connector/connection_cext.py", line 714, in cmd_query
    raise get_mysql_exception(
mysql.connector.errors.ProgrammingError: 1054 (42S22): Unknown column 'last_modified' in 'field list'
2024-11-30 19:27:49,461 - app - INFO - Database connection pool created successfully.
2024-11-30 19:28:02,911 - app - ERROR - Failed to create client: 1054 (42S22): Unknown column 'last_modified' in 'field list'
Traceback (most recent call last):
  File "/home/tygilman/School/CS3200/real-estate-htmx-fastapi/.venv/lib/python3.12/site-packages/mysql/connector/connection_cext.py", line 706, in cmd_query
    self._cmysql.query(
_mysql_connector.MySQLInterfaceError: Unknown column 'last_modified' in 'field list'

The above exception was the direct cause of the following exception:

Traceback (most recent call last):
  File "/home/tygilman/School/CS3200/real-estate-htmx-fastapi/app/routes/admin.py", line 92, in create_client
    execute_procedure(
  File "/home/tygilman/School/CS3200/real-estate-htmx-fastapi/app/core/database.py", line 48, in execute_procedure
    cursor.callproc(procedure_name, params)
  File "/home/tygilman/School/CS3200/real-estate-htmx-fastapi/.venv/lib/python3.12/site-packages/mysql/connector/cursor_cext.py", line 566, in callproc
    result = self._connection.cmd_query(
             ^^^^^^^^^^^^^^^^^^^^^^^^^^^
  File "/home/tygilman/School/CS3200/real-estate-htmx-fastapi/.venv/lib/python3.12/site-packages/mysql/connector/opentelemetry/context_propagation.py", line 97, in wrapper
    return method(cnx, *args, **kwargs)
           ^^^^^^^^^^^^^^^^^^^^^^^^^^^^
  File "/home/tygilman/School/CS3200/real-estate-htmx-fastapi/.venv/lib/python3.12/site-packages/mysql/connector/connection_cext.py", line 714, in cmd_query
    raise get_mysql_exception(
mysql.connector.errors.ProgrammingError: 1054 (42S22): Unknown column 'last_modified' in 'field list'
2024-11-30 19:28:42,043 - app - INFO - Database connection pool created successfully.
2024-11-30 19:28:44,001 - app - ERROR - Failed to create client: 1054 (42S22): Unknown column 'last_modified' in 'field list'
Traceback (most recent call last):
  File "/home/tygilman/School/CS3200/real-estate-htmx-fastapi/.venv/lib/python3.12/site-packages/mysql/connector/connection_cext.py", line 706, in cmd_query
    self._cmysql.query(
_mysql_connector.MySQLInterfaceError: Unknown column 'last_modified' in 'field list'

The above exception was the direct cause of the following exception:

Traceback (most recent call last):
  File "/home/tygilman/School/CS3200/real-estate-htmx-fastapi/app/routes/admin.py", line 92, in create_client
    execute_procedure(
  File "/home/tygilman/School/CS3200/real-estate-htmx-fastapi/app/core/database.py", line 48, in execute_procedure
    cursor.callproc(procedure_name, params)
  File "/home/tygilman/School/CS3200/real-estate-htmx-fastapi/.venv/lib/python3.12/site-packages/mysql/connector/cursor_cext.py", line 566, in callproc
    result = self._connection.cmd_query(
             ^^^^^^^^^^^^^^^^^^^^^^^^^^^
  File "/home/tygilman/School/CS3200/real-estate-htmx-fastapi/.venv/lib/python3.12/site-packages/mysql/connector/opentelemetry/context_propagation.py", line 97, in wrapper
    return method(cnx, *args, **kwargs)
           ^^^^^^^^^^^^^^^^^^^^^^^^^^^^
  File "/home/tygilman/School/CS3200/real-estate-htmx-fastapi/.venv/lib/python3.12/site-packages/mysql/connector/connection_cext.py", line 714, in cmd_query
    raise get_mysql_exception(
mysql.connector.errors.ProgrammingError: 1054 (42S22): Unknown column 'last_modified' in 'field list'
2024-11-30 20:00:30,677 - app - ERROR - Failed to create agent: 1318 (42000): Incorrect number of arguments for PROCEDURE real_estate.create_agent; expected 10, got 8
Traceback (most recent call last):
  File "/home/tygilman/School/CS3200/real-estate-htmx-fastapi/.venv/lib/python3.12/site-packages/mysql/connector/connection_cext.py", line 706, in cmd_query
    self._cmysql.query(
_mysql_connector.MySQLInterfaceError: Incorrect number of arguments for PROCEDURE real_estate.create_agent; expected 10, got 8

The above exception was the direct cause of the following exception:

Traceback (most recent call last):
  File "/home/tygilman/School/CS3200/real-estate-htmx-fastapi/app/routes/admin.py", line 273, in create_agent
    execute_procedure(
  File "/home/tygilman/School/CS3200/real-estate-htmx-fastapi/app/core/database.py", line 48, in execute_procedure
    cursor.callproc(procedure_name, params)
  File "/home/tygilman/School/CS3200/real-estate-htmx-fastapi/.venv/lib/python3.12/site-packages/mysql/connector/cursor_cext.py", line 566, in callproc
    result = self._connection.cmd_query(
             ^^^^^^^^^^^^^^^^^^^^^^^^^^^
  File "/home/tygilman/School/CS3200/real-estate-htmx-fastapi/.venv/lib/python3.12/site-packages/mysql/connector/opentelemetry/context_propagation.py", line 97, in wrapper
    return method(cnx, *args, **kwargs)
           ^^^^^^^^^^^^^^^^^^^^^^^^^^^^
  File "/home/tygilman/School/CS3200/real-estate-htmx-fastapi/.venv/lib/python3.12/site-packages/mysql/connector/connection_cext.py", line 714, in cmd_query
    raise get_mysql_exception(
mysql.connector.errors.ProgrammingError: 1318 (42000): Incorrect number of arguments for PROCEDURE real_estate.create_agent; expected 10, got 8
2024-11-30 20:01:48,163 - app - INFO - Database connection pool created successfully.
2024-11-30 20:02:11,868 - app - ERROR - Failed to create client: 1136 (21S01): Column count doesn't match value count at row 1
Traceback (most recent call last):
  File "/home/tygilman/School/CS3200/real-estate-htmx-fastapi/.venv/lib/python3.12/site-packages/mysql/connector/connection_cext.py", line 706, in cmd_query
    self._cmysql.query(
_mysql_connector.MySQLInterfaceError: Column count doesn't match value count at row 1

The above exception was the direct cause of the following exception:

Traceback (most recent call last):
  File "/home/tygilman/School/CS3200/real-estate-htmx-fastapi/app/routes/admin.py", line 92, in create_client
    execute_procedure(
  File "/home/tygilman/School/CS3200/real-estate-htmx-fastapi/app/core/database.py", line 48, in execute_procedure
    cursor.callproc(procedure_name, params)
  File "/home/tygilman/School/CS3200/real-estate-htmx-fastapi/.venv/lib/python3.12/site-packages/mysql/connector/cursor_cext.py", line 566, in callproc
    result = self._connection.cmd_query(
             ^^^^^^^^^^^^^^^^^^^^^^^^^^^
  File "/home/tygilman/School/CS3200/real-estate-htmx-fastapi/.venv/lib/python3.12/site-packages/mysql/connector/opentelemetry/context_propagation.py", line 97, in wrapper
    return method(cnx, *args, **kwargs)
           ^^^^^^^^^^^^^^^^^^^^^^^^^^^^
  File "/home/tygilman/School/CS3200/real-estate-htmx-fastapi/.venv/lib/python3.12/site-packages/mysql/connector/connection_cext.py", line 714, in cmd_query
    raise get_mysql_exception(
mysql.connector.errors.DataError: 1136 (21S01): Column count doesn't match value count at row 1
2024-11-30 20:04:42,494 - app - INFO - Database connection pool created successfully.
2024-11-30 20:05:32,502 - app - ERROR - Failed to create agent: 1318 (42000): Incorrect number of arguments for PROCEDURE real_estate.create_agent; expected 10, got 8
Traceback (most recent call last):
  File "/home/tygilman/School/CS3200/real-estate-htmx-fastapi/.venv/lib/python3.12/site-packages/mysql/connector/connection_cext.py", line 706, in cmd_query
    self._cmysql.query(
_mysql_connector.MySQLInterfaceError: Incorrect number of arguments for PROCEDURE real_estate.create_agent; expected 10, got 8

The above exception was the direct cause of the following exception:

Traceback (most recent call last):
  File "/home/tygilman/School/CS3200/real-estate-htmx-fastapi/app/routes/admin.py", line 273, in create_agent
    execute_procedure(
  File "/home/tygilman/School/CS3200/real-estate-htmx-fastapi/app/core/database.py", line 48, in execute_procedure
    cursor.callproc(procedure_name, params)
  File "/home/tygilman/School/CS3200/real-estate-htmx-fastapi/.venv/lib/python3.12/site-packages/mysql/connector/cursor_cext.py", line 566, in callproc
    result = self._connection.cmd_query(
             ^^^^^^^^^^^^^^^^^^^^^^^^^^^
  File "/home/tygilman/School/CS3200/real-estate-htmx-fastapi/.venv/lib/python3.12/site-packages/mysql/connector/opentelemetry/context_propagation.py", line 97, in wrapper
    return method(cnx, *args, **kwargs)
           ^^^^^^^^^^^^^^^^^^^^^^^^^^^^
  File "/home/tygilman/School/CS3200/real-estate-htmx-fastapi/.venv/lib/python3.12/site-packages/mysql/connector/connection_cext.py", line 714, in cmd_query
    raise get_mysql_exception(
mysql.connector.errors.ProgrammingError: 1318 (42000): Incorrect number of arguments for PROCEDURE real_estate.create_agent; expected 10, got 8
2024-11-30 20:08:54,106 - app - INFO - Database connection pool created successfully.
2024-11-30 20:09:47,279 - app - ERROR - Failed to create agent: 1644 (45000): Invalid email format
Traceback (most recent call last):
  File "/home/tygilman/School/CS3200/real-estate-htmx-fastapi/.venv/lib/python3.12/site-packages/mysql/connector/connection_cext.py", line 706, in cmd_query
    self._cmysql.query(
_mysql_connector.MySQLInterfaceError: Invalid email format

The above exception was the direct cause of the following exception:

Traceback (most recent call last):
  File "/home/tygilman/School/CS3200/real-estate-htmx-fastapi/app/routes/admin.py", line 273, in create_agent
    execute_procedure(
  File "/home/tygilman/School/CS3200/real-estate-htmx-fastapi/app/core/database.py", line 48, in execute_procedure
    cursor.callproc(procedure_name, params)
  File "/home/tygilman/School/CS3200/real-estate-htmx-fastapi/.venv/lib/python3.12/site-packages/mysql/connector/cursor_cext.py", line 566, in callproc
    result = self._connection.cmd_query(
             ^^^^^^^^^^^^^^^^^^^^^^^^^^^
  File "/home/tygilman/School/CS3200/real-estate-htmx-fastapi/.venv/lib/python3.12/site-packages/mysql/connector/opentelemetry/context_propagation.py", line 97, in wrapper
    return method(cnx, *args, **kwargs)
           ^^^^^^^^^^^^^^^^^^^^^^^^^^^^
  File "/home/tygilman/School/CS3200/real-estate-htmx-fastapi/.venv/lib/python3.12/site-packages/mysql/connector/connection_cext.py", line 714, in cmd_query
    raise get_mysql_exception(
mysql.connector.errors.DatabaseError: 1644 (45000): Invalid email format
2024-11-30 20:09:55,576 - app - ERROR - Failed to create agent: 1452 (23000): Cannot add or update a child row: a foreign key constraint fails (`real_estate`.`Agent`, CONSTRAINT `Agent_ibfk_1` FOREIGN KEY (`broker_id`) REFERENCES `Brokerage` (`broker_id`))
Traceback (most recent call last):
  File "/home/tygilman/School/CS3200/real-estate-htmx-fastapi/.venv/lib/python3.12/site-packages/mysql/connector/connection_cext.py", line 706, in cmd_query
    self._cmysql.query(
_mysql_connector.MySQLInterfaceError: Cannot add or update a child row: a foreign key constraint fails (`real_estate`.`Agent`, CONSTRAINT `Agent_ibfk_1` FOREIGN KEY (`broker_id`) REFERENCES `Brokerage` (`broker_id`))

The above exception was the direct cause of the following exception:

Traceback (most recent call last):
  File "/home/tygilman/School/CS3200/real-estate-htmx-fastapi/app/routes/admin.py", line 273, in create_agent
    execute_procedure(
  File "/home/tygilman/School/CS3200/real-estate-htmx-fastapi/app/core/database.py", line 48, in execute_procedure
    cursor.callproc(procedure_name, params)
  File "/home/tygilman/School/CS3200/real-estate-htmx-fastapi/.venv/lib/python3.12/site-packages/mysql/connector/cursor_cext.py", line 566, in callproc
    result = self._connection.cmd_query(
             ^^^^^^^^^^^^^^^^^^^^^^^^^^^
  File "/home/tygilman/School/CS3200/real-estate-htmx-fastapi/.venv/lib/python3.12/site-packages/mysql/connector/opentelemetry/context_propagation.py", line 97, in wrapper
    return method(cnx, *args, **kwargs)
           ^^^^^^^^^^^^^^^^^^^^^^^^^^^^
  File "/home/tygilman/School/CS3200/real-estate-htmx-fastapi/.venv/lib/python3.12/site-packages/mysql/connector/connection_cext.py", line 714, in cmd_query
    raise get_mysql_exception(
mysql.connector.errors.IntegrityError: 1452 (23000): Cannot add or update a child row: a foreign key constraint fails (`real_estate`.`Agent`, CONSTRAINT `Agent_ibfk_1` FOREIGN KEY (`broker_id`) REFERENCES `Brokerage` (`broker_id`))
2024-11-30 20:10:18,830 - app - ERROR - Failed to create agent: 1452 (23000): Cannot add or update a child row: a foreign key constraint fails (`real_estate`.`Agent`, CONSTRAINT `Agent_ibfk_1` FOREIGN KEY (`broker_id`) REFERENCES `Brokerage` (`broker_id`))
Traceback (most recent call last):
  File "/home/tygilman/School/CS3200/real-estate-htmx-fastapi/.venv/lib/python3.12/site-packages/mysql/connector/connection_cext.py", line 706, in cmd_query
    self._cmysql.query(
_mysql_connector.MySQLInterfaceError: Cannot add or update a child row: a foreign key constraint fails (`real_estate`.`Agent`, CONSTRAINT `Agent_ibfk_1` FOREIGN KEY (`broker_id`) REFERENCES `Brokerage` (`broker_id`))

The above exception was the direct cause of the following exception:

Traceback (most recent call last):
  File "/home/tygilman/School/CS3200/real-estate-htmx-fastapi/app/routes/admin.py", line 273, in create_agent
    execute_procedure(
  File "/home/tygilman/School/CS3200/real-estate-htmx-fastapi/app/core/database.py", line 48, in execute_procedure
    cursor.callproc(procedure_name, params)
  File "/home/tygilman/School/CS3200/real-estate-htmx-fastapi/.venv/lib/python3.12/site-packages/mysql/connector/cursor_cext.py", line 566, in callproc
    result = self._connection.cmd_query(
             ^^^^^^^^^^^^^^^^^^^^^^^^^^^
  File "/home/tygilman/School/CS3200/real-estate-htmx-fastapi/.venv/lib/python3.12/site-packages/mysql/connector/opentelemetry/context_propagation.py", line 97, in wrapper
    return method(cnx, *args, **kwargs)
           ^^^^^^^^^^^^^^^^^^^^^^^^^^^^
  File "/home/tygilman/School/CS3200/real-estate-htmx-fastapi/.venv/lib/python3.12/site-packages/mysql/connector/connection_cext.py", line 714, in cmd_query
    raise get_mysql_exception(
mysql.connector.errors.IntegrityError: 1452 (23000): Cannot add or update a child row: a foreign key constraint fails (`real_estate`.`Agent`, CONSTRAINT `Agent_ibfk_1` FOREIGN KEY (`broker_id`) REFERENCES `Brokerage` (`broker_id`))
2024-11-30 20:10:25,044 - app - ERROR - Failed to create agent: 1452 (23000): Cannot add or update a child row: a foreign key constraint fails (`real_estate`.`Agent`, CONSTRAINT `Agent_ibfk_1` FOREIGN KEY (`broker_id`) REFERENCES `Brokerage` (`broker_id`))
Traceback (most recent call last):
  File "/home/tygilman/School/CS3200/real-estate-htmx-fastapi/.venv/lib/python3.12/site-packages/mysql/connector/connection_cext.py", line 706, in cmd_query
    self._cmysql.query(
_mysql_connector.MySQLInterfaceError: Cannot add or update a child row: a foreign key constraint fails (`real_estate`.`Agent`, CONSTRAINT `Agent_ibfk_1` FOREIGN KEY (`broker_id`) REFERENCES `Brokerage` (`broker_id`))

The above exception was the direct cause of the following exception:

Traceback (most recent call last):
  File "/home/tygilman/School/CS3200/real-estate-htmx-fastapi/app/routes/admin.py", line 273, in create_agent
    execute_procedure(
  File "/home/tygilman/School/CS3200/real-estate-htmx-fastapi/app/core/database.py", line 48, in execute_procedure
    cursor.callproc(procedure_name, params)
  File "/home/tygilman/School/CS3200/real-estate-htmx-fastapi/.venv/lib/python3.12/site-packages/mysql/connector/cursor_cext.py", line 566, in callproc
    result = self._connection.cmd_query(
             ^^^^^^^^^^^^^^^^^^^^^^^^^^^
  File "/home/tygilman/School/CS3200/real-estate-htmx-fastapi/.venv/lib/python3.12/site-packages/mysql/connector/opentelemetry/context_propagation.py", line 97, in wrapper
    return method(cnx, *args, **kwargs)
           ^^^^^^^^^^^^^^^^^^^^^^^^^^^^
  File "/home/tygilman/School/CS3200/real-estate-htmx-fastapi/.venv/lib/python3.12/site-packages/mysql/connector/connection_cext.py", line 714, in cmd_query
    raise get_mysql_exception(
mysql.connector.errors.IntegrityError: 1452 (23000): Cannot add or update a child row: a foreign key constraint fails (`real_estate`.`Agent`, CONSTRAINT `Agent_ibfk_1` FOREIGN KEY (`broker_id`) REFERENCES `Brokerage` (`broker_id`))
2024-11-30 20:10:25,676 - app - ERROR - Failed to create agent: 1452 (23000): Cannot add or update a child row: a foreign key constraint fails (`real_estate`.`Agent`, CONSTRAINT `Agent_ibfk_1` FOREIGN KEY (`broker_id`) REFERENCES `Brokerage` (`broker_id`))
Traceback (most recent call last):
  File "/home/tygilman/School/CS3200/real-estate-htmx-fastapi/.venv/lib/python3.12/site-packages/mysql/connector/connection_cext.py", line 706, in cmd_query
    self._cmysql.query(
_mysql_connector.MySQLInterfaceError: Cannot add or update a child row: a foreign key constraint fails (`real_estate`.`Agent`, CONSTRAINT `Agent_ibfk_1` FOREIGN KEY (`broker_id`) REFERENCES `Brokerage` (`broker_id`))

The above exception was the direct cause of the following exception:

Traceback (most recent call last):
  File "/home/tygilman/School/CS3200/real-estate-htmx-fastapi/app/routes/admin.py", line 273, in create_agent
    execute_procedure(
  File "/home/tygilman/School/CS3200/real-estate-htmx-fastapi/app/core/database.py", line 48, in execute_procedure
    cursor.callproc(procedure_name, params)
  File "/home/tygilman/School/CS3200/real-estate-htmx-fastapi/.venv/lib/python3.12/site-packages/mysql/connector/cursor_cext.py", line 566, in callproc
    result = self._connection.cmd_query(
             ^^^^^^^^^^^^^^^^^^^^^^^^^^^
  File "/home/tygilman/School/CS3200/real-estate-htmx-fastapi/.venv/lib/python3.12/site-packages/mysql/connector/opentelemetry/context_propagation.py", line 97, in wrapper
    return method(cnx, *args, **kwargs)
           ^^^^^^^^^^^^^^^^^^^^^^^^^^^^
  File "/home/tygilman/School/CS3200/real-estate-htmx-fastapi/.venv/lib/python3.12/site-packages/mysql/connector/connection_cext.py", line 714, in cmd_query
    raise get_mysql_exception(
mysql.connector.errors.IntegrityError: 1452 (23000): Cannot add or update a child row: a foreign key constraint fails (`real_estate`.`Agent`, CONSTRAINT `Agent_ibfk_1` FOREIGN KEY (`broker_id`) REFERENCES `Brokerage` (`broker_id`))
2024-11-30 20:11:43,931 - app - ERROR - Failed to create agent: 1452 (23000): Cannot add or update a child row: a foreign key constraint fails (`real_estate`.`Agent`, CONSTRAINT `Agent_ibfk_1` FOREIGN KEY (`broker_id`) REFERENCES `Brokerage` (`broker_id`))
Traceback (most recent call last):
  File "/home/tygilman/School/CS3200/real-estate-htmx-fastapi/.venv/lib/python3.12/site-packages/mysql/connector/connection_cext.py", line 706, in cmd_query
    self._cmysql.query(
_mysql_connector.MySQLInterfaceError: Cannot add or update a child row: a foreign key constraint fails (`real_estate`.`Agent`, CONSTRAINT `Agent_ibfk_1` FOREIGN KEY (`broker_id`) REFERENCES `Brokerage` (`broker_id`))

The above exception was the direct cause of the following exception:

Traceback (most recent call last):
  File "/home/tygilman/School/CS3200/real-estate-htmx-fastapi/app/routes/admin.py", line 273, in create_agent
    execute_procedure(
  File "/home/tygilman/School/CS3200/real-estate-htmx-fastapi/app/core/database.py", line 48, in execute_procedure
    cursor.callproc(procedure_name, params)
  File "/home/tygilman/School/CS3200/real-estate-htmx-fastapi/.venv/lib/python3.12/site-packages/mysql/connector/cursor_cext.py", line 566, in callproc
    result = self._connection.cmd_query(
             ^^^^^^^^^^^^^^^^^^^^^^^^^^^
  File "/home/tygilman/School/CS3200/real-estate-htmx-fastapi/.venv/lib/python3.12/site-packages/mysql/connector/opentelemetry/context_propagation.py", line 97, in wrapper
    return method(cnx, *args, **kwargs)
           ^^^^^^^^^^^^^^^^^^^^^^^^^^^^
  File "/home/tygilman/School/CS3200/real-estate-htmx-fastapi/.venv/lib/python3.12/site-packages/mysql/connector/connection_cext.py", line 714, in cmd_query
    raise get_mysql_exception(
mysql.connector.errors.IntegrityError: 1452 (23000): Cannot add or update a child row: a foreign key constraint fails (`real_estate`.`Agent`, CONSTRAINT `Agent_ibfk_1` FOREIGN KEY (`broker_id`) REFERENCES `Brokerage` (`broker_id`))
2024-11-30 20:11:44,535 - app - ERROR - Failed to create agent: 1452 (23000): Cannot add or update a child row: a foreign key constraint fails (`real_estate`.`Agent`, CONSTRAINT `Agent_ibfk_1` FOREIGN KEY (`broker_id`) REFERENCES `Brokerage` (`broker_id`))
Traceback (most recent call last):
  File "/home/tygilman/School/CS3200/real-estate-htmx-fastapi/.venv/lib/python3.12/site-packages/mysql/connector/connection_cext.py", line 706, in cmd_query
    self._cmysql.query(
_mysql_connector.MySQLInterfaceError: Cannot add or update a child row: a foreign key constraint fails (`real_estate`.`Agent`, CONSTRAINT `Agent_ibfk_1` FOREIGN KEY (`broker_id`) REFERENCES `Brokerage` (`broker_id`))

The above exception was the direct cause of the following exception:

Traceback (most recent call last):
  File "/home/tygilman/School/CS3200/real-estate-htmx-fastapi/app/routes/admin.py", line 273, in create_agent
    execute_procedure(
  File "/home/tygilman/School/CS3200/real-estate-htmx-fastapi/app/core/database.py", line 48, in execute_procedure
    cursor.callproc(procedure_name, params)
  File "/home/tygilman/School/CS3200/real-estate-htmx-fastapi/.venv/lib/python3.12/site-packages/mysql/connector/cursor_cext.py", line 566, in callproc
    result = self._connection.cmd_query(
             ^^^^^^^^^^^^^^^^^^^^^^^^^^^
  File "/home/tygilman/School/CS3200/real-estate-htmx-fastapi/.venv/lib/python3.12/site-packages/mysql/connector/opentelemetry/context_propagation.py", line 97, in wrapper
    return method(cnx, *args, **kwargs)
           ^^^^^^^^^^^^^^^^^^^^^^^^^^^^
  File "/home/tygilman/School/CS3200/real-estate-htmx-fastapi/.venv/lib/python3.12/site-packages/mysql/connector/connection_cext.py", line 714, in cmd_query
    raise get_mysql_exception(
mysql.connector.errors.IntegrityError: 1452 (23000): Cannot add or update a child row: a foreign key constraint fails (`real_estate`.`Agent`, CONSTRAINT `Agent_ibfk_1` FOREIGN KEY (`broker_id`) REFERENCES `Brokerage` (`broker_id`))
2024-11-30 20:12:45,206 - app - INFO - Database connection pool created successfully.
2024-11-30 21:30:26,877 - app - INFO - Database connection pool created successfully.
2024-11-30 21:33:02,770 - app - INFO - Database connection pool created successfully.
2024-11-30 21:33:17,754 - app - INFO - Database connection pool created successfully.
2024-11-30 21:35:11,167 - app - INFO - Database connection pool created successfully.
2024-11-30 21:40:19,138 - app - INFO - Database connection pool created successfully.
2024-11-30 21:40:32,539 - app - INFO - Database connection pool created successfully.
2024-11-30 21:40:51,129 - app - INFO - Database connection pool created successfully.
2024-11-30 21:41:08,319 - app - INFO - Database connection pool created successfully.
