{"timestamp": "2024-12-03T22:35:03.600395", "level": "ERROR", "message": "Error updating property: 1318 (42000): Incorrect number of arguments for PROCEDURE real_estate.update_property; expected 22, got 10", "module": "admin", "function": "update_property", "line": 534, "thread_id": 126019624163136, "environment": "development", "exception": {"type": "ProgrammingError", "message": "1318 (42000): Incorrect number of arguments for PROCEDURE real_estate.update_property; expected 22, got 10", "traceback": "Traceback (most recent call last):\n  File \"/home/tygilman/School/CS3200/real-estate-htmx-fastapi/.venv/lib/python3.12/site-packages/mysql/connector/connection_cext.py\", line 706, in cmd_query\n    self._cmysql.query(\n_mysql_connector.MySQLInterfaceError: Incorrect number of arguments for PROCEDURE real_estate.update_property; expected 22, got 10\n\nThe above exception was the direct cause of the following exception:\n\nTraceback (most recent call last):\n  File \"/home/tygilman/School/CS3200/real-estate-htmx-fastapi/app/routes/admin.py\", line 460, in update_property\n    execute_procedure(\n  File \"/home/tygilman/School/CS3200/real-estate-htmx-fastapi/app/core/database.py\", line 50, in execute_procedure\n    cursor.callproc(procedure_name, params)\n  File \"/home/tygilman/School/CS3200/real-estate-htmx-fastapi/.venv/lib/python3.12/site-packages/mysql/connector/cursor_cext.py\", line 566, in callproc\n    result = self._connection.cmd_query(\n             ^^^^^^^^^^^^^^^^^^^^^^^^^^^\n  File \"/home/tygilman/School/CS3200/real-estate-htmx-fastapi/.venv/lib/python3.12/site-packages/mysql/connector/opentelemetry/context_propagation.py\", line 97, in wrapper\n    return method(cnx, *args, **kwargs)\n           ^^^^^^^^^^^^^^^^^^^^^^^^^^^^\n  File \"/home/tygilman/School/CS3200/real-estate-htmx-fastapi/.venv/lib/python3.12/site-packages/mysql/connector/connection_cext.py\", line 714, in cmd_query\n    raise get_mysql_exception(\nmysql.connector.errors.ProgrammingError: 1318 (42000): Incorrect number of arguments for PROCEDURE real_estate.update_property; expected 22, got 10"}}
{"timestamp": "2024-12-03T22:48:03.831954", "level": "ERROR", "message": "Error updating property: 1054 (42S22): Unknown column 'last_modified' in 'field list'", "module": "admin", "function": "update_property", "line": 530, "thread_id": 133893227808576, "environment": "development", "exception": {"type": "ProgrammingError", "message": "1054 (42S22): Unknown column 'last_modified' in 'field list'", "traceback": "Traceback (most recent call last):\n  File \"/home/tygilman/School/CS3200/real-estate-htmx-fastapi/.venv/lib/python3.12/site-packages/mysql/connector/connection_cext.py\", line 706, in cmd_query\n    self._cmysql.query(\n_mysql_connector.MySQLInterfaceError: Unknown column 'last_modified' in 'field list'\n\nThe above exception was the direct cause of the following exception:\n\nTraceback (most recent call last):\n  File \"/home/tygilman/School/CS3200/real-estate-htmx-fastapi/app/routes/admin.py\", line 455, in update_property\n    execute_procedure(\n  File \"/home/tygilman/School/CS3200/real-estate-htmx-fastapi/app/core/database.py\", line 50, in execute_procedure\n    cursor.callproc(procedure_name, params)\n  File \"/home/tygilman/School/CS3200/real-estate-htmx-fastapi/.venv/lib/python3.12/site-packages/mysql/connector/cursor_cext.py\", line 566, in callproc\n    result = self._connection.cmd_query(\n             ^^^^^^^^^^^^^^^^^^^^^^^^^^^\n  File \"/home/tygilman/School/CS3200/real-estate-htmx-fastapi/.venv/lib/python3.12/site-packages/mysql/connector/opentelemetry/context_propagation.py\", line 97, in wrapper\n    return method(cnx, *args, **kwargs)\n           ^^^^^^^^^^^^^^^^^^^^^^^^^^^^\n  File \"/home/tygilman/School/CS3200/real-estate-htmx-fastapi/.venv/lib/python3.12/site-packages/mysql/connector/connection_cext.py\", line 714, in cmd_query\n    raise get_mysql_exception(\nmysql.connector.errors.ProgrammingError: 1054 (42S22): Unknown column 'last_modified' in 'field list'"}}
{"timestamp": "2024-12-03T22:51:07.166900", "level": "ERROR", "message": "Error updating property: 1364 (HY000): Field 'asking_price' doesn't have a default value", "module": "admin", "function": "update_property", "line": 530, "thread_id": 130350035203904, "environment": "development", "exception": {"type": "DatabaseError", "message": "1364 (HY000): Field 'asking_price' doesn't have a default value", "traceback": "Traceback (most recent call last):\n  File \"/home/tygilman/School/CS3200/real-estate-htmx-fastapi/.venv/lib/python3.12/site-packages/mysql/connector/connection_cext.py\", line 706, in cmd_query\n    self._cmysql.query(\n_mysql_connector.MySQLInterfaceError: Field 'asking_price' doesn't have a default value\n\nThe above exception was the direct cause of the following exception:\n\nTraceback (most recent call last):\n  File \"/home/tygilman/School/CS3200/real-estate-htmx-fastapi/app/routes/admin.py\", line 468, in update_property\n    execute_procedure(\n  File \"/home/tygilman/School/CS3200/real-estate-htmx-fastapi/app/core/database.py\", line 50, in execute_procedure\n    cursor.callproc(procedure_name, params)\n  File \"/home/tygilman/School/CS3200/real-estate-htmx-fastapi/.venv/lib/python3.12/site-packages/mysql/connector/cursor_cext.py\", line 566, in callproc\n    result = self._connection.cmd_query(\n             ^^^^^^^^^^^^^^^^^^^^^^^^^^^\n  File \"/home/tygilman/School/CS3200/real-estate-htmx-fastapi/.venv/lib/python3.12/site-packages/mysql/connector/opentelemetry/context_propagation.py\", line 97, in wrapper\n    return method(cnx, *args, **kwargs)\n           ^^^^^^^^^^^^^^^^^^^^^^^^^^^^\n  File \"/home/tygilman/School/CS3200/real-estate-htmx-fastapi/.venv/lib/python3.12/site-packages/mysql/connector/connection_cext.py\", line 714, in cmd_query\n    raise get_mysql_exception(\nmysql.connector.errors.DatabaseError: 1364 (HY000): Field 'asking_price' doesn't have a default value"}}
{"timestamp": "2024-12-03T22:53:28.959809", "level": "ERROR", "message": "Error updating property: name 'lot_size' is not defined", "module": "admin", "function": "update_property", "line": 512, "thread_id": 136800325289792, "environment": "development", "exception": {"type": "NameError", "message": "name 'lot_size' is not defined", "traceback": "Traceback (most recent call last):\n  File \"/home/tygilman/School/CS3200/real-estate-htmx-fastapi/app/routes/admin.py\", line 442, in update_property\n    lot_size, year_built, zoning, property_tax,\n    ^^^^^^^^\nNameError: name 'lot_size' is not defined"}}
{"timestamp": "2024-12-03T22:54:41.032227", "level": "ERROR", "message": "Error updating property: 1292 (22007): Incorrect date value: 'SellerAgent' for column 'p_listing_date' at row 1", "module": "admin", "function": "update_property", "line": 549, "thread_id": 134995715573568, "environment": "development", "exception": {"type": "DataError", "message": "1292 (22007): Incorrect date value: 'SellerAgent' for column 'p_listing_date' at row 1", "traceback": "Traceback (most recent call last):\n  File \"/home/tygilman/School/CS3200/real-estate-htmx-fastapi/.venv/lib/python3.12/site-packages/mysql/connector/connection_cext.py\", line 706, in cmd_query\n    self._cmysql.query(\n_mysql_connector.MySQLInterfaceError: Incorrect date value: 'SellerAgent' for column 'p_listing_date' at row 1\n\nThe above exception was the direct cause of the following exception:\n\nTraceback (most recent call last):\n  File \"/home/tygilman/School/CS3200/real-estate-htmx-fastapi/app/routes/admin.py\", line 487, in update_property\n    execute_procedure(\n  File \"/home/tygilman/School/CS3200/real-estate-htmx-fastapi/app/core/database.py\", line 50, in execute_procedure\n    cursor.callproc(procedure_name, params)\n  File \"/home/tygilman/School/CS3200/real-estate-htmx-fastapi/.venv/lib/python3.12/site-packages/mysql/connector/cursor_cext.py\", line 566, in callproc\n    result = self._connection.cmd_query(\n             ^^^^^^^^^^^^^^^^^^^^^^^^^^^\n  File \"/home/tygilman/School/CS3200/real-estate-htmx-fastapi/.venv/lib/python3.12/site-packages/mysql/connector/opentelemetry/context_propagation.py\", line 97, in wrapper\n    return method(cnx, *args, **kwargs)\n           ^^^^^^^^^^^^^^^^^^^^^^^^^^^^\n  File \"/home/tygilman/School/CS3200/real-estate-htmx-fastapi/.venv/lib/python3.12/site-packages/mysql/connector/connection_cext.py\", line 714, in cmd_query\n    raise get_mysql_exception(\nmysql.connector.errors.DataError: 1292 (22007): Incorrect date value: 'SellerAgent' for column 'p_listing_date' at row 1"}}
{"timestamp": "2024-12-03T22:54:42.149506", "level": "ERROR", "message": "Error updating property: 1292 (22007): Incorrect date value: 'SellerAgent' for column 'p_listing_date' at row 1", "module": "admin", "function": "update_property", "line": 549, "thread_id": 134995715573568, "environment": "development", "exception": {"type": "DataError", "message": "1292 (22007): Incorrect date value: 'SellerAgent' for column 'p_listing_date' at row 1", "traceback": "Traceback (most recent call last):\n  File \"/home/tygilman/School/CS3200/real-estate-htmx-fastapi/.venv/lib/python3.12/site-packages/mysql/connector/connection_cext.py\", line 706, in cmd_query\n    self._cmysql.query(\n_mysql_connector.MySQLInterfaceError: Incorrect date value: 'SellerAgent' for column 'p_listing_date' at row 1\n\nThe above exception was the direct cause of the following exception:\n\nTraceback (most recent call last):\n  File \"/home/tygilman/School/CS3200/real-estate-htmx-fastapi/app/routes/admin.py\", line 487, in update_property\n    execute_procedure(\n  File \"/home/tygilman/School/CS3200/real-estate-htmx-fastapi/app/core/database.py\", line 50, in execute_procedure\n    cursor.callproc(procedure_name, params)\n  File \"/home/tygilman/School/CS3200/real-estate-htmx-fastapi/.venv/lib/python3.12/site-packages/mysql/connector/cursor_cext.py\", line 566, in callproc\n    result = self._connection.cmd_query(\n             ^^^^^^^^^^^^^^^^^^^^^^^^^^^\n  File \"/home/tygilman/School/CS3200/real-estate-htmx-fastapi/.venv/lib/python3.12/site-packages/mysql/connector/opentelemetry/context_propagation.py\", line 97, in wrapper\n    return method(cnx, *args, **kwargs)\n           ^^^^^^^^^^^^^^^^^^^^^^^^^^^^\n  File \"/home/tygilman/School/CS3200/real-estate-htmx-fastapi/.venv/lib/python3.12/site-packages/mysql/connector/connection_cext.py\", line 714, in cmd_query\n    raise get_mysql_exception(\nmysql.connector.errors.DataError: 1292 (22007): Incorrect date value: 'SellerAgent' for column 'p_listing_date' at row 1"}}
