{"timestamp": "2024-12-03T22:35:03.600395", "level": "ERROR", "message": "Error updating property: 1318 (42000): Incorrect number of arguments for PROCEDURE real_estate.update_property; expected 22, got 10", "module": "admin", "function": "update_property", "line": 534, "thread_id": 126019624163136, "environment": "development", "exception": {"type": "ProgrammingError", "message": "1318 (42000): Incorrect number of arguments for PROCEDURE real_estate.update_property; expected 22, got 10", "traceback": "Traceback (most recent call last):\n  File \"/home/tygilman/School/CS3200/real-estate-htmx-fastapi/.venv/lib/python3.12/site-packages/mysql/connector/connection_cext.py\", line 706, in cmd_query\n    self._cmysql.query(\n_mysql_connector.MySQLInterfaceError: Incorrect number of arguments for PROCEDURE real_estate.update_property; expected 22, got 10\n\nThe above exception was the direct cause of the following exception:\n\nTraceback (most recent call last):\n  File \"/home/tygilman/School/CS3200/real-estate-htmx-fastapi/app/routes/admin.py\", line 460, in update_property\n    execute_procedure(\n  File \"/home/tygilman/School/CS3200/real-estate-htmx-fastapi/app/core/database.py\", line 50, in execute_procedure\n    cursor.callproc(procedure_name, params)\n  File \"/home/tygilman/School/CS3200/real-estate-htmx-fastapi/.venv/lib/python3.12/site-packages/mysql/connector/cursor_cext.py\", line 566, in callproc\n    result = self._connection.cmd_query(\n             ^^^^^^^^^^^^^^^^^^^^^^^^^^^\n  File \"/home/tygilman/School/CS3200/real-estate-htmx-fastapi/.venv/lib/python3.12/site-packages/mysql/connector/opentelemetry/context_propagation.py\", line 97, in wrapper\n    return method(cnx, *args, **kwargs)\n           ^^^^^^^^^^^^^^^^^^^^^^^^^^^^\n  File \"/home/tygilman/School/CS3200/real-estate-htmx-fastapi/.venv/lib/python3.12/site-packages/mysql/connector/connection_cext.py\", line 714, in cmd_query\n    raise get_mysql_exception(\nmysql.connector.errors.ProgrammingError: 1318 (42000): Incorrect number of arguments for PROCEDURE real_estate.update_property; expected 22, got 10"}}
{"timestamp": "2024-12-03T22:48:03.831954", "level": "ERROR", "message": "Error updating property: 1054 (42S22): Unknown column 'last_modified' in 'field list'", "module": "admin", "function": "update_property", "line": 530, "thread_id": 133893227808576, "environment": "development", "exception": {"type": "ProgrammingError", "message": "1054 (42S22): Unknown column 'last_modified' in 'field list'", "traceback": "Traceback (most recent call last):\n  File \"/home/tygilman/School/CS3200/real-estate-htmx-fastapi/.venv/lib/python3.12/site-packages/mysql/connector/connection_cext.py\", line 706, in cmd_query\n    self._cmysql.query(\n_mysql_connector.MySQLInterfaceError: Unknown column 'last_modified' in 'field list'\n\nThe above exception was the direct cause of the following exception:\n\nTraceback (most recent call last):\n  File \"/home/tygilman/School/CS3200/real-estate-htmx-fastapi/app/routes/admin.py\", line 455, in update_property\n    execute_procedure(\n  File \"/home/tygilman/School/CS3200/real-estate-htmx-fastapi/app/core/database.py\", line 50, in execute_procedure\n    cursor.callproc(procedure_name, params)\n  File \"/home/tygilman/School/CS3200/real-estate-htmx-fastapi/.venv/lib/python3.12/site-packages/mysql/connector/cursor_cext.py\", line 566, in callproc\n    result = self._connection.cmd_query(\n             ^^^^^^^^^^^^^^^^^^^^^^^^^^^\n  File \"/home/tygilman/School/CS3200/real-estate-htmx-fastapi/.venv/lib/python3.12/site-packages/mysql/connector/opentelemetry/context_propagation.py\", line 97, in wrapper\n    return method(cnx, *args, **kwargs)\n           ^^^^^^^^^^^^^^^^^^^^^^^^^^^^\n  File \"/home/tygilman/School/CS3200/real-estate-htmx-fastapi/.venv/lib/python3.12/site-packages/mysql/connector/connection_cext.py\", line 714, in cmd_query\n    raise get_mysql_exception(\nmysql.connector.errors.ProgrammingError: 1054 (42S22): Unknown column 'last_modified' in 'field list'"}}
{"timestamp": "2024-12-03T22:51:07.166900", "level": "ERROR", "message": "Error updating property: 1364 (HY000): Field 'asking_price' doesn't have a default value", "module": "admin", "function": "update_property", "line": 530, "thread_id": 130350035203904, "environment": "development", "exception": {"type": "DatabaseError", "message": "1364 (HY000): Field 'asking_price' doesn't have a default value", "traceback": "Traceback (most recent call last):\n  File \"/home/tygilman/School/CS3200/real-estate-htmx-fastapi/.venv/lib/python3.12/site-packages/mysql/connector/connection_cext.py\", line 706, in cmd_query\n    self._cmysql.query(\n_mysql_connector.MySQLInterfaceError: Field 'asking_price' doesn't have a default value\n\nThe above exception was the direct cause of the following exception:\n\nTraceback (most recent call last):\n  File \"/home/tygilman/School/CS3200/real-estate-htmx-fastapi/app/routes/admin.py\", line 468, in update_property\n    execute_procedure(\n  File \"/home/tygilman/School/CS3200/real-estate-htmx-fastapi/app/core/database.py\", line 50, in execute_procedure\n    cursor.callproc(procedure_name, params)\n  File \"/home/tygilman/School/CS3200/real-estate-htmx-fastapi/.venv/lib/python3.12/site-packages/mysql/connector/cursor_cext.py\", line 566, in callproc\n    result = self._connection.cmd_query(\n             ^^^^^^^^^^^^^^^^^^^^^^^^^^^\n  File \"/home/tygilman/School/CS3200/real-estate-htmx-fastapi/.venv/lib/python3.12/site-packages/mysql/connector/opentelemetry/context_propagation.py\", line 97, in wrapper\n    return method(cnx, *args, **kwargs)\n           ^^^^^^^^^^^^^^^^^^^^^^^^^^^^\n  File \"/home/tygilman/School/CS3200/real-estate-htmx-fastapi/.venv/lib/python3.12/site-packages/mysql/connector/connection_cext.py\", line 714, in cmd_query\n    raise get_mysql_exception(\nmysql.connector.errors.DatabaseError: 1364 (HY000): Field 'asking_price' doesn't have a default value"}}
{"timestamp": "2024-12-03T22:53:28.959809", "level": "ERROR", "message": "Error updating property: name 'lot_size' is not defined", "module": "admin", "function": "update_property", "line": 512, "thread_id": 136800325289792, "environment": "development", "exception": {"type": "NameError", "message": "name 'lot_size' is not defined", "traceback": "Traceback (most recent call last):\n  File \"/home/tygilman/School/CS3200/real-estate-htmx-fastapi/app/routes/admin.py\", line 442, in update_property\n    lot_size, year_built, zoning, property_tax,\n    ^^^^^^^^\nNameError: name 'lot_size' is not defined"}}
{"timestamp": "2024-12-03T22:54:41.032227", "level": "ERROR", "message": "Error updating property: 1292 (22007): Incorrect date value: 'SellerAgent' for column 'p_listing_date' at row 1", "module": "admin", "function": "update_property", "line": 549, "thread_id": 134995715573568, "environment": "development", "exception": {"type": "DataError", "message": "1292 (22007): Incorrect date value: 'SellerAgent' for column 'p_listing_date' at row 1", "traceback": "Traceback (most recent call last):\n  File \"/home/tygilman/School/CS3200/real-estate-htmx-fastapi/.venv/lib/python3.12/site-packages/mysql/connector/connection_cext.py\", line 706, in cmd_query\n    self._cmysql.query(\n_mysql_connector.MySQLInterfaceError: Incorrect date value: 'SellerAgent' for column 'p_listing_date' at row 1\n\nThe above exception was the direct cause of the following exception:\n\nTraceback (most recent call last):\n  File \"/home/tygilman/School/CS3200/real-estate-htmx-fastapi/app/routes/admin.py\", line 487, in update_property\n    execute_procedure(\n  File \"/home/tygilman/School/CS3200/real-estate-htmx-fastapi/app/core/database.py\", line 50, in execute_procedure\n    cursor.callproc(procedure_name, params)\n  File \"/home/tygilman/School/CS3200/real-estate-htmx-fastapi/.venv/lib/python3.12/site-packages/mysql/connector/cursor_cext.py\", line 566, in callproc\n    result = self._connection.cmd_query(\n             ^^^^^^^^^^^^^^^^^^^^^^^^^^^\n  File \"/home/tygilman/School/CS3200/real-estate-htmx-fastapi/.venv/lib/python3.12/site-packages/mysql/connector/opentelemetry/context_propagation.py\", line 97, in wrapper\n    return method(cnx, *args, **kwargs)\n           ^^^^^^^^^^^^^^^^^^^^^^^^^^^^\n  File \"/home/tygilman/School/CS3200/real-estate-htmx-fastapi/.venv/lib/python3.12/site-packages/mysql/connector/connection_cext.py\", line 714, in cmd_query\n    raise get_mysql_exception(\nmysql.connector.errors.DataError: 1292 (22007): Incorrect date value: 'SellerAgent' for column 'p_listing_date' at row 1"}}
{"timestamp": "2024-12-03T22:54:42.149506", "level": "ERROR", "message": "Error updating property: 1292 (22007): Incorrect date value: 'SellerAgent' for column 'p_listing_date' at row 1", "module": "admin", "function": "update_property", "line": 549, "thread_id": 134995715573568, "environment": "development", "exception": {"type": "DataError", "message": "1292 (22007): Incorrect date value: 'SellerAgent' for column 'p_listing_date' at row 1", "traceback": "Traceback (most recent call last):\n  File \"/home/tygilman/School/CS3200/real-estate-htmx-fastapi/.venv/lib/python3.12/site-packages/mysql/connector/connection_cext.py\", line 706, in cmd_query\n    self._cmysql.query(\n_mysql_connector.MySQLInterfaceError: Incorrect date value: 'SellerAgent' for column 'p_listing_date' at row 1\n\nThe above exception was the direct cause of the following exception:\n\nTraceback (most recent call last):\n  File \"/home/tygilman/School/CS3200/real-estate-htmx-fastapi/app/routes/admin.py\", line 487, in update_property\n    execute_procedure(\n  File \"/home/tygilman/School/CS3200/real-estate-htmx-fastapi/app/core/database.py\", line 50, in execute_procedure\n    cursor.callproc(procedure_name, params)\n  File \"/home/tygilman/School/CS3200/real-estate-htmx-fastapi/.venv/lib/python3.12/site-packages/mysql/connector/cursor_cext.py\", line 566, in callproc\n    result = self._connection.cmd_query(\n             ^^^^^^^^^^^^^^^^^^^^^^^^^^^\n  File \"/home/tygilman/School/CS3200/real-estate-htmx-fastapi/.venv/lib/python3.12/site-packages/mysql/connector/opentelemetry/context_propagation.py\", line 97, in wrapper\n    return method(cnx, *args, **kwargs)\n           ^^^^^^^^^^^^^^^^^^^^^^^^^^^^\n  File \"/home/tygilman/School/CS3200/real-estate-htmx-fastapi/.venv/lib/python3.12/site-packages/mysql/connector/connection_cext.py\", line 714, in cmd_query\n    raise get_mysql_exception(\nmysql.connector.errors.DataError: 1292 (22007): Incorrect date value: 'SellerAgent' for column 'p_listing_date' at row 1"}}
{"timestamp": "2024-12-03T23:03:00.193155", "level": "ERROR", "message": "Error updating property: 1292 (22007): Incorrect date value: 'SellerAgent' for column 'p_listing_date' at row 1", "module": "admin", "function": "update_property", "line": 549, "thread_id": 128096542099264, "environment": "development", "exception": {"type": "DataError", "message": "1292 (22007): Incorrect date value: 'SellerAgent' for column 'p_listing_date' at row 1", "traceback": "Traceback (most recent call last):\n  File \"/home/tygilman/School/CS3200/real-estate-htmx-fastapi/.venv/lib/python3.12/site-packages/mysql/connector/connection_cext.py\", line 706, in cmd_query\n    self._cmysql.query(\n_mysql_connector.MySQLInterfaceError: Incorrect date value: 'SellerAgent' for column 'p_listing_date' at row 1\n\nThe above exception was the direct cause of the following exception:\n\nTraceback (most recent call last):\n  File \"/home/tygilman/School/CS3200/real-estate-htmx-fastapi/app/routes/admin.py\", line 487, in update_property\n    execute_procedure(\n  File \"/home/tygilman/School/CS3200/real-estate-htmx-fastapi/app/core/database.py\", line 50, in execute_procedure\n    cursor.callproc(procedure_name, params)\n  File \"/home/tygilman/School/CS3200/real-estate-htmx-fastapi/.venv/lib/python3.12/site-packages/mysql/connector/cursor_cext.py\", line 566, in callproc\n    result = self._connection.cmd_query(\n             ^^^^^^^^^^^^^^^^^^^^^^^^^^^\n  File \"/home/tygilman/School/CS3200/real-estate-htmx-fastapi/.venv/lib/python3.12/site-packages/mysql/connector/opentelemetry/context_propagation.py\", line 97, in wrapper\n    return method(cnx, *args, **kwargs)\n           ^^^^^^^^^^^^^^^^^^^^^^^^^^^^\n  File \"/home/tygilman/School/CS3200/real-estate-htmx-fastapi/.venv/lib/python3.12/site-packages/mysql/connector/connection_cext.py\", line 714, in cmd_query\n    raise get_mysql_exception(\nmysql.connector.errors.DataError: 1292 (22007): Incorrect date value: 'SellerAgent' for column 'p_listing_date' at row 1"}}
{"timestamp": "2024-12-03T23:04:46.703664", "level": "ERROR", "message": "Error updating property: 1264 (22003): Out of range value for column 'p_exclusive' at row 1", "module": "admin", "function": "update_property", "line": 549, "thread_id": 136963105793856, "environment": "development", "exception": {"type": "DataError", "message": "1264 (22003): Out of range value for column 'p_exclusive' at row 1", "traceback": "Traceback (most recent call last):\n  File \"/home/tygilman/School/CS3200/real-estate-htmx-fastapi/.venv/lib/python3.12/site-packages/mysql/connector/connection_cext.py\", line 706, in cmd_query\n    self._cmysql.query(\n_mysql_connector.MySQLInterfaceError: Out of range value for column 'p_exclusive' at row 1\n\nThe above exception was the direct cause of the following exception:\n\nTraceback (most recent call last):\n  File \"/home/tygilman/School/CS3200/real-estate-htmx-fastapi/app/routes/admin.py\", line 487, in update_property\n    execute_procedure(\n  File \"/home/tygilman/School/CS3200/real-estate-htmx-fastapi/app/core/database.py\", line 50, in execute_procedure\n    cursor.callproc(procedure_name, params)\n  File \"/home/tygilman/School/CS3200/real-estate-htmx-fastapi/.venv/lib/python3.12/site-packages/mysql/connector/cursor_cext.py\", line 566, in callproc\n    result = self._connection.cmd_query(\n             ^^^^^^^^^^^^^^^^^^^^^^^^^^^\n  File \"/home/tygilman/School/CS3200/real-estate-htmx-fastapi/.venv/lib/python3.12/site-packages/mysql/connector/opentelemetry/context_propagation.py\", line 97, in wrapper\n    return method(cnx, *args, **kwargs)\n           ^^^^^^^^^^^^^^^^^^^^^^^^^^^^\n  File \"/home/tygilman/School/CS3200/real-estate-htmx-fastapi/.venv/lib/python3.12/site-packages/mysql/connector/connection_cext.py\", line 714, in cmd_query\n    raise get_mysql_exception(\nmysql.connector.errors.DataError: 1264 (22003): Out of range value for column 'p_exclusive' at row 1"}}
{"timestamp": "2024-12-03T23:11:04.377727", "level": "ERROR", "message": "Error updating property: 1265 (01000): Data truncated for column 'agent_role' at row 1", "module": "admin", "function": "update_property", "line": 549, "thread_id": 131104276252480, "environment": "development", "exception": {"type": "DatabaseError", "message": "1265 (01000): Data truncated for column 'agent_role' at row 1", "traceback": "Traceback (most recent call last):\n  File \"/home/tygilman/School/CS3200/real-estate-htmx-fastapi/.venv/lib/python3.12/site-packages/mysql/connector/connection_cext.py\", line 706, in cmd_query\n    self._cmysql.query(\n_mysql_connector.MySQLInterfaceError: Data truncated for column 'agent_role' at row 1\n\nThe above exception was the direct cause of the following exception:\n\nTraceback (most recent call last):\n  File \"/home/tygilman/School/CS3200/real-estate-htmx-fastapi/app/routes/admin.py\", line 487, in update_property\n    execute_procedure(\n  File \"/home/tygilman/School/CS3200/real-estate-htmx-fastapi/app/core/database.py\", line 50, in execute_procedure\n    cursor.callproc(procedure_name, params)\n  File \"/home/tygilman/School/CS3200/real-estate-htmx-fastapi/.venv/lib/python3.12/site-packages/mysql/connector/cursor_cext.py\", line 566, in callproc\n    result = self._connection.cmd_query(\n             ^^^^^^^^^^^^^^^^^^^^^^^^^^^\n  File \"/home/tygilman/School/CS3200/real-estate-htmx-fastapi/.venv/lib/python3.12/site-packages/mysql/connector/opentelemetry/context_propagation.py\", line 97, in wrapper\n    return method(cnx, *args, **kwargs)\n           ^^^^^^^^^^^^^^^^^^^^^^^^^^^^\n  File \"/home/tygilman/School/CS3200/real-estate-htmx-fastapi/.venv/lib/python3.12/site-packages/mysql/connector/connection_cext.py\", line 714, in cmd_query\n    raise get_mysql_exception(\nmysql.connector.errors.DatabaseError: 1265 (01000): Data truncated for column 'agent_role' at row 1"}}
{"timestamp": "2024-12-03T23:15:17.147394", "level": "ERROR", "message": "Error updating property: 1364 (HY000): Field 'exclusive' doesn't have a default value", "module": "admin", "function": "update_property", "line": 549, "thread_id": 125917301708608, "environment": "development", "exception": {"type": "DatabaseError", "message": "1364 (HY000): Field 'exclusive' doesn't have a default value", "traceback": "Traceback (most recent call last):\n  File \"/home/tygilman/School/CS3200/real-estate-htmx-fastapi/.venv/lib/python3.12/site-packages/mysql/connector/connection_cext.py\", line 706, in cmd_query\n    self._cmysql.query(\n_mysql_connector.MySQLInterfaceError: Field 'exclusive' doesn't have a default value\n\nThe above exception was the direct cause of the following exception:\n\nTraceback (most recent call last):\n  File \"/home/tygilman/School/CS3200/real-estate-htmx-fastapi/app/routes/admin.py\", line 487, in update_property\n    execute_procedure(\n  File \"/home/tygilman/School/CS3200/real-estate-htmx-fastapi/app/core/database.py\", line 50, in execute_procedure\n    cursor.callproc(procedure_name, params)\n  File \"/home/tygilman/School/CS3200/real-estate-htmx-fastapi/.venv/lib/python3.12/site-packages/mysql/connector/cursor_cext.py\", line 566, in callproc\n    result = self._connection.cmd_query(\n             ^^^^^^^^^^^^^^^^^^^^^^^^^^^\n  File \"/home/tygilman/School/CS3200/real-estate-htmx-fastapi/.venv/lib/python3.12/site-packages/mysql/connector/opentelemetry/context_propagation.py\", line 97, in wrapper\n    return method(cnx, *args, **kwargs)\n           ^^^^^^^^^^^^^^^^^^^^^^^^^^^^\n  File \"/home/tygilman/School/CS3200/real-estate-htmx-fastapi/.venv/lib/python3.12/site-packages/mysql/connector/connection_cext.py\", line 714, in cmd_query\n    raise get_mysql_exception(\nmysql.connector.errors.DatabaseError: 1364 (HY000): Field 'exclusive' doesn't have a default value"}}
{"timestamp": "2024-12-03T23:19:01.600528", "level": "ERROR", "message": "Error updating property: 1318 (42000): Incorrect number of arguments for PROCEDURE real_estate.update_agent_listing; expected 5, got 6", "module": "admin", "function": "update_property", "line": 551, "thread_id": 125515111954240, "environment": "development", "exception": {"type": "ProgrammingError", "message": "1318 (42000): Incorrect number of arguments for PROCEDURE real_estate.update_agent_listing; expected 5, got 6", "traceback": "Traceback (most recent call last):\n  File \"/home/tygilman/School/CS3200/real-estate-htmx-fastapi/.venv/lib/python3.12/site-packages/mysql/connector/connection_cext.py\", line 706, in cmd_query\n    self._cmysql.query(\n_mysql_connector.MySQLInterfaceError: Incorrect number of arguments for PROCEDURE real_estate.update_agent_listing; expected 5, got 6\n\nThe above exception was the direct cause of the following exception:\n\nTraceback (most recent call last):\n  File \"/home/tygilman/School/CS3200/real-estate-htmx-fastapi/app/routes/admin.py\", line 488, in update_property\n    execute_procedure(\n  File \"/home/tygilman/School/CS3200/real-estate-htmx-fastapi/app/core/database.py\", line 50, in execute_procedure\n    cursor.callproc(procedure_name, params)\n  File \"/home/tygilman/School/CS3200/real-estate-htmx-fastapi/.venv/lib/python3.12/site-packages/mysql/connector/cursor_cext.py\", line 566, in callproc\n    result = self._connection.cmd_query(\n             ^^^^^^^^^^^^^^^^^^^^^^^^^^^\n  File \"/home/tygilman/School/CS3200/real-estate-htmx-fastapi/.venv/lib/python3.12/site-packages/mysql/connector/opentelemetry/context_propagation.py\", line 97, in wrapper\n    return method(cnx, *args, **kwargs)\n           ^^^^^^^^^^^^^^^^^^^^^^^^^^^^\n  File \"/home/tygilman/School/CS3200/real-estate-htmx-fastapi/.venv/lib/python3.12/site-packages/mysql/connector/connection_cext.py\", line 714, in cmd_query\n    raise get_mysql_exception(\nmysql.connector.errors.ProgrammingError: 1318 (42000): Incorrect number of arguments for PROCEDURE real_estate.update_agent_listing; expected 5, got 6"}}
{"timestamp": "2024-12-03T23:50:35.976663", "level": "ERROR", "message": "Error fetching agent edit form: admin/agents/edit_form.html", "module": "admin", "function": "edit_agent_form", "line": 156, "thread_id": 134635109832512, "environment": "development", "exception": {"type": "TemplateNotFound", "message": "admin/agents/edit_form.html", "traceback": "Traceback (most recent call last):\n  File \"/home/tygilman/School/CS3200/real-estate-htmx-fastapi/app/routes/admin.py\", line 152, in edit_agent_form\n    return templates.TemplateResponse(\n           ^^^^^^^^^^^^^^^^^^^^^^^^^^^\n  File \"/home/tygilman/School/CS3200/real-estate-htmx-fastapi/.venv/lib/python3.12/site-packages/starlette/templating.py\", line 112, in TemplateResponse\n    template = self.get_template(name)\n               ^^^^^^^^^^^^^^^^^^^^^^^\n  File \"/home/tygilman/School/CS3200/real-estate-htmx-fastapi/.venv/lib/python3.12/site-packages/starlette/templating.py\", line 94, in get_template\n    return self.env.get_template(name)\n           ^^^^^^^^^^^^^^^^^^^^^^^^^^^\n  File \"/home/tygilman/School/CS3200/real-estate-htmx-fastapi/.venv/lib/python3.12/site-packages/jinja2/environment.py\", line 1010, in get_template\n    return self._load_template(name, globals)\n           ^^^^^^^^^^^^^^^^^^^^^^^^^^^^^^^^^^\n  File \"/home/tygilman/School/CS3200/real-estate-htmx-fastapi/.venv/lib/python3.12/site-packages/jinja2/environment.py\", line 969, in _load_template\n    template = self.loader.load(self, name, self.make_globals(globals))\n               ^^^^^^^^^^^^^^^^^^^^^^^^^^^^^^^^^^^^^^^^^^^^^^^^^^^^^^^^\n  File \"/home/tygilman/School/CS3200/real-estate-htmx-fastapi/.venv/lib/python3.12/site-packages/jinja2/loaders.py\", line 126, in load\n    source, filename, uptodate = self.get_source(environment, name)\n                                 ^^^^^^^^^^^^^^^^^^^^^^^^^^^^^^^^^^\n  File \"/home/tygilman/School/CS3200/real-estate-htmx-fastapi/.venv/lib/python3.12/site-packages/jinja2/loaders.py\", line 218, in get_source\n    raise TemplateNotFound(template)\njinja2.exceptions.TemplateNotFound: admin/agents/edit_form.html"}}
{"timestamp": "2024-12-03T23:50:56.272045", "level": "ERROR", "message": "Error fetching agent edit form: admin/agents/edit_form.html", "module": "admin", "function": "edit_agent_form", "line": 156, "thread_id": 137419731531584, "environment": "development", "exception": {"type": "TemplateNotFound", "message": "admin/agents/edit_form.html", "traceback": "Traceback (most recent call last):\n  File \"/home/tygilman/School/CS3200/real-estate-htmx-fastapi/app/routes/admin.py\", line 152, in edit_agent_form\n    return templates.TemplateResponse(\n           ^^^^^^^^^^^^^^^^^^^^^^^^^^^\n  File \"/home/tygilman/School/CS3200/real-estate-htmx-fastapi/.venv/lib/python3.12/site-packages/starlette/templating.py\", line 112, in TemplateResponse\n    template = self.get_template(name)\n               ^^^^^^^^^^^^^^^^^^^^^^^\n  File \"/home/tygilman/School/CS3200/real-estate-htmx-fastapi/.venv/lib/python3.12/site-packages/starlette/templating.py\", line 94, in get_template\n    return self.env.get_template(name)\n           ^^^^^^^^^^^^^^^^^^^^^^^^^^^\n  File \"/home/tygilman/School/CS3200/real-estate-htmx-fastapi/.venv/lib/python3.12/site-packages/jinja2/environment.py\", line 1010, in get_template\n    return self._load_template(name, globals)\n           ^^^^^^^^^^^^^^^^^^^^^^^^^^^^^^^^^^\n  File \"/home/tygilman/School/CS3200/real-estate-htmx-fastapi/.venv/lib/python3.12/site-packages/jinja2/environment.py\", line 969, in _load_template\n    template = self.loader.load(self, name, self.make_globals(globals))\n               ^^^^^^^^^^^^^^^^^^^^^^^^^^^^^^^^^^^^^^^^^^^^^^^^^^^^^^^^\n  File \"/home/tygilman/School/CS3200/real-estate-htmx-fastapi/.venv/lib/python3.12/site-packages/jinja2/loaders.py\", line 126, in load\n    source, filename, uptodate = self.get_source(environment, name)\n                                 ^^^^^^^^^^^^^^^^^^^^^^^^^^^^^^^^^^\n  File \"/home/tygilman/School/CS3200/real-estate-htmx-fastapi/.venv/lib/python3.12/site-packages/jinja2/loaders.py\", line 218, in get_source\n    raise TemplateNotFound(template)\njinja2.exceptions.TemplateNotFound: admin/agents/edit_form.html"}}
{"timestamp": "2024-12-03T23:52:24.459535", "level": "ERROR", "message": "Failed to update agent: 1318 (42000): Incorrect number of arguments for PROCEDURE real_estate.update_agent; expected 8, got 7", "module": "admin", "function": "update_agent", "line": 637, "thread_id": 133110291629888, "environment": "development", "exception": {"type": "ProgrammingError", "message": "1318 (42000): Incorrect number of arguments for PROCEDURE real_estate.update_agent; expected 8, got 7", "traceback": "Traceback (most recent call last):\n  File \"/home/tygilman/School/CS3200/real-estate-htmx-fastapi/.venv/lib/python3.12/site-packages/mysql/connector/connection_cext.py\", line 706, in cmd_query\n    self._cmysql.query(\n_mysql_connector.MySQLInterfaceError: Incorrect number of arguments for PROCEDURE real_estate.update_agent; expected 8, got 7\n\nThe above exception was the direct cause of the following exception:\n\nTraceback (most recent call last):\n  File \"/home/tygilman/School/CS3200/real-estate-htmx-fastapi/app/routes/admin.py\", line 614, in update_agent\n    execute_procedure(\n  File \"/home/tygilman/School/CS3200/real-estate-htmx-fastapi/app/core/database.py\", line 50, in execute_procedure\n    cursor.callproc(procedure_name, params)\n  File \"/home/tygilman/School/CS3200/real-estate-htmx-fastapi/.venv/lib/python3.12/site-packages/mysql/connector/cursor_cext.py\", line 566, in callproc\n    result = self._connection.cmd_query(\n             ^^^^^^^^^^^^^^^^^^^^^^^^^^^\n  File \"/home/tygilman/School/CS3200/real-estate-htmx-fastapi/.venv/lib/python3.12/site-packages/mysql/connector/opentelemetry/context_propagation.py\", line 97, in wrapper\n    return method(cnx, *args, **kwargs)\n           ^^^^^^^^^^^^^^^^^^^^^^^^^^^^\n  File \"/home/tygilman/School/CS3200/real-estate-htmx-fastapi/.venv/lib/python3.12/site-packages/mysql/connector/connection_cext.py\", line 714, in cmd_query\n    raise get_mysql_exception(\nmysql.connector.errors.ProgrammingError: 1318 (42000): Incorrect number of arguments for PROCEDURE real_estate.update_agent; expected 8, got 7"}}
{"timestamp": "2024-12-03T23:52:24.599365", "level": "ERROR", "message": "Failed to update agent: 1318 (42000): Incorrect number of arguments for PROCEDURE real_estate.update_agent; expected 8, got 7", "module": "admin", "function": "update_agent", "line": 637, "thread_id": 133110291629888, "environment": "development", "exception": {"type": "ProgrammingError", "message": "1318 (42000): Incorrect number of arguments for PROCEDURE real_estate.update_agent; expected 8, got 7", "traceback": "Traceback (most recent call last):\n  File \"/home/tygilman/School/CS3200/real-estate-htmx-fastapi/.venv/lib/python3.12/site-packages/mysql/connector/connection_cext.py\", line 706, in cmd_query\n    self._cmysql.query(\n_mysql_connector.MySQLInterfaceError: Incorrect number of arguments for PROCEDURE real_estate.update_agent; expected 8, got 7\n\nThe above exception was the direct cause of the following exception:\n\nTraceback (most recent call last):\n  File \"/home/tygilman/School/CS3200/real-estate-htmx-fastapi/app/routes/admin.py\", line 614, in update_agent\n    execute_procedure(\n  File \"/home/tygilman/School/CS3200/real-estate-htmx-fastapi/app/core/database.py\", line 50, in execute_procedure\n    cursor.callproc(procedure_name, params)\n  File \"/home/tygilman/School/CS3200/real-estate-htmx-fastapi/.venv/lib/python3.12/site-packages/mysql/connector/cursor_cext.py\", line 566, in callproc\n    result = self._connection.cmd_query(\n             ^^^^^^^^^^^^^^^^^^^^^^^^^^^\n  File \"/home/tygilman/School/CS3200/real-estate-htmx-fastapi/.venv/lib/python3.12/site-packages/mysql/connector/opentelemetry/context_propagation.py\", line 97, in wrapper\n    return method(cnx, *args, **kwargs)\n           ^^^^^^^^^^^^^^^^^^^^^^^^^^^^\n  File \"/home/tygilman/School/CS3200/real-estate-htmx-fastapi/.venv/lib/python3.12/site-packages/mysql/connector/connection_cext.py\", line 714, in cmd_query\n    raise get_mysql_exception(\nmysql.connector.errors.ProgrammingError: 1318 (42000): Incorrect number of arguments for PROCEDURE real_estate.update_agent; expected 8, got 7"}}
{"timestamp": "2024-12-03T23:52:24.805965", "level": "ERROR", "message": "Failed to update agent: 1318 (42000): Incorrect number of arguments for PROCEDURE real_estate.update_agent; expected 8, got 7", "module": "admin", "function": "update_agent", "line": 637, "thread_id": 133110291629888, "environment": "development", "exception": {"type": "ProgrammingError", "message": "1318 (42000): Incorrect number of arguments for PROCEDURE real_estate.update_agent; expected 8, got 7", "traceback": "Traceback (most recent call last):\n  File \"/home/tygilman/School/CS3200/real-estate-htmx-fastapi/.venv/lib/python3.12/site-packages/mysql/connector/connection_cext.py\", line 706, in cmd_query\n    self._cmysql.query(\n_mysql_connector.MySQLInterfaceError: Incorrect number of arguments for PROCEDURE real_estate.update_agent; expected 8, got 7\n\nThe above exception was the direct cause of the following exception:\n\nTraceback (most recent call last):\n  File \"/home/tygilman/School/CS3200/real-estate-htmx-fastapi/app/routes/admin.py\", line 614, in update_agent\n    execute_procedure(\n  File \"/home/tygilman/School/CS3200/real-estate-htmx-fastapi/app/core/database.py\", line 50, in execute_procedure\n    cursor.callproc(procedure_name, params)\n  File \"/home/tygilman/School/CS3200/real-estate-htmx-fastapi/.venv/lib/python3.12/site-packages/mysql/connector/cursor_cext.py\", line 566, in callproc\n    result = self._connection.cmd_query(\n             ^^^^^^^^^^^^^^^^^^^^^^^^^^^\n  File \"/home/tygilman/School/CS3200/real-estate-htmx-fastapi/.venv/lib/python3.12/site-packages/mysql/connector/opentelemetry/context_propagation.py\", line 97, in wrapper\n    return method(cnx, *args, **kwargs)\n           ^^^^^^^^^^^^^^^^^^^^^^^^^^^^\n  File \"/home/tygilman/School/CS3200/real-estate-htmx-fastapi/.venv/lib/python3.12/site-packages/mysql/connector/connection_cext.py\", line 714, in cmd_query\n    raise get_mysql_exception(\nmysql.connector.errors.ProgrammingError: 1318 (42000): Incorrect number of arguments for PROCEDURE real_estate.update_agent; expected 8, got 7"}}
{"timestamp": "2024-12-03T23:59:34.128028", "level": "ERROR", "message": "Failed to update agent: 1318 (42000): Incorrect number of arguments for PROCEDURE real_estate.update_agent; expected 8, got 7", "module": "admin", "function": "update_agent", "line": 637, "thread_id": 133110291629888, "environment": "development", "exception": {"type": "ProgrammingError", "message": "1318 (42000): Incorrect number of arguments for PROCEDURE real_estate.update_agent; expected 8, got 7", "traceback": "Traceback (most recent call last):\n  File \"/home/tygilman/School/CS3200/real-estate-htmx-fastapi/.venv/lib/python3.12/site-packages/mysql/connector/connection_cext.py\", line 706, in cmd_query\n    self._cmysql.query(\n_mysql_connector.MySQLInterfaceError: Incorrect number of arguments for PROCEDURE real_estate.update_agent; expected 8, got 7\n\nThe above exception was the direct cause of the following exception:\n\nTraceback (most recent call last):\n  File \"/home/tygilman/School/CS3200/real-estate-htmx-fastapi/app/routes/admin.py\", line 614, in update_agent\n    execute_procedure(\n  File \"/home/tygilman/School/CS3200/real-estate-htmx-fastapi/app/core/database.py\", line 50, in execute_procedure\n    cursor.callproc(procedure_name, params)\n  File \"/home/tygilman/School/CS3200/real-estate-htmx-fastapi/.venv/lib/python3.12/site-packages/mysql/connector/cursor_cext.py\", line 566, in callproc\n    result = self._connection.cmd_query(\n             ^^^^^^^^^^^^^^^^^^^^^^^^^^^\n  File \"/home/tygilman/School/CS3200/real-estate-htmx-fastapi/.venv/lib/python3.12/site-packages/mysql/connector/opentelemetry/context_propagation.py\", line 97, in wrapper\n    return method(cnx, *args, **kwargs)\n           ^^^^^^^^^^^^^^^^^^^^^^^^^^^^\n  File \"/home/tygilman/School/CS3200/real-estate-htmx-fastapi/.venv/lib/python3.12/site-packages/mysql/connector/connection_cext.py\", line 714, in cmd_query\n    raise get_mysql_exception(\nmysql.connector.errors.ProgrammingError: 1318 (42000): Incorrect number of arguments for PROCEDURE real_estate.update_agent; expected 8, got 7"}}
