{"timestamp": "2024-11-30T21:06:26.842055", "level": "ERROR", "message": "Error fetching properties: 1305 (42000): PROCEDURE real_estate.get_all_properties_with_details does not exist", "module": "main", "function": "index", "line": 36, "thread_id": 127026495670080, "environment": "development"}
{"timestamp": "2024-11-30T21:06:37.992221", "level": "ERROR", "message": "Error fetching properties: 1305 (42000): PROCEDURE real_estate.get_all_properties_with_details does not exist", "module": "main", "function": "index", "line": 36, "thread_id": 127026495670080, "environment": "development"}
{"timestamp": "2024-11-30T21:27:37.738301", "level": "ERROR", "message": "Failed to create client: 1146 (42S02): Table 'real_estate.Clients' doesn't exist", "module": "admin", "function": "create_client", "line": 103, "thread_id": 134262068442944, "environment": "development", "exception": {"type": "ProgrammingError", "message": "1146 (42S02): Table 'real_estate.Clients' doesn't exist", "traceback": "Traceback (most recent call last):\n  File \"/home/tygilman/School/CS3200/real-estate-htmx-fastapi/.venv/lib/python3.12/site-packages/mysql/connector/connection_cext.py\", line 706, in cmd_query\n    self._cmysql.query(\n_mysql_connector.MySQLInterfaceError: Table 'real_estate.Clients' doesn't exist\n\nThe above exception was the direct cause of the following exception:\n\nTraceback (most recent call last):\n  File \"/home/tygilman/School/CS3200/real-estate-htmx-fastapi/app/routes/admin.py\", line 88, in create_client\n    execute_procedure(\n  File \"/home/tygilman/School/CS3200/real-estate-htmx-fastapi/app/core/database.py\", line 48, in execute_procedure\n    cursor.callproc(procedure_name, params)\n  File \"/home/tygilman/School/CS3200/real-estate-htmx-fastapi/.venv/lib/python3.12/site-packages/mysql/connector/cursor_cext.py\", line 566, in callproc\n    result = self._connection.cmd_query(\n             ^^^^^^^^^^^^^^^^^^^^^^^^^^^\n  File \"/home/tygilman/School/CS3200/real-estate-htmx-fastapi/.venv/lib/python3.12/site-packages/mysql/connector/opentelemetry/context_propagation.py\", line 97, in wrapper\n    return method(cnx, *args, **kwargs)\n           ^^^^^^^^^^^^^^^^^^^^^^^^^^^^\n  File \"/home/tygilman/School/CS3200/real-estate-htmx-fastapi/.venv/lib/python3.12/site-packages/mysql/connector/connection_cext.py\", line 714, in cmd_query\n    raise get_mysql_exception(\nmysql.connector.errors.ProgrammingError: 1146 (42S02): Table 'real_estate.Clients' doesn't exist"}}
{"timestamp": "2024-11-30T21:35:48.365300", "level": "ERROR", "message": "Failed to create client: 'None' has no attribute 'split'", "module": "admin", "function": "create_client", "line": 106, "thread_id": 135772140271424, "environment": "development", "exception": {"type": "UndefinedError", "message": "'None' has no attribute 'split'", "traceback": "Traceback (most recent call last):\n  File \"/home/tygilman/School/CS3200/real-estate-htmx-fastapi/app/routes/admin.py\", line 98, in create_client\n    return templates.TemplateResponse(\n           ^^^^^^^^^^^^^^^^^^^^^^^^^^^\n  File \"/home/tygilman/School/CS3200/real-estate-htmx-fastapi/.venv/lib/python3.12/site-packages/starlette/templating.py\", line 113, in TemplateResponse\n    return _TemplateResponse(\n           ^^^^^^^^^^^^^^^^^^\n  File \"/home/tygilman/School/CS3200/real-estate-htmx-fastapi/.venv/lib/python3.12/site-packages/starlette/templating.py\", line 39, in __init__\n    content = template.render(context)\n              ^^^^^^^^^^^^^^^^^^^^^^^^\n  File \"/home/tygilman/School/CS3200/real-estate-htmx-fastapi/.venv/lib/python3.12/site-packages/jinja2/environment.py\", line 1301, in render\n    self.environment.handle_exception()\n  File \"/home/tygilman/School/CS3200/real-estate-htmx-fastapi/.venv/lib/python3.12/site-packages/jinja2/environment.py\", line 936, in handle_exception\n    raise rewrite_traceback_stack(source=source)\n  File \"app/templates/admin/clients/table_row.html\", line 22, in top-level template code\n    {% for role in client.roles.split(',') if client.roles %}\n    ^^^^^^^^^^^^^^^^^^^^^^^^^\n  File \"/home/tygilman/School/CS3200/real-estate-htmx-fastapi/.venv/lib/python3.12/site-packages/jinja2/utils.py\", line 83, in from_obj\n    if hasattr(obj, \"jinja_pass_arg\"):\n       ^^^^^^^^^^^^^^^^^^^^^^^^^^^^^^\njinja2.exceptions.UndefinedError: 'None' has no attribute 'split'"}}
{"timestamp": "2024-11-30T21:35:51.215506", "level": "ERROR", "message": "Failed to create client: 'None' has no attribute 'split'", "module": "admin", "function": "create_client", "line": 106, "thread_id": 135772140271424, "environment": "development", "exception": {"type": "UndefinedError", "message": "'None' has no attribute 'split'", "traceback": "Traceback (most recent call last):\n  File \"/home/tygilman/School/CS3200/real-estate-htmx-fastapi/app/routes/admin.py\", line 98, in create_client\n    return templates.TemplateResponse(\n           ^^^^^^^^^^^^^^^^^^^^^^^^^^^\n  File \"/home/tygilman/School/CS3200/real-estate-htmx-fastapi/.venv/lib/python3.12/site-packages/starlette/templating.py\", line 113, in TemplateResponse\n    return _TemplateResponse(\n           ^^^^^^^^^^^^^^^^^^\n  File \"/home/tygilman/School/CS3200/real-estate-htmx-fastapi/.venv/lib/python3.12/site-packages/starlette/templating.py\", line 39, in __init__\n    content = template.render(context)\n              ^^^^^^^^^^^^^^^^^^^^^^^^\n  File \"/home/tygilman/School/CS3200/real-estate-htmx-fastapi/.venv/lib/python3.12/site-packages/jinja2/environment.py\", line 1301, in render\n    self.environment.handle_exception()\n  File \"/home/tygilman/School/CS3200/real-estate-htmx-fastapi/.venv/lib/python3.12/site-packages/jinja2/environment.py\", line 936, in handle_exception\n    raise rewrite_traceback_stack(source=source)\n  File \"app/templates/admin/clients/table_row.html\", line 22, in top-level template code\n    {% for role in client.roles.split(',') if client.roles %}\n    ^^^^^^^^^^^^^^^^^^^^^^^^^\n  File \"/home/tygilman/School/CS3200/real-estate-htmx-fastapi/.venv/lib/python3.12/site-packages/jinja2/utils.py\", line 83, in from_obj\n    if hasattr(obj, \"jinja_pass_arg\"):\n       ^^^^^^^^^^^^^^^^^^^^^^^^^^^^^^\njinja2.exceptions.UndefinedError: 'None' has no attribute 'split'"}}
{"timestamp": "2024-11-30T21:38:06.099784", "level": "ERROR", "message": "Dashboard error: No test named 'contains'.", "module": "admin", "function": "admin_dashboard", "line": 51, "thread_id": 135908475512640, "environment": "development", "exception": {"type": "TemplateRuntimeError", "message": "No test named 'contains'.", "traceback": "Traceback (most recent call last):\n  File \"/home/tygilman/School/CS3200/real-estate-htmx-fastapi/app/routes/admin.py\", line 49, in admin_dashboard\n    return templates.TemplateResponse(\"admin/dashboard.html\", context)\n           ^^^^^^^^^^^^^^^^^^^^^^^^^^^^^^^^^^^^^^^^^^^^^^^^^^^^^^^^^^^\n  File \"/home/tygilman/School/CS3200/real-estate-htmx-fastapi/.venv/lib/python3.12/site-packages/starlette/templating.py\", line 113, in TemplateResponse\n    return _TemplateResponse(\n           ^^^^^^^^^^^^^^^^^^\n  File \"/home/tygilman/School/CS3200/real-estate-htmx-fastapi/.venv/lib/python3.12/site-packages/starlette/templating.py\", line 39, in __init__\n    content = template.render(context)\n              ^^^^^^^^^^^^^^^^^^^^^^^^\n  File \"/home/tygilman/School/CS3200/real-estate-htmx-fastapi/.venv/lib/python3.12/site-packages/jinja2/environment.py\", line 1301, in render\n    self.environment.handle_exception()\n  File \"/home/tygilman/School/CS3200/real-estate-htmx-fastapi/.venv/lib/python3.12/site-packages/jinja2/environment.py\", line 936, in handle_exception\n    raise rewrite_traceback_stack(source=source)\n  File \"app/templates/admin/dashboard.html\", line 1, in top-level template code\n    {% extends \"admin/admin_base.html\" %}\n    ^^^^^^^^^^^^^^^^^^^^^^^^^\n  File \"app/templates/admin/admin_base.html\", line 1, in top-level template code\n    {% extends \"base.html\" %}\n  File \"app/templates/base.html\", line 26, in top-level template code\n    {% block content %}{% endblock %}\n    ^^^^^^^^^^^^^^^^^^^^^^^^^\n  File \"app/templates/admin/dashboard.html\", line 23, in block 'content'\n    </div>{% include \"admin/clients/table.html\" %}\n    ^^^^^^^^^^^^^^^^^^^^^^^^^\n  File \"app/templates/admin/clients/table.html\", line 10, in top-level template code\n    {{ clients|selectattr('roles', 'contains', 'SELLER')|list|length }}\n    ^^^^^^^^^^^^^^^^^^^^^^^^^\n  File \"/home/tygilman/School/CS3200/real-estate-htmx-fastapi/.venv/lib/python3.12/site-packages/jinja2/async_utils.py\", line 45, in wrapper\n    return normal_func(*args, **kwargs)\n           ^^^^^^^^^^^^^^^^^^^^^^^^^^^^\n  File \"/home/tygilman/School/CS3200/real-estate-htmx-fastapi/.venv/lib/python3.12/site-packages/jinja2/filters.py\", line 1324, in sync_do_list\n    return list(value)\n           ^^^^^^^^^^^\n  File \"/home/tygilman/School/CS3200/real-estate-htmx-fastapi/.venv/lib/python3.12/site-packages/jinja2/filters.py\", line 1765, in select_or_reject\n    if func(item):\n       ^^^^^^^^^^\n  File \"/home/tygilman/School/CS3200/real-estate-htmx-fastapi/.venv/lib/python3.12/site-packages/jinja2/filters.py\", line 1750, in <lambda>\n    return lambda item: modfunc(func(transfunc(item)))\n                                ^^^^^^^^^^^^^^^^^^^^^\n  File \"/home/tygilman/School/CS3200/real-estate-htmx-fastapi/.venv/lib/python3.12/site-packages/jinja2/filters.py\", line 1745, in func\n    return context.environment.call_test(name, item, args, kwargs)\n           ^^^^^^^^^^^^^^^^^^^^^^^^^^^^^^^^^^^^^^^^^^^^^^^^^^^^^^^\n  File \"/home/tygilman/School/CS3200/real-estate-htmx-fastapi/.venv/lib/python3.12/site-packages/jinja2/environment.py\", line 589, in call_test\n    return self._filter_test_common(\n           ^^^^^^^^^^^^^^^^^^^^^^^^^\n  File \"/home/tygilman/School/CS3200/real-estate-htmx-fastapi/.venv/lib/python3.12/site-packages/jinja2/environment.py\", line 521, in _filter_test_common\n    raise TemplateRuntimeError(msg)\njinja2.exceptions.TemplateRuntimeError: No test named 'contains'."}}
{"timestamp": "2024-11-30T21:38:06.925393", "level": "ERROR", "message": "Dashboard error: No test named 'contains'.", "module": "admin", "function": "admin_dashboard", "line": 51, "thread_id": 135908475512640, "environment": "development", "exception": {"type": "TemplateRuntimeError", "message": "No test named 'contains'.", "traceback": "Traceback (most recent call last):\n  File \"/home/tygilman/School/CS3200/real-estate-htmx-fastapi/app/routes/admin.py\", line 49, in admin_dashboard\n    return templates.TemplateResponse(\"admin/dashboard.html\", context)\n           ^^^^^^^^^^^^^^^^^^^^^^^^^^^^^^^^^^^^^^^^^^^^^^^^^^^^^^^^^^^\n  File \"/home/tygilman/School/CS3200/real-estate-htmx-fastapi/.venv/lib/python3.12/site-packages/starlette/templating.py\", line 113, in TemplateResponse\n    return _TemplateResponse(\n           ^^^^^^^^^^^^^^^^^^\n  File \"/home/tygilman/School/CS3200/real-estate-htmx-fastapi/.venv/lib/python3.12/site-packages/starlette/templating.py\", line 39, in __init__\n    content = template.render(context)\n              ^^^^^^^^^^^^^^^^^^^^^^^^\n  File \"/home/tygilman/School/CS3200/real-estate-htmx-fastapi/.venv/lib/python3.12/site-packages/jinja2/environment.py\", line 1301, in render\n    self.environment.handle_exception()\n  File \"/home/tygilman/School/CS3200/real-estate-htmx-fastapi/.venv/lib/python3.12/site-packages/jinja2/environment.py\", line 936, in handle_exception\n    raise rewrite_traceback_stack(source=source)\n  File \"app/templates/admin/dashboard.html\", line 1, in top-level template code\n    {% extends \"admin/admin_base.html\" %}\n    ^^^^^^^^^^^^^^^^^^^^^^^^^\n  File \"app/templates/admin/admin_base.html\", line 1, in top-level template code\n    {% extends \"base.html\" %}\n  File \"app/templates/base.html\", line 26, in top-level template code\n    {% block content %}{% endblock %}\n    ^^^^^^^^^^^^^^^^^^^^^^^^^\n  File \"app/templates/admin/dashboard.html\", line 23, in block 'content'\n    </div>{% include \"admin/clients/table.html\" %}\n    ^^^^^^^^^^^^^^^^^^^^^^^^^\n  File \"app/templates/admin/clients/table.html\", line 10, in top-level template code\n    {{ clients|selectattr('roles', 'contains', 'SELLER')|list|length }}\n    ^^^^^^^^^^^^^^^^^^^^^^^^^\n  File \"/home/tygilman/School/CS3200/real-estate-htmx-fastapi/.venv/lib/python3.12/site-packages/jinja2/async_utils.py\", line 45, in wrapper\n    return normal_func(*args, **kwargs)\n           ^^^^^^^^^^^^^^^^^^^^^^^^^^^^\n  File \"/home/tygilman/School/CS3200/real-estate-htmx-fastapi/.venv/lib/python3.12/site-packages/jinja2/filters.py\", line 1324, in sync_do_list\n    return list(value)\n           ^^^^^^^^^^^\n  File \"/home/tygilman/School/CS3200/real-estate-htmx-fastapi/.venv/lib/python3.12/site-packages/jinja2/filters.py\", line 1765, in select_or_reject\n    if func(item):\n       ^^^^^^^^^^\n  File \"/home/tygilman/School/CS3200/real-estate-htmx-fastapi/.venv/lib/python3.12/site-packages/jinja2/filters.py\", line 1750, in <lambda>\n    return lambda item: modfunc(func(transfunc(item)))\n                                ^^^^^^^^^^^^^^^^^^^^^\n  File \"/home/tygilman/School/CS3200/real-estate-htmx-fastapi/.venv/lib/python3.12/site-packages/jinja2/filters.py\", line 1745, in func\n    return context.environment.call_test(name, item, args, kwargs)\n           ^^^^^^^^^^^^^^^^^^^^^^^^^^^^^^^^^^^^^^^^^^^^^^^^^^^^^^^\n  File \"/home/tygilman/School/CS3200/real-estate-htmx-fastapi/.venv/lib/python3.12/site-packages/jinja2/environment.py\", line 589, in call_test\n    return self._filter_test_common(\n           ^^^^^^^^^^^^^^^^^^^^^^^^^\n  File \"/home/tygilman/School/CS3200/real-estate-htmx-fastapi/.venv/lib/python3.12/site-packages/jinja2/environment.py\", line 521, in _filter_test_common\n    raise TemplateRuntimeError(msg)\njinja2.exceptions.TemplateRuntimeError: No test named 'contains'."}}
{"timestamp": "2024-11-30T21:38:08.231568", "level": "ERROR", "message": "Dashboard error: No test named 'contains'.", "module": "admin", "function": "admin_dashboard", "line": 51, "thread_id": 135908475512640, "environment": "development", "exception": {"type": "TemplateRuntimeError", "message": "No test named 'contains'.", "traceback": "Traceback (most recent call last):\n  File \"/home/tygilman/School/CS3200/real-estate-htmx-fastapi/app/routes/admin.py\", line 49, in admin_dashboard\n    return templates.TemplateResponse(\"admin/dashboard.html\", context)\n           ^^^^^^^^^^^^^^^^^^^^^^^^^^^^^^^^^^^^^^^^^^^^^^^^^^^^^^^^^^^\n  File \"/home/tygilman/School/CS3200/real-estate-htmx-fastapi/.venv/lib/python3.12/site-packages/starlette/templating.py\", line 113, in TemplateResponse\n    return _TemplateResponse(\n           ^^^^^^^^^^^^^^^^^^\n  File \"/home/tygilman/School/CS3200/real-estate-htmx-fastapi/.venv/lib/python3.12/site-packages/starlette/templating.py\", line 39, in __init__\n    content = template.render(context)\n              ^^^^^^^^^^^^^^^^^^^^^^^^\n  File \"/home/tygilman/School/CS3200/real-estate-htmx-fastapi/.venv/lib/python3.12/site-packages/jinja2/environment.py\", line 1301, in render\n    self.environment.handle_exception()\n  File \"/home/tygilman/School/CS3200/real-estate-htmx-fastapi/.venv/lib/python3.12/site-packages/jinja2/environment.py\", line 936, in handle_exception\n    raise rewrite_traceback_stack(source=source)\n  File \"app/templates/admin/dashboard.html\", line 1, in top-level template code\n    {% extends \"admin/admin_base.html\" %}\n    ^^^^^^^^^^^^^^^^^^^^^^^^^\n  File \"app/templates/admin/admin_base.html\", line 1, in top-level template code\n    {% extends \"base.html\" %}\n  File \"app/templates/base.html\", line 26, in top-level template code\n    {% block content %}{% endblock %}\n    ^^^^^^^^^^^^^^^^^^^^^^^^^\n  File \"app/templates/admin/dashboard.html\", line 23, in block 'content'\n    </div>{% include \"admin/clients/table.html\" %}\n    ^^^^^^^^^^^^^^^^^^^^^^^^^\n  File \"app/templates/admin/clients/table.html\", line 10, in top-level template code\n    {{ clients|selectattr('roles', 'contains', 'SELLER')|list|length }}\n    ^^^^^^^^^^^^^^^^^^^^^^^^^\n  File \"/home/tygilman/School/CS3200/real-estate-htmx-fastapi/.venv/lib/python3.12/site-packages/jinja2/async_utils.py\", line 45, in wrapper\n    return normal_func(*args, **kwargs)\n           ^^^^^^^^^^^^^^^^^^^^^^^^^^^^\n  File \"/home/tygilman/School/CS3200/real-estate-htmx-fastapi/.venv/lib/python3.12/site-packages/jinja2/filters.py\", line 1324, in sync_do_list\n    return list(value)\n           ^^^^^^^^^^^\n  File \"/home/tygilman/School/CS3200/real-estate-htmx-fastapi/.venv/lib/python3.12/site-packages/jinja2/filters.py\", line 1765, in select_or_reject\n    if func(item):\n       ^^^^^^^^^^\n  File \"/home/tygilman/School/CS3200/real-estate-htmx-fastapi/.venv/lib/python3.12/site-packages/jinja2/filters.py\", line 1750, in <lambda>\n    return lambda item: modfunc(func(transfunc(item)))\n                                ^^^^^^^^^^^^^^^^^^^^^\n  File \"/home/tygilman/School/CS3200/real-estate-htmx-fastapi/.venv/lib/python3.12/site-packages/jinja2/filters.py\", line 1745, in func\n    return context.environment.call_test(name, item, args, kwargs)\n           ^^^^^^^^^^^^^^^^^^^^^^^^^^^^^^^^^^^^^^^^^^^^^^^^^^^^^^^\n  File \"/home/tygilman/School/CS3200/real-estate-htmx-fastapi/.venv/lib/python3.12/site-packages/jinja2/environment.py\", line 589, in call_test\n    return self._filter_test_common(\n           ^^^^^^^^^^^^^^^^^^^^^^^^^\n  File \"/home/tygilman/School/CS3200/real-estate-htmx-fastapi/.venv/lib/python3.12/site-packages/jinja2/environment.py\", line 521, in _filter_test_common\n    raise TemplateRuntimeError(msg)\njinja2.exceptions.TemplateRuntimeError: No test named 'contains'."}}
{"timestamp": "2024-11-30T21:40:05.123767", "level": "ERROR", "message": "Failed to create agent: 1305 (42000): PROCEDURE real_estate.create_agent does not exist", "module": "admin", "function": "create_agent", "line": 284, "thread_id": 135908475512640, "environment": "development", "exception": {"type": "ProgrammingError", "message": "1305 (42000): PROCEDURE real_estate.create_agent does not exist", "traceback": "Traceback (most recent call last):\n  File \"/home/tygilman/School/CS3200/real-estate-htmx-fastapi/.venv/lib/python3.12/site-packages/mysql/connector/connection_cext.py\", line 706, in cmd_query\n    self._cmysql.query(\n_mysql_connector.MySQLInterfaceError: PROCEDURE real_estate.create_agent does not exist\n\nThe above exception was the direct cause of the following exception:\n\nTraceback (most recent call last):\n  File \"/home/tygilman/School/CS3200/real-estate-htmx-fastapi/app/routes/admin.py\", line 273, in create_agent\n    execute_procedure(\n  File \"/home/tygilman/School/CS3200/real-estate-htmx-fastapi/app/core/database.py\", line 48, in execute_procedure\n    cursor.callproc(procedure_name, params)\n  File \"/home/tygilman/School/CS3200/real-estate-htmx-fastapi/.venv/lib/python3.12/site-packages/mysql/connector/cursor_cext.py\", line 566, in callproc\n    result = self._connection.cmd_query(\n             ^^^^^^^^^^^^^^^^^^^^^^^^^^^\n  File \"/home/tygilman/School/CS3200/real-estate-htmx-fastapi/.venv/lib/python3.12/site-packages/mysql/connector/opentelemetry/context_propagation.py\", line 97, in wrapper\n    return method(cnx, *args, **kwargs)\n           ^^^^^^^^^^^^^^^^^^^^^^^^^^^^\n  File \"/home/tygilman/School/CS3200/real-estate-htmx-fastapi/.venv/lib/python3.12/site-packages/mysql/connector/connection_cext.py\", line 714, in cmd_query\n    raise get_mysql_exception(\nmysql.connector.errors.ProgrammingError: 1305 (42000): PROCEDURE real_estate.create_agent does not exist"}}
{"timestamp": "2024-11-30T21:40:05.767925", "level": "ERROR", "message": "Failed to create agent: 1305 (42000): PROCEDURE real_estate.create_agent does not exist", "module": "admin", "function": "create_agent", "line": 284, "thread_id": 135908475512640, "environment": "development", "exception": {"type": "ProgrammingError", "message": "1305 (42000): PROCEDURE real_estate.create_agent does not exist", "traceback": "Traceback (most recent call last):\n  File \"/home/tygilman/School/CS3200/real-estate-htmx-fastapi/.venv/lib/python3.12/site-packages/mysql/connector/connection_cext.py\", line 706, in cmd_query\n    self._cmysql.query(\n_mysql_connector.MySQLInterfaceError: PROCEDURE real_estate.create_agent does not exist\n\nThe above exception was the direct cause of the following exception:\n\nTraceback (most recent call last):\n  File \"/home/tygilman/School/CS3200/real-estate-htmx-fastapi/app/routes/admin.py\", line 273, in create_agent\n    execute_procedure(\n  File \"/home/tygilman/School/CS3200/real-estate-htmx-fastapi/app/core/database.py\", line 48, in execute_procedure\n    cursor.callproc(procedure_name, params)\n  File \"/home/tygilman/School/CS3200/real-estate-htmx-fastapi/.venv/lib/python3.12/site-packages/mysql/connector/cursor_cext.py\", line 566, in callproc\n    result = self._connection.cmd_query(\n             ^^^^^^^^^^^^^^^^^^^^^^^^^^^\n  File \"/home/tygilman/School/CS3200/real-estate-htmx-fastapi/.venv/lib/python3.12/site-packages/mysql/connector/opentelemetry/context_propagation.py\", line 97, in wrapper\n    return method(cnx, *args, **kwargs)\n           ^^^^^^^^^^^^^^^^^^^^^^^^^^^^\n  File \"/home/tygilman/School/CS3200/real-estate-htmx-fastapi/.venv/lib/python3.12/site-packages/mysql/connector/connection_cext.py\", line 714, in cmd_query\n    raise get_mysql_exception(\nmysql.connector.errors.ProgrammingError: 1305 (42000): PROCEDURE real_estate.create_agent does not exist"}}
{"timestamp": "2024-11-30T21:40:08.208060", "level": "ERROR", "message": "Failed to create agent: 1305 (42000): PROCEDURE real_estate.create_agent does not exist", "module": "admin", "function": "create_agent", "line": 284, "thread_id": 135908475512640, "environment": "development", "exception": {"type": "ProgrammingError", "message": "1305 (42000): PROCEDURE real_estate.create_agent does not exist", "traceback": "Traceback (most recent call last):\n  File \"/home/tygilman/School/CS3200/real-estate-htmx-fastapi/.venv/lib/python3.12/site-packages/mysql/connector/connection_cext.py\", line 706, in cmd_query\n    self._cmysql.query(\n_mysql_connector.MySQLInterfaceError: PROCEDURE real_estate.create_agent does not exist\n\nThe above exception was the direct cause of the following exception:\n\nTraceback (most recent call last):\n  File \"/home/tygilman/School/CS3200/real-estate-htmx-fastapi/app/routes/admin.py\", line 273, in create_agent\n    execute_procedure(\n  File \"/home/tygilman/School/CS3200/real-estate-htmx-fastapi/app/core/database.py\", line 48, in execute_procedure\n    cursor.callproc(procedure_name, params)\n  File \"/home/tygilman/School/CS3200/real-estate-htmx-fastapi/.venv/lib/python3.12/site-packages/mysql/connector/cursor_cext.py\", line 566, in callproc\n    result = self._connection.cmd_query(\n             ^^^^^^^^^^^^^^^^^^^^^^^^^^^\n  File \"/home/tygilman/School/CS3200/real-estate-htmx-fastapi/.venv/lib/python3.12/site-packages/mysql/connector/opentelemetry/context_propagation.py\", line 97, in wrapper\n    return method(cnx, *args, **kwargs)\n           ^^^^^^^^^^^^^^^^^^^^^^^^^^^^\n  File \"/home/tygilman/School/CS3200/real-estate-htmx-fastapi/.venv/lib/python3.12/site-packages/mysql/connector/connection_cext.py\", line 714, in cmd_query\n    raise get_mysql_exception(\nmysql.connector.errors.ProgrammingError: 1305 (42000): PROCEDURE real_estate.create_agent does not exist"}}
{"timestamp": "2024-11-30T21:40:08.439732", "level": "ERROR", "message": "Failed to create agent: 1305 (42000): PROCEDURE real_estate.create_agent does not exist", "module": "admin", "function": "create_agent", "line": 284, "thread_id": 135908475512640, "environment": "development", "exception": {"type": "ProgrammingError", "message": "1305 (42000): PROCEDURE real_estate.create_agent does not exist", "traceback": "Traceback (most recent call last):\n  File \"/home/tygilman/School/CS3200/real-estate-htmx-fastapi/.venv/lib/python3.12/site-packages/mysql/connector/connection_cext.py\", line 706, in cmd_query\n    self._cmysql.query(\n_mysql_connector.MySQLInterfaceError: PROCEDURE real_estate.create_agent does not exist\n\nThe above exception was the direct cause of the following exception:\n\nTraceback (most recent call last):\n  File \"/home/tygilman/School/CS3200/real-estate-htmx-fastapi/app/routes/admin.py\", line 273, in create_agent\n    execute_procedure(\n  File \"/home/tygilman/School/CS3200/real-estate-htmx-fastapi/app/core/database.py\", line 48, in execute_procedure\n    cursor.callproc(procedure_name, params)\n  File \"/home/tygilman/School/CS3200/real-estate-htmx-fastapi/.venv/lib/python3.12/site-packages/mysql/connector/cursor_cext.py\", line 566, in callproc\n    result = self._connection.cmd_query(\n             ^^^^^^^^^^^^^^^^^^^^^^^^^^^\n  File \"/home/tygilman/School/CS3200/real-estate-htmx-fastapi/.venv/lib/python3.12/site-packages/mysql/connector/opentelemetry/context_propagation.py\", line 97, in wrapper\n    return method(cnx, *args, **kwargs)\n           ^^^^^^^^^^^^^^^^^^^^^^^^^^^^\n  File \"/home/tygilman/School/CS3200/real-estate-htmx-fastapi/.venv/lib/python3.12/site-packages/mysql/connector/connection_cext.py\", line 714, in cmd_query\n    raise get_mysql_exception(\nmysql.connector.errors.ProgrammingError: 1305 (42000): PROCEDURE real_estate.create_agent does not exist"}}
{"timestamp": "2024-11-30T21:40:09.309197", "level": "ERROR", "message": "Failed to create agent: 1305 (42000): PROCEDURE real_estate.create_agent does not exist", "module": "admin", "function": "create_agent", "line": 284, "thread_id": 135908475512640, "environment": "development", "exception": {"type": "ProgrammingError", "message": "1305 (42000): PROCEDURE real_estate.create_agent does not exist", "traceback": "Traceback (most recent call last):\n  File \"/home/tygilman/School/CS3200/real-estate-htmx-fastapi/.venv/lib/python3.12/site-packages/mysql/connector/connection_cext.py\", line 706, in cmd_query\n    self._cmysql.query(\n_mysql_connector.MySQLInterfaceError: PROCEDURE real_estate.create_agent does not exist\n\nThe above exception was the direct cause of the following exception:\n\nTraceback (most recent call last):\n  File \"/home/tygilman/School/CS3200/real-estate-htmx-fastapi/app/routes/admin.py\", line 273, in create_agent\n    execute_procedure(\n  File \"/home/tygilman/School/CS3200/real-estate-htmx-fastapi/app/core/database.py\", line 48, in execute_procedure\n    cursor.callproc(procedure_name, params)\n  File \"/home/tygilman/School/CS3200/real-estate-htmx-fastapi/.venv/lib/python3.12/site-packages/mysql/connector/cursor_cext.py\", line 566, in callproc\n    result = self._connection.cmd_query(\n             ^^^^^^^^^^^^^^^^^^^^^^^^^^^\n  File \"/home/tygilman/School/CS3200/real-estate-htmx-fastapi/.venv/lib/python3.12/site-packages/mysql/connector/opentelemetry/context_propagation.py\", line 97, in wrapper\n    return method(cnx, *args, **kwargs)\n           ^^^^^^^^^^^^^^^^^^^^^^^^^^^^\n  File \"/home/tygilman/School/CS3200/real-estate-htmx-fastapi/.venv/lib/python3.12/site-packages/mysql/connector/connection_cext.py\", line 714, in cmd_query\n    raise get_mysql_exception(\nmysql.connector.errors.ProgrammingError: 1305 (42000): PROCEDURE real_estate.create_agent does not exist"}}
{"timestamp": "2024-11-30T21:41:39.331867", "level": "ERROR", "message": "Authentication error: 1305 (42000): PROCEDURE real_estate.get_or_create_admin_role does not exist", "module": "security", "function": "get_current_user", "line": 63, "thread_id": 137540181784384, "environment": "development"}
{"timestamp": "2024-11-30T21:41:40.278911", "level": "ERROR", "message": "Authentication error: 1305 (42000): PROCEDURE real_estate.get_or_create_admin_role does not exist", "module": "security", "function": "get_current_user", "line": 63, "thread_id": 137540181784384, "environment": "development"}
{"timestamp": "2024-11-30T21:41:42.759443", "level": "ERROR", "message": "Authentication error: 1305 (42000): PROCEDURE real_estate.get_or_create_admin_role does not exist", "module": "security", "function": "get_current_user", "line": 63, "thread_id": 137540181784384, "environment": "development"}
{"timestamp": "2024-11-30T21:41:43.479220", "level": "ERROR", "message": "Authentication error: 1305 (42000): PROCEDURE real_estate.get_or_create_admin_role does not exist", "module": "security", "function": "get_current_user", "line": 63, "thread_id": 137540181784384, "environment": "development"}
{"timestamp": "2024-11-30T21:42:11.986868", "level": "ERROR", "message": "Authentication error: 1305 (42000): PROCEDURE real_estate.get_or_create_admin_role does not exist", "module": "security", "function": "get_current_user", "line": 63, "thread_id": 134798576637760, "environment": "development"}
{"timestamp": "2024-11-30T21:42:14.591157", "level": "ERROR", "message": "Authentication error: 1305 (42000): PROCEDURE real_estate.get_or_create_admin_role does not exist", "module": "security", "function": "get_current_user", "line": 63, "thread_id": 134798576637760, "environment": "development"}
{"timestamp": "2024-11-30T21:42:15.508061", "level": "ERROR", "message": "Authentication error: 1305 (42000): PROCEDURE real_estate.get_or_create_admin_role does not exist", "module": "security", "function": "get_current_user", "line": 63, "thread_id": 134798576637760, "environment": "development"}
{"timestamp": "2024-11-30T21:43:40.145009", "level": "ERROR", "message": "Authentication error: 1305 (42000): PROCEDURE real_estate.get_or_create_admin_role does not exist", "module": "security", "function": "get_current_user", "line": 63, "thread_id": 136156975662912, "environment": "development"}
{"timestamp": "2024-11-30T21:47:29.283173", "level": "ERROR", "message": "Authentication error: 1305 (42000): PROCEDURE real_estate.get_or_create_admin_role does not exist", "module": "security", "function": "get_current_user", "line": 63, "thread_id": 139465178666816, "environment": "development"}
{"timestamp": "2024-11-30T21:47:31.606985", "level": "ERROR", "message": "Authentication error: 1305 (42000): PROCEDURE real_estate.get_or_create_admin_role does not exist", "module": "security", "function": "get_current_user", "line": 63, "thread_id": 139465178666816, "environment": "development"}
{"timestamp": "2024-11-30T21:49:38.984191", "level": "ERROR", "message": "Authentication error: 1305 (42000): PROCEDURE real_estate.get_or_create_admin_role does not exist", "module": "security", "function": "get_current_user", "line": 63, "thread_id": 129019965007680, "environment": "development"}
{"timestamp": "2024-11-30T21:50:52.522817", "level": "ERROR", "message": "Authentication error: 1305 (42000): PROCEDURE real_estate.get_or_create_admin_role does not exist", "module": "security", "function": "get_current_user", "line": 63, "thread_id": 124979606251328, "environment": "development"}
{"timestamp": "2024-11-30T21:50:55.458953", "level": "ERROR", "message": "Error fetching properties: 1305 (42000): PROCEDURE real_estate.get_all_properties_with_details does not exist", "module": "main", "function": "index", "line": 36, "thread_id": 124979606251328, "environment": "development"}
{"timestamp": "2024-11-30T21:51:18.993693", "level": "ERROR", "message": "Database error during authentication: 1305 (42000): PROCEDURE real_estate.get_or_create_admin_role does not exist", "module": "auth", "function": "authenticate_user", "line": 58, "thread_id": 124979606251328, "environment": "development"}
{"timestamp": "2024-11-30T21:51:39.933741", "level": "ERROR", "message": "Database error during authentication: 1305 (42000): PROCEDURE real_estate.get_or_create_admin_role does not exist", "module": "auth", "function": "authenticate_user", "line": 58, "thread_id": 124979606251328, "environment": "development"}
{"timestamp": "2024-11-30T21:54:16.558615", "level": "ERROR", "message": "Authentication error: 1305 (42000): PROCEDURE real_estate.get_or_create_admin_role does not exist", "module": "security", "function": "get_current_user", "line": 63, "thread_id": 129888780801856, "environment": "development"}
{"timestamp": "2024-11-30T21:54:17.827922", "level": "ERROR", "message": "Authentication error: 1305 (42000): PROCEDURE real_estate.get_or_create_admin_role does not exist", "module": "security", "function": "get_current_user", "line": 63, "thread_id": 129888780801856, "environment": "development"}
{"timestamp": "2024-11-30T22:55:24.962772", "level": "ERROR", "message": "Error fetching properties: 1305 (42000): PROCEDURE real_estate.get_all_properties_with_details does not exist", "module": "main", "function": "index", "line": 36, "thread_id": 133575989339968, "environment": "development"}
{"timestamp": "2024-11-30T22:55:30.182584", "level": "ERROR", "message": "Authentication error: 1305 (42000): PROCEDURE real_estate.get_or_create_admin_role does not exist", "module": "security", "function": "get_current_user", "line": 63, "thread_id": 133575989339968, "environment": "development"}
{"timestamp": "2024-11-30T22:55:31.047712", "level": "ERROR", "message": "Authentication error: 1305 (42000): PROCEDURE real_estate.get_or_create_admin_role does not exist", "module": "security", "function": "get_current_user", "line": 63, "thread_id": 133575989339968, "environment": "development"}
{"timestamp": "2024-11-30T22:55:32.286760", "level": "ERROR", "message": "Authentication error: 1305 (42000): PROCEDURE real_estate.get_or_create_admin_role does not exist", "module": "security", "function": "get_current_user", "line": 63, "thread_id": 133575989339968, "environment": "development"}
{"timestamp": "2024-11-30T22:55:32.795486", "level": "ERROR", "message": "Authentication error: 1305 (42000): PROCEDURE real_estate.get_or_create_admin_role does not exist", "module": "security", "function": "get_current_user", "line": 63, "thread_id": 133575989339968, "environment": "development"}
{"timestamp": "2024-11-30T22:57:06.191790", "level": "ERROR", "message": "Authentication error: 1305 (42000): PROCEDURE real_estate.get_or_create_admin_role does not exist", "module": "security", "function": "get_current_user", "line": 63, "thread_id": 135772870121280, "environment": "development"}
{"timestamp": "2024-11-30T22:57:06.633188", "level": "ERROR", "message": "Authentication error: 1305 (42000): PROCEDURE real_estate.get_or_create_admin_role does not exist", "module": "security", "function": "get_current_user", "line": 63, "thread_id": 135772870121280, "environment": "development"}
{"timestamp": "2024-11-30T23:05:05.530904", "level": "ERROR", "message": "Authentication error: 1305 (42000): PROCEDURE real_estate.get_or_create_admin_role does not exist", "module": "security", "function": "get_current_user", "line": 63, "thread_id": 125008100501312, "environment": "development"}
{"timestamp": "2024-11-30T23:05:07.456721", "level": "ERROR", "message": "Authentication error: 1305 (42000): PROCEDURE real_estate.get_or_create_admin_role does not exist", "module": "security", "function": "get_current_user", "line": 63, "thread_id": 125008100501312, "environment": "development"}
{"timestamp": "2024-11-30T23:05:08.459151", "level": "ERROR", "message": "Authentication error: 1305 (42000): PROCEDURE real_estate.get_or_create_admin_role does not exist", "module": "security", "function": "get_current_user", "line": 63, "thread_id": 125008100501312, "environment": "development"}
{"timestamp": "2024-11-30T23:05:14.846739", "level": "ERROR", "message": "Error fetching properties: 1305 (42000): PROCEDURE real_estate.get_all_properties_with_details does not exist", "module": "main", "function": "index", "line": 36, "thread_id": 125008100501312, "environment": "development"}
{"timestamp": "2024-11-30T23:05:26.333089", "level": "ERROR", "message": "Database error during authentication: 1305 (42000): PROCEDURE real_estate.get_or_create_admin_role does not exist", "module": "auth", "function": "authenticate_user", "line": 58, "thread_id": 125008100501312, "environment": "development"}
{"timestamp": "2024-11-30T23:18:10.343909", "level": "ERROR", "message": "Dashboard error: 1305 (42000): PROCEDURE real_estate.get_all_clients does not exist", "module": "admin", "function": "admin_dashboard", "line": 51, "thread_id": 136547089602368, "environment": "development", "exception": {"type": "ProgrammingError", "message": "1305 (42000): PROCEDURE real_estate.get_all_clients does not exist", "traceback": "Traceback (most recent call last):\n  File \"/home/tygilman/School/CS3200/real-estate-htmx-fastapi/.venv/lib/python3.12/site-packages/mysql/connector/connection_cext.py\", line 706, in cmd_query\n    self._cmysql.query(\n_mysql_connector.MySQLInterfaceError: PROCEDURE real_estate.get_all_clients does not exist\n\nThe above exception was the direct cause of the following exception:\n\nTraceback (most recent call last):\n  File \"/home/tygilman/School/CS3200/real-estate-htmx-fastapi/app/routes/admin.py\", line 24, in admin_dashboard\n    clients = execute_procedure(conn, 'get_all_clients')\n              ^^^^^^^^^^^^^^^^^^^^^^^^^^^^^^^^^^^^^^^^^^\n  File \"/home/tygilman/School/CS3200/real-estate-htmx-fastapi/app/core/database.py\", line 48, in execute_procedure\n    cursor.callproc(procedure_name, params)\n  File \"/home/tygilman/School/CS3200/real-estate-htmx-fastapi/.venv/lib/python3.12/site-packages/mysql/connector/cursor_cext.py\", line 566, in callproc\n    result = self._connection.cmd_query(\n             ^^^^^^^^^^^^^^^^^^^^^^^^^^^\n  File \"/home/tygilman/School/CS3200/real-estate-htmx-fastapi/.venv/lib/python3.12/site-packages/mysql/connector/opentelemetry/context_propagation.py\", line 97, in wrapper\n    return method(cnx, *args, **kwargs)\n           ^^^^^^^^^^^^^^^^^^^^^^^^^^^^\n  File \"/home/tygilman/School/CS3200/real-estate-htmx-fastapi/.venv/lib/python3.12/site-packages/mysql/connector/connection_cext.py\", line 714, in cmd_query\n    raise get_mysql_exception(\nmysql.connector.errors.ProgrammingError: 1305 (42000): PROCEDURE real_estate.get_all_clients does not exist"}}
{"timestamp": "2024-11-30T23:41:15.234070", "level": "ERROR", "message": "Dashboard error: 1305 (42000): PROCEDURE real_estate.get_all_clients does not exist", "module": "admin", "function": "admin_dashboard", "line": 51, "thread_id": 134023966758720, "environment": "development", "exception": {"type": "ProgrammingError", "message": "1305 (42000): PROCEDURE real_estate.get_all_clients does not exist", "traceback": "Traceback (most recent call last):\n  File \"/home/tygilman/School/CS3200/real-estate-htmx-fastapi/.venv/lib/python3.12/site-packages/mysql/connector/connection_cext.py\", line 706, in cmd_query\n    self._cmysql.query(\n_mysql_connector.MySQLInterfaceError: PROCEDURE real_estate.get_all_clients does not exist\n\nThe above exception was the direct cause of the following exception:\n\nTraceback (most recent call last):\n  File \"/home/tygilman/School/CS3200/real-estate-htmx-fastapi/app/routes/admin.py\", line 24, in admin_dashboard\n    clients = execute_procedure(conn, 'get_all_clients')\n              ^^^^^^^^^^^^^^^^^^^^^^^^^^^^^^^^^^^^^^^^^^\n  File \"/home/tygilman/School/CS3200/real-estate-htmx-fastapi/app/core/database.py\", line 48, in execute_procedure\n    cursor.callproc(procedure_name, params)\n  File \"/home/tygilman/School/CS3200/real-estate-htmx-fastapi/.venv/lib/python3.12/site-packages/mysql/connector/cursor_cext.py\", line 566, in callproc\n    result = self._connection.cmd_query(\n             ^^^^^^^^^^^^^^^^^^^^^^^^^^^\n  File \"/home/tygilman/School/CS3200/real-estate-htmx-fastapi/.venv/lib/python3.12/site-packages/mysql/connector/opentelemetry/context_propagation.py\", line 97, in wrapper\n    return method(cnx, *args, **kwargs)\n           ^^^^^^^^^^^^^^^^^^^^^^^^^^^^\n  File \"/home/tygilman/School/CS3200/real-estate-htmx-fastapi/.venv/lib/python3.12/site-packages/mysql/connector/connection_cext.py\", line 714, in cmd_query\n    raise get_mysql_exception(\nmysql.connector.errors.ProgrammingError: 1305 (42000): PROCEDURE real_estate.get_all_clients does not exist"}}
{"timestamp": "2024-11-30T23:41:18.834391", "level": "ERROR", "message": "Dashboard error: 1305 (42000): PROCEDURE real_estate.get_all_clients does not exist", "module": "admin", "function": "admin_dashboard", "line": 51, "thread_id": 134023966758720, "environment": "development", "exception": {"type": "ProgrammingError", "message": "1305 (42000): PROCEDURE real_estate.get_all_clients does not exist", "traceback": "Traceback (most recent call last):\n  File \"/home/tygilman/School/CS3200/real-estate-htmx-fastapi/.venv/lib/python3.12/site-packages/mysql/connector/connection_cext.py\", line 706, in cmd_query\n    self._cmysql.query(\n_mysql_connector.MySQLInterfaceError: PROCEDURE real_estate.get_all_clients does not exist\n\nThe above exception was the direct cause of the following exception:\n\nTraceback (most recent call last):\n  File \"/home/tygilman/School/CS3200/real-estate-htmx-fastapi/app/routes/admin.py\", line 24, in admin_dashboard\n    clients = execute_procedure(conn, 'get_all_clients')\n              ^^^^^^^^^^^^^^^^^^^^^^^^^^^^^^^^^^^^^^^^^^\n  File \"/home/tygilman/School/CS3200/real-estate-htmx-fastapi/app/core/database.py\", line 48, in execute_procedure\n    cursor.callproc(procedure_name, params)\n  File \"/home/tygilman/School/CS3200/real-estate-htmx-fastapi/.venv/lib/python3.12/site-packages/mysql/connector/cursor_cext.py\", line 566, in callproc\n    result = self._connection.cmd_query(\n             ^^^^^^^^^^^^^^^^^^^^^^^^^^^\n  File \"/home/tygilman/School/CS3200/real-estate-htmx-fastapi/.venv/lib/python3.12/site-packages/mysql/connector/opentelemetry/context_propagation.py\", line 97, in wrapper\n    return method(cnx, *args, **kwargs)\n           ^^^^^^^^^^^^^^^^^^^^^^^^^^^^\n  File \"/home/tygilman/School/CS3200/real-estate-htmx-fastapi/.venv/lib/python3.12/site-packages/mysql/connector/connection_cext.py\", line 714, in cmd_query\n    raise get_mysql_exception(\nmysql.connector.errors.ProgrammingError: 1305 (42000): PROCEDURE real_estate.get_all_clients does not exist"}}
{"timestamp": "2024-11-30T23:41:19.458936", "level": "ERROR", "message": "Dashboard error: 1305 (42000): PROCEDURE real_estate.get_all_clients does not exist", "module": "admin", "function": "admin_dashboard", "line": 51, "thread_id": 134023966758720, "environment": "development", "exception": {"type": "ProgrammingError", "message": "1305 (42000): PROCEDURE real_estate.get_all_clients does not exist", "traceback": "Traceback (most recent call last):\n  File \"/home/tygilman/School/CS3200/real-estate-htmx-fastapi/.venv/lib/python3.12/site-packages/mysql/connector/connection_cext.py\", line 706, in cmd_query\n    self._cmysql.query(\n_mysql_connector.MySQLInterfaceError: PROCEDURE real_estate.get_all_clients does not exist\n\nThe above exception was the direct cause of the following exception:\n\nTraceback (most recent call last):\n  File \"/home/tygilman/School/CS3200/real-estate-htmx-fastapi/app/routes/admin.py\", line 24, in admin_dashboard\n    clients = execute_procedure(conn, 'get_all_clients')\n              ^^^^^^^^^^^^^^^^^^^^^^^^^^^^^^^^^^^^^^^^^^\n  File \"/home/tygilman/School/CS3200/real-estate-htmx-fastapi/app/core/database.py\", line 48, in execute_procedure\n    cursor.callproc(procedure_name, params)\n  File \"/home/tygilman/School/CS3200/real-estate-htmx-fastapi/.venv/lib/python3.12/site-packages/mysql/connector/cursor_cext.py\", line 566, in callproc\n    result = self._connection.cmd_query(\n             ^^^^^^^^^^^^^^^^^^^^^^^^^^^\n  File \"/home/tygilman/School/CS3200/real-estate-htmx-fastapi/.venv/lib/python3.12/site-packages/mysql/connector/opentelemetry/context_propagation.py\", line 97, in wrapper\n    return method(cnx, *args, **kwargs)\n           ^^^^^^^^^^^^^^^^^^^^^^^^^^^^\n  File \"/home/tygilman/School/CS3200/real-estate-htmx-fastapi/.venv/lib/python3.12/site-packages/mysql/connector/connection_cext.py\", line 714, in cmd_query\n    raise get_mysql_exception(\nmysql.connector.errors.ProgrammingError: 1305 (42000): PROCEDURE real_estate.get_all_clients does not exist"}}
{"timestamp": "2024-11-30T23:45:03.517695", "level": "ERROR", "message": "Dashboard error: 1054 (42S22): Unknown column 'last_modified' in 'field list'", "module": "admin", "function": "admin_dashboard", "line": 51, "thread_id": 129491351697216, "environment": "development", "exception": {"type": "ProgrammingError", "message": "1054 (42S22): Unknown column 'last_modified' in 'field list'", "traceback": "Traceback (most recent call last):\n  File \"/home/tygilman/School/CS3200/real-estate-htmx-fastapi/.venv/lib/python3.12/site-packages/mysql/connector/connection_cext.py\", line 706, in cmd_query\n    self._cmysql.query(\n_mysql_connector.MySQLInterfaceError: Unknown column 'last_modified' in 'field list'\n\nThe above exception was the direct cause of the following exception:\n\nTraceback (most recent call last):\n  File \"/home/tygilman/School/CS3200/real-estate-htmx-fastapi/app/routes/admin.py\", line 24, in admin_dashboard\n    clients = execute_procedure(conn, 'get_all_clients')\n              ^^^^^^^^^^^^^^^^^^^^^^^^^^^^^^^^^^^^^^^^^^\n  File \"/home/tygilman/School/CS3200/real-estate-htmx-fastapi/app/core/database.py\", line 48, in execute_procedure\n    cursor.callproc(procedure_name, params)\n  File \"/home/tygilman/School/CS3200/real-estate-htmx-fastapi/.venv/lib/python3.12/site-packages/mysql/connector/cursor_cext.py\", line 566, in callproc\n    result = self._connection.cmd_query(\n             ^^^^^^^^^^^^^^^^^^^^^^^^^^^\n  File \"/home/tygilman/School/CS3200/real-estate-htmx-fastapi/.venv/lib/python3.12/site-packages/mysql/connector/opentelemetry/context_propagation.py\", line 97, in wrapper\n    return method(cnx, *args, **kwargs)\n           ^^^^^^^^^^^^^^^^^^^^^^^^^^^^\n  File \"/home/tygilman/School/CS3200/real-estate-htmx-fastapi/.venv/lib/python3.12/site-packages/mysql/connector/connection_cext.py\", line 714, in cmd_query\n    raise get_mysql_exception(\nmysql.connector.errors.ProgrammingError: 1054 (42S22): Unknown column 'last_modified' in 'field list'"}}
{"timestamp": "2024-11-30T23:47:25.212245", "level": "ERROR", "message": "Dashboard error: 1305 (42000): PROCEDURE real_estate.get_all_clients does not exist", "module": "admin", "function": "admin_dashboard", "line": 51, "thread_id": 123323617937216, "environment": "development", "exception": {"type": "ProgrammingError", "message": "1305 (42000): PROCEDURE real_estate.get_all_clients does not exist", "traceback": "Traceback (most recent call last):\n  File \"/home/tygilman/School/CS3200/real-estate-htmx-fastapi/.venv/lib/python3.12/site-packages/mysql/connector/connection_cext.py\", line 706, in cmd_query\n    self._cmysql.query(\n_mysql_connector.MySQLInterfaceError: PROCEDURE real_estate.get_all_clients does not exist\n\nThe above exception was the direct cause of the following exception:\n\nTraceback (most recent call last):\n  File \"/home/tygilman/School/CS3200/real-estate-htmx-fastapi/app/routes/admin.py\", line 24, in admin_dashboard\n    clients = execute_procedure(conn, 'get_all_clients')\n              ^^^^^^^^^^^^^^^^^^^^^^^^^^^^^^^^^^^^^^^^^^\n  File \"/home/tygilman/School/CS3200/real-estate-htmx-fastapi/app/core/database.py\", line 48, in execute_procedure\n    cursor.callproc(procedure_name, params)\n  File \"/home/tygilman/School/CS3200/real-estate-htmx-fastapi/.venv/lib/python3.12/site-packages/mysql/connector/cursor_cext.py\", line 566, in callproc\n    result = self._connection.cmd_query(\n             ^^^^^^^^^^^^^^^^^^^^^^^^^^^\n  File \"/home/tygilman/School/CS3200/real-estate-htmx-fastapi/.venv/lib/python3.12/site-packages/mysql/connector/opentelemetry/context_propagation.py\", line 97, in wrapper\n    return method(cnx, *args, **kwargs)\n           ^^^^^^^^^^^^^^^^^^^^^^^^^^^^\n  File \"/home/tygilman/School/CS3200/real-estate-htmx-fastapi/.venv/lib/python3.12/site-packages/mysql/connector/connection_cext.py\", line 714, in cmd_query\n    raise get_mysql_exception(\nmysql.connector.errors.ProgrammingError: 1305 (42000): PROCEDURE real_estate.get_all_clients does not exist"}}
{"timestamp": "2024-11-30T23:47:26.748125", "level": "ERROR", "message": "Dashboard error: 1305 (42000): PROCEDURE real_estate.get_all_clients does not exist", "module": "admin", "function": "admin_dashboard", "line": 51, "thread_id": 123323617937216, "environment": "development", "exception": {"type": "ProgrammingError", "message": "1305 (42000): PROCEDURE real_estate.get_all_clients does not exist", "traceback": "Traceback (most recent call last):\n  File \"/home/tygilman/School/CS3200/real-estate-htmx-fastapi/.venv/lib/python3.12/site-packages/mysql/connector/connection_cext.py\", line 706, in cmd_query\n    self._cmysql.query(\n_mysql_connector.MySQLInterfaceError: PROCEDURE real_estate.get_all_clients does not exist\n\nThe above exception was the direct cause of the following exception:\n\nTraceback (most recent call last):\n  File \"/home/tygilman/School/CS3200/real-estate-htmx-fastapi/app/routes/admin.py\", line 24, in admin_dashboard\n    clients = execute_procedure(conn, 'get_all_clients')\n              ^^^^^^^^^^^^^^^^^^^^^^^^^^^^^^^^^^^^^^^^^^\n  File \"/home/tygilman/School/CS3200/real-estate-htmx-fastapi/app/core/database.py\", line 48, in execute_procedure\n    cursor.callproc(procedure_name, params)\n  File \"/home/tygilman/School/CS3200/real-estate-htmx-fastapi/.venv/lib/python3.12/site-packages/mysql/connector/cursor_cext.py\", line 566, in callproc\n    result = self._connection.cmd_query(\n             ^^^^^^^^^^^^^^^^^^^^^^^^^^^\n  File \"/home/tygilman/School/CS3200/real-estate-htmx-fastapi/.venv/lib/python3.12/site-packages/mysql/connector/opentelemetry/context_propagation.py\", line 97, in wrapper\n    return method(cnx, *args, **kwargs)\n           ^^^^^^^^^^^^^^^^^^^^^^^^^^^^\n  File \"/home/tygilman/School/CS3200/real-estate-htmx-fastapi/.venv/lib/python3.12/site-packages/mysql/connector/connection_cext.py\", line 714, in cmd_query\n    raise get_mysql_exception(\nmysql.connector.errors.ProgrammingError: 1305 (42000): PROCEDURE real_estate.get_all_clients does not exist"}}
{"timestamp": "2024-11-30T23:47:27.021627", "level": "ERROR", "message": "Dashboard error: 1305 (42000): PROCEDURE real_estate.get_all_clients does not exist", "module": "admin", "function": "admin_dashboard", "line": 51, "thread_id": 123323617937216, "environment": "development", "exception": {"type": "ProgrammingError", "message": "1305 (42000): PROCEDURE real_estate.get_all_clients does not exist", "traceback": "Traceback (most recent call last):\n  File \"/home/tygilman/School/CS3200/real-estate-htmx-fastapi/.venv/lib/python3.12/site-packages/mysql/connector/connection_cext.py\", line 706, in cmd_query\n    self._cmysql.query(\n_mysql_connector.MySQLInterfaceError: PROCEDURE real_estate.get_all_clients does not exist\n\nThe above exception was the direct cause of the following exception:\n\nTraceback (most recent call last):\n  File \"/home/tygilman/School/CS3200/real-estate-htmx-fastapi/app/routes/admin.py\", line 24, in admin_dashboard\n    clients = execute_procedure(conn, 'get_all_clients')\n              ^^^^^^^^^^^^^^^^^^^^^^^^^^^^^^^^^^^^^^^^^^\n  File \"/home/tygilman/School/CS3200/real-estate-htmx-fastapi/app/core/database.py\", line 48, in execute_procedure\n    cursor.callproc(procedure_name, params)\n  File \"/home/tygilman/School/CS3200/real-estate-htmx-fastapi/.venv/lib/python3.12/site-packages/mysql/connector/cursor_cext.py\", line 566, in callproc\n    result = self._connection.cmd_query(\n             ^^^^^^^^^^^^^^^^^^^^^^^^^^^\n  File \"/home/tygilman/School/CS3200/real-estate-htmx-fastapi/.venv/lib/python3.12/site-packages/mysql/connector/opentelemetry/context_propagation.py\", line 97, in wrapper\n    return method(cnx, *args, **kwargs)\n           ^^^^^^^^^^^^^^^^^^^^^^^^^^^^\n  File \"/home/tygilman/School/CS3200/real-estate-htmx-fastapi/.venv/lib/python3.12/site-packages/mysql/connector/connection_cext.py\", line 714, in cmd_query\n    raise get_mysql_exception(\nmysql.connector.errors.ProgrammingError: 1305 (42000): PROCEDURE real_estate.get_all_clients does not exist"}}
{"timestamp": "2024-11-30T23:48:46.423450", "level": "ERROR", "message": "Dashboard error: 1305 (42000): PROCEDURE real_estate.get_all_clients does not exist", "module": "admin", "function": "admin_dashboard", "line": 51, "thread_id": 127966295050048, "environment": "development", "exception": {"type": "ProgrammingError", "message": "1305 (42000): PROCEDURE real_estate.get_all_clients does not exist", "traceback": "Traceback (most recent call last):\n  File \"/home/tygilman/School/CS3200/real-estate-htmx-fastapi/.venv/lib/python3.12/site-packages/mysql/connector/connection_cext.py\", line 706, in cmd_query\n    self._cmysql.query(\n_mysql_connector.MySQLInterfaceError: PROCEDURE real_estate.get_all_clients does not exist\n\nThe above exception was the direct cause of the following exception:\n\nTraceback (most recent call last):\n  File \"/home/tygilman/School/CS3200/real-estate-htmx-fastapi/app/routes/admin.py\", line 24, in admin_dashboard\n    clients = execute_procedure(conn, 'get_all_clients')\n              ^^^^^^^^^^^^^^^^^^^^^^^^^^^^^^^^^^^^^^^^^^\n  File \"/home/tygilman/School/CS3200/real-estate-htmx-fastapi/app/core/database.py\", line 48, in execute_procedure\n    cursor.callproc(procedure_name, params)\n  File \"/home/tygilman/School/CS3200/real-estate-htmx-fastapi/.venv/lib/python3.12/site-packages/mysql/connector/cursor_cext.py\", line 566, in callproc\n    result = self._connection.cmd_query(\n             ^^^^^^^^^^^^^^^^^^^^^^^^^^^\n  File \"/home/tygilman/School/CS3200/real-estate-htmx-fastapi/.venv/lib/python3.12/site-packages/mysql/connector/opentelemetry/context_propagation.py\", line 97, in wrapper\n    return method(cnx, *args, **kwargs)\n           ^^^^^^^^^^^^^^^^^^^^^^^^^^^^\n  File \"/home/tygilman/School/CS3200/real-estate-htmx-fastapi/.venv/lib/python3.12/site-packages/mysql/connector/connection_cext.py\", line 714, in cmd_query\n    raise get_mysql_exception(\nmysql.connector.errors.ProgrammingError: 1305 (42000): PROCEDURE real_estate.get_all_clients does not exist"}}
{"timestamp": "2024-11-30T23:51:14.450029", "level": "ERROR", "message": "Dashboard error: 1305 (42000): PROCEDURE real_estate.get_all_clients does not exist", "module": "admin", "function": "admin_dashboard", "line": 51, "thread_id": 131499009980224, "environment": "development", "exception": {"type": "ProgrammingError", "message": "1305 (42000): PROCEDURE real_estate.get_all_clients does not exist", "traceback": "Traceback (most recent call last):\n  File \"/home/tygilman/School/CS3200/real-estate-htmx-fastapi/.venv/lib/python3.12/site-packages/mysql/connector/connection_cext.py\", line 706, in cmd_query\n    self._cmysql.query(\n_mysql_connector.MySQLInterfaceError: PROCEDURE real_estate.get_all_clients does not exist\n\nThe above exception was the direct cause of the following exception:\n\nTraceback (most recent call last):\n  File \"/home/tygilman/School/CS3200/real-estate-htmx-fastapi/app/routes/admin.py\", line 24, in admin_dashboard\n    clients = execute_procedure(conn, 'get_all_clients')\n              ^^^^^^^^^^^^^^^^^^^^^^^^^^^^^^^^^^^^^^^^^^\n  File \"/home/tygilman/School/CS3200/real-estate-htmx-fastapi/app/core/database.py\", line 48, in execute_procedure\n    cursor.callproc(procedure_name, params)\n  File \"/home/tygilman/School/CS3200/real-estate-htmx-fastapi/.venv/lib/python3.12/site-packages/mysql/connector/cursor_cext.py\", line 566, in callproc\n    result = self._connection.cmd_query(\n             ^^^^^^^^^^^^^^^^^^^^^^^^^^^\n  File \"/home/tygilman/School/CS3200/real-estate-htmx-fastapi/.venv/lib/python3.12/site-packages/mysql/connector/opentelemetry/context_propagation.py\", line 97, in wrapper\n    return method(cnx, *args, **kwargs)\n           ^^^^^^^^^^^^^^^^^^^^^^^^^^^^\n  File \"/home/tygilman/School/CS3200/real-estate-htmx-fastapi/.venv/lib/python3.12/site-packages/mysql/connector/connection_cext.py\", line 714, in cmd_query\n    raise get_mysql_exception(\nmysql.connector.errors.ProgrammingError: 1305 (42000): PROCEDURE real_estate.get_all_clients does not exist"}}
{"timestamp": "2024-11-30T23:51:15.245330", "level": "ERROR", "message": "Dashboard error: 1305 (42000): PROCEDURE real_estate.get_all_clients does not exist", "module": "admin", "function": "admin_dashboard", "line": 51, "thread_id": 131499009980224, "environment": "development", "exception": {"type": "ProgrammingError", "message": "1305 (42000): PROCEDURE real_estate.get_all_clients does not exist", "traceback": "Traceback (most recent call last):\n  File \"/home/tygilman/School/CS3200/real-estate-htmx-fastapi/.venv/lib/python3.12/site-packages/mysql/connector/connection_cext.py\", line 706, in cmd_query\n    self._cmysql.query(\n_mysql_connector.MySQLInterfaceError: PROCEDURE real_estate.get_all_clients does not exist\n\nThe above exception was the direct cause of the following exception:\n\nTraceback (most recent call last):\n  File \"/home/tygilman/School/CS3200/real-estate-htmx-fastapi/app/routes/admin.py\", line 24, in admin_dashboard\n    clients = execute_procedure(conn, 'get_all_clients')\n              ^^^^^^^^^^^^^^^^^^^^^^^^^^^^^^^^^^^^^^^^^^\n  File \"/home/tygilman/School/CS3200/real-estate-htmx-fastapi/app/core/database.py\", line 48, in execute_procedure\n    cursor.callproc(procedure_name, params)\n  File \"/home/tygilman/School/CS3200/real-estate-htmx-fastapi/.venv/lib/python3.12/site-packages/mysql/connector/cursor_cext.py\", line 566, in callproc\n    result = self._connection.cmd_query(\n             ^^^^^^^^^^^^^^^^^^^^^^^^^^^\n  File \"/home/tygilman/School/CS3200/real-estate-htmx-fastapi/.venv/lib/python3.12/site-packages/mysql/connector/opentelemetry/context_propagation.py\", line 97, in wrapper\n    return method(cnx, *args, **kwargs)\n           ^^^^^^^^^^^^^^^^^^^^^^^^^^^^\n  File \"/home/tygilman/School/CS3200/real-estate-htmx-fastapi/.venv/lib/python3.12/site-packages/mysql/connector/connection_cext.py\", line 714, in cmd_query\n    raise get_mysql_exception(\nmysql.connector.errors.ProgrammingError: 1305 (42000): PROCEDURE real_estate.get_all_clients does not exist"}}
{"timestamp": "2024-11-30T23:53:46.373160", "level": "ERROR", "message": "Dashboard error: 1305 (42000): PROCEDURE real_estate.get_all_clients does not exist", "module": "admin", "function": "admin_dashboard", "line": 51, "thread_id": 126728265918272, "environment": "development", "exception": {"type": "ProgrammingError", "message": "1305 (42000): PROCEDURE real_estate.get_all_clients does not exist", "traceback": "Traceback (most recent call last):\n  File \"/home/tygilman/School/CS3200/real-estate-htmx-fastapi/.venv/lib/python3.12/site-packages/mysql/connector/connection_cext.py\", line 706, in cmd_query\n    self._cmysql.query(\n_mysql_connector.MySQLInterfaceError: PROCEDURE real_estate.get_all_clients does not exist\n\nThe above exception was the direct cause of the following exception:\n\nTraceback (most recent call last):\n  File \"/home/tygilman/School/CS3200/real-estate-htmx-fastapi/app/routes/admin.py\", line 24, in admin_dashboard\n    clients = execute_procedure(conn, 'get_all_clients')\n              ^^^^^^^^^^^^^^^^^^^^^^^^^^^^^^^^^^^^^^^^^^\n  File \"/home/tygilman/School/CS3200/real-estate-htmx-fastapi/app/core/database.py\", line 48, in execute_procedure\n    cursor.callproc(procedure_name, params)\n  File \"/home/tygilman/School/CS3200/real-estate-htmx-fastapi/.venv/lib/python3.12/site-packages/mysql/connector/cursor_cext.py\", line 566, in callproc\n    result = self._connection.cmd_query(\n             ^^^^^^^^^^^^^^^^^^^^^^^^^^^\n  File \"/home/tygilman/School/CS3200/real-estate-htmx-fastapi/.venv/lib/python3.12/site-packages/mysql/connector/opentelemetry/context_propagation.py\", line 97, in wrapper\n    return method(cnx, *args, **kwargs)\n           ^^^^^^^^^^^^^^^^^^^^^^^^^^^^\n  File \"/home/tygilman/School/CS3200/real-estate-htmx-fastapi/.venv/lib/python3.12/site-packages/mysql/connector/connection_cext.py\", line 714, in cmd_query\n    raise get_mysql_exception(\nmysql.connector.errors.ProgrammingError: 1305 (42000): PROCEDURE real_estate.get_all_clients does not exist"}}
{"timestamp": "2024-11-30T23:58:10.094281", "level": "ERROR", "message": "Dashboard error: 1305 (42000): PROCEDURE real_estate.get_admin_dashboard_stats does not exist", "module": "admin", "function": "admin_dashboard", "line": 51, "thread_id": 137169189275456, "environment": "development", "exception": {"type": "ProgrammingError", "message": "1305 (42000): PROCEDURE real_estate.get_admin_dashboard_stats does not exist", "traceback": "Traceback (most recent call last):\n  File \"/home/tygilman/School/CS3200/real-estate-htmx-fastapi/.venv/lib/python3.12/site-packages/mysql/connector/connection_cext.py\", line 706, in cmd_query\n    self._cmysql.query(\n_mysql_connector.MySQLInterfaceError: PROCEDURE real_estate.get_admin_dashboard_stats does not exist\n\nThe above exception was the direct cause of the following exception:\n\nTraceback (most recent call last):\n  File \"/home/tygilman/School/CS3200/real-estate-htmx-fastapi/app/routes/admin.py\", line 41, in admin_dashboard\n    dashboard_stats = execute_procedure(conn, 'get_admin_dashboard_stats')\n                      ^^^^^^^^^^^^^^^^^^^^^^^^^^^^^^^^^^^^^^^^^^^^^^^^^^^^\n  File \"/home/tygilman/School/CS3200/real-estate-htmx-fastapi/app/core/database.py\", line 48, in execute_procedure\n    cursor.callproc(procedure_name, params)\n  File \"/home/tygilman/School/CS3200/real-estate-htmx-fastapi/.venv/lib/python3.12/site-packages/mysql/connector/cursor_cext.py\", line 566, in callproc\n    result = self._connection.cmd_query(\n             ^^^^^^^^^^^^^^^^^^^^^^^^^^^\n  File \"/home/tygilman/School/CS3200/real-estate-htmx-fastapi/.venv/lib/python3.12/site-packages/mysql/connector/opentelemetry/context_propagation.py\", line 97, in wrapper\n    return method(cnx, *args, **kwargs)\n           ^^^^^^^^^^^^^^^^^^^^^^^^^^^^\n  File \"/home/tygilman/School/CS3200/real-estate-htmx-fastapi/.venv/lib/python3.12/site-packages/mysql/connector/connection_cext.py\", line 714, in cmd_query\n    raise get_mysql_exception(\nmysql.connector.errors.ProgrammingError: 1305 (42000): PROCEDURE real_estate.get_admin_dashboard_stats does not exist"}}
{"timestamp": "2024-11-30T23:59:21.002968", "level": "ERROR", "message": "Dashboard error: 1146 (42S02): Table 'real_estate.Users' doesn't exist", "module": "admin", "function": "admin_dashboard", "line": 51, "thread_id": 131229935187776, "environment": "development", "exception": {"type": "ProgrammingError", "message": "1146 (42S02): Table 'real_estate.Users' doesn't exist", "traceback": "Traceback (most recent call last):\n  File \"/home/tygilman/School/CS3200/real-estate-htmx-fastapi/.venv/lib/python3.12/site-packages/mysql/connector/connection_cext.py\", line 706, in cmd_query\n    self._cmysql.query(\n_mysql_connector.MySQLInterfaceError: Table 'real_estate.Users' doesn't exist\n\nThe above exception was the direct cause of the following exception:\n\nTraceback (most recent call last):\n  File \"/home/tygilman/School/CS3200/real-estate-htmx-fastapi/app/routes/admin.py\", line 41, in admin_dashboard\n    dashboard_stats = execute_procedure(conn, 'get_admin_dashboard_stats')\n                      ^^^^^^^^^^^^^^^^^^^^^^^^^^^^^^^^^^^^^^^^^^^^^^^^^^^^\n  File \"/home/tygilman/School/CS3200/real-estate-htmx-fastapi/app/core/database.py\", line 48, in execute_procedure\n    cursor.callproc(procedure_name, params)\n  File \"/home/tygilman/School/CS3200/real-estate-htmx-fastapi/.venv/lib/python3.12/site-packages/mysql/connector/cursor_cext.py\", line 566, in callproc\n    result = self._connection.cmd_query(\n             ^^^^^^^^^^^^^^^^^^^^^^^^^^^\n  File \"/home/tygilman/School/CS3200/real-estate-htmx-fastapi/.venv/lib/python3.12/site-packages/mysql/connector/opentelemetry/context_propagation.py\", line 97, in wrapper\n    return method(cnx, *args, **kwargs)\n           ^^^^^^^^^^^^^^^^^^^^^^^^^^^^\n  File \"/home/tygilman/School/CS3200/real-estate-htmx-fastapi/.venv/lib/python3.12/site-packages/mysql/connector/connection_cext.py\", line 714, in cmd_query\n    raise get_mysql_exception(\nmysql.connector.errors.ProgrammingError: 1146 (42S02): Table 'real_estate.Users' doesn't exist"}}
{"timestamp": "2024-11-30T23:59:22.632047", "level": "ERROR", "message": "Dashboard error: 1146 (42S02): Table 'real_estate.Users' doesn't exist", "module": "admin", "function": "admin_dashboard", "line": 51, "thread_id": 131229935187776, "environment": "development", "exception": {"type": "ProgrammingError", "message": "1146 (42S02): Table 'real_estate.Users' doesn't exist", "traceback": "Traceback (most recent call last):\n  File \"/home/tygilman/School/CS3200/real-estate-htmx-fastapi/.venv/lib/python3.12/site-packages/mysql/connector/connection_cext.py\", line 706, in cmd_query\n    self._cmysql.query(\n_mysql_connector.MySQLInterfaceError: Table 'real_estate.Users' doesn't exist\n\nThe above exception was the direct cause of the following exception:\n\nTraceback (most recent call last):\n  File \"/home/tygilman/School/CS3200/real-estate-htmx-fastapi/app/routes/admin.py\", line 41, in admin_dashboard\n    dashboard_stats = execute_procedure(conn, 'get_admin_dashboard_stats')\n                      ^^^^^^^^^^^^^^^^^^^^^^^^^^^^^^^^^^^^^^^^^^^^^^^^^^^^\n  File \"/home/tygilman/School/CS3200/real-estate-htmx-fastapi/app/core/database.py\", line 48, in execute_procedure\n    cursor.callproc(procedure_name, params)\n  File \"/home/tygilman/School/CS3200/real-estate-htmx-fastapi/.venv/lib/python3.12/site-packages/mysql/connector/cursor_cext.py\", line 566, in callproc\n    result = self._connection.cmd_query(\n             ^^^^^^^^^^^^^^^^^^^^^^^^^^^\n  File \"/home/tygilman/School/CS3200/real-estate-htmx-fastapi/.venv/lib/python3.12/site-packages/mysql/connector/opentelemetry/context_propagation.py\", line 97, in wrapper\n    return method(cnx, *args, **kwargs)\n           ^^^^^^^^^^^^^^^^^^^^^^^^^^^^\n  File \"/home/tygilman/School/CS3200/real-estate-htmx-fastapi/.venv/lib/python3.12/site-packages/mysql/connector/connection_cext.py\", line 714, in cmd_query\n    raise get_mysql_exception(\nmysql.connector.errors.ProgrammingError: 1146 (42S02): Table 'real_estate.Users' doesn't exist"}}
{"timestamp": "2024-12-01T00:00:09.970804", "level": "ERROR", "message": "Dashboard error: 1146 (42S02): Table 'real_estate.Users' doesn't exist", "module": "admin", "function": "admin_dashboard", "line": 51, "thread_id": 130726137911104, "environment": "development", "exception": {"type": "ProgrammingError", "message": "1146 (42S02): Table 'real_estate.Users' doesn't exist", "traceback": "Traceback (most recent call last):\n  File \"/home/tygilman/School/CS3200/real-estate-htmx-fastapi/.venv/lib/python3.12/site-packages/mysql/connector/connection_cext.py\", line 706, in cmd_query\n    self._cmysql.query(\n_mysql_connector.MySQLInterfaceError: Table 'real_estate.Users' doesn't exist\n\nThe above exception was the direct cause of the following exception:\n\nTraceback (most recent call last):\n  File \"/home/tygilman/School/CS3200/real-estate-htmx-fastapi/app/routes/admin.py\", line 41, in admin_dashboard\n    dashboard_stats = execute_procedure(conn, 'get_admin_dashboard_stats')\n                      ^^^^^^^^^^^^^^^^^^^^^^^^^^^^^^^^^^^^^^^^^^^^^^^^^^^^\n  File \"/home/tygilman/School/CS3200/real-estate-htmx-fastapi/app/core/database.py\", line 48, in execute_procedure\n    cursor.callproc(procedure_name, params)\n  File \"/home/tygilman/School/CS3200/real-estate-htmx-fastapi/.venv/lib/python3.12/site-packages/mysql/connector/cursor_cext.py\", line 566, in callproc\n    result = self._connection.cmd_query(\n             ^^^^^^^^^^^^^^^^^^^^^^^^^^^\n  File \"/home/tygilman/School/CS3200/real-estate-htmx-fastapi/.venv/lib/python3.12/site-packages/mysql/connector/opentelemetry/context_propagation.py\", line 97, in wrapper\n    return method(cnx, *args, **kwargs)\n           ^^^^^^^^^^^^^^^^^^^^^^^^^^^^\n  File \"/home/tygilman/School/CS3200/real-estate-htmx-fastapi/.venv/lib/python3.12/site-packages/mysql/connector/connection_cext.py\", line 714, in cmd_query\n    raise get_mysql_exception(\nmysql.connector.errors.ProgrammingError: 1146 (42S02): Table 'real_estate.Users' doesn't exist"}}
{"timestamp": "2024-12-01T00:01:53.426236", "level": "ERROR", "message": "Dashboard error: 1146 (42S02): Table 'real_estate.Properties' doesn't exist", "module": "admin", "function": "admin_dashboard", "line": 51, "thread_id": 127695858960192, "environment": "development", "exception": {"type": "ProgrammingError", "message": "1146 (42S02): Table 'real_estate.Properties' doesn't exist", "traceback": "Traceback (most recent call last):\n  File \"/home/tygilman/School/CS3200/real-estate-htmx-fastapi/.venv/lib/python3.12/site-packages/mysql/connector/connection_cext.py\", line 706, in cmd_query\n    self._cmysql.query(\n_mysql_connector.MySQLInterfaceError: Table 'real_estate.Properties' doesn't exist\n\nThe above exception was the direct cause of the following exception:\n\nTraceback (most recent call last):\n  File \"/home/tygilman/School/CS3200/real-estate-htmx-fastapi/app/routes/admin.py\", line 41, in admin_dashboard\n    dashboard_stats = execute_procedure(conn, 'get_admin_dashboard_stats')\n                      ^^^^^^^^^^^^^^^^^^^^^^^^^^^^^^^^^^^^^^^^^^^^^^^^^^^^\n  File \"/home/tygilman/School/CS3200/real-estate-htmx-fastapi/app/core/database.py\", line 48, in execute_procedure\n    cursor.callproc(procedure_name, params)\n  File \"/home/tygilman/School/CS3200/real-estate-htmx-fastapi/.venv/lib/python3.12/site-packages/mysql/connector/cursor_cext.py\", line 566, in callproc\n    result = self._connection.cmd_query(\n             ^^^^^^^^^^^^^^^^^^^^^^^^^^^\n  File \"/home/tygilman/School/CS3200/real-estate-htmx-fastapi/.venv/lib/python3.12/site-packages/mysql/connector/opentelemetry/context_propagation.py\", line 97, in wrapper\n    return method(cnx, *args, **kwargs)\n           ^^^^^^^^^^^^^^^^^^^^^^^^^^^^\n  File \"/home/tygilman/School/CS3200/real-estate-htmx-fastapi/.venv/lib/python3.12/site-packages/mysql/connector/connection_cext.py\", line 714, in cmd_query\n    raise get_mysql_exception(\nmysql.connector.errors.ProgrammingError: 1146 (42S02): Table 'real_estate.Properties' doesn't exist"}}
{"timestamp": "2024-12-01T00:01:56.242466", "level": "ERROR", "message": "Dashboard error: 1146 (42S02): Table 'real_estate.Properties' doesn't exist", "module": "admin", "function": "admin_dashboard", "line": 51, "thread_id": 127695858960192, "environment": "development", "exception": {"type": "ProgrammingError", "message": "1146 (42S02): Table 'real_estate.Properties' doesn't exist", "traceback": "Traceback (most recent call last):\n  File \"/home/tygilman/School/CS3200/real-estate-htmx-fastapi/.venv/lib/python3.12/site-packages/mysql/connector/connection_cext.py\", line 706, in cmd_query\n    self._cmysql.query(\n_mysql_connector.MySQLInterfaceError: Table 'real_estate.Properties' doesn't exist\n\nThe above exception was the direct cause of the following exception:\n\nTraceback (most recent call last):\n  File \"/home/tygilman/School/CS3200/real-estate-htmx-fastapi/app/routes/admin.py\", line 41, in admin_dashboard\n    dashboard_stats = execute_procedure(conn, 'get_admin_dashboard_stats')\n                      ^^^^^^^^^^^^^^^^^^^^^^^^^^^^^^^^^^^^^^^^^^^^^^^^^^^^\n  File \"/home/tygilman/School/CS3200/real-estate-htmx-fastapi/app/core/database.py\", line 48, in execute_procedure\n    cursor.callproc(procedure_name, params)\n  File \"/home/tygilman/School/CS3200/real-estate-htmx-fastapi/.venv/lib/python3.12/site-packages/mysql/connector/cursor_cext.py\", line 566, in callproc\n    result = self._connection.cmd_query(\n             ^^^^^^^^^^^^^^^^^^^^^^^^^^^\n  File \"/home/tygilman/School/CS3200/real-estate-htmx-fastapi/.venv/lib/python3.12/site-packages/mysql/connector/opentelemetry/context_propagation.py\", line 97, in wrapper\n    return method(cnx, *args, **kwargs)\n           ^^^^^^^^^^^^^^^^^^^^^^^^^^^^\n  File \"/home/tygilman/School/CS3200/real-estate-htmx-fastapi/.venv/lib/python3.12/site-packages/mysql/connector/connection_cext.py\", line 714, in cmd_query\n    raise get_mysql_exception(\nmysql.connector.errors.ProgrammingError: 1146 (42S02): Table 'real_estate.Properties' doesn't exist"}}
{"timestamp": "2024-12-01T00:03:51.319309", "level": "ERROR", "message": "Authentication error: 1146 (42S02): Table 'real_estate.UserRole' doesn't exist", "module": "security", "function": "get_current_user", "line": 63, "thread_id": 137237079959360, "environment": "development"}
{"timestamp": "2024-12-01T00:05:27.254522", "level": "ERROR", "message": "Dashboard error: 1146 (42S02): Table 'real_estate.Properties' doesn't exist", "module": "admin", "function": "admin_dashboard", "line": 51, "thread_id": 130089338517312, "environment": "development", "exception": {"type": "ProgrammingError", "message": "1146 (42S02): Table 'real_estate.Properties' doesn't exist", "traceback": "Traceback (most recent call last):\n  File \"/home/tygilman/School/CS3200/real-estate-htmx-fastapi/.venv/lib/python3.12/site-packages/mysql/connector/connection_cext.py\", line 706, in cmd_query\n    self._cmysql.query(\n_mysql_connector.MySQLInterfaceError: Table 'real_estate.Properties' doesn't exist\n\nThe above exception was the direct cause of the following exception:\n\nTraceback (most recent call last):\n  File \"/home/tygilman/School/CS3200/real-estate-htmx-fastapi/app/routes/admin.py\", line 41, in admin_dashboard\n    dashboard_stats = execute_procedure(conn, 'get_admin_dashboard_stats')\n                      ^^^^^^^^^^^^^^^^^^^^^^^^^^^^^^^^^^^^^^^^^^^^^^^^^^^^\n  File \"/home/tygilman/School/CS3200/real-estate-htmx-fastapi/app/core/database.py\", line 48, in execute_procedure\n    cursor.callproc(procedure_name, params)\n  File \"/home/tygilman/School/CS3200/real-estate-htmx-fastapi/.venv/lib/python3.12/site-packages/mysql/connector/cursor_cext.py\", line 566, in callproc\n    result = self._connection.cmd_query(\n             ^^^^^^^^^^^^^^^^^^^^^^^^^^^\n  File \"/home/tygilman/School/CS3200/real-estate-htmx-fastapi/.venv/lib/python3.12/site-packages/mysql/connector/opentelemetry/context_propagation.py\", line 97, in wrapper\n    return method(cnx, *args, **kwargs)\n           ^^^^^^^^^^^^^^^^^^^^^^^^^^^^\n  File \"/home/tygilman/School/CS3200/real-estate-htmx-fastapi/.venv/lib/python3.12/site-packages/mysql/connector/connection_cext.py\", line 714, in cmd_query\n    raise get_mysql_exception(\nmysql.connector.errors.ProgrammingError: 1146 (42S02): Table 'real_estate.Properties' doesn't exist"}}
{"timestamp": "2024-12-01T00:05:30.566628", "level": "ERROR", "message": "Dashboard error: 1146 (42S02): Table 'real_estate.Properties' doesn't exist", "module": "admin", "function": "admin_dashboard", "line": 51, "thread_id": 130089338517312, "environment": "development", "exception": {"type": "ProgrammingError", "message": "1146 (42S02): Table 'real_estate.Properties' doesn't exist", "traceback": "Traceback (most recent call last):\n  File \"/home/tygilman/School/CS3200/real-estate-htmx-fastapi/.venv/lib/python3.12/site-packages/mysql/connector/connection_cext.py\", line 706, in cmd_query\n    self._cmysql.query(\n_mysql_connector.MySQLInterfaceError: Table 'real_estate.Properties' doesn't exist\n\nThe above exception was the direct cause of the following exception:\n\nTraceback (most recent call last):\n  File \"/home/tygilman/School/CS3200/real-estate-htmx-fastapi/app/routes/admin.py\", line 41, in admin_dashboard\n    dashboard_stats = execute_procedure(conn, 'get_admin_dashboard_stats')\n                      ^^^^^^^^^^^^^^^^^^^^^^^^^^^^^^^^^^^^^^^^^^^^^^^^^^^^\n  File \"/home/tygilman/School/CS3200/real-estate-htmx-fastapi/app/core/database.py\", line 48, in execute_procedure\n    cursor.callproc(procedure_name, params)\n  File \"/home/tygilman/School/CS3200/real-estate-htmx-fastapi/.venv/lib/python3.12/site-packages/mysql/connector/cursor_cext.py\", line 566, in callproc\n    result = self._connection.cmd_query(\n             ^^^^^^^^^^^^^^^^^^^^^^^^^^^\n  File \"/home/tygilman/School/CS3200/real-estate-htmx-fastapi/.venv/lib/python3.12/site-packages/mysql/connector/opentelemetry/context_propagation.py\", line 97, in wrapper\n    return method(cnx, *args, **kwargs)\n           ^^^^^^^^^^^^^^^^^^^^^^^^^^^^\n  File \"/home/tygilman/School/CS3200/real-estate-htmx-fastapi/.venv/lib/python3.12/site-packages/mysql/connector/connection_cext.py\", line 714, in cmd_query\n    raise get_mysql_exception(\nmysql.connector.errors.ProgrammingError: 1146 (42S02): Table 'real_estate.Properties' doesn't exist"}}
{"timestamp": "2024-12-01T00:10:44.446288", "level": "ERROR", "message": "Dashboard error: 1305 (42000): PROCEDURE real_estate.get_all_clients does not exist", "module": "admin", "function": "admin_dashboard", "line": 51, "thread_id": 127705191003968, "environment": "development", "exception": {"type": "ProgrammingError", "message": "1305 (42000): PROCEDURE real_estate.get_all_clients does not exist", "traceback": "Traceback (most recent call last):\n  File \"/home/tygilman/School/CS3200/real-estate-htmx-fastapi/.venv/lib/python3.12/site-packages/mysql/connector/connection_cext.py\", line 706, in cmd_query\n    self._cmysql.query(\n_mysql_connector.MySQLInterfaceError: PROCEDURE real_estate.get_all_clients does not exist\n\nThe above exception was the direct cause of the following exception:\n\nTraceback (most recent call last):\n  File \"/home/tygilman/School/CS3200/real-estate-htmx-fastapi/app/routes/admin.py\", line 24, in admin_dashboard\n    clients = execute_procedure(conn, 'get_all_clients')\n              ^^^^^^^^^^^^^^^^^^^^^^^^^^^^^^^^^^^^^^^^^^\n  File \"/home/tygilman/School/CS3200/real-estate-htmx-fastapi/app/core/database.py\", line 48, in execute_procedure\n    cursor.callproc(procedure_name, params)\n  File \"/home/tygilman/School/CS3200/real-estate-htmx-fastapi/.venv/lib/python3.12/site-packages/mysql/connector/cursor_cext.py\", line 566, in callproc\n    result = self._connection.cmd_query(\n             ^^^^^^^^^^^^^^^^^^^^^^^^^^^\n  File \"/home/tygilman/School/CS3200/real-estate-htmx-fastapi/.venv/lib/python3.12/site-packages/mysql/connector/opentelemetry/context_propagation.py\", line 97, in wrapper\n    return method(cnx, *args, **kwargs)\n           ^^^^^^^^^^^^^^^^^^^^^^^^^^^^\n  File \"/home/tygilman/School/CS3200/real-estate-htmx-fastapi/.venv/lib/python3.12/site-packages/mysql/connector/connection_cext.py\", line 714, in cmd_query\n    raise get_mysql_exception(\nmysql.connector.errors.ProgrammingError: 1305 (42000): PROCEDURE real_estate.get_all_clients does not exist"}}
{"timestamp": "2024-12-01T00:10:46.182897", "level": "ERROR", "message": "Dashboard error: 1305 (42000): PROCEDURE real_estate.get_all_clients does not exist", "module": "admin", "function": "admin_dashboard", "line": 51, "thread_id": 127705191003968, "environment": "development", "exception": {"type": "ProgrammingError", "message": "1305 (42000): PROCEDURE real_estate.get_all_clients does not exist", "traceback": "Traceback (most recent call last):\n  File \"/home/tygilman/School/CS3200/real-estate-htmx-fastapi/.venv/lib/python3.12/site-packages/mysql/connector/connection_cext.py\", line 706, in cmd_query\n    self._cmysql.query(\n_mysql_connector.MySQLInterfaceError: PROCEDURE real_estate.get_all_clients does not exist\n\nThe above exception was the direct cause of the following exception:\n\nTraceback (most recent call last):\n  File \"/home/tygilman/School/CS3200/real-estate-htmx-fastapi/app/routes/admin.py\", line 24, in admin_dashboard\n    clients = execute_procedure(conn, 'get_all_clients')\n              ^^^^^^^^^^^^^^^^^^^^^^^^^^^^^^^^^^^^^^^^^^\n  File \"/home/tygilman/School/CS3200/real-estate-htmx-fastapi/app/core/database.py\", line 48, in execute_procedure\n    cursor.callproc(procedure_name, params)\n  File \"/home/tygilman/School/CS3200/real-estate-htmx-fastapi/.venv/lib/python3.12/site-packages/mysql/connector/cursor_cext.py\", line 566, in callproc\n    result = self._connection.cmd_query(\n             ^^^^^^^^^^^^^^^^^^^^^^^^^^^\n  File \"/home/tygilman/School/CS3200/real-estate-htmx-fastapi/.venv/lib/python3.12/site-packages/mysql/connector/opentelemetry/context_propagation.py\", line 97, in wrapper\n    return method(cnx, *args, **kwargs)\n           ^^^^^^^^^^^^^^^^^^^^^^^^^^^^\n  File \"/home/tygilman/School/CS3200/real-estate-htmx-fastapi/.venv/lib/python3.12/site-packages/mysql/connector/connection_cext.py\", line 714, in cmd_query\n    raise get_mysql_exception(\nmysql.connector.errors.ProgrammingError: 1305 (42000): PROCEDURE real_estate.get_all_clients does not exist"}}
{"timestamp": "2024-12-01T00:14:32.737201", "level": "ERROR", "message": "Dashboard error: 1146 (42S02): Table 'real_estate.Properties' doesn't exist", "module": "admin", "function": "admin_dashboard", "line": 51, "thread_id": 131276625811264, "environment": "development", "exception": {"type": "ProgrammingError", "message": "1146 (42S02): Table 'real_estate.Properties' doesn't exist", "traceback": "Traceback (most recent call last):\n  File \"/home/tygilman/School/CS3200/real-estate-htmx-fastapi/.venv/lib/python3.12/site-packages/mysql/connector/connection_cext.py\", line 706, in cmd_query\n    self._cmysql.query(\n_mysql_connector.MySQLInterfaceError: Table 'real_estate.Properties' doesn't exist\n\nThe above exception was the direct cause of the following exception:\n\nTraceback (most recent call last):\n  File \"/home/tygilman/School/CS3200/real-estate-htmx-fastapi/app/routes/admin.py\", line 41, in admin_dashboard\n    dashboard_stats = execute_procedure(conn, 'get_admin_dashboard_stats')\n                      ^^^^^^^^^^^^^^^^^^^^^^^^^^^^^^^^^^^^^^^^^^^^^^^^^^^^\n  File \"/home/tygilman/School/CS3200/real-estate-htmx-fastapi/app/core/database.py\", line 48, in execute_procedure\n    cursor.callproc(procedure_name, params)\n  File \"/home/tygilman/School/CS3200/real-estate-htmx-fastapi/.venv/lib/python3.12/site-packages/mysql/connector/cursor_cext.py\", line 566, in callproc\n    result = self._connection.cmd_query(\n             ^^^^^^^^^^^^^^^^^^^^^^^^^^^\n  File \"/home/tygilman/School/CS3200/real-estate-htmx-fastapi/.venv/lib/python3.12/site-packages/mysql/connector/opentelemetry/context_propagation.py\", line 97, in wrapper\n    return method(cnx, *args, **kwargs)\n           ^^^^^^^^^^^^^^^^^^^^^^^^^^^^\n  File \"/home/tygilman/School/CS3200/real-estate-htmx-fastapi/.venv/lib/python3.12/site-packages/mysql/connector/connection_cext.py\", line 714, in cmd_query\n    raise get_mysql_exception(\nmysql.connector.errors.ProgrammingError: 1146 (42S02): Table 'real_estate.Properties' doesn't exist"}}
{"timestamp": "2024-12-01T00:14:34.009240", "level": "ERROR", "message": "Dashboard error: 1146 (42S02): Table 'real_estate.Properties' doesn't exist", "module": "admin", "function": "admin_dashboard", "line": 51, "thread_id": 131276625811264, "environment": "development", "exception": {"type": "ProgrammingError", "message": "1146 (42S02): Table 'real_estate.Properties' doesn't exist", "traceback": "Traceback (most recent call last):\n  File \"/home/tygilman/School/CS3200/real-estate-htmx-fastapi/.venv/lib/python3.12/site-packages/mysql/connector/connection_cext.py\", line 706, in cmd_query\n    self._cmysql.query(\n_mysql_connector.MySQLInterfaceError: Table 'real_estate.Properties' doesn't exist\n\nThe above exception was the direct cause of the following exception:\n\nTraceback (most recent call last):\n  File \"/home/tygilman/School/CS3200/real-estate-htmx-fastapi/app/routes/admin.py\", line 41, in admin_dashboard\n    dashboard_stats = execute_procedure(conn, 'get_admin_dashboard_stats')\n                      ^^^^^^^^^^^^^^^^^^^^^^^^^^^^^^^^^^^^^^^^^^^^^^^^^^^^\n  File \"/home/tygilman/School/CS3200/real-estate-htmx-fastapi/app/core/database.py\", line 48, in execute_procedure\n    cursor.callproc(procedure_name, params)\n  File \"/home/tygilman/School/CS3200/real-estate-htmx-fastapi/.venv/lib/python3.12/site-packages/mysql/connector/cursor_cext.py\", line 566, in callproc\n    result = self._connection.cmd_query(\n             ^^^^^^^^^^^^^^^^^^^^^^^^^^^\n  File \"/home/tygilman/School/CS3200/real-estate-htmx-fastapi/.venv/lib/python3.12/site-packages/mysql/connector/opentelemetry/context_propagation.py\", line 97, in wrapper\n    return method(cnx, *args, **kwargs)\n           ^^^^^^^^^^^^^^^^^^^^^^^^^^^^\n  File \"/home/tygilman/School/CS3200/real-estate-htmx-fastapi/.venv/lib/python3.12/site-packages/mysql/connector/connection_cext.py\", line 714, in cmd_query\n    raise get_mysql_exception(\nmysql.connector.errors.ProgrammingError: 1146 (42S02): Table 'real_estate.Properties' doesn't exist"}}
{"timestamp": "2024-12-01T00:14:34.867437", "level": "ERROR", "message": "Dashboard error: 1146 (42S02): Table 'real_estate.Properties' doesn't exist", "module": "admin", "function": "admin_dashboard", "line": 51, "thread_id": 131276625811264, "environment": "development", "exception": {"type": "ProgrammingError", "message": "1146 (42S02): Table 'real_estate.Properties' doesn't exist", "traceback": "Traceback (most recent call last):\n  File \"/home/tygilman/School/CS3200/real-estate-htmx-fastapi/.venv/lib/python3.12/site-packages/mysql/connector/connection_cext.py\", line 706, in cmd_query\n    self._cmysql.query(\n_mysql_connector.MySQLInterfaceError: Table 'real_estate.Properties' doesn't exist\n\nThe above exception was the direct cause of the following exception:\n\nTraceback (most recent call last):\n  File \"/home/tygilman/School/CS3200/real-estate-htmx-fastapi/app/routes/admin.py\", line 41, in admin_dashboard\n    dashboard_stats = execute_procedure(conn, 'get_admin_dashboard_stats')\n                      ^^^^^^^^^^^^^^^^^^^^^^^^^^^^^^^^^^^^^^^^^^^^^^^^^^^^\n  File \"/home/tygilman/School/CS3200/real-estate-htmx-fastapi/app/core/database.py\", line 48, in execute_procedure\n    cursor.callproc(procedure_name, params)\n  File \"/home/tygilman/School/CS3200/real-estate-htmx-fastapi/.venv/lib/python3.12/site-packages/mysql/connector/cursor_cext.py\", line 566, in callproc\n    result = self._connection.cmd_query(\n             ^^^^^^^^^^^^^^^^^^^^^^^^^^^\n  File \"/home/tygilman/School/CS3200/real-estate-htmx-fastapi/.venv/lib/python3.12/site-packages/mysql/connector/opentelemetry/context_propagation.py\", line 97, in wrapper\n    return method(cnx, *args, **kwargs)\n           ^^^^^^^^^^^^^^^^^^^^^^^^^^^^\n  File \"/home/tygilman/School/CS3200/real-estate-htmx-fastapi/.venv/lib/python3.12/site-packages/mysql/connector/connection_cext.py\", line 714, in cmd_query\n    raise get_mysql_exception(\nmysql.connector.errors.ProgrammingError: 1146 (42S02): Table 'real_estate.Properties' doesn't exist"}}
{"timestamp": "2024-12-01T00:14:35.772605", "level": "ERROR", "message": "Dashboard error: 1146 (42S02): Table 'real_estate.Properties' doesn't exist", "module": "admin", "function": "admin_dashboard", "line": 51, "thread_id": 131276625811264, "environment": "development", "exception": {"type": "ProgrammingError", "message": "1146 (42S02): Table 'real_estate.Properties' doesn't exist", "traceback": "Traceback (most recent call last):\n  File \"/home/tygilman/School/CS3200/real-estate-htmx-fastapi/.venv/lib/python3.12/site-packages/mysql/connector/connection_cext.py\", line 706, in cmd_query\n    self._cmysql.query(\n_mysql_connector.MySQLInterfaceError: Table 'real_estate.Properties' doesn't exist\n\nThe above exception was the direct cause of the following exception:\n\nTraceback (most recent call last):\n  File \"/home/tygilman/School/CS3200/real-estate-htmx-fastapi/app/routes/admin.py\", line 41, in admin_dashboard\n    dashboard_stats = execute_procedure(conn, 'get_admin_dashboard_stats')\n                      ^^^^^^^^^^^^^^^^^^^^^^^^^^^^^^^^^^^^^^^^^^^^^^^^^^^^\n  File \"/home/tygilman/School/CS3200/real-estate-htmx-fastapi/app/core/database.py\", line 48, in execute_procedure\n    cursor.callproc(procedure_name, params)\n  File \"/home/tygilman/School/CS3200/real-estate-htmx-fastapi/.venv/lib/python3.12/site-packages/mysql/connector/cursor_cext.py\", line 566, in callproc\n    result = self._connection.cmd_query(\n             ^^^^^^^^^^^^^^^^^^^^^^^^^^^\n  File \"/home/tygilman/School/CS3200/real-estate-htmx-fastapi/.venv/lib/python3.12/site-packages/mysql/connector/opentelemetry/context_propagation.py\", line 97, in wrapper\n    return method(cnx, *args, **kwargs)\n           ^^^^^^^^^^^^^^^^^^^^^^^^^^^^\n  File \"/home/tygilman/School/CS3200/real-estate-htmx-fastapi/.venv/lib/python3.12/site-packages/mysql/connector/connection_cext.py\", line 714, in cmd_query\n    raise get_mysql_exception(\nmysql.connector.errors.ProgrammingError: 1146 (42S02): Table 'real_estate.Properties' doesn't exist"}}
{"timestamp": "2024-12-01T00:14:59.892720", "level": "ERROR", "message": "Dashboard error: 1146 (42S02): Table 'real_estate.Properties' doesn't exist", "module": "admin", "function": "admin_dashboard", "line": 51, "thread_id": 136548237526848, "environment": "development", "exception": {"type": "ProgrammingError", "message": "1146 (42S02): Table 'real_estate.Properties' doesn't exist", "traceback": "Traceback (most recent call last):\n  File \"/home/tygilman/School/CS3200/real-estate-htmx-fastapi/.venv/lib/python3.12/site-packages/mysql/connector/connection_cext.py\", line 706, in cmd_query\n    self._cmysql.query(\n_mysql_connector.MySQLInterfaceError: Table 'real_estate.Properties' doesn't exist\n\nThe above exception was the direct cause of the following exception:\n\nTraceback (most recent call last):\n  File \"/home/tygilman/School/CS3200/real-estate-htmx-fastapi/app/routes/admin.py\", line 41, in admin_dashboard\n    dashboard_stats = execute_procedure(conn, 'get_admin_dashboard_stats')\n                      ^^^^^^^^^^^^^^^^^^^^^^^^^^^^^^^^^^^^^^^^^^^^^^^^^^^^\n  File \"/home/tygilman/School/CS3200/real-estate-htmx-fastapi/app/core/database.py\", line 48, in execute_procedure\n    cursor.callproc(procedure_name, params)\n  File \"/home/tygilman/School/CS3200/real-estate-htmx-fastapi/.venv/lib/python3.12/site-packages/mysql/connector/cursor_cext.py\", line 566, in callproc\n    result = self._connection.cmd_query(\n             ^^^^^^^^^^^^^^^^^^^^^^^^^^^\n  File \"/home/tygilman/School/CS3200/real-estate-htmx-fastapi/.venv/lib/python3.12/site-packages/mysql/connector/opentelemetry/context_propagation.py\", line 97, in wrapper\n    return method(cnx, *args, **kwargs)\n           ^^^^^^^^^^^^^^^^^^^^^^^^^^^^\n  File \"/home/tygilman/School/CS3200/real-estate-htmx-fastapi/.venv/lib/python3.12/site-packages/mysql/connector/connection_cext.py\", line 714, in cmd_query\n    raise get_mysql_exception(\nmysql.connector.errors.ProgrammingError: 1146 (42S02): Table 'real_estate.Properties' doesn't exist"}}
{"timestamp": "2024-12-01T00:16:32.065380", "level": "ERROR", "message": "Dashboard error: 1146 (42S02): Table 'real_estate.Transactions' doesn't exist", "module": "admin", "function": "admin_dashboard", "line": 51, "thread_id": 139227304404800, "environment": "development", "exception": {"type": "ProgrammingError", "message": "1146 (42S02): Table 'real_estate.Transactions' doesn't exist", "traceback": "Traceback (most recent call last):\n  File \"/home/tygilman/School/CS3200/real-estate-htmx-fastapi/.venv/lib/python3.12/site-packages/mysql/connector/connection_cext.py\", line 706, in cmd_query\n    self._cmysql.query(\n_mysql_connector.MySQLInterfaceError: Table 'real_estate.Transactions' doesn't exist\n\nThe above exception was the direct cause of the following exception:\n\nTraceback (most recent call last):\n  File \"/home/tygilman/School/CS3200/real-estate-htmx-fastapi/app/routes/admin.py\", line 41, in admin_dashboard\n    dashboard_stats = execute_procedure(conn, 'get_admin_dashboard_stats')\n                      ^^^^^^^^^^^^^^^^^^^^^^^^^^^^^^^^^^^^^^^^^^^^^^^^^^^^\n  File \"/home/tygilman/School/CS3200/real-estate-htmx-fastapi/app/core/database.py\", line 48, in execute_procedure\n    cursor.callproc(procedure_name, params)\n  File \"/home/tygilman/School/CS3200/real-estate-htmx-fastapi/.venv/lib/python3.12/site-packages/mysql/connector/cursor_cext.py\", line 566, in callproc\n    result = self._connection.cmd_query(\n             ^^^^^^^^^^^^^^^^^^^^^^^^^^^\n  File \"/home/tygilman/School/CS3200/real-estate-htmx-fastapi/.venv/lib/python3.12/site-packages/mysql/connector/opentelemetry/context_propagation.py\", line 97, in wrapper\n    return method(cnx, *args, **kwargs)\n           ^^^^^^^^^^^^^^^^^^^^^^^^^^^^\n  File \"/home/tygilman/School/CS3200/real-estate-htmx-fastapi/.venv/lib/python3.12/site-packages/mysql/connector/connection_cext.py\", line 714, in cmd_query\n    raise get_mysql_exception(\nmysql.connector.errors.ProgrammingError: 1146 (42S02): Table 'real_estate.Transactions' doesn't exist"}}
{"timestamp": "2024-12-01T00:16:34.403962", "level": "ERROR", "message": "Dashboard error: 1146 (42S02): Table 'real_estate.Transactions' doesn't exist", "module": "admin", "function": "admin_dashboard", "line": 51, "thread_id": 139227304404800, "environment": "development", "exception": {"type": "ProgrammingError", "message": "1146 (42S02): Table 'real_estate.Transactions' doesn't exist", "traceback": "Traceback (most recent call last):\n  File \"/home/tygilman/School/CS3200/real-estate-htmx-fastapi/.venv/lib/python3.12/site-packages/mysql/connector/connection_cext.py\", line 706, in cmd_query\n    self._cmysql.query(\n_mysql_connector.MySQLInterfaceError: Table 'real_estate.Transactions' doesn't exist\n\nThe above exception was the direct cause of the following exception:\n\nTraceback (most recent call last):\n  File \"/home/tygilman/School/CS3200/real-estate-htmx-fastapi/app/routes/admin.py\", line 41, in admin_dashboard\n    dashboard_stats = execute_procedure(conn, 'get_admin_dashboard_stats')\n                      ^^^^^^^^^^^^^^^^^^^^^^^^^^^^^^^^^^^^^^^^^^^^^^^^^^^^\n  File \"/home/tygilman/School/CS3200/real-estate-htmx-fastapi/app/core/database.py\", line 48, in execute_procedure\n    cursor.callproc(procedure_name, params)\n  File \"/home/tygilman/School/CS3200/real-estate-htmx-fastapi/.venv/lib/python3.12/site-packages/mysql/connector/cursor_cext.py\", line 566, in callproc\n    result = self._connection.cmd_query(\n             ^^^^^^^^^^^^^^^^^^^^^^^^^^^\n  File \"/home/tygilman/School/CS3200/real-estate-htmx-fastapi/.venv/lib/python3.12/site-packages/mysql/connector/opentelemetry/context_propagation.py\", line 97, in wrapper\n    return method(cnx, *args, **kwargs)\n           ^^^^^^^^^^^^^^^^^^^^^^^^^^^^\n  File \"/home/tygilman/School/CS3200/real-estate-htmx-fastapi/.venv/lib/python3.12/site-packages/mysql/connector/connection_cext.py\", line 714, in cmd_query\n    raise get_mysql_exception(\nmysql.connector.errors.ProgrammingError: 1146 (42S02): Table 'real_estate.Transactions' doesn't exist"}}
{"timestamp": "2024-12-01T00:17:20.390571", "level": "ERROR", "message": "Dashboard error: 1146 (42S02): Table 'real_estate.Transactions' doesn't exist", "module": "admin", "function": "admin_dashboard", "line": 51, "thread_id": 130516341503808, "environment": "development", "exception": {"type": "ProgrammingError", "message": "1146 (42S02): Table 'real_estate.Transactions' doesn't exist", "traceback": "Traceback (most recent call last):\n  File \"/home/tygilman/School/CS3200/real-estate-htmx-fastapi/.venv/lib/python3.12/site-packages/mysql/connector/connection_cext.py\", line 706, in cmd_query\n    self._cmysql.query(\n_mysql_connector.MySQLInterfaceError: Table 'real_estate.Transactions' doesn't exist\n\nThe above exception was the direct cause of the following exception:\n\nTraceback (most recent call last):\n  File \"/home/tygilman/School/CS3200/real-estate-htmx-fastapi/app/routes/admin.py\", line 41, in admin_dashboard\n    dashboard_stats = execute_procedure(conn, 'get_admin_dashboard_stats')\n                      ^^^^^^^^^^^^^^^^^^^^^^^^^^^^^^^^^^^^^^^^^^^^^^^^^^^^\n  File \"/home/tygilman/School/CS3200/real-estate-htmx-fastapi/app/core/database.py\", line 48, in execute_procedure\n    cursor.callproc(procedure_name, params)\n  File \"/home/tygilman/School/CS3200/real-estate-htmx-fastapi/.venv/lib/python3.12/site-packages/mysql/connector/cursor_cext.py\", line 566, in callproc\n    result = self._connection.cmd_query(\n             ^^^^^^^^^^^^^^^^^^^^^^^^^^^\n  File \"/home/tygilman/School/CS3200/real-estate-htmx-fastapi/.venv/lib/python3.12/site-packages/mysql/connector/opentelemetry/context_propagation.py\", line 97, in wrapper\n    return method(cnx, *args, **kwargs)\n           ^^^^^^^^^^^^^^^^^^^^^^^^^^^^\n  File \"/home/tygilman/School/CS3200/real-estate-htmx-fastapi/.venv/lib/python3.12/site-packages/mysql/connector/connection_cext.py\", line 714, in cmd_query\n    raise get_mysql_exception(\nmysql.connector.errors.ProgrammingError: 1146 (42S02): Table 'real_estate.Transactions' doesn't exist"}}
{"timestamp": "2024-12-01T00:17:22.384689", "level": "ERROR", "message": "Dashboard error: 1146 (42S02): Table 'real_estate.Transactions' doesn't exist", "module": "admin", "function": "admin_dashboard", "line": 51, "thread_id": 130516341503808, "environment": "development", "exception": {"type": "ProgrammingError", "message": "1146 (42S02): Table 'real_estate.Transactions' doesn't exist", "traceback": "Traceback (most recent call last):\n  File \"/home/tygilman/School/CS3200/real-estate-htmx-fastapi/.venv/lib/python3.12/site-packages/mysql/connector/connection_cext.py\", line 706, in cmd_query\n    self._cmysql.query(\n_mysql_connector.MySQLInterfaceError: Table 'real_estate.Transactions' doesn't exist\n\nThe above exception was the direct cause of the following exception:\n\nTraceback (most recent call last):\n  File \"/home/tygilman/School/CS3200/real-estate-htmx-fastapi/app/routes/admin.py\", line 41, in admin_dashboard\n    dashboard_stats = execute_procedure(conn, 'get_admin_dashboard_stats')\n                      ^^^^^^^^^^^^^^^^^^^^^^^^^^^^^^^^^^^^^^^^^^^^^^^^^^^^\n  File \"/home/tygilman/School/CS3200/real-estate-htmx-fastapi/app/core/database.py\", line 48, in execute_procedure\n    cursor.callproc(procedure_name, params)\n  File \"/home/tygilman/School/CS3200/real-estate-htmx-fastapi/.venv/lib/python3.12/site-packages/mysql/connector/cursor_cext.py\", line 566, in callproc\n    result = self._connection.cmd_query(\n             ^^^^^^^^^^^^^^^^^^^^^^^^^^^\n  File \"/home/tygilman/School/CS3200/real-estate-htmx-fastapi/.venv/lib/python3.12/site-packages/mysql/connector/opentelemetry/context_propagation.py\", line 97, in wrapper\n    return method(cnx, *args, **kwargs)\n           ^^^^^^^^^^^^^^^^^^^^^^^^^^^^\n  File \"/home/tygilman/School/CS3200/real-estate-htmx-fastapi/.venv/lib/python3.12/site-packages/mysql/connector/connection_cext.py\", line 714, in cmd_query\n    raise get_mysql_exception(\nmysql.connector.errors.ProgrammingError: 1146 (42S02): Table 'real_estate.Transactions' doesn't exist"}}
{"timestamp": "2024-12-01T00:17:47.308307", "level": "ERROR", "message": "Dashboard error: 1146 (42S02): Table 'real_estate.Agents' doesn't exist", "module": "admin", "function": "admin_dashboard", "line": 51, "thread_id": 123242785068864, "environment": "development", "exception": {"type": "ProgrammingError", "message": "1146 (42S02): Table 'real_estate.Agents' doesn't exist", "traceback": "Traceback (most recent call last):\n  File \"/home/tygilman/School/CS3200/real-estate-htmx-fastapi/.venv/lib/python3.12/site-packages/mysql/connector/connection_cext.py\", line 706, in cmd_query\n    self._cmysql.query(\n_mysql_connector.MySQLInterfaceError: Table 'real_estate.Agents' doesn't exist\n\nThe above exception was the direct cause of the following exception:\n\nTraceback (most recent call last):\n  File \"/home/tygilman/School/CS3200/real-estate-htmx-fastapi/app/routes/admin.py\", line 41, in admin_dashboard\n    dashboard_stats = execute_procedure(conn, 'get_admin_dashboard_stats')\n                      ^^^^^^^^^^^^^^^^^^^^^^^^^^^^^^^^^^^^^^^^^^^^^^^^^^^^\n  File \"/home/tygilman/School/CS3200/real-estate-htmx-fastapi/app/core/database.py\", line 48, in execute_procedure\n    cursor.callproc(procedure_name, params)\n  File \"/home/tygilman/School/CS3200/real-estate-htmx-fastapi/.venv/lib/python3.12/site-packages/mysql/connector/cursor_cext.py\", line 566, in callproc\n    result = self._connection.cmd_query(\n             ^^^^^^^^^^^^^^^^^^^^^^^^^^^\n  File \"/home/tygilman/School/CS3200/real-estate-htmx-fastapi/.venv/lib/python3.12/site-packages/mysql/connector/opentelemetry/context_propagation.py\", line 97, in wrapper\n    return method(cnx, *args, **kwargs)\n           ^^^^^^^^^^^^^^^^^^^^^^^^^^^^\n  File \"/home/tygilman/School/CS3200/real-estate-htmx-fastapi/.venv/lib/python3.12/site-packages/mysql/connector/connection_cext.py\", line 714, in cmd_query\n    raise get_mysql_exception(\nmysql.connector.errors.ProgrammingError: 1146 (42S02): Table 'real_estate.Agents' doesn't exist"}}
{"timestamp": "2024-12-01T00:18:29.522422", "level": "ERROR", "message": "Dashboard error: 1305 (42000): PROCEDURE real_estate.get_all_properties does not exist", "module": "admin", "function": "admin_dashboard", "line": 51, "thread_id": 135205757941568, "environment": "development", "exception": {"type": "ProgrammingError", "message": "1305 (42000): PROCEDURE real_estate.get_all_properties does not exist", "traceback": "Traceback (most recent call last):\n  File \"/home/tygilman/School/CS3200/real-estate-htmx-fastapi/.venv/lib/python3.12/site-packages/mysql/connector/connection_cext.py\", line 706, in cmd_query\n    self._cmysql.query(\n_mysql_connector.MySQLInterfaceError: PROCEDURE real_estate.get_all_properties does not exist\n\nThe above exception was the direct cause of the following exception:\n\nTraceback (most recent call last):\n  File \"/home/tygilman/School/CS3200/real-estate-htmx-fastapi/app/routes/admin.py\", line 46, in admin_dashboard\n    context[\"properties\"] = execute_procedure(conn, 'get_all_properties')\n                            ^^^^^^^^^^^^^^^^^^^^^^^^^^^^^^^^^^^^^^^^^^^^^\n  File \"/home/tygilman/School/CS3200/real-estate-htmx-fastapi/app/core/database.py\", line 48, in execute_procedure\n    cursor.callproc(procedure_name, params)\n  File \"/home/tygilman/School/CS3200/real-estate-htmx-fastapi/.venv/lib/python3.12/site-packages/mysql/connector/cursor_cext.py\", line 566, in callproc\n    result = self._connection.cmd_query(\n             ^^^^^^^^^^^^^^^^^^^^^^^^^^^\n  File \"/home/tygilman/School/CS3200/real-estate-htmx-fastapi/.venv/lib/python3.12/site-packages/mysql/connector/opentelemetry/context_propagation.py\", line 97, in wrapper\n    return method(cnx, *args, **kwargs)\n           ^^^^^^^^^^^^^^^^^^^^^^^^^^^^\n  File \"/home/tygilman/School/CS3200/real-estate-htmx-fastapi/.venv/lib/python3.12/site-packages/mysql/connector/connection_cext.py\", line 714, in cmd_query\n    raise get_mysql_exception(\nmysql.connector.errors.ProgrammingError: 1305 (42000): PROCEDURE real_estate.get_all_properties does not exist"}}
{"timestamp": "2024-12-01T00:20:06.240997", "level": "ERROR", "message": "Dashboard error: 1318 (42000): Incorrect number of arguments for PROCEDURE real_estate.get_all_agents; expected 4, got 0", "module": "admin", "function": "admin_dashboard", "line": 51, "thread_id": 134466589341504, "environment": "development", "exception": {"type": "ProgrammingError", "message": "1318 (42000): Incorrect number of arguments for PROCEDURE real_estate.get_all_agents; expected 4, got 0", "traceback": "Traceback (most recent call last):\n  File \"/home/tygilman/School/CS3200/real-estate-htmx-fastapi/.venv/lib/python3.12/site-packages/mysql/connector/connection_cext.py\", line 706, in cmd_query\n    self._cmysql.query(\n_mysql_connector.MySQLInterfaceError: Incorrect number of arguments for PROCEDURE real_estate.get_all_agents; expected 4, got 0\n\nThe above exception was the direct cause of the following exception:\n\nTraceback (most recent call last):\n  File \"/home/tygilman/School/CS3200/real-estate-htmx-fastapi/app/routes/admin.py\", line 47, in admin_dashboard\n    context[\"agents\"] = execute_procedure(conn, 'get_all_agents')\n                        ^^^^^^^^^^^^^^^^^^^^^^^^^^^^^^^^^^^^^^^^^\n  File \"/home/tygilman/School/CS3200/real-estate-htmx-fastapi/app/core/database.py\", line 48, in execute_procedure\n    cursor.callproc(procedure_name, params)\n  File \"/home/tygilman/School/CS3200/real-estate-htmx-fastapi/.venv/lib/python3.12/site-packages/mysql/connector/cursor_cext.py\", line 566, in callproc\n    result = self._connection.cmd_query(\n             ^^^^^^^^^^^^^^^^^^^^^^^^^^^\n  File \"/home/tygilman/School/CS3200/real-estate-htmx-fastapi/.venv/lib/python3.12/site-packages/mysql/connector/opentelemetry/context_propagation.py\", line 97, in wrapper\n    return method(cnx, *args, **kwargs)\n           ^^^^^^^^^^^^^^^^^^^^^^^^^^^^\n  File \"/home/tygilman/School/CS3200/real-estate-htmx-fastapi/.venv/lib/python3.12/site-packages/mysql/connector/connection_cext.py\", line 714, in cmd_query\n    raise get_mysql_exception(\nmysql.connector.errors.ProgrammingError: 1318 (42000): Incorrect number of arguments for PROCEDURE real_estate.get_all_agents; expected 4, got 0"}}
{"timestamp": "2024-12-01T00:21:49.849121", "level": "ERROR", "message": "Dashboard error: 1146 (42S02): Table 'real_estate.Agents' doesn't exist", "module": "admin", "function": "admin_dashboard", "line": 51, "thread_id": 136859003578176, "environment": "development", "exception": {"type": "ProgrammingError", "message": "1146 (42S02): Table 'real_estate.Agents' doesn't exist", "traceback": "Traceback (most recent call last):\n  File \"/home/tygilman/School/CS3200/real-estate-htmx-fastapi/.venv/lib/python3.12/site-packages/mysql/connector/connection_cext.py\", line 706, in cmd_query\n    self._cmysql.query(\n_mysql_connector.MySQLInterfaceError: Table 'real_estate.Agents' doesn't exist\n\nThe above exception was the direct cause of the following exception:\n\nTraceback (most recent call last):\n  File \"/home/tygilman/School/CS3200/real-estate-htmx-fastapi/app/routes/admin.py\", line 47, in admin_dashboard\n    context[\"agents\"] = execute_procedure(conn, 'get_all_agents')\n                        ^^^^^^^^^^^^^^^^^^^^^^^^^^^^^^^^^^^^^^^^^\n  File \"/home/tygilman/School/CS3200/real-estate-htmx-fastapi/app/core/database.py\", line 48, in execute_procedure\n    cursor.callproc(procedure_name, params)\n  File \"/home/tygilman/School/CS3200/real-estate-htmx-fastapi/.venv/lib/python3.12/site-packages/mysql/connector/cursor_cext.py\", line 566, in callproc\n    result = self._connection.cmd_query(\n             ^^^^^^^^^^^^^^^^^^^^^^^^^^^\n  File \"/home/tygilman/School/CS3200/real-estate-htmx-fastapi/.venv/lib/python3.12/site-packages/mysql/connector/opentelemetry/context_propagation.py\", line 97, in wrapper\n    return method(cnx, *args, **kwargs)\n           ^^^^^^^^^^^^^^^^^^^^^^^^^^^^\n  File \"/home/tygilman/School/CS3200/real-estate-htmx-fastapi/.venv/lib/python3.12/site-packages/mysql/connector/connection_cext.py\", line 714, in cmd_query\n    raise get_mysql_exception(\nmysql.connector.errors.ProgrammingError: 1146 (42S02): Table 'real_estate.Agents' doesn't exist"}}
{"timestamp": "2024-12-01T00:22:15.510078", "level": "ERROR", "message": "Dashboard error: 1054 (42S22): Unknown column 'email' in 'field list'", "module": "admin", "function": "admin_dashboard", "line": 51, "thread_id": 131853661763392, "environment": "development", "exception": {"type": "ProgrammingError", "message": "1054 (42S22): Unknown column 'email' in 'field list'", "traceback": "Traceback (most recent call last):\n  File \"/home/tygilman/School/CS3200/real-estate-htmx-fastapi/.venv/lib/python3.12/site-packages/mysql/connector/connection_cext.py\", line 706, in cmd_query\n    self._cmysql.query(\n_mysql_connector.MySQLInterfaceError: Unknown column 'email' in 'field list'\n\nThe above exception was the direct cause of the following exception:\n\nTraceback (most recent call last):\n  File \"/home/tygilman/School/CS3200/real-estate-htmx-fastapi/app/routes/admin.py\", line 47, in admin_dashboard\n    context[\"agents\"] = execute_procedure(conn, 'get_all_agents')\n                        ^^^^^^^^^^^^^^^^^^^^^^^^^^^^^^^^^^^^^^^^^\n  File \"/home/tygilman/School/CS3200/real-estate-htmx-fastapi/app/core/database.py\", line 48, in execute_procedure\n    cursor.callproc(procedure_name, params)\n  File \"/home/tygilman/School/CS3200/real-estate-htmx-fastapi/.venv/lib/python3.12/site-packages/mysql/connector/cursor_cext.py\", line 566, in callproc\n    result = self._connection.cmd_query(\n             ^^^^^^^^^^^^^^^^^^^^^^^^^^^\n  File \"/home/tygilman/School/CS3200/real-estate-htmx-fastapi/.venv/lib/python3.12/site-packages/mysql/connector/opentelemetry/context_propagation.py\", line 97, in wrapper\n    return method(cnx, *args, **kwargs)\n           ^^^^^^^^^^^^^^^^^^^^^^^^^^^^\n  File \"/home/tygilman/School/CS3200/real-estate-htmx-fastapi/.venv/lib/python3.12/site-packages/mysql/connector/connection_cext.py\", line 714, in cmd_query\n    raise get_mysql_exception(\nmysql.connector.errors.ProgrammingError: 1054 (42S22): Unknown column 'email' in 'field list'"}}
{"timestamp": "2024-12-01T00:22:17.838774", "level": "ERROR", "message": "Dashboard error: 1054 (42S22): Unknown column 'email' in 'field list'", "module": "admin", "function": "admin_dashboard", "line": 51, "thread_id": 131853661763392, "environment": "development", "exception": {"type": "ProgrammingError", "message": "1054 (42S22): Unknown column 'email' in 'field list'", "traceback": "Traceback (most recent call last):\n  File \"/home/tygilman/School/CS3200/real-estate-htmx-fastapi/.venv/lib/python3.12/site-packages/mysql/connector/connection_cext.py\", line 706, in cmd_query\n    self._cmysql.query(\n_mysql_connector.MySQLInterfaceError: Unknown column 'email' in 'field list'\n\nThe above exception was the direct cause of the following exception:\n\nTraceback (most recent call last):\n  File \"/home/tygilman/School/CS3200/real-estate-htmx-fastapi/app/routes/admin.py\", line 47, in admin_dashboard\n    context[\"agents\"] = execute_procedure(conn, 'get_all_agents')\n                        ^^^^^^^^^^^^^^^^^^^^^^^^^^^^^^^^^^^^^^^^^\n  File \"/home/tygilman/School/CS3200/real-estate-htmx-fastapi/app/core/database.py\", line 48, in execute_procedure\n    cursor.callproc(procedure_name, params)\n  File \"/home/tygilman/School/CS3200/real-estate-htmx-fastapi/.venv/lib/python3.12/site-packages/mysql/connector/cursor_cext.py\", line 566, in callproc\n    result = self._connection.cmd_query(\n             ^^^^^^^^^^^^^^^^^^^^^^^^^^^\n  File \"/home/tygilman/School/CS3200/real-estate-htmx-fastapi/.venv/lib/python3.12/site-packages/mysql/connector/opentelemetry/context_propagation.py\", line 97, in wrapper\n    return method(cnx, *args, **kwargs)\n           ^^^^^^^^^^^^^^^^^^^^^^^^^^^^\n  File \"/home/tygilman/School/CS3200/real-estate-htmx-fastapi/.venv/lib/python3.12/site-packages/mysql/connector/connection_cext.py\", line 714, in cmd_query\n    raise get_mysql_exception(\nmysql.connector.errors.ProgrammingError: 1054 (42S22): Unknown column 'email' in 'field list'"}}
{"timestamp": "2024-12-01T00:26:21.510068", "level": "ERROR", "message": "Failed to create client: 1054 (42S22): Unknown column 'last_modified' in 'field list'", "module": "admin", "function": "create_client", "line": 110, "thread_id": 124840038471488, "environment": "development", "exception": {"type": "ProgrammingError", "message": "1054 (42S22): Unknown column 'last_modified' in 'field list'", "traceback": "Traceback (most recent call last):\n  File \"/home/tygilman/School/CS3200/real-estate-htmx-fastapi/.venv/lib/python3.12/site-packages/mysql/connector/connection_cext.py\", line 706, in cmd_query\n    self._cmysql.query(\n_mysql_connector.MySQLInterfaceError: Unknown column 'last_modified' in 'field list'\n\nThe above exception was the direct cause of the following exception:\n\nTraceback (most recent call last):\n  File \"/home/tygilman/School/CS3200/real-estate-htmx-fastapi/app/routes/admin.py\", line 92, in create_client\n    execute_procedure(\n  File \"/home/tygilman/School/CS3200/real-estate-htmx-fastapi/app/core/database.py\", line 48, in execute_procedure\n    cursor.callproc(procedure_name, params)\n  File \"/home/tygilman/School/CS3200/real-estate-htmx-fastapi/.venv/lib/python3.12/site-packages/mysql/connector/cursor_cext.py\", line 566, in callproc\n    result = self._connection.cmd_query(\n             ^^^^^^^^^^^^^^^^^^^^^^^^^^^\n  File \"/home/tygilman/School/CS3200/real-estate-htmx-fastapi/.venv/lib/python3.12/site-packages/mysql/connector/opentelemetry/context_propagation.py\", line 97, in wrapper\n    return method(cnx, *args, **kwargs)\n           ^^^^^^^^^^^^^^^^^^^^^^^^^^^^\n  File \"/home/tygilman/School/CS3200/real-estate-htmx-fastapi/.venv/lib/python3.12/site-packages/mysql/connector/connection_cext.py\", line 714, in cmd_query\n    raise get_mysql_exception(\nmysql.connector.errors.ProgrammingError: 1054 (42S22): Unknown column 'last_modified' in 'field list'"}}
{"timestamp": "2024-12-01T00:28:02.914574", "level": "ERROR", "message": "Failed to create client: 1054 (42S22): Unknown column 'last_modified' in 'field list'", "module": "admin", "function": "create_client", "line": 110, "thread_id": 133611603810112, "environment": "development", "exception": {"type": "ProgrammingError", "message": "1054 (42S22): Unknown column 'last_modified' in 'field list'", "traceback": "Traceback (most recent call last):\n  File \"/home/tygilman/School/CS3200/real-estate-htmx-fastapi/.venv/lib/python3.12/site-packages/mysql/connector/connection_cext.py\", line 706, in cmd_query\n    self._cmysql.query(\n_mysql_connector.MySQLInterfaceError: Unknown column 'last_modified' in 'field list'\n\nThe above exception was the direct cause of the following exception:\n\nTraceback (most recent call last):\n  File \"/home/tygilman/School/CS3200/real-estate-htmx-fastapi/app/routes/admin.py\", line 92, in create_client\n    execute_procedure(\n  File \"/home/tygilman/School/CS3200/real-estate-htmx-fastapi/app/core/database.py\", line 48, in execute_procedure\n    cursor.callproc(procedure_name, params)\n  File \"/home/tygilman/School/CS3200/real-estate-htmx-fastapi/.venv/lib/python3.12/site-packages/mysql/connector/cursor_cext.py\", line 566, in callproc\n    result = self._connection.cmd_query(\n             ^^^^^^^^^^^^^^^^^^^^^^^^^^^\n  File \"/home/tygilman/School/CS3200/real-estate-htmx-fastapi/.venv/lib/python3.12/site-packages/mysql/connector/opentelemetry/context_propagation.py\", line 97, in wrapper\n    return method(cnx, *args, **kwargs)\n           ^^^^^^^^^^^^^^^^^^^^^^^^^^^^\n  File \"/home/tygilman/School/CS3200/real-estate-htmx-fastapi/.venv/lib/python3.12/site-packages/mysql/connector/connection_cext.py\", line 714, in cmd_query\n    raise get_mysql_exception(\nmysql.connector.errors.ProgrammingError: 1054 (42S22): Unknown column 'last_modified' in 'field list'"}}
{"timestamp": "2024-12-01T00:28:44.005121", "level": "ERROR", "message": "Failed to create client: 1054 (42S22): Unknown column 'last_modified' in 'field list'", "module": "admin", "function": "create_client", "line": 110, "thread_id": 123889667774272, "environment": "development", "exception": {"type": "ProgrammingError", "message": "1054 (42S22): Unknown column 'last_modified' in 'field list'", "traceback": "Traceback (most recent call last):\n  File \"/home/tygilman/School/CS3200/real-estate-htmx-fastapi/.venv/lib/python3.12/site-packages/mysql/connector/connection_cext.py\", line 706, in cmd_query\n    self._cmysql.query(\n_mysql_connector.MySQLInterfaceError: Unknown column 'last_modified' in 'field list'\n\nThe above exception was the direct cause of the following exception:\n\nTraceback (most recent call last):\n  File \"/home/tygilman/School/CS3200/real-estate-htmx-fastapi/app/routes/admin.py\", line 92, in create_client\n    execute_procedure(\n  File \"/home/tygilman/School/CS3200/real-estate-htmx-fastapi/app/core/database.py\", line 48, in execute_procedure\n    cursor.callproc(procedure_name, params)\n  File \"/home/tygilman/School/CS3200/real-estate-htmx-fastapi/.venv/lib/python3.12/site-packages/mysql/connector/cursor_cext.py\", line 566, in callproc\n    result = self._connection.cmd_query(\n             ^^^^^^^^^^^^^^^^^^^^^^^^^^^\n  File \"/home/tygilman/School/CS3200/real-estate-htmx-fastapi/.venv/lib/python3.12/site-packages/mysql/connector/opentelemetry/context_propagation.py\", line 97, in wrapper\n    return method(cnx, *args, **kwargs)\n           ^^^^^^^^^^^^^^^^^^^^^^^^^^^^\n  File \"/home/tygilman/School/CS3200/real-estate-htmx-fastapi/.venv/lib/python3.12/site-packages/mysql/connector/connection_cext.py\", line 714, in cmd_query\n    raise get_mysql_exception(\nmysql.connector.errors.ProgrammingError: 1054 (42S22): Unknown column 'last_modified' in 'field list'"}}
{"timestamp": "2024-12-01T01:00:30.684237", "level": "ERROR", "message": "Failed to create agent: 1318 (42000): Incorrect number of arguments for PROCEDURE real_estate.create_agent; expected 10, got 8", "module": "admin", "function": "create_agent", "line": 284, "thread_id": 123889667774272, "environment": "development", "exception": {"type": "ProgrammingError", "message": "1318 (42000): Incorrect number of arguments for PROCEDURE real_estate.create_agent; expected 10, got 8", "traceback": "Traceback (most recent call last):\n  File \"/home/tygilman/School/CS3200/real-estate-htmx-fastapi/.venv/lib/python3.12/site-packages/mysql/connector/connection_cext.py\", line 706, in cmd_query\n    self._cmysql.query(\n_mysql_connector.MySQLInterfaceError: Incorrect number of arguments for PROCEDURE real_estate.create_agent; expected 10, got 8\n\nThe above exception was the direct cause of the following exception:\n\nTraceback (most recent call last):\n  File \"/home/tygilman/School/CS3200/real-estate-htmx-fastapi/app/routes/admin.py\", line 273, in create_agent\n    execute_procedure(\n  File \"/home/tygilman/School/CS3200/real-estate-htmx-fastapi/app/core/database.py\", line 48, in execute_procedure\n    cursor.callproc(procedure_name, params)\n  File \"/home/tygilman/School/CS3200/real-estate-htmx-fastapi/.venv/lib/python3.12/site-packages/mysql/connector/cursor_cext.py\", line 566, in callproc\n    result = self._connection.cmd_query(\n             ^^^^^^^^^^^^^^^^^^^^^^^^^^^\n  File \"/home/tygilman/School/CS3200/real-estate-htmx-fastapi/.venv/lib/python3.12/site-packages/mysql/connector/opentelemetry/context_propagation.py\", line 97, in wrapper\n    return method(cnx, *args, **kwargs)\n           ^^^^^^^^^^^^^^^^^^^^^^^^^^^^\n  File \"/home/tygilman/School/CS3200/real-estate-htmx-fastapi/.venv/lib/python3.12/site-packages/mysql/connector/connection_cext.py\", line 714, in cmd_query\n    raise get_mysql_exception(\nmysql.connector.errors.ProgrammingError: 1318 (42000): Incorrect number of arguments for PROCEDURE real_estate.create_agent; expected 10, got 8"}}
{"timestamp": "2024-12-01T01:02:11.876742", "level": "ERROR", "message": "Failed to create client: 1136 (21S01): Column count doesn't match value count at row 1", "module": "admin", "function": "create_client", "line": 110, "thread_id": 135655930623808, "environment": "development", "exception": {"type": "DataError", "message": "1136 (21S01): Column count doesn't match value count at row 1", "traceback": "Traceback (most recent call last):\n  File \"/home/tygilman/School/CS3200/real-estate-htmx-fastapi/.venv/lib/python3.12/site-packages/mysql/connector/connection_cext.py\", line 706, in cmd_query\n    self._cmysql.query(\n_mysql_connector.MySQLInterfaceError: Column count doesn't match value count at row 1\n\nThe above exception was the direct cause of the following exception:\n\nTraceback (most recent call last):\n  File \"/home/tygilman/School/CS3200/real-estate-htmx-fastapi/app/routes/admin.py\", line 92, in create_client\n    execute_procedure(\n  File \"/home/tygilman/School/CS3200/real-estate-htmx-fastapi/app/core/database.py\", line 48, in execute_procedure\n    cursor.callproc(procedure_name, params)\n  File \"/home/tygilman/School/CS3200/real-estate-htmx-fastapi/.venv/lib/python3.12/site-packages/mysql/connector/cursor_cext.py\", line 566, in callproc\n    result = self._connection.cmd_query(\n             ^^^^^^^^^^^^^^^^^^^^^^^^^^^\n  File \"/home/tygilman/School/CS3200/real-estate-htmx-fastapi/.venv/lib/python3.12/site-packages/mysql/connector/opentelemetry/context_propagation.py\", line 97, in wrapper\n    return method(cnx, *args, **kwargs)\n           ^^^^^^^^^^^^^^^^^^^^^^^^^^^^\n  File \"/home/tygilman/School/CS3200/real-estate-htmx-fastapi/.venv/lib/python3.12/site-packages/mysql/connector/connection_cext.py\", line 714, in cmd_query\n    raise get_mysql_exception(\nmysql.connector.errors.DataError: 1136 (21S01): Column count doesn't match value count at row 1"}}
{"timestamp": "2024-12-01T01:05:32.505720", "level": "ERROR", "message": "Failed to create agent: 1318 (42000): Incorrect number of arguments for PROCEDURE real_estate.create_agent; expected 10, got 8", "module": "admin", "function": "create_agent", "line": 284, "thread_id": 129474782275392, "environment": "development", "exception": {"type": "ProgrammingError", "message": "1318 (42000): Incorrect number of arguments for PROCEDURE real_estate.create_agent; expected 10, got 8", "traceback": "Traceback (most recent call last):\n  File \"/home/tygilman/School/CS3200/real-estate-htmx-fastapi/.venv/lib/python3.12/site-packages/mysql/connector/connection_cext.py\", line 706, in cmd_query\n    self._cmysql.query(\n_mysql_connector.MySQLInterfaceError: Incorrect number of arguments for PROCEDURE real_estate.create_agent; expected 10, got 8\n\nThe above exception was the direct cause of the following exception:\n\nTraceback (most recent call last):\n  File \"/home/tygilman/School/CS3200/real-estate-htmx-fastapi/app/routes/admin.py\", line 273, in create_agent\n    execute_procedure(\n  File \"/home/tygilman/School/CS3200/real-estate-htmx-fastapi/app/core/database.py\", line 48, in execute_procedure\n    cursor.callproc(procedure_name, params)\n  File \"/home/tygilman/School/CS3200/real-estate-htmx-fastapi/.venv/lib/python3.12/site-packages/mysql/connector/cursor_cext.py\", line 566, in callproc\n    result = self._connection.cmd_query(\n             ^^^^^^^^^^^^^^^^^^^^^^^^^^^\n  File \"/home/tygilman/School/CS3200/real-estate-htmx-fastapi/.venv/lib/python3.12/site-packages/mysql/connector/opentelemetry/context_propagation.py\", line 97, in wrapper\n    return method(cnx, *args, **kwargs)\n           ^^^^^^^^^^^^^^^^^^^^^^^^^^^^\n  File \"/home/tygilman/School/CS3200/real-estate-htmx-fastapi/.venv/lib/python3.12/site-packages/mysql/connector/connection_cext.py\", line 714, in cmd_query\n    raise get_mysql_exception(\nmysql.connector.errors.ProgrammingError: 1318 (42000): Incorrect number of arguments for PROCEDURE real_estate.create_agent; expected 10, got 8"}}
{"timestamp": "2024-12-01T01:09:47.282654", "level": "ERROR", "message": "Failed to create agent: 1644 (45000): Invalid email format", "module": "admin", "function": "create_agent", "line": 284, "thread_id": 139190996641600, "environment": "development", "exception": {"type": "DatabaseError", "message": "1644 (45000): Invalid email format", "traceback": "Traceback (most recent call last):\n  File \"/home/tygilman/School/CS3200/real-estate-htmx-fastapi/.venv/lib/python3.12/site-packages/mysql/connector/connection_cext.py\", line 706, in cmd_query\n    self._cmysql.query(\n_mysql_connector.MySQLInterfaceError: Invalid email format\n\nThe above exception was the direct cause of the following exception:\n\nTraceback (most recent call last):\n  File \"/home/tygilman/School/CS3200/real-estate-htmx-fastapi/app/routes/admin.py\", line 273, in create_agent\n    execute_procedure(\n  File \"/home/tygilman/School/CS3200/real-estate-htmx-fastapi/app/core/database.py\", line 48, in execute_procedure\n    cursor.callproc(procedure_name, params)\n  File \"/home/tygilman/School/CS3200/real-estate-htmx-fastapi/.venv/lib/python3.12/site-packages/mysql/connector/cursor_cext.py\", line 566, in callproc\n    result = self._connection.cmd_query(\n             ^^^^^^^^^^^^^^^^^^^^^^^^^^^\n  File \"/home/tygilman/School/CS3200/real-estate-htmx-fastapi/.venv/lib/python3.12/site-packages/mysql/connector/opentelemetry/context_propagation.py\", line 97, in wrapper\n    return method(cnx, *args, **kwargs)\n           ^^^^^^^^^^^^^^^^^^^^^^^^^^^^\n  File \"/home/tygilman/School/CS3200/real-estate-htmx-fastapi/.venv/lib/python3.12/site-packages/mysql/connector/connection_cext.py\", line 714, in cmd_query\n    raise get_mysql_exception(\nmysql.connector.errors.DatabaseError: 1644 (45000): Invalid email format"}}
{"timestamp": "2024-12-01T01:09:55.578911", "level": "ERROR", "message": "Failed to create agent: 1452 (23000): Cannot add or update a child row: a foreign key constraint fails (`real_estate`.`Agent`, CONSTRAINT `Agent_ibfk_1` FOREIGN KEY (`broker_id`) REFERENCES `Brokerage` (`broker_id`))", "module": "admin", "function": "create_agent", "line": 284, "thread_id": 139190996641600, "environment": "development", "exception": {"type": "IntegrityError", "message": "1452 (23000): Cannot add or update a child row: a foreign key constraint fails (`real_estate`.`Agent`, CONSTRAINT `Agent_ibfk_1` FOREIGN KEY (`broker_id`) REFERENCES `Brokerage` (`broker_id`))", "traceback": "Traceback (most recent call last):\n  File \"/home/tygilman/School/CS3200/real-estate-htmx-fastapi/.venv/lib/python3.12/site-packages/mysql/connector/connection_cext.py\", line 706, in cmd_query\n    self._cmysql.query(\n_mysql_connector.MySQLInterfaceError: Cannot add or update a child row: a foreign key constraint fails (`real_estate`.`Agent`, CONSTRAINT `Agent_ibfk_1` FOREIGN KEY (`broker_id`) REFERENCES `Brokerage` (`broker_id`))\n\nThe above exception was the direct cause of the following exception:\n\nTraceback (most recent call last):\n  File \"/home/tygilman/School/CS3200/real-estate-htmx-fastapi/app/routes/admin.py\", line 273, in create_agent\n    execute_procedure(\n  File \"/home/tygilman/School/CS3200/real-estate-htmx-fastapi/app/core/database.py\", line 48, in execute_procedure\n    cursor.callproc(procedure_name, params)\n  File \"/home/tygilman/School/CS3200/real-estate-htmx-fastapi/.venv/lib/python3.12/site-packages/mysql/connector/cursor_cext.py\", line 566, in callproc\n    result = self._connection.cmd_query(\n             ^^^^^^^^^^^^^^^^^^^^^^^^^^^\n  File \"/home/tygilman/School/CS3200/real-estate-htmx-fastapi/.venv/lib/python3.12/site-packages/mysql/connector/opentelemetry/context_propagation.py\", line 97, in wrapper\n    return method(cnx, *args, **kwargs)\n           ^^^^^^^^^^^^^^^^^^^^^^^^^^^^\n  File \"/home/tygilman/School/CS3200/real-estate-htmx-fastapi/.venv/lib/python3.12/site-packages/mysql/connector/connection_cext.py\", line 714, in cmd_query\n    raise get_mysql_exception(\nmysql.connector.errors.IntegrityError: 1452 (23000): Cannot add or update a child row: a foreign key constraint fails (`real_estate`.`Agent`, CONSTRAINT `Agent_ibfk_1` FOREIGN KEY (`broker_id`) REFERENCES `Brokerage` (`broker_id`))"}}
{"timestamp": "2024-12-01T01:10:18.837858", "level": "ERROR", "message": "Failed to create agent: 1452 (23000): Cannot add or update a child row: a foreign key constraint fails (`real_estate`.`Agent`, CONSTRAINT `Agent_ibfk_1` FOREIGN KEY (`broker_id`) REFERENCES `Brokerage` (`broker_id`))", "module": "admin", "function": "create_agent", "line": 284, "thread_id": 139190996641600, "environment": "development", "exception": {"type": "IntegrityError", "message": "1452 (23000): Cannot add or update a child row: a foreign key constraint fails (`real_estate`.`Agent`, CONSTRAINT `Agent_ibfk_1` FOREIGN KEY (`broker_id`) REFERENCES `Brokerage` (`broker_id`))", "traceback": "Traceback (most recent call last):\n  File \"/home/tygilman/School/CS3200/real-estate-htmx-fastapi/.venv/lib/python3.12/site-packages/mysql/connector/connection_cext.py\", line 706, in cmd_query\n    self._cmysql.query(\n_mysql_connector.MySQLInterfaceError: Cannot add or update a child row: a foreign key constraint fails (`real_estate`.`Agent`, CONSTRAINT `Agent_ibfk_1` FOREIGN KEY (`broker_id`) REFERENCES `Brokerage` (`broker_id`))\n\nThe above exception was the direct cause of the following exception:\n\nTraceback (most recent call last):\n  File \"/home/tygilman/School/CS3200/real-estate-htmx-fastapi/app/routes/admin.py\", line 273, in create_agent\n    execute_procedure(\n  File \"/home/tygilman/School/CS3200/real-estate-htmx-fastapi/app/core/database.py\", line 48, in execute_procedure\n    cursor.callproc(procedure_name, params)\n  File \"/home/tygilman/School/CS3200/real-estate-htmx-fastapi/.venv/lib/python3.12/site-packages/mysql/connector/cursor_cext.py\", line 566, in callproc\n    result = self._connection.cmd_query(\n             ^^^^^^^^^^^^^^^^^^^^^^^^^^^\n  File \"/home/tygilman/School/CS3200/real-estate-htmx-fastapi/.venv/lib/python3.12/site-packages/mysql/connector/opentelemetry/context_propagation.py\", line 97, in wrapper\n    return method(cnx, *args, **kwargs)\n           ^^^^^^^^^^^^^^^^^^^^^^^^^^^^\n  File \"/home/tygilman/School/CS3200/real-estate-htmx-fastapi/.venv/lib/python3.12/site-packages/mysql/connector/connection_cext.py\", line 714, in cmd_query\n    raise get_mysql_exception(\nmysql.connector.errors.IntegrityError: 1452 (23000): Cannot add or update a child row: a foreign key constraint fails (`real_estate`.`Agent`, CONSTRAINT `Agent_ibfk_1` FOREIGN KEY (`broker_id`) REFERENCES `Brokerage` (`broker_id`))"}}
{"timestamp": "2024-12-01T01:10:25.046854", "level": "ERROR", "message": "Failed to create agent: 1452 (23000): Cannot add or update a child row: a foreign key constraint fails (`real_estate`.`Agent`, CONSTRAINT `Agent_ibfk_1` FOREIGN KEY (`broker_id`) REFERENCES `Brokerage` (`broker_id`))", "module": "admin", "function": "create_agent", "line": 284, "thread_id": 139190996641600, "environment": "development", "exception": {"type": "IntegrityError", "message": "1452 (23000): Cannot add or update a child row: a foreign key constraint fails (`real_estate`.`Agent`, CONSTRAINT `Agent_ibfk_1` FOREIGN KEY (`broker_id`) REFERENCES `Brokerage` (`broker_id`))", "traceback": "Traceback (most recent call last):\n  File \"/home/tygilman/School/CS3200/real-estate-htmx-fastapi/.venv/lib/python3.12/site-packages/mysql/connector/connection_cext.py\", line 706, in cmd_query\n    self._cmysql.query(\n_mysql_connector.MySQLInterfaceError: Cannot add or update a child row: a foreign key constraint fails (`real_estate`.`Agent`, CONSTRAINT `Agent_ibfk_1` FOREIGN KEY (`broker_id`) REFERENCES `Brokerage` (`broker_id`))\n\nThe above exception was the direct cause of the following exception:\n\nTraceback (most recent call last):\n  File \"/home/tygilman/School/CS3200/real-estate-htmx-fastapi/app/routes/admin.py\", line 273, in create_agent\n    execute_procedure(\n  File \"/home/tygilman/School/CS3200/real-estate-htmx-fastapi/app/core/database.py\", line 48, in execute_procedure\n    cursor.callproc(procedure_name, params)\n  File \"/home/tygilman/School/CS3200/real-estate-htmx-fastapi/.venv/lib/python3.12/site-packages/mysql/connector/cursor_cext.py\", line 566, in callproc\n    result = self._connection.cmd_query(\n             ^^^^^^^^^^^^^^^^^^^^^^^^^^^\n  File \"/home/tygilman/School/CS3200/real-estate-htmx-fastapi/.venv/lib/python3.12/site-packages/mysql/connector/opentelemetry/context_propagation.py\", line 97, in wrapper\n    return method(cnx, *args, **kwargs)\n           ^^^^^^^^^^^^^^^^^^^^^^^^^^^^\n  File \"/home/tygilman/School/CS3200/real-estate-htmx-fastapi/.venv/lib/python3.12/site-packages/mysql/connector/connection_cext.py\", line 714, in cmd_query\n    raise get_mysql_exception(\nmysql.connector.errors.IntegrityError: 1452 (23000): Cannot add or update a child row: a foreign key constraint fails (`real_estate`.`Agent`, CONSTRAINT `Agent_ibfk_1` FOREIGN KEY (`broker_id`) REFERENCES `Brokerage` (`broker_id`))"}}
{"timestamp": "2024-12-01T01:10:25.678541", "level": "ERROR", "message": "Failed to create agent: 1452 (23000): Cannot add or update a child row: a foreign key constraint fails (`real_estate`.`Agent`, CONSTRAINT `Agent_ibfk_1` FOREIGN KEY (`broker_id`) REFERENCES `Brokerage` (`broker_id`))", "module": "admin", "function": "create_agent", "line": 284, "thread_id": 139190996641600, "environment": "development", "exception": {"type": "IntegrityError", "message": "1452 (23000): Cannot add or update a child row: a foreign key constraint fails (`real_estate`.`Agent`, CONSTRAINT `Agent_ibfk_1` FOREIGN KEY (`broker_id`) REFERENCES `Brokerage` (`broker_id`))", "traceback": "Traceback (most recent call last):\n  File \"/home/tygilman/School/CS3200/real-estate-htmx-fastapi/.venv/lib/python3.12/site-packages/mysql/connector/connection_cext.py\", line 706, in cmd_query\n    self._cmysql.query(\n_mysql_connector.MySQLInterfaceError: Cannot add or update a child row: a foreign key constraint fails (`real_estate`.`Agent`, CONSTRAINT `Agent_ibfk_1` FOREIGN KEY (`broker_id`) REFERENCES `Brokerage` (`broker_id`))\n\nThe above exception was the direct cause of the following exception:\n\nTraceback (most recent call last):\n  File \"/home/tygilman/School/CS3200/real-estate-htmx-fastapi/app/routes/admin.py\", line 273, in create_agent\n    execute_procedure(\n  File \"/home/tygilman/School/CS3200/real-estate-htmx-fastapi/app/core/database.py\", line 48, in execute_procedure\n    cursor.callproc(procedure_name, params)\n  File \"/home/tygilman/School/CS3200/real-estate-htmx-fastapi/.venv/lib/python3.12/site-packages/mysql/connector/cursor_cext.py\", line 566, in callproc\n    result = self._connection.cmd_query(\n             ^^^^^^^^^^^^^^^^^^^^^^^^^^^\n  File \"/home/tygilman/School/CS3200/real-estate-htmx-fastapi/.venv/lib/python3.12/site-packages/mysql/connector/opentelemetry/context_propagation.py\", line 97, in wrapper\n    return method(cnx, *args, **kwargs)\n           ^^^^^^^^^^^^^^^^^^^^^^^^^^^^\n  File \"/home/tygilman/School/CS3200/real-estate-htmx-fastapi/.venv/lib/python3.12/site-packages/mysql/connector/connection_cext.py\", line 714, in cmd_query\n    raise get_mysql_exception(\nmysql.connector.errors.IntegrityError: 1452 (23000): Cannot add or update a child row: a foreign key constraint fails (`real_estate`.`Agent`, CONSTRAINT `Agent_ibfk_1` FOREIGN KEY (`broker_id`) REFERENCES `Brokerage` (`broker_id`))"}}
{"timestamp": "2024-12-01T01:11:43.933401", "level": "ERROR", "message": "Failed to create agent: 1452 (23000): Cannot add or update a child row: a foreign key constraint fails (`real_estate`.`Agent`, CONSTRAINT `Agent_ibfk_1` FOREIGN KEY (`broker_id`) REFERENCES `Brokerage` (`broker_id`))", "module": "admin", "function": "create_agent", "line": 284, "thread_id": 139190996641600, "environment": "development", "exception": {"type": "IntegrityError", "message": "1452 (23000): Cannot add or update a child row: a foreign key constraint fails (`real_estate`.`Agent`, CONSTRAINT `Agent_ibfk_1` FOREIGN KEY (`broker_id`) REFERENCES `Brokerage` (`broker_id`))", "traceback": "Traceback (most recent call last):\n  File \"/home/tygilman/School/CS3200/real-estate-htmx-fastapi/.venv/lib/python3.12/site-packages/mysql/connector/connection_cext.py\", line 706, in cmd_query\n    self._cmysql.query(\n_mysql_connector.MySQLInterfaceError: Cannot add or update a child row: a foreign key constraint fails (`real_estate`.`Agent`, CONSTRAINT `Agent_ibfk_1` FOREIGN KEY (`broker_id`) REFERENCES `Brokerage` (`broker_id`))\n\nThe above exception was the direct cause of the following exception:\n\nTraceback (most recent call last):\n  File \"/home/tygilman/School/CS3200/real-estate-htmx-fastapi/app/routes/admin.py\", line 273, in create_agent\n    execute_procedure(\n  File \"/home/tygilman/School/CS3200/real-estate-htmx-fastapi/app/core/database.py\", line 48, in execute_procedure\n    cursor.callproc(procedure_name, params)\n  File \"/home/tygilman/School/CS3200/real-estate-htmx-fastapi/.venv/lib/python3.12/site-packages/mysql/connector/cursor_cext.py\", line 566, in callproc\n    result = self._connection.cmd_query(\n             ^^^^^^^^^^^^^^^^^^^^^^^^^^^\n  File \"/home/tygilman/School/CS3200/real-estate-htmx-fastapi/.venv/lib/python3.12/site-packages/mysql/connector/opentelemetry/context_propagation.py\", line 97, in wrapper\n    return method(cnx, *args, **kwargs)\n           ^^^^^^^^^^^^^^^^^^^^^^^^^^^^\n  File \"/home/tygilman/School/CS3200/real-estate-htmx-fastapi/.venv/lib/python3.12/site-packages/mysql/connector/connection_cext.py\", line 714, in cmd_query\n    raise get_mysql_exception(\nmysql.connector.errors.IntegrityError: 1452 (23000): Cannot add or update a child row: a foreign key constraint fails (`real_estate`.`Agent`, CONSTRAINT `Agent_ibfk_1` FOREIGN KEY (`broker_id`) REFERENCES `Brokerage` (`broker_id`))"}}
{"timestamp": "2024-12-01T01:11:44.537548", "level": "ERROR", "message": "Failed to create agent: 1452 (23000): Cannot add or update a child row: a foreign key constraint fails (`real_estate`.`Agent`, CONSTRAINT `Agent_ibfk_1` FOREIGN KEY (`broker_id`) REFERENCES `Brokerage` (`broker_id`))", "module": "admin", "function": "create_agent", "line": 284, "thread_id": 139190996641600, "environment": "development", "exception": {"type": "IntegrityError", "message": "1452 (23000): Cannot add or update a child row: a foreign key constraint fails (`real_estate`.`Agent`, CONSTRAINT `Agent_ibfk_1` FOREIGN KEY (`broker_id`) REFERENCES `Brokerage` (`broker_id`))", "traceback": "Traceback (most recent call last):\n  File \"/home/tygilman/School/CS3200/real-estate-htmx-fastapi/.venv/lib/python3.12/site-packages/mysql/connector/connection_cext.py\", line 706, in cmd_query\n    self._cmysql.query(\n_mysql_connector.MySQLInterfaceError: Cannot add or update a child row: a foreign key constraint fails (`real_estate`.`Agent`, CONSTRAINT `Agent_ibfk_1` FOREIGN KEY (`broker_id`) REFERENCES `Brokerage` (`broker_id`))\n\nThe above exception was the direct cause of the following exception:\n\nTraceback (most recent call last):\n  File \"/home/tygilman/School/CS3200/real-estate-htmx-fastapi/app/routes/admin.py\", line 273, in create_agent\n    execute_procedure(\n  File \"/home/tygilman/School/CS3200/real-estate-htmx-fastapi/app/core/database.py\", line 48, in execute_procedure\n    cursor.callproc(procedure_name, params)\n  File \"/home/tygilman/School/CS3200/real-estate-htmx-fastapi/.venv/lib/python3.12/site-packages/mysql/connector/cursor_cext.py\", line 566, in callproc\n    result = self._connection.cmd_query(\n             ^^^^^^^^^^^^^^^^^^^^^^^^^^^\n  File \"/home/tygilman/School/CS3200/real-estate-htmx-fastapi/.venv/lib/python3.12/site-packages/mysql/connector/opentelemetry/context_propagation.py\", line 97, in wrapper\n    return method(cnx, *args, **kwargs)\n           ^^^^^^^^^^^^^^^^^^^^^^^^^^^^\n  File \"/home/tygilman/School/CS3200/real-estate-htmx-fastapi/.venv/lib/python3.12/site-packages/mysql/connector/connection_cext.py\", line 714, in cmd_query\n    raise get_mysql_exception(\nmysql.connector.errors.IntegrityError: 1452 (23000): Cannot add or update a child row: a foreign key constraint fails (`real_estate`.`Agent`, CONSTRAINT `Agent_ibfk_1` FOREIGN KEY (`broker_id`) REFERENCES `Brokerage` (`broker_id`))"}}
