{"timestamp": "2024-11-26T18:29:53.489352", "level": "ERROR", "message": "Failed to create property", "module": "admin", "function": "create_property", "line": 224, "thread_id": 126343480993600, "exception": {"type": "NameError", "message": "name 'random' is not defined", "traceback": "Traceback (most recent call last):\n  File \"/home/tygilman/School/CS3200/real-estate-htmx-fastapi/app/routes/admin.py\", line 150, in create_property\n    tax_id = f\"TAX{random.randint(100000, 999999)}\"\n                   ^^^^^^\nNameError: name 'random' is not defined. Did you forget to import 'random'"}}
{"timestamp": "2024-11-26T18:31:26.841740", "level": "ERROR", "message": "Failed to create property", "module": "admin", "function": "create_property", "line": 225, "thread_id": 136264655836992, "exception": {"type": "TypeError", "message": "unsupported format string passed to Undefined.__format__", "traceback": "Traceback (most recent call last):\n  File \"/home/tygilman/School/CS3200/real-estate-htmx-fastapi/app/routes/admin.py\", line 204, in create_property\n    property_row = templates.TemplateResponse(\n                   ^^^^^^^^^^^^^^^^^^^^^^^^^^^\n  File \"/home/tygilman/School/CS3200/real-estate-htmx-fastapi/.venv/lib/python3.12/site-packages/starlette/templating.py\", line 113, in TemplateResponse\n    return _TemplateResponse(\n           ^^^^^^^^^^^^^^^^^^\n  File \"/home/tygilman/School/CS3200/real-estate-htmx-fastapi/.venv/lib/python3.12/site-packages/starlette/templating.py\", line 39, in __init__\n    content = template.render(context)\n              ^^^^^^^^^^^^^^^^^^^^^^^^\n  File \"/home/tygilman/School/CS3200/real-estate-htmx-fastapi/.venv/lib/python3.12/site-packages/jinja2/environment.py\", line 1301, in render\n    self.environment.handle_exception()\n  File \"/home/tygilman/School/CS3200/real-estate-htmx-fastapi/.venv/lib/python3.12/site-packages/jinja2/environment.py\", line 936, in handle_exception\n    raise rewrite_traceback_stack(source=source)\n  File \"app/templates/admin/properties/table_row.html\", line 14, in top-level template code\n    {{ \"{:,.0f}\".format(property.square_feet) }} sqft\n    ^^^^^^^^^^^^^^^^^^^^^^^^^\nTypeError: unsupported format string passed to Undefined.__format__"}}
{"timestamp": "2024-11-26T18:37:34.054347", "level": "ERROR", "message": "Failed to create property", "module": "admin", "function": "create_property", "line": 225, "thread_id": 136264655836992, "exception": {"type": "TypeError", "message": "unsupported format string passed to Undefined.__format__", "traceback": "Traceback (most recent call last):\n  File \"/home/tygilman/School/CS3200/real-estate-htmx-fastapi/app/routes/admin.py\", line 204, in create_property\n    property_row = templates.TemplateResponse(\n                   ^^^^^^^^^^^^^^^^^^^^^^^^^^^\n  File \"/home/tygilman/School/CS3200/real-estate-htmx-fastapi/.venv/lib/python3.12/site-packages/starlette/templating.py\", line 113, in TemplateResponse\n    return _TemplateResponse(\n           ^^^^^^^^^^^^^^^^^^\n  File \"/home/tygilman/School/CS3200/real-estate-htmx-fastapi/.venv/lib/python3.12/site-packages/starlette/templating.py\", line 39, in __init__\n    content = template.render(context)\n              ^^^^^^^^^^^^^^^^^^^^^^^^\n  File \"/home/tygilman/School/CS3200/real-estate-htmx-fastapi/.venv/lib/python3.12/site-packages/jinja2/environment.py\", line 1301, in render\n    self.environment.handle_exception()\n  File \"/home/tygilman/School/CS3200/real-estate-htmx-fastapi/.venv/lib/python3.12/site-packages/jinja2/environment.py\", line 936, in handle_exception\n    raise rewrite_traceback_stack(source=source)\n  File \"app/templates/admin/properties/table_row.html\", line 14, in top-level template code\n    {{ \"{:,.0f}\".format(property.square_feet) }} sqft\n    ^^^^^^^^^^^^^^^^^^^^^^^^^\nTypeError: unsupported format string passed to Undefined.__format__"}}
{"timestamp": "2024-11-26T18:44:25.453807", "level": "ERROR", "message": "Failed to create property: name 'PropertyStatus' is not defined", "module": "admin", "function": "create_property", "line": 235, "thread_id": 133919540541248, "exception": {"type": "NameError", "message": "name 'PropertyStatus' is not defined", "traceback": "Traceback (most recent call last):\n  File \"/home/tygilman/School/CS3200/real-estate-htmx-fastapi/app/routes/admin.py\", line 159, in create_property\n    status=PropertyStatus(status),\n           ^^^^^^^^^^^^^^\nNameError: name 'PropertyStatus' is not defined. Did you mean: 'property_tax'?"}}
{"timestamp": "2024-11-26T19:52:54.326540", "level": "ERROR", "message": "Failed to delete property 1: name 'text' is not defined", "module": "admin", "function": "delete_property", "line": 471, "thread_id": 137583919757120, "exception": {"type": "NameError", "message": "name 'text' is not defined", "traceback": "Traceback (most recent call last):\n  File \"/home/tygilman/School/CS3200/real-estate-htmx-fastapi/app/routes/admin.py\", line 460, in delete_property\n    text(\"CALL delete_property(:property_id)\"), {\"property_id\": property_id}\n    ^^^^\nNameError: name 'text' is not defined. Did you mean: 'next'?"}}
{"timestamp": "2024-11-26T19:53:56.287157", "level": "ERROR", "message": "Failed to delete property 1: name 'text' is not defined", "module": "admin", "function": "delete_property", "line": 471, "thread_id": 137583919757120, "exception": {"type": "NameError", "message": "name 'text' is not defined", "traceback": "Traceback (most recent call last):\n  File \"/home/tygilman/School/CS3200/real-estate-htmx-fastapi/app/routes/admin.py\", line 460, in delete_property\n    text(\"CALL delete_property(:property_id)\"), {\"property_id\": property_id}\n    ^^^^\nNameError: name 'text' is not defined. Did you mean: 'next'?"}}
{"timestamp": "2024-11-26T19:57:24.822403", "level": "ERROR", "message": "Failed to delete property 1: name 'text' is not defined", "module": "admin", "function": "delete_property", "line": 471, "thread_id": 137583919757120, "exception": {"type": "NameError", "message": "name 'text' is not defined", "traceback": "Traceback (most recent call last):\n  File \"/home/tygilman/School/CS3200/real-estate-htmx-fastapi/app/routes/admin.py\", line 460, in delete_property\n    text(\"CALL delete_property(:property_id)\"), {\"property_id\": property_id}\n    ^^^^\nNameError: name 'text' is not defined. Did you mean: 'next'?"}}
{"timestamp": "2024-11-26T19:58:27.323770", "level": "ERROR", "message": "Failed to delete property 1: (mysql.connector.errors.ProgrammingError) 1305 (42000): PROCEDURE real_estate.delete_property does not exist\n[SQL: CALL delete_property(%(property_id)s)]\n[parameters: {'property_id': 1}]\n(Background on this error at: https://sqlalche.me/e/20/f405)", "module": "admin", "function": "delete_property", "line": 471, "thread_id": 128901907683136, "exception": {"type": "ProgrammingError", "message": "(mysql.connector.errors.ProgrammingError) 1305 (42000): PROCEDURE real_estate.delete_property does not exist\n[SQL: CALL delete_property(%(property_id)s)]\n[parameters: {'property_id': 1}]\n(Background on this error at: https://sqlalche.me/e/20/f405)", "traceback": "Traceback (most recent call last):\n  File \"/home/tygilman/School/CS3200/real-estate-htmx-fastapi/.venv/lib/python3.12/site-packages/mysql/connector/connection_cext.py\", line 706, in cmd_query\n    self._cmysql.query(\n_mysql_connector.MySQLInterfaceError: PROCEDURE real_estate.delete_property does not exist\n\nThe above exception was the direct cause of the following exception:\n\nTraceback (most recent call last):\n  File \"/home/tygilman/School/CS3200/real-estate-htmx-fastapi/.venv/lib/python3.12/site-packages/sqlalchemy/engine/base.py\", line 1969, in _exec_single_context\n    self.dialect.do_execute(\n  File \"/home/tygilman/School/CS3200/real-estate-htmx-fastapi/.venv/lib/python3.12/site-packages/sqlalchemy/engine/default.py\", line 922, in do_execute\n    cursor.execute(statement, parameters)\n  File \"/home/tygilman/School/CS3200/real-estate-htmx-fastapi/.venv/lib/python3.12/site-packages/mysql/connector/cursor_cext.py\", line 357, in execute\n    result = self._connection.cmd_query(\n             ^^^^^^^^^^^^^^^^^^^^^^^^^^^\n  File \"/home/tygilman/School/CS3200/real-estate-htmx-fastapi/.venv/lib/python3.12/site-packages/mysql/connector/opentelemetry/context_propagation.py\", line 97, in wrapper\n    return method(cnx, *args, **kwargs)\n           ^^^^^^^^^^^^^^^^^^^^^^^^^^^^\n  File \"/home/tygilman/School/CS3200/real-estate-htmx-fastapi/.venv/lib/python3.12/site-packages/mysql/connector/connection_cext.py\", line 714, in cmd_query\n    raise get_mysql_exception(\nmysql.connector.errors.ProgrammingError: 1305 (42000): PROCEDURE real_estate.delete_property does not exist\n\nThe above exception was the direct cause of the following exception:\n\nTraceback (most recent call last):\n  File \"/home/tygilman/School/CS3200/real-estate-htmx-fastapi/app/routes/admin.py\", line 459, in delete_property\n    db.execute(\n  File \"/home/tygilman/School/CS3200/real-estate-htmx-fastapi/.venv/lib/python3.12/site-packages/sqlalchemy/orm/session.py\", line 2308, in execute\n    return self._execute_internal(\n           ^^^^^^^^^^^^^^^^^^^^^^^\n  File \"/home/tygilman/School/CS3200/real-estate-htmx-fastapi/.venv/lib/python3.12/site-packages/sqlalchemy/orm/session.py\", line 2199, in _execute_internal\n    result = conn.execute(\n             ^^^^^^^^^^^^^\n  File \"/home/tygilman/School/CS3200/real-estate-htmx-fastapi/.venv/lib/python3.12/site-packages/sqlalchemy/engine/base.py\", line 1416, in execute\n    return meth(\n           ^^^^^\n  File \"/home/tygilman/School/CS3200/real-estate-htmx-fastapi/.venv/lib/python3.12/site-packages/sqlalchemy/sql/elements.py\", line 516, in _execute_on_connection\n    return connection._execute_clauseelement(\n           ^^^^^^^^^^^^^^^^^^^^^^^^^^^^^^^^^^\n  File \"/home/tygilman/School/CS3200/real-estate-htmx-fastapi/.venv/lib/python3.12/site-packages/sqlalchemy/engine/base.py\", line 1639, in _execute_clauseelement\n    ret = self._execute_context(\n          ^^^^^^^^^^^^^^^^^^^^^^\n  File \"/home/tygilman/School/CS3200/real-estate-htmx-fastapi/.venv/lib/python3.12/site-packages/sqlalchemy/engine/base.py\", line 1848, in _execute_context\n    return self._exec_single_context(\n           ^^^^^^^^^^^^^^^^^^^^^^^^^^\n  File \"/home/tygilman/School/CS3200/real-estate-htmx-fastapi/.venv/lib/python3.12/site-packages/sqlalchemy/engine/base.py\", line 1988, in _exec_single_context\n    self._handle_dbapi_exception(\n  File \"/home/tygilman/School/CS3200/real-estate-htmx-fastapi/.venv/lib/python3.12/site-packages/sqlalchemy/engine/base.py\", line 2343, in _handle_dbapi_exception\n    raise sqlalchemy_exception.with_traceback(exc_info[2]) from e\n  File \"/home/tygilman/School/CS3200/real-estate-htmx-fastapi/.venv/lib/python3.12/site-packages/sqlalchemy/engine/base.py\", line 1969, in _exec_single_context\n    self.dialect.do_execute(\n  File \"/home/tygilman/School/CS3200/real-estate-htmx-fastapi/.venv/lib/python3.12/site-packages/sqlalchemy/engine/default.py\", line 922, in do_execute\n    cursor.execute(statement, parameters)\n  File \"/home/tygilman/School/CS3200/real-estate-htmx-fastapi/.venv/lib/python3.12/site-packages/mysql/connector/cursor_cext.py\", line 357, in execute\n    result = self._connection.cmd_query(\n             ^^^^^^^^^^^^^^^^^^^^^^^^^^^\n  File \"/home/tygilman/School/CS3200/real-estate-htmx-fastapi/.venv/lib/python3.12/site-packages/mysql/connector/opentelemetry/context_propagation.py\", line 97, in wrapper\n    return method(cnx, *args, **kwargs)\n           ^^^^^^^^^^^^^^^^^^^^^^^^^^^^\n  File \"/home/tygilman/School/CS3200/real-estate-htmx-fastapi/.venv/lib/python3.12/site-packages/mysql/connector/connection_cext.py\", line 714, in cmd_query\n    raise get_mysql_exception(\nsqlalchemy.exc.ProgrammingError: (mysql.connector.errors.ProgrammingError) 1305 (42000): PROCEDURE real_estate.delete_property does not exist\n[SQL: CALL delete_property(%(property_id)s)]\n[parameters: {'property_id': 1}]\n(Background on this error at: https://sqlalche.me/e/20/f405)"}}
{"timestamp": "2024-11-26T20:04:25.378870", "level": "ERROR", "message": "Failed to delete property 4: Class 'builtins.NoneType' is not mapped", "module": "admin", "function": "delete_property", "line": 487, "thread_id": 134533482547008, "exception": {"type": "UnmappedInstanceError", "message": "Class 'builtins.NoneType' is not mapped", "traceback": "Traceback (most recent call last):\n  File \"/home/tygilman/School/CS3200/real-estate-htmx-fastapi/.venv/lib/python3.12/site-packages/sqlalchemy/orm/session.py\", line 3494, in delete\n    state = attributes.instance_state(instance)\n            ^^^^^^^^^^^^^^^^^^^^^^^^^^^^^^^^^^^\nAttributeError: 'NoneType' object has no attribute '_sa_instance_state'\n\nThe above exception was the direct cause of the following exception:\n\nTraceback (most recent call last):\n  File \"/home/tygilman/School/CS3200/real-estate-htmx-fastapi/app/routes/admin.py\", line 467, in delete_property\n    db.delete(property.residential)\n  File \"/home/tygilman/School/CS3200/real-estate-htmx-fastapi/.venv/lib/python3.12/site-packages/sqlalchemy/orm/session.py\", line 3496, in delete\n    raise exc.UnmappedInstanceError(instance) from err\nsqlalchemy.orm.exc.UnmappedInstanceError: Class 'builtins.NoneType' is not mapped"}}
{"timestamp": "2024-11-26T20:04:29.816492", "level": "ERROR", "message": "Failed to delete property 5: Class 'builtins.NoneType' is not mapped", "module": "admin", "function": "delete_property", "line": 487, "thread_id": 134533482547008, "exception": {"type": "UnmappedInstanceError", "message": "Class 'builtins.NoneType' is not mapped", "traceback": "Traceback (most recent call last):\n  File \"/home/tygilman/School/CS3200/real-estate-htmx-fastapi/.venv/lib/python3.12/site-packages/sqlalchemy/orm/session.py\", line 3494, in delete\n    state = attributes.instance_state(instance)\n            ^^^^^^^^^^^^^^^^^^^^^^^^^^^^^^^^^^^\nAttributeError: 'NoneType' object has no attribute '_sa_instance_state'\n\nThe above exception was the direct cause of the following exception:\n\nTraceback (most recent call last):\n  File \"/home/tygilman/School/CS3200/real-estate-htmx-fastapi/app/routes/admin.py\", line 467, in delete_property\n    db.delete(property.residential)\n  File \"/home/tygilman/School/CS3200/real-estate-htmx-fastapi/.venv/lib/python3.12/site-packages/sqlalchemy/orm/session.py\", line 3496, in delete\n    raise exc.UnmappedInstanceError(instance) from err\nsqlalchemy.orm.exc.UnmappedInstanceError: Class 'builtins.NoneType' is not mapped"}}
{"timestamp": "2024-11-26T20:04:33.950855", "level": "ERROR", "message": "Failed to delete property 5: Class 'builtins.NoneType' is not mapped", "module": "admin", "function": "delete_property", "line": 487, "thread_id": 134533482547008, "exception": {"type": "UnmappedInstanceError", "message": "Class 'builtins.NoneType' is not mapped", "traceback": "Traceback (most recent call last):\n  File \"/home/tygilman/School/CS3200/real-estate-htmx-fastapi/.venv/lib/python3.12/site-packages/sqlalchemy/orm/session.py\", line 3494, in delete\n    state = attributes.instance_state(instance)\n            ^^^^^^^^^^^^^^^^^^^^^^^^^^^^^^^^^^^\nAttributeError: 'NoneType' object has no attribute '_sa_instance_state'\n\nThe above exception was the direct cause of the following exception:\n\nTraceback (most recent call last):\n  File \"/home/tygilman/School/CS3200/real-estate-htmx-fastapi/app/routes/admin.py\", line 467, in delete_property\n    db.delete(property.residential)\n  File \"/home/tygilman/School/CS3200/real-estate-htmx-fastapi/.venv/lib/python3.12/site-packages/sqlalchemy/orm/session.py\", line 3496, in delete\n    raise exc.UnmappedInstanceError(instance) from err\nsqlalchemy.orm.exc.UnmappedInstanceError: Class 'builtins.NoneType' is not mapped"}}
{"timestamp": "2024-11-26T20:05:09.482208", "level": "ERROR", "message": "Failed to delete property 7: Class 'builtins.NoneType' is not mapped", "module": "admin", "function": "delete_property", "line": 487, "thread_id": 134533482547008, "exception": {"type": "UnmappedInstanceError", "message": "Class 'builtins.NoneType' is not mapped", "traceback": "Traceback (most recent call last):\n  File \"/home/tygilman/School/CS3200/real-estate-htmx-fastapi/.venv/lib/python3.12/site-packages/sqlalchemy/orm/session.py\", line 3494, in delete\n    state = attributes.instance_state(instance)\n            ^^^^^^^^^^^^^^^^^^^^^^^^^^^^^^^^^^^\nAttributeError: 'NoneType' object has no attribute '_sa_instance_state'\n\nThe above exception was the direct cause of the following exception:\n\nTraceback (most recent call last):\n  File \"/home/tygilman/School/CS3200/real-estate-htmx-fastapi/app/routes/admin.py\", line 467, in delete_property\n    db.delete(property.residential)\n  File \"/home/tygilman/School/CS3200/real-estate-htmx-fastapi/.venv/lib/python3.12/site-packages/sqlalchemy/orm/session.py\", line 3496, in delete\n    raise exc.UnmappedInstanceError(instance) from err\nsqlalchemy.orm.exc.UnmappedInstanceError: Class 'builtins.NoneType' is not mapped"}}
{"timestamp": "2024-11-26T20:05:55.832603", "level": "ERROR", "message": "Failed to delete property 4: name 'Contract' is not defined", "module": "admin", "function": "delete_property", "line": 498, "thread_id": 139920310724416, "exception": {"type": "NameError", "message": "name 'Contract' is not defined", "traceback": "Traceback (most recent call last):\n  File \"/home/tygilman/School/CS3200/real-estate-htmx-fastapi/app/routes/admin.py\", line 485, in delete_property\n    db.query(Contract).filter(Contract.property_id == property_id).delete()\n             ^^^^^^^^\nNameError: name 'Contract' is not defined"}}
{"timestamp": "2024-11-26T22:43:46.503816", "level": "ERROR", "message": "Failed to create property", "module": "admin", "function": "create_property", "line": 258, "thread_id": 126749084710720, "exception": {"type": "DataError", "message": "(mysql.connector.errors.DataError) 1264 (22003): Out of range value for column 'price' at row 1\n[SQL: INSERT INTO `Property` (tax_id, property_address, status, price, lot_size, year_built, zoning, property_tax, created_at, updated_at, image_url) VALUES (%(tax_id)s, %(property_address)s, %(status)s, %(price)s, %(lot_size)s, %(year_built)s, %(zoning)s, %(property_tax)s, now(), now(), %(image_url)s)]\n[parameters: {'tax_id': 'TAX430416', 'property_address': '234234afasf', 'status': 'FOR_SALE', 'price': 234234234234234.0, 'lot_size': 2343.0, 'year_built': 2000, 'zoning': None, 'property_tax': 234234234.0, 'image_url': None}]\n(Background on this error at: https://sqlalche.me/e/20/9h9h)", "traceback": "Traceback (most recent call last):\n  File \"/home/tygilman/School/CS3200/real-estate-htmx-fastapi/.venv/lib/python3.12/site-packages/mysql/connector/connection_cext.py\", line 706, in cmd_query\n    self._cmysql.query(\n_mysql_connector.MySQLInterfaceError: Out of range value for column 'price' at row 1\n\nThe above exception was the direct cause of the following exception:\n\nTraceback (most recent call last):\n  File \"/home/tygilman/School/CS3200/real-estate-htmx-fastapi/.venv/lib/python3.12/site-packages/sqlalchemy/engine/base.py\", line 1969, in _exec_single_context\n    self.dialect.do_execute(\n  File \"/home/tygilman/School/CS3200/real-estate-htmx-fastapi/.venv/lib/python3.12/site-packages/sqlalchemy/engine/default.py\", line 922, in do_execute\n    cursor.execute(statement, parameters)\n  File \"/home/tygilman/School/CS3200/real-estate-htmx-fastapi/.venv/lib/python3.12/site-packages/mysql/connector/cursor_cext.py\", line 357, in execute\n    result = self._connection.cmd_query(\n             ^^^^^^^^^^^^^^^^^^^^^^^^^^^\n  File \"/home/tygilman/School/CS3200/real-estate-htmx-fastapi/.venv/lib/python3.12/site-packages/mysql/connector/opentelemetry/context_propagation.py\", line 97, in wrapper\n    return method(cnx, *args, **kwargs)\n           ^^^^^^^^^^^^^^^^^^^^^^^^^^^^\n  File \"/home/tygilman/School/CS3200/real-estate-htmx-fastapi/.venv/lib/python3.12/site-packages/mysql/connector/connection_cext.py\", line 714, in cmd_query\n    raise get_mysql_exception(\nmysql.connector.errors.DataError: 1264 (22003): Out of range value for column 'price' at row 1\n\nThe above exception was the direct cause of the following exception:\n\nTraceback (most recent call last):\n  File \"/home/tygilman/School/CS3200/real-estate-htmx-fastapi/app/routes/admin.py\", line 190, in create_property\n    db.flush()  # Get the property_id\n    ^^^^^^^^^^\n  File \"/home/tygilman/School/CS3200/real-estate-htmx-fastapi/.venv/lib/python3.12/site-packages/sqlalchemy/orm/session.py\", line 4312, in flush\n    self._flush(objects)\n  File \"/home/tygilman/School/CS3200/real-estate-htmx-fastapi/.venv/lib/python3.12/site-packages/sqlalchemy/orm/session.py\", line 4447, in _flush\n    with util.safe_reraise():\n  File \"/home/tygilman/School/CS3200/real-estate-htmx-fastapi/.venv/lib/python3.12/site-packages/sqlalchemy/util/langhelpers.py\", line 146, in __exit__\n    raise exc_value.with_traceback(exc_tb)\n  File \"/home/tygilman/School/CS3200/real-estate-htmx-fastapi/.venv/lib/python3.12/site-packages/sqlalchemy/orm/session.py\", line 4408, in _flush\n    flush_context.execute()\n  File \"/home/tygilman/School/CS3200/real-estate-htmx-fastapi/.venv/lib/python3.12/site-packages/sqlalchemy/orm/unitofwork.py\", line 466, in execute\n    rec.execute(self)\n  File \"/home/tygilman/School/CS3200/real-estate-htmx-fastapi/.venv/lib/python3.12/site-packages/sqlalchemy/orm/unitofwork.py\", line 642, in execute\n    util.preloaded.orm_persistence.save_obj(\n  File \"/home/tygilman/School/CS3200/real-estate-htmx-fastapi/.venv/lib/python3.12/site-packages/sqlalchemy/orm/persistence.py\", line 93, in save_obj\n    _emit_insert_statements(\n  File \"/home/tygilman/School/CS3200/real-estate-htmx-fastapi/.venv/lib/python3.12/site-packages/sqlalchemy/orm/persistence.py\", line 1226, in _emit_insert_statements\n    result = connection.execute(\n             ^^^^^^^^^^^^^^^^^^^\n  File \"/home/tygilman/School/CS3200/real-estate-htmx-fastapi/.venv/lib/python3.12/site-packages/sqlalchemy/engine/base.py\", line 1416, in execute\n    return meth(\n           ^^^^^\n  File \"/home/tygilman/School/CS3200/real-estate-htmx-fastapi/.venv/lib/python3.12/site-packages/sqlalchemy/sql/elements.py\", line 516, in _execute_on_connection\n    return connection._execute_clauseelement(\n           ^^^^^^^^^^^^^^^^^^^^^^^^^^^^^^^^^^\n  File \"/home/tygilman/School/CS3200/real-estate-htmx-fastapi/.venv/lib/python3.12/site-packages/sqlalchemy/engine/base.py\", line 1639, in _execute_clauseelement\n    ret = self._execute_context(\n          ^^^^^^^^^^^^^^^^^^^^^^\n  File \"/home/tygilman/School/CS3200/real-estate-htmx-fastapi/.venv/lib/python3.12/site-packages/sqlalchemy/engine/base.py\", line 1848, in _execute_context\n    return self._exec_single_context(\n           ^^^^^^^^^^^^^^^^^^^^^^^^^^\n  File \"/home/tygilman/School/CS3200/real-estate-htmx-fastapi/.venv/lib/python3.12/site-packages/sqlalchemy/engine/base.py\", line 1988, in _exec_single_context\n    self._handle_dbapi_exception(\n  File \"/home/tygilman/School/CS3200/real-estate-htmx-fastapi/.venv/lib/python3.12/site-packages/sqlalchemy/engine/base.py\", line 2343, in _handle_dbapi_exception\n    raise sqlalchemy_exception.with_traceback(exc_info[2]) from e\n  File \"/home/tygilman/School/CS3200/real-estate-htmx-fastapi/.venv/lib/python3.12/site-packages/sqlalchemy/engine/base.py\", line 1969, in _exec_single_context\n    self.dialect.do_execute(\n  File \"/home/tygilman/School/CS3200/real-estate-htmx-fastapi/.venv/lib/python3.12/site-packages/sqlalchemy/engine/default.py\", line 922, in do_execute\n    cursor.execute(statement, parameters)\n  File \"/home/tygilman/School/CS3200/real-estate-htmx-fastapi/.venv/lib/python3.12/site-packages/mysql/connector/cursor_cext.py\", line 357, in execute\n    result = self._connection.cmd_query(\n             ^^^^^^^^^^^^^^^^^^^^^^^^^^^\n  File \"/home/tygilman/School/CS3200/real-estate-htmx-fastapi/.venv/lib/python3.12/site-packages/mysql/connector/opentelemetry/context_propagation.py\", line 97, in wrapper\n    return method(cnx, *args, **kwargs)\n           ^^^^^^^^^^^^^^^^^^^^^^^^^^^^\n  File \"/home/tygilman/School/CS3200/real-estate-htmx-fastapi/.venv/lib/python3.12/site-packages/mysql/connector/connection_cext.py\", line 714, in cmd_query\n    raise get_mysql_exception(\nsqlalchemy.exc.DataError: (mysql.connector.errors.DataError) 1264 (22003): Out of range value for column 'price' at row 1\n[SQL: INSERT INTO `Property` (tax_id, property_address, status, price, lot_size, year_built, zoning, property_tax, created_at, updated_at, image_url) VALUES (%(tax_id)s, %(property_address)s, %(status)s, %(price)s, %(lot_size)s, %(year_built)s, %(zoning)s, %(property_tax)s, now(), now(), %(image_url)s)]\n[parameters: {'tax_id': 'TAX430416', 'property_address': '234234afasf', 'status': 'FOR_SALE', 'price': 234234234234234.0, 'lot_size': 2343.0, 'year_built': 2000, 'zoning': None, 'property_tax': 234234234.0, 'image_url': None}]\n(Background on this error at: https://sqlalche.me/e/20/9h9h)"}}
{"timestamp": "2024-11-26T22:45:19.451637", "level": "ERROR", "message": "Failed to create property", "module": "admin", "function": "create_property", "line": 258, "thread_id": 126749084710720, "exception": {"type": "NameError", "message": "name 'sqft' is not defined", "traceback": "Traceback (most recent call last):\n  File \"/home/tygilman/School/CS3200/real-estate-htmx-fastapi/app/routes/admin.py\", line 237, in create_property\n    sqft=sqft if sqft else None,\n                 ^^^^\nNameError: name 'sqft' is not defined"}}
{"timestamp": "2024-11-26T23:20:21.446047", "level": "ERROR", "message": "Failed to create user account: name 'User' is not defined", "module": "admin", "function": "create_user", "line": 79, "thread_id": 127974469289792, "exception": {"type": "NameError", "message": "name 'User' is not defined", "traceback": "Traceback (most recent call last):\n  File \"/home/tygilman/School/CS3200/real-estate-htmx-fastapi/app/routes/admin.py\", line 50, in create_user\n    if db.query(User).filter(User.username == username).first():\n                ^^^^\nNameError: name 'User' is not defined"}}
{"timestamp": "2024-11-26T23:21:36.207306", "level": "ERROR", "message": "Failed to create user account: (mysql.connector.errors.ProgrammingError) 1146 (42S02): Table 'real_estate.User' doesn't exist\n[SQL: SELECT `User`.user_id AS `User_user_id`, `User`.username AS `User_username`, `User`.password_hash AS `User_password_hash`, `User`.role_id AS `User_role_id`, `User`.agent_id AS `User_agent_id`, `User`.created_at AS `User_created_at` \nFROM `User` \nWHERE `User`.username = %(username_1)s \n LIMIT %(param_1)s]\n[parameters: {'username_1': 'nick', 'param_1': 1}]\n(Background on this error at: https://sqlalche.me/e/20/f405)", "module": "admin", "function": "create_user", "line": 81, "thread_id": 124050064787264, "exception": {"type": "ProgrammingError", "message": "(mysql.connector.errors.ProgrammingError) 1146 (42S02): Table 'real_estate.User' doesn't exist\n[SQL: SELECT `User`.user_id AS `User_user_id`, `User`.username AS `User_username`, `User`.password_hash AS `User_password_hash`, `User`.role_id AS `User_role_id`, `User`.agent_id AS `User_agent_id`, `User`.created_at AS `User_created_at` \nFROM `User` \nWHERE `User`.username = %(username_1)s \n LIMIT %(param_1)s]\n[parameters: {'username_1': 'nick', 'param_1': 1}]\n(Background on this error at: https://sqlalche.me/e/20/f405)", "traceback": "Traceback (most recent call last):\n  File \"/home/tygilman/School/CS3200/real-estate-htmx-fastapi/.venv/lib/python3.12/site-packages/mysql/connector/connection_cext.py\", line 706, in cmd_query\n    self._cmysql.query(\n_mysql_connector.MySQLInterfaceError: Table 'real_estate.User' doesn't exist\n\nThe above exception was the direct cause of the following exception:\n\nTraceback (most recent call last):\n  File \"/home/tygilman/School/CS3200/real-estate-htmx-fastapi/.venv/lib/python3.12/site-packages/sqlalchemy/engine/base.py\", line 1969, in _exec_single_context\n    self.dialect.do_execute(\n  File \"/home/tygilman/School/CS3200/real-estate-htmx-fastapi/.venv/lib/python3.12/site-packages/sqlalchemy/engine/default.py\", line 922, in do_execute\n    cursor.execute(statement, parameters)\n  File \"/home/tygilman/School/CS3200/real-estate-htmx-fastapi/.venv/lib/python3.12/site-packages/mysql/connector/cursor_cext.py\", line 357, in execute\n    result = self._connection.cmd_query(\n             ^^^^^^^^^^^^^^^^^^^^^^^^^^^\n  File \"/home/tygilman/School/CS3200/real-estate-htmx-fastapi/.venv/lib/python3.12/site-packages/mysql/connector/opentelemetry/context_propagation.py\", line 97, in wrapper\n    return method(cnx, *args, **kwargs)\n           ^^^^^^^^^^^^^^^^^^^^^^^^^^^^\n  File \"/home/tygilman/School/CS3200/real-estate-htmx-fastapi/.venv/lib/python3.12/site-packages/mysql/connector/connection_cext.py\", line 714, in cmd_query\n    raise get_mysql_exception(\nmysql.connector.errors.ProgrammingError: 1146 (42S02): Table 'real_estate.User' doesn't exist\n\nThe above exception was the direct cause of the following exception:\n\nTraceback (most recent call last):\n  File \"/home/tygilman/School/CS3200/real-estate-htmx-fastapi/app/routes/admin.py\", line 52, in create_user\n    if db.query(User).filter(User.username == username).first():\n       ^^^^^^^^^^^^^^^^^^^^^^^^^^^^^^^^^^^^^^^^^^^^^^^^^^^^^^^^\n  File \"/home/tygilman/School/CS3200/real-estate-htmx-fastapi/.venv/lib/python3.12/site-packages/sqlalchemy/orm/query.py\", line 2748, in first\n    return self.limit(1)._iter().first()  # type: ignore\n           ^^^^^^^^^^^^^^^^^^^^^\n  File \"/home/tygilman/School/CS3200/real-estate-htmx-fastapi/.venv/lib/python3.12/site-packages/sqlalchemy/orm/query.py\", line 2847, in _iter\n    result: Union[ScalarResult[_T], Result[_T]] = self.session.execute(\n                                                  ^^^^^^^^^^^^^^^^^^^^^\n  File \"/home/tygilman/School/CS3200/real-estate-htmx-fastapi/.venv/lib/python3.12/site-packages/sqlalchemy/orm/session.py\", line 2308, in execute\n    return self._execute_internal(\n           ^^^^^^^^^^^^^^^^^^^^^^^\n  File \"/home/tygilman/School/CS3200/real-estate-htmx-fastapi/.venv/lib/python3.12/site-packages/sqlalchemy/orm/session.py\", line 2190, in _execute_internal\n    result: Result[Any] = compile_state_cls.orm_execute_statement(\n                          ^^^^^^^^^^^^^^^^^^^^^^^^^^^^^^^^^^^^^^^^\n  File \"/home/tygilman/School/CS3200/real-estate-htmx-fastapi/.venv/lib/python3.12/site-packages/sqlalchemy/orm/context.py\", line 293, in orm_execute_statement\n    result = conn.execute(\n             ^^^^^^^^^^^^^\n  File \"/home/tygilman/School/CS3200/real-estate-htmx-fastapi/.venv/lib/python3.12/site-packages/sqlalchemy/engine/base.py\", line 1416, in execute\n    return meth(\n           ^^^^^\n  File \"/home/tygilman/School/CS3200/real-estate-htmx-fastapi/.venv/lib/python3.12/site-packages/sqlalchemy/sql/elements.py\", line 516, in _execute_on_connection\n    return connection._execute_clauseelement(\n           ^^^^^^^^^^^^^^^^^^^^^^^^^^^^^^^^^^\n  File \"/home/tygilman/School/CS3200/real-estate-htmx-fastapi/.venv/lib/python3.12/site-packages/sqlalchemy/engine/base.py\", line 1639, in _execute_clauseelement\n    ret = self._execute_context(\n          ^^^^^^^^^^^^^^^^^^^^^^\n  File \"/home/tygilman/School/CS3200/real-estate-htmx-fastapi/.venv/lib/python3.12/site-packages/sqlalchemy/engine/base.py\", line 1848, in _execute_context\n    return self._exec_single_context(\n           ^^^^^^^^^^^^^^^^^^^^^^^^^^\n  File \"/home/tygilman/School/CS3200/real-estate-htmx-fastapi/.venv/lib/python3.12/site-packages/sqlalchemy/engine/base.py\", line 1988, in _exec_single_context\n    self._handle_dbapi_exception(\n  File \"/home/tygilman/School/CS3200/real-estate-htmx-fastapi/.venv/lib/python3.12/site-packages/sqlalchemy/engine/base.py\", line 2343, in _handle_dbapi_exception\n    raise sqlalchemy_exception.with_traceback(exc_info[2]) from e\n  File \"/home/tygilman/School/CS3200/real-estate-htmx-fastapi/.venv/lib/python3.12/site-packages/sqlalchemy/engine/base.py\", line 1969, in _exec_single_context\n    self.dialect.do_execute(\n  File \"/home/tygilman/School/CS3200/real-estate-htmx-fastapi/.venv/lib/python3.12/site-packages/sqlalchemy/engine/default.py\", line 922, in do_execute\n    cursor.execute(statement, parameters)\n  File \"/home/tygilman/School/CS3200/real-estate-htmx-fastapi/.venv/lib/python3.12/site-packages/mysql/connector/cursor_cext.py\", line 357, in execute\n    result = self._connection.cmd_query(\n             ^^^^^^^^^^^^^^^^^^^^^^^^^^^\n  File \"/home/tygilman/School/CS3200/real-estate-htmx-fastapi/.venv/lib/python3.12/site-packages/mysql/connector/opentelemetry/context_propagation.py\", line 97, in wrapper\n    return method(cnx, *args, **kwargs)\n           ^^^^^^^^^^^^^^^^^^^^^^^^^^^^\n  File \"/home/tygilman/School/CS3200/real-estate-htmx-fastapi/.venv/lib/python3.12/site-packages/mysql/connector/connection_cext.py\", line 714, in cmd_query\n    raise get_mysql_exception(\nsqlalchemy.exc.ProgrammingError: (mysql.connector.errors.ProgrammingError) 1146 (42S02): Table 'real_estate.User' doesn't exist\n[SQL: SELECT `User`.user_id AS `User_user_id`, `User`.username AS `User_username`, `User`.password_hash AS `User_password_hash`, `User`.role_id AS `User_role_id`, `User`.agent_id AS `User_agent_id`, `User`.created_at AS `User_created_at` \nFROM `User` \nWHERE `User`.username = %(username_1)s \n LIMIT %(param_1)s]\n[parameters: {'username_1': 'nick', 'param_1': 1}]\n(Background on this error at: https://sqlalche.me/e/20/f405)"}}
{"timestamp": "2024-11-27T00:42:56.061302", "level": "ERROR", "message": "Error loading agent dashboard: 'RedirectResponse' object is not subscriptable", "module": "agents", "function": "agent_dashboard", "line": 85, "thread_id": 131364007970624, "exception": {"type": "TypeError", "message": "'RedirectResponse' object is not subscriptable", "traceback": "Traceback (most recent call last):\n  File \"/home/tygilman/School/CS3200/real-estate-htmx-fastapi/app/routes/agents.py\", line 33, in agent_dashboard\n    agent = current_user[\"agent\"]\n            ~~~~~~~~~~~~^^^^^^^^^\nTypeError: 'RedirectResponse' object is not subscriptable"}}
{"timestamp": "2024-11-27T02:14:32.140195", "level": "ERROR", "message": "Failed to render dashboard", "module": "admin", "function": "admin_dashboard", "line": 136, "thread_id": 131994909423424, "exception": {"type": "TemplateNotFound", "message": "admin/base.html", "traceback": "Traceback (most recent call last):\n  File \"/home/tygilman/School/CS3200/real-estate-htmx-fastapi/app/routes/admin.py\", line 133, in admin_dashboard\n    return templates.TemplateResponse(\"admin/dashboard.html\", context)\n           ^^^^^^^^^^^^^^^^^^^^^^^^^^^^^^^^^^^^^^^^^^^^^^^^^^^^^^^^^^^\n  File \"/home/tygilman/School/CS3200/real-estate-htmx-fastapi/.venv/lib/python3.12/site-packages/starlette/templating.py\", line 113, in TemplateResponse\n    return _TemplateResponse(\n           ^^^^^^^^^^^^^^^^^^\n  File \"/home/tygilman/School/CS3200/real-estate-htmx-fastapi/.venv/lib/python3.12/site-packages/starlette/templating.py\", line 39, in __init__\n    content = template.render(context)\n              ^^^^^^^^^^^^^^^^^^^^^^^^\n  File \"/home/tygilman/School/CS3200/real-estate-htmx-fastapi/.venv/lib/python3.12/site-packages/jinja2/environment.py\", line 1301, in render\n    self.environment.handle_exception()\n  File \"/home/tygilman/School/CS3200/real-estate-htmx-fastapi/.venv/lib/python3.12/site-packages/jinja2/environment.py\", line 936, in handle_exception\n    raise rewrite_traceback_stack(source=source)\n  File \"app/templates/admin/dashboard.html\", line 1, in top-level template code\n    {% extends \"admin/base.html\" %}\n    ^^^^^^^^^^^^^^^^^^^^^^^^^\n  File \"/home/tygilman/School/CS3200/real-estate-htmx-fastapi/.venv/lib/python3.12/site-packages/jinja2/loaders.py\", line 218, in get_source\n    raise TemplateNotFound(template)\njinja2.exceptions.TemplateNotFound: admin/base.html"}}
{"timestamp": "2024-11-27T02:14:33.026541", "level": "ERROR", "message": "Failed to render dashboard", "module": "admin", "function": "admin_dashboard", "line": 136, "thread_id": 131994909423424, "exception": {"type": "TemplateNotFound", "message": "admin/base.html", "traceback": "Traceback (most recent call last):\n  File \"/home/tygilman/School/CS3200/real-estate-htmx-fastapi/app/routes/admin.py\", line 133, in admin_dashboard\n    return templates.TemplateResponse(\"admin/dashboard.html\", context)\n           ^^^^^^^^^^^^^^^^^^^^^^^^^^^^^^^^^^^^^^^^^^^^^^^^^^^^^^^^^^^\n  File \"/home/tygilman/School/CS3200/real-estate-htmx-fastapi/.venv/lib/python3.12/site-packages/starlette/templating.py\", line 113, in TemplateResponse\n    return _TemplateResponse(\n           ^^^^^^^^^^^^^^^^^^\n  File \"/home/tygilman/School/CS3200/real-estate-htmx-fastapi/.venv/lib/python3.12/site-packages/starlette/templating.py\", line 39, in __init__\n    content = template.render(context)\n              ^^^^^^^^^^^^^^^^^^^^^^^^\n  File \"/home/tygilman/School/CS3200/real-estate-htmx-fastapi/.venv/lib/python3.12/site-packages/jinja2/environment.py\", line 1301, in render\n    self.environment.handle_exception()\n  File \"/home/tygilman/School/CS3200/real-estate-htmx-fastapi/.venv/lib/python3.12/site-packages/jinja2/environment.py\", line 936, in handle_exception\n    raise rewrite_traceback_stack(source=source)\n  File \"app/templates/admin/dashboard.html\", line 1, in top-level template code\n    {% extends \"admin/base.html\" %}\n    ^^^^^^^^^^^^^^^^^^^^^^^^^\n  File \"/home/tygilman/School/CS3200/real-estate-htmx-fastapi/.venv/lib/python3.12/site-packages/jinja2/loaders.py\", line 218, in get_source\n    raise TemplateNotFound(template)\njinja2.exceptions.TemplateNotFound: admin/base.html"}}
{"timestamp": "2024-11-27T02:15:18.441597", "level": "ERROR", "message": "Error loading agent dashboard: agent_base.html", "module": "agents", "function": "agent_dashboard", "line": 85, "thread_id": 131994909423424, "exception": {"type": "TemplateNotFound", "message": "agent_base.html", "traceback": "Traceback (most recent call last):\n  File \"/home/tygilman/School/CS3200/real-estate-htmx-fastapi/app/routes/agents.py\", line 82, in agent_dashboard\n    return templates.TemplateResponse(\"agents/dashboard.html\", context)\n           ^^^^^^^^^^^^^^^^^^^^^^^^^^^^^^^^^^^^^^^^^^^^^^^^^^^^^^^^^^^^\n  File \"/home/tygilman/School/CS3200/real-estate-htmx-fastapi/.venv/lib/python3.12/site-packages/starlette/templating.py\", line 113, in TemplateResponse\n    return _TemplateResponse(\n           ^^^^^^^^^^^^^^^^^^\n  File \"/home/tygilman/School/CS3200/real-estate-htmx-fastapi/.venv/lib/python3.12/site-packages/starlette/templating.py\", line 39, in __init__\n    content = template.render(context)\n              ^^^^^^^^^^^^^^^^^^^^^^^^\n  File \"/home/tygilman/School/CS3200/real-estate-htmx-fastapi/.venv/lib/python3.12/site-packages/jinja2/environment.py\", line 1301, in render\n    self.environment.handle_exception()\n  File \"/home/tygilman/School/CS3200/real-estate-htmx-fastapi/.venv/lib/python3.12/site-packages/jinja2/environment.py\", line 936, in handle_exception\n    raise rewrite_traceback_stack(source=source)\n  File \"app/templates/agents/dashboard.html\", line 1, in top-level template code\n    {% extends \"agent_base.html\" %}\n    ^^^^^^^^^^^^^^^^^^^^^^^^^\n  File \"/home/tygilman/School/CS3200/real-estate-htmx-fastapi/.venv/lib/python3.12/site-packages/jinja2/loaders.py\", line 218, in get_source\n    raise TemplateNotFound(template)\njinja2.exceptions.TemplateNotFound: agent_base.html"}}
{"timestamp": "2024-11-27T02:25:21.016477", "level": "ERROR", "message": "Error loading agent dashboard: can only concatenate str (not \"Agent\") to str", "module": "agents", "function": "agent_dashboard", "line": 84, "thread_id": 132740003653440, "exception": {"type": "TypeError", "message": "can only concatenate str (not \"Agent\") to str", "traceback": "Traceback (most recent call last):\n  File \"/home/tygilman/School/CS3200/real-estate-htmx-fastapi/app/routes/agents.py\", line 33, in agent_dashboard\n    print(\"Agent - \" + agent)\n          ~~~~~~~~~~~^~~~~~~\nTypeError: can only concatenate str (not \"Agent\") to str"}}
{"timestamp": "2024-11-27T02:25:37.974348", "level": "ERROR", "message": "Error loading agent dashboard: can only concatenate str (not \"Agent\") to str", "module": "agents", "function": "agent_dashboard", "line": 84, "thread_id": 132740003653440, "exception": {"type": "TypeError", "message": "can only concatenate str (not \"Agent\") to str", "traceback": "Traceback (most recent call last):\n  File \"/home/tygilman/School/CS3200/real-estate-htmx-fastapi/app/routes/agents.py\", line 33, in agent_dashboard\n    print(\"Agent - \" + agent)\n          ~~~~~~~~~~~^~~~~~~\nTypeError: can only concatenate str (not \"Agent\") to str"}}
{"timestamp": "2024-11-27T02:27:51.140338", "level": "ERROR", "message": "Error loading agent dashboard: 'Agent' object has no attribute 'name'", "module": "agents", "function": "agent_dashboard", "line": 84, "thread_id": 129930804352832, "exception": {"type": "AttributeError", "message": "'Agent' object has no attribute 'name'", "traceback": "Traceback (most recent call last):\n  File \"/home/tygilman/School/CS3200/real-estate-htmx-fastapi/app/routes/agents.py\", line 33, in agent_dashboard\n    print(\"Agent - \" + str(agent.name))\n                           ^^^^^^^^^^\nAttributeError: 'Agent' object has no attribute 'name'"}}
{"timestamp": "2024-11-27T02:27:52.491299", "level": "ERROR", "message": "Error loading agent dashboard: 'Agent' object has no attribute 'name'", "module": "agents", "function": "agent_dashboard", "line": 84, "thread_id": 129930804352832, "exception": {"type": "AttributeError", "message": "'Agent' object has no attribute 'name'", "traceback": "Traceback (most recent call last):\n  File \"/home/tygilman/School/CS3200/real-estate-htmx-fastapi/app/routes/agents.py\", line 33, in agent_dashboard\n    print(\"Agent - \" + str(agent.name))\n                           ^^^^^^^^^^\nAttributeError: 'Agent' object has no attribute 'name'"}}
{"timestamp": "2024-11-27T02:30:45.882061", "level": "ERROR", "message": "Error loading agent dashboard: agent_base.html", "module": "agents", "function": "agent_dashboard", "line": 84, "thread_id": 136068230027072, "exception": {"type": "TemplateNotFound", "message": "agent_base.html", "traceback": "Traceback (most recent call last):\n  File \"/home/tygilman/School/CS3200/real-estate-htmx-fastapi/app/routes/agents.py\", line 81, in agent_dashboard\n    return templates.TemplateResponse(\"agents/dashboard.html\", context)\n           ^^^^^^^^^^^^^^^^^^^^^^^^^^^^^^^^^^^^^^^^^^^^^^^^^^^^^^^^^^^^\n  File \"/home/tygilman/School/CS3200/real-estate-htmx-fastapi/.venv/lib/python3.12/site-packages/starlette/templating.py\", line 113, in TemplateResponse\n    return _TemplateResponse(\n           ^^^^^^^^^^^^^^^^^^\n  File \"/home/tygilman/School/CS3200/real-estate-htmx-fastapi/.venv/lib/python3.12/site-packages/starlette/templating.py\", line 39, in __init__\n    content = template.render(context)\n              ^^^^^^^^^^^^^^^^^^^^^^^^\n  File \"/home/tygilman/School/CS3200/real-estate-htmx-fastapi/.venv/lib/python3.12/site-packages/jinja2/environment.py\", line 1301, in render\n    self.environment.handle_exception()\n  File \"/home/tygilman/School/CS3200/real-estate-htmx-fastapi/.venv/lib/python3.12/site-packages/jinja2/environment.py\", line 936, in handle_exception\n    raise rewrite_traceback_stack(source=source)\n  File \"app/templates/agents/dashboard.html\", line 1, in top-level template code\n    {% extends \"agent_base.html\" %}\n    ^^^^^^^^^^^^^^^^^^^^^^^^^\n  File \"/home/tygilman/School/CS3200/real-estate-htmx-fastapi/.venv/lib/python3.12/site-packages/jinja2/loaders.py\", line 218, in get_source\n    raise TemplateNotFound(template)\njinja2.exceptions.TemplateNotFound: agent_base.html"}}
{"timestamp": "2024-11-27T03:07:06.041862", "level": "ERROR", "message": "Error creating property: (mysql.connector.errors.DatabaseError) 1265 (01000): Data truncated for column 'status' at row 1\n[SQL: \n                CALL create_property(\n                    %(tax_id)s, %(property_address)s, %(status)s, %(price)s, %(lot_size)s, %(year_built)s, %(zoning)s, %(property_tax)s,\n                    %(property_type)s, %(bedrooms)s, %(bathrooms)s, %(r_type)s, %(square_feet)s, %(garage_spaces)s, %(has_basement)s,\n                    %(has_pool)s, %(commercial_sqft)s, %(industry)s, %(c_type)s, %(num_units)s, %(parking_spaces)s, %(zoning_type)s,\n                    @property_id\n                )\n            ]\n[parameters: {'tax_id': 'TAX377327', 'property_address': '234', 'status': 'For Sale', 'price': 234.0, 'lot_size': 2334.0, 'year_built': 2000, 'zoning': 'Unknown', 'property_tax': 23423423.0, 'property_type': 'RESIDENTIAL', 'bedrooms': 23, 'bathrooms': 3.0, 'r_type': 'Single Family', 'square_feet': 0.0, 'garage_spaces': 0, 'has_basement': False, 'has_pool': False, 'commercial_sqft': 0.0, 'industry': 'General', 'c_type': 'Office', 'num_units': 0, 'parking_spaces': 0, 'zoning_type': 'General'}]\n(Background on this error at: https://sqlalche.me/e/20/4xp6)", "module": "admin", "function": "create_property", "line": 339, "thread_id": 133427846895424, "exception": {"type": "DatabaseError", "message": "(mysql.connector.errors.DatabaseError) 1265 (01000): Data truncated for column 'status' at row 1\n[SQL: \n                CALL create_property(\n                    %(tax_id)s, %(property_address)s, %(status)s, %(price)s, %(lot_size)s, %(year_built)s, %(zoning)s, %(property_tax)s,\n                    %(property_type)s, %(bedrooms)s, %(bathrooms)s, %(r_type)s, %(square_feet)s, %(garage_spaces)s, %(has_basement)s,\n                    %(has_pool)s, %(commercial_sqft)s, %(industry)s, %(c_type)s, %(num_units)s, %(parking_spaces)s, %(zoning_type)s,\n                    @property_id\n                )\n            ]\n[parameters: {'tax_id': 'TAX377327', 'property_address': '234', 'status': 'For Sale', 'price': 234.0, 'lot_size': 2334.0, 'year_built': 2000, 'zoning': 'Unknown', 'property_tax': 23423423.0, 'property_type': 'RESIDENTIAL', 'bedrooms': 23, 'bathrooms': 3.0, 'r_type': 'Single Family', 'square_feet': 0.0, 'garage_spaces': 0, 'has_basement': False, 'has_pool': False, 'commercial_sqft': 0.0, 'industry': 'General', 'c_type': 'Office', 'num_units': 0, 'parking_spaces': 0, 'zoning_type': 'General'}]\n(Background on this error at: https://sqlalche.me/e/20/4xp6)", "traceback": "Traceback (most recent call last):\n  File \"/home/tygilman/School/CS3200/real-estate-htmx-fastapi/.venv/lib/python3.12/site-packages/mysql/connector/connection_cext.py\", line 706, in cmd_query\n    self._cmysql.query(\n_mysql_connector.MySQLInterfaceError: Data truncated for column 'status' at row 1\n\nThe above exception was the direct cause of the following exception:\n\nTraceback (most recent call last):\n  File \"/home/tygilman/School/CS3200/real-estate-htmx-fastapi/.venv/lib/python3.12/site-packages/sqlalchemy/engine/base.py\", line 1969, in _exec_single_context\n    self.dialect.do_execute(\n  File \"/home/tygilman/School/CS3200/real-estate-htmx-fastapi/.venv/lib/python3.12/site-packages/sqlalchemy/engine/default.py\", line 922, in do_execute\n    cursor.execute(statement, parameters)\n  File \"/home/tygilman/School/CS3200/real-estate-htmx-fastapi/.venv/lib/python3.12/site-packages/mysql/connector/cursor_cext.py\", line 357, in execute\n    result = self._connection.cmd_query(\n             ^^^^^^^^^^^^^^^^^^^^^^^^^^^\n  File \"/home/tygilman/School/CS3200/real-estate-htmx-fastapi/.venv/lib/python3.12/site-packages/mysql/connector/opentelemetry/context_propagation.py\", line 97, in wrapper\n    return method(cnx, *args, **kwargs)\n           ^^^^^^^^^^^^^^^^^^^^^^^^^^^^\n  File \"/home/tygilman/School/CS3200/real-estate-htmx-fastapi/.venv/lib/python3.12/site-packages/mysql/connector/connection_cext.py\", line 714, in cmd_query\n    raise get_mysql_exception(\nmysql.connector.errors.DatabaseError: 1265 (01000): Data truncated for column 'status' at row 1\n\nThe above exception was the direct cause of the following exception:\n\nTraceback (most recent call last):\n  File \"/home/tygilman/School/CS3200/real-estate-htmx-fastapi/app/routes/admin.py\", line 263, in create_property\n    result = db.execute(\n             ^^^^^^^^^^^\n  File \"/home/tygilman/School/CS3200/real-estate-htmx-fastapi/.venv/lib/python3.12/site-packages/sqlalchemy/orm/session.py\", line 2308, in execute\n    return self._execute_internal(\n           ^^^^^^^^^^^^^^^^^^^^^^^\n  File \"/home/tygilman/School/CS3200/real-estate-htmx-fastapi/.venv/lib/python3.12/site-packages/sqlalchemy/orm/session.py\", line 2199, in _execute_internal\n    result = conn.execute(\n             ^^^^^^^^^^^^^\n  File \"/home/tygilman/School/CS3200/real-estate-htmx-fastapi/.venv/lib/python3.12/site-packages/sqlalchemy/engine/base.py\", line 1416, in execute\n    return meth(\n           ^^^^^\n  File \"/home/tygilman/School/CS3200/real-estate-htmx-fastapi/.venv/lib/python3.12/site-packages/sqlalchemy/sql/elements.py\", line 516, in _execute_on_connection\n    return connection._execute_clauseelement(\n           ^^^^^^^^^^^^^^^^^^^^^^^^^^^^^^^^^^\n  File \"/home/tygilman/School/CS3200/real-estate-htmx-fastapi/.venv/lib/python3.12/site-packages/sqlalchemy/engine/base.py\", line 1639, in _execute_clauseelement\n    ret = self._execute_context(\n          ^^^^^^^^^^^^^^^^^^^^^^\n  File \"/home/tygilman/School/CS3200/real-estate-htmx-fastapi/.venv/lib/python3.12/site-packages/sqlalchemy/engine/base.py\", line 1848, in _execute_context\n    return self._exec_single_context(\n           ^^^^^^^^^^^^^^^^^^^^^^^^^^\n  File \"/home/tygilman/School/CS3200/real-estate-htmx-fastapi/.venv/lib/python3.12/site-packages/sqlalchemy/engine/base.py\", line 1988, in _exec_single_context\n    self._handle_dbapi_exception(\n  File \"/home/tygilman/School/CS3200/real-estate-htmx-fastapi/.venv/lib/python3.12/site-packages/sqlalchemy/engine/base.py\", line 2343, in _handle_dbapi_exception\n    raise sqlalchemy_exception.with_traceback(exc_info[2]) from e\n  File \"/home/tygilman/School/CS3200/real-estate-htmx-fastapi/.venv/lib/python3.12/site-packages/sqlalchemy/engine/base.py\", line 1969, in _exec_single_context\n    self.dialect.do_execute(\n  File \"/home/tygilman/School/CS3200/real-estate-htmx-fastapi/.venv/lib/python3.12/site-packages/sqlalchemy/engine/default.py\", line 922, in do_execute\n    cursor.execute(statement, parameters)\n  File \"/home/tygilman/School/CS3200/real-estate-htmx-fastapi/.venv/lib/python3.12/site-packages/mysql/connector/cursor_cext.py\", line 357, in execute\n    result = self._connection.cmd_query(\n             ^^^^^^^^^^^^^^^^^^^^^^^^^^^\n  File \"/home/tygilman/School/CS3200/real-estate-htmx-fastapi/.venv/lib/python3.12/site-packages/mysql/connector/opentelemetry/context_propagation.py\", line 97, in wrapper\n    return method(cnx, *args, **kwargs)\n           ^^^^^^^^^^^^^^^^^^^^^^^^^^^^\n  File \"/home/tygilman/School/CS3200/real-estate-htmx-fastapi/.venv/lib/python3.12/site-packages/mysql/connector/connection_cext.py\", line 714, in cmd_query\n    raise get_mysql_exception(\nsqlalchemy.exc.DatabaseError: (mysql.connector.errors.DatabaseError) 1265 (01000): Data truncated for column 'status' at row 1\n[SQL: \n                CALL create_property(\n                    %(tax_id)s, %(property_address)s, %(status)s, %(price)s, %(lot_size)s, %(year_built)s, %(zoning)s, %(property_tax)s,\n                    %(property_type)s, %(bedrooms)s, %(bathrooms)s, %(r_type)s, %(square_feet)s, %(garage_spaces)s, %(has_basement)s,\n                    %(has_pool)s, %(commercial_sqft)s, %(industry)s, %(c_type)s, %(num_units)s, %(parking_spaces)s, %(zoning_type)s,\n                    @property_id\n                )\n            ]\n[parameters: {'tax_id': 'TAX377327', 'property_address': '234', 'status': 'For Sale', 'price': 234.0, 'lot_size': 2334.0, 'year_built': 2000, 'zoning': 'Unknown', 'property_tax': 23423423.0, 'property_type': 'RESIDENTIAL', 'bedrooms': 23, 'bathrooms': 3.0, 'r_type': 'Single Family', 'square_feet': 0.0, 'garage_spaces': 0, 'has_basement': False, 'has_pool': False, 'commercial_sqft': 0.0, 'industry': 'General', 'c_type': 'Office', 'num_units': 0, 'parking_spaces': 0, 'zoning_type': 'General'}]\n(Background on this error at: https://sqlalche.me/e/20/4xp6)"}}
{"timestamp": "2024-11-27T03:13:12.089296", "level": "ERROR", "message": "Error creating property: (mysql.connector.errors.DataError) 1264 (22003): Out of range value for column 'p_bathrooms' at row 1\n[SQL: \n                CALL create_property(\n                    %(tax_id)s, %(property_address)s, %(status)s, %(price)s, %(lot_size)s, %(year_built)s, %(zoning)s, %(property_tax)s,\n                    %(property_type)s, %(bedrooms)s, %(bathrooms)s, %(r_type)s, %(square_feet)s, %(garage_spaces)s, %(has_basement)s,\n                    %(has_pool)s, %(commercial_sqft)s, %(industry)s, %(c_type)s, %(num_units)s, %(parking_spaces)s, %(zoning_type)s,\n                    @property_id\n                )\n            ]\n[parameters: {'tax_id': 'TAX665555', 'property_address': '234', 'status': 'For Lease', 'price': 234.0, 'lot_size': 2334.0, 'year_built': 2000, 'zoning': 'Unknown', 'property_tax': 234234.0, 'property_type': 'RESIDENTIAL', 'bedrooms': 234, 'bathrooms': 234.0, 'r_type': 'Single Family', 'square_feet': 0.0, 'garage_spaces': 0, 'has_basement': False, 'has_pool': False, 'commercial_sqft': 0.0, 'industry': 'General', 'c_type': 'Office', 'num_units': 0, 'parking_spaces': 0, 'zoning_type': 'General'}]\n(Background on this error at: https://sqlalche.me/e/20/9h9h)", "module": "admin", "function": "create_property", "line": 339, "thread_id": 128049763514176, "exception": {"type": "DataError", "message": "(mysql.connector.errors.DataError) 1264 (22003): Out of range value for column 'p_bathrooms' at row 1\n[SQL: \n                CALL create_property(\n                    %(tax_id)s, %(property_address)s, %(status)s, %(price)s, %(lot_size)s, %(year_built)s, %(zoning)s, %(property_tax)s,\n                    %(property_type)s, %(bedrooms)s, %(bathrooms)s, %(r_type)s, %(square_feet)s, %(garage_spaces)s, %(has_basement)s,\n                    %(has_pool)s, %(commercial_sqft)s, %(industry)s, %(c_type)s, %(num_units)s, %(parking_spaces)s, %(zoning_type)s,\n                    @property_id\n                )\n            ]\n[parameters: {'tax_id': 'TAX665555', 'property_address': '234', 'status': 'For Lease', 'price': 234.0, 'lot_size': 2334.0, 'year_built': 2000, 'zoning': 'Unknown', 'property_tax': 234234.0, 'property_type': 'RESIDENTIAL', 'bedrooms': 234, 'bathrooms': 234.0, 'r_type': 'Single Family', 'square_feet': 0.0, 'garage_spaces': 0, 'has_basement': False, 'has_pool': False, 'commercial_sqft': 0.0, 'industry': 'General', 'c_type': 'Office', 'num_units': 0, 'parking_spaces': 0, 'zoning_type': 'General'}]\n(Background on this error at: https://sqlalche.me/e/20/9h9h)", "traceback": "Traceback (most recent call last):\n  File \"/home/tygilman/School/CS3200/real-estate-htmx-fastapi/.venv/lib/python3.12/site-packages/mysql/connector/connection_cext.py\", line 706, in cmd_query\n    self._cmysql.query(\n_mysql_connector.MySQLInterfaceError: Out of range value for column 'p_bathrooms' at row 1\n\nThe above exception was the direct cause of the following exception:\n\nTraceback (most recent call last):\n  File \"/home/tygilman/School/CS3200/real-estate-htmx-fastapi/.venv/lib/python3.12/site-packages/sqlalchemy/engine/base.py\", line 1969, in _exec_single_context\n    self.dialect.do_execute(\n  File \"/home/tygilman/School/CS3200/real-estate-htmx-fastapi/.venv/lib/python3.12/site-packages/sqlalchemy/engine/default.py\", line 922, in do_execute\n    cursor.execute(statement, parameters)\n  File \"/home/tygilman/School/CS3200/real-estate-htmx-fastapi/.venv/lib/python3.12/site-packages/mysql/connector/cursor_cext.py\", line 357, in execute\n    result = self._connection.cmd_query(\n             ^^^^^^^^^^^^^^^^^^^^^^^^^^^\n  File \"/home/tygilman/School/CS3200/real-estate-htmx-fastapi/.venv/lib/python3.12/site-packages/mysql/connector/opentelemetry/context_propagation.py\", line 97, in wrapper\n    return method(cnx, *args, **kwargs)\n           ^^^^^^^^^^^^^^^^^^^^^^^^^^^^\n  File \"/home/tygilman/School/CS3200/real-estate-htmx-fastapi/.venv/lib/python3.12/site-packages/mysql/connector/connection_cext.py\", line 714, in cmd_query\n    raise get_mysql_exception(\nmysql.connector.errors.DataError: 1264 (22003): Out of range value for column 'p_bathrooms' at row 1\n\nThe above exception was the direct cause of the following exception:\n\nTraceback (most recent call last):\n  File \"/home/tygilman/School/CS3200/real-estate-htmx-fastapi/app/routes/admin.py\", line 263, in create_property\n    result = db.execute(\n             ^^^^^^^^^^^\n  File \"/home/tygilman/School/CS3200/real-estate-htmx-fastapi/.venv/lib/python3.12/site-packages/sqlalchemy/orm/session.py\", line 2308, in execute\n    return self._execute_internal(\n           ^^^^^^^^^^^^^^^^^^^^^^^\n  File \"/home/tygilman/School/CS3200/real-estate-htmx-fastapi/.venv/lib/python3.12/site-packages/sqlalchemy/orm/session.py\", line 2199, in _execute_internal\n    result = conn.execute(\n             ^^^^^^^^^^^^^\n  File \"/home/tygilman/School/CS3200/real-estate-htmx-fastapi/.venv/lib/python3.12/site-packages/sqlalchemy/engine/base.py\", line 1416, in execute\n    return meth(\n           ^^^^^\n  File \"/home/tygilman/School/CS3200/real-estate-htmx-fastapi/.venv/lib/python3.12/site-packages/sqlalchemy/sql/elements.py\", line 516, in _execute_on_connection\n    return connection._execute_clauseelement(\n           ^^^^^^^^^^^^^^^^^^^^^^^^^^^^^^^^^^\n  File \"/home/tygilman/School/CS3200/real-estate-htmx-fastapi/.venv/lib/python3.12/site-packages/sqlalchemy/engine/base.py\", line 1639, in _execute_clauseelement\n    ret = self._execute_context(\n          ^^^^^^^^^^^^^^^^^^^^^^\n  File \"/home/tygilman/School/CS3200/real-estate-htmx-fastapi/.venv/lib/python3.12/site-packages/sqlalchemy/engine/base.py\", line 1848, in _execute_context\n    return self._exec_single_context(\n           ^^^^^^^^^^^^^^^^^^^^^^^^^^\n  File \"/home/tygilman/School/CS3200/real-estate-htmx-fastapi/.venv/lib/python3.12/site-packages/sqlalchemy/engine/base.py\", line 1988, in _exec_single_context\n    self._handle_dbapi_exception(\n  File \"/home/tygilman/School/CS3200/real-estate-htmx-fastapi/.venv/lib/python3.12/site-packages/sqlalchemy/engine/base.py\", line 2343, in _handle_dbapi_exception\n    raise sqlalchemy_exception.with_traceback(exc_info[2]) from e\n  File \"/home/tygilman/School/CS3200/real-estate-htmx-fastapi/.venv/lib/python3.12/site-packages/sqlalchemy/engine/base.py\", line 1969, in _exec_single_context\n    self.dialect.do_execute(\n  File \"/home/tygilman/School/CS3200/real-estate-htmx-fastapi/.venv/lib/python3.12/site-packages/sqlalchemy/engine/default.py\", line 922, in do_execute\n    cursor.execute(statement, parameters)\n  File \"/home/tygilman/School/CS3200/real-estate-htmx-fastapi/.venv/lib/python3.12/site-packages/mysql/connector/cursor_cext.py\", line 357, in execute\n    result = self._connection.cmd_query(\n             ^^^^^^^^^^^^^^^^^^^^^^^^^^^\n  File \"/home/tygilman/School/CS3200/real-estate-htmx-fastapi/.venv/lib/python3.12/site-packages/mysql/connector/opentelemetry/context_propagation.py\", line 97, in wrapper\n    return method(cnx, *args, **kwargs)\n           ^^^^^^^^^^^^^^^^^^^^^^^^^^^^\n  File \"/home/tygilman/School/CS3200/real-estate-htmx-fastapi/.venv/lib/python3.12/site-packages/mysql/connector/connection_cext.py\", line 714, in cmd_query\n    raise get_mysql_exception(\nsqlalchemy.exc.DataError: (mysql.connector.errors.DataError) 1264 (22003): Out of range value for column 'p_bathrooms' at row 1\n[SQL: \n                CALL create_property(\n                    %(tax_id)s, %(property_address)s, %(status)s, %(price)s, %(lot_size)s, %(year_built)s, %(zoning)s, %(property_tax)s,\n                    %(property_type)s, %(bedrooms)s, %(bathrooms)s, %(r_type)s, %(square_feet)s, %(garage_spaces)s, %(has_basement)s,\n                    %(has_pool)s, %(commercial_sqft)s, %(industry)s, %(c_type)s, %(num_units)s, %(parking_spaces)s, %(zoning_type)s,\n                    @property_id\n                )\n            ]\n[parameters: {'tax_id': 'TAX665555', 'property_address': '234', 'status': 'For Lease', 'price': 234.0, 'lot_size': 2334.0, 'year_built': 2000, 'zoning': 'Unknown', 'property_tax': 234234.0, 'property_type': 'RESIDENTIAL', 'bedrooms': 234, 'bathrooms': 234.0, 'r_type': 'Single Family', 'square_feet': 0.0, 'garage_spaces': 0, 'has_basement': False, 'has_pool': False, 'commercial_sqft': 0.0, 'industry': 'General', 'c_type': 'Office', 'num_units': 0, 'parking_spaces': 0, 'zoning_type': 'General'}]\n(Background on this error at: https://sqlalche.me/e/20/9h9h)"}}
{"timestamp": "2024-11-27T03:14:27.587104", "level": "ERROR", "message": "Error creating property: (mysql.connector.errors.DatabaseError) 1265 (01000): Data truncated for column 'status' at row 1\n[SQL: \n                CALL create_property(\n                    %(tax_id)s, %(property_address)s, %(status)s, %(price)s, %(lot_size)s, %(year_built)s, %(zoning)s, %(property_tax)s,\n                    %(property_type)s, %(bedrooms)s, %(bathrooms)s, %(r_type)s, %(square_feet)s, %(garage_spaces)s, %(has_basement)s,\n                    %(has_pool)s, %(commercial_sqft)s, %(industry)s, %(c_type)s, %(num_units)s, %(parking_spaces)s, %(zoning_type)s,\n                    @property_id\n                )\n            ]\n[parameters: {'tax_id': 'TAX687391', 'property_address': '23434', 'status': 'For Sale', 'price': 234234.0, 'lot_size': 234.0, 'year_built': 2000, 'zoning': 'Unknown', 'property_tax': 234.0, 'property_type': 'RESIDENTIAL', 'bedrooms': 32, 'bathrooms': 23.0, 'r_type': 'Single Family', 'square_feet': 0.0, 'garage_spaces': 0, 'has_basement': False, 'has_pool': False, 'commercial_sqft': 0.0, 'industry': 'General', 'c_type': 'Office', 'num_units': 0, 'parking_spaces': 0, 'zoning_type': 'General'}]\n(Background on this error at: https://sqlalche.me/e/20/4xp6)", "module": "admin", "function": "create_property", "line": 339, "thread_id": 131418836424512, "exception": {"type": "DatabaseError", "message": "(mysql.connector.errors.DatabaseError) 1265 (01000): Data truncated for column 'status' at row 1\n[SQL: \n                CALL create_property(\n                    %(tax_id)s, %(property_address)s, %(status)s, %(price)s, %(lot_size)s, %(year_built)s, %(zoning)s, %(property_tax)s,\n                    %(property_type)s, %(bedrooms)s, %(bathrooms)s, %(r_type)s, %(square_feet)s, %(garage_spaces)s, %(has_basement)s,\n                    %(has_pool)s, %(commercial_sqft)s, %(industry)s, %(c_type)s, %(num_units)s, %(parking_spaces)s, %(zoning_type)s,\n                    @property_id\n                )\n            ]\n[parameters: {'tax_id': 'TAX687391', 'property_address': '23434', 'status': 'For Sale', 'price': 234234.0, 'lot_size': 234.0, 'year_built': 2000, 'zoning': 'Unknown', 'property_tax': 234.0, 'property_type': 'RESIDENTIAL', 'bedrooms': 32, 'bathrooms': 23.0, 'r_type': 'Single Family', 'square_feet': 0.0, 'garage_spaces': 0, 'has_basement': False, 'has_pool': False, 'commercial_sqft': 0.0, 'industry': 'General', 'c_type': 'Office', 'num_units': 0, 'parking_spaces': 0, 'zoning_type': 'General'}]\n(Background on this error at: https://sqlalche.me/e/20/4xp6)", "traceback": "Traceback (most recent call last):\n  File \"/home/tygilman/School/CS3200/real-estate-htmx-fastapi/.venv/lib/python3.12/site-packages/mysql/connector/connection_cext.py\", line 706, in cmd_query\n    self._cmysql.query(\n_mysql_connector.MySQLInterfaceError: Data truncated for column 'status' at row 1\n\nThe above exception was the direct cause of the following exception:\n\nTraceback (most recent call last):\n  File \"/home/tygilman/School/CS3200/real-estate-htmx-fastapi/.venv/lib/python3.12/site-packages/sqlalchemy/engine/base.py\", line 1969, in _exec_single_context\n    self.dialect.do_execute(\n  File \"/home/tygilman/School/CS3200/real-estate-htmx-fastapi/.venv/lib/python3.12/site-packages/sqlalchemy/engine/default.py\", line 922, in do_execute\n    cursor.execute(statement, parameters)\n  File \"/home/tygilman/School/CS3200/real-estate-htmx-fastapi/.venv/lib/python3.12/site-packages/mysql/connector/cursor_cext.py\", line 357, in execute\n    result = self._connection.cmd_query(\n             ^^^^^^^^^^^^^^^^^^^^^^^^^^^\n  File \"/home/tygilman/School/CS3200/real-estate-htmx-fastapi/.venv/lib/python3.12/site-packages/mysql/connector/opentelemetry/context_propagation.py\", line 97, in wrapper\n    return method(cnx, *args, **kwargs)\n           ^^^^^^^^^^^^^^^^^^^^^^^^^^^^\n  File \"/home/tygilman/School/CS3200/real-estate-htmx-fastapi/.venv/lib/python3.12/site-packages/mysql/connector/connection_cext.py\", line 714, in cmd_query\n    raise get_mysql_exception(\nmysql.connector.errors.DatabaseError: 1265 (01000): Data truncated for column 'status' at row 1\n\nThe above exception was the direct cause of the following exception:\n\nTraceback (most recent call last):\n  File \"/home/tygilman/School/CS3200/real-estate-htmx-fastapi/app/routes/admin.py\", line 263, in create_property\n    result = db.execute(\n             ^^^^^^^^^^^\n  File \"/home/tygilman/School/CS3200/real-estate-htmx-fastapi/.venv/lib/python3.12/site-packages/sqlalchemy/orm/session.py\", line 2308, in execute\n    return self._execute_internal(\n           ^^^^^^^^^^^^^^^^^^^^^^^\n  File \"/home/tygilman/School/CS3200/real-estate-htmx-fastapi/.venv/lib/python3.12/site-packages/sqlalchemy/orm/session.py\", line 2199, in _execute_internal\n    result = conn.execute(\n             ^^^^^^^^^^^^^\n  File \"/home/tygilman/School/CS3200/real-estate-htmx-fastapi/.venv/lib/python3.12/site-packages/sqlalchemy/engine/base.py\", line 1416, in execute\n    return meth(\n           ^^^^^\n  File \"/home/tygilman/School/CS3200/real-estate-htmx-fastapi/.venv/lib/python3.12/site-packages/sqlalchemy/sql/elements.py\", line 516, in _execute_on_connection\n    return connection._execute_clauseelement(\n           ^^^^^^^^^^^^^^^^^^^^^^^^^^^^^^^^^^\n  File \"/home/tygilman/School/CS3200/real-estate-htmx-fastapi/.venv/lib/python3.12/site-packages/sqlalchemy/engine/base.py\", line 1639, in _execute_clauseelement\n    ret = self._execute_context(\n          ^^^^^^^^^^^^^^^^^^^^^^\n  File \"/home/tygilman/School/CS3200/real-estate-htmx-fastapi/.venv/lib/python3.12/site-packages/sqlalchemy/engine/base.py\", line 1848, in _execute_context\n    return self._exec_single_context(\n           ^^^^^^^^^^^^^^^^^^^^^^^^^^\n  File \"/home/tygilman/School/CS3200/real-estate-htmx-fastapi/.venv/lib/python3.12/site-packages/sqlalchemy/engine/base.py\", line 1988, in _exec_single_context\n    self._handle_dbapi_exception(\n  File \"/home/tygilman/School/CS3200/real-estate-htmx-fastapi/.venv/lib/python3.12/site-packages/sqlalchemy/engine/base.py\", line 2343, in _handle_dbapi_exception\n    raise sqlalchemy_exception.with_traceback(exc_info[2]) from e\n  File \"/home/tygilman/School/CS3200/real-estate-htmx-fastapi/.venv/lib/python3.12/site-packages/sqlalchemy/engine/base.py\", line 1969, in _exec_single_context\n    self.dialect.do_execute(\n  File \"/home/tygilman/School/CS3200/real-estate-htmx-fastapi/.venv/lib/python3.12/site-packages/sqlalchemy/engine/default.py\", line 922, in do_execute\n    cursor.execute(statement, parameters)\n  File \"/home/tygilman/School/CS3200/real-estate-htmx-fastapi/.venv/lib/python3.12/site-packages/mysql/connector/cursor_cext.py\", line 357, in execute\n    result = self._connection.cmd_query(\n             ^^^^^^^^^^^^^^^^^^^^^^^^^^^\n  File \"/home/tygilman/School/CS3200/real-estate-htmx-fastapi/.venv/lib/python3.12/site-packages/mysql/connector/opentelemetry/context_propagation.py\", line 97, in wrapper\n    return method(cnx, *args, **kwargs)\n           ^^^^^^^^^^^^^^^^^^^^^^^^^^^^\n  File \"/home/tygilman/School/CS3200/real-estate-htmx-fastapi/.venv/lib/python3.12/site-packages/mysql/connector/connection_cext.py\", line 714, in cmd_query\n    raise get_mysql_exception(\nsqlalchemy.exc.DatabaseError: (mysql.connector.errors.DatabaseError) 1265 (01000): Data truncated for column 'status' at row 1\n[SQL: \n                CALL create_property(\n                    %(tax_id)s, %(property_address)s, %(status)s, %(price)s, %(lot_size)s, %(year_built)s, %(zoning)s, %(property_tax)s,\n                    %(property_type)s, %(bedrooms)s, %(bathrooms)s, %(r_type)s, %(square_feet)s, %(garage_spaces)s, %(has_basement)s,\n                    %(has_pool)s, %(commercial_sqft)s, %(industry)s, %(c_type)s, %(num_units)s, %(parking_spaces)s, %(zoning_type)s,\n                    @property_id\n                )\n            ]\n[parameters: {'tax_id': 'TAX687391', 'property_address': '23434', 'status': 'For Sale', 'price': 234234.0, 'lot_size': 234.0, 'year_built': 2000, 'zoning': 'Unknown', 'property_tax': 234.0, 'property_type': 'RESIDENTIAL', 'bedrooms': 32, 'bathrooms': 23.0, 'r_type': 'Single Family', 'square_feet': 0.0, 'garage_spaces': 0, 'has_basement': False, 'has_pool': False, 'commercial_sqft': 0.0, 'industry': 'General', 'c_type': 'Office', 'num_units': 0, 'parking_spaces': 0, 'zoning_type': 'General'}]\n(Background on this error at: https://sqlalche.me/e/20/4xp6)"}}
{"timestamp": "2024-11-27T03:15:06.420676", "level": "ERROR", "message": "Error creating property: (mysql.connector.errors.DatabaseError) 1265 (01000): Data truncated for column 'status' at row 1\n[SQL: \n                CALL create_property(\n                    %(tax_id)s, %(property_address)s, %(status)s, %(price)s, %(lot_size)s, %(year_built)s, %(zoning)s, %(property_tax)s,\n                    %(property_type)s, %(bedrooms)s, %(bathrooms)s, %(r_type)s, %(square_feet)s, %(garage_spaces)s, %(has_basement)s,\n                    %(has_pool)s, %(commercial_sqft)s, %(industry)s, %(c_type)s, %(num_units)s, %(parking_spaces)s, %(zoning_type)s,\n                    @property_id\n                )\n            ]\n[parameters: {'tax_id': 'TAX576571', 'property_address': '23434', 'status': 'For Sale', 'price': 234234.0, 'lot_size': 234.0, 'year_built': 2000, 'zoning': 'Unknown', 'property_tax': 234.0, 'property_type': 'RESIDENTIAL', 'bedrooms': 32, 'bathrooms': 23.0, 'r_type': 'Single Family', 'square_feet': 0.0, 'garage_spaces': 0, 'has_basement': False, 'has_pool': False, 'commercial_sqft': 0.0, 'industry': 'General', 'c_type': 'Office', 'num_units': 0, 'parking_spaces': 0, 'zoning_type': 'General'}]\n(Background on this error at: https://sqlalche.me/e/20/4xp6)", "module": "admin", "function": "create_property", "line": 339, "thread_id": 131418836424512, "exception": {"type": "DatabaseError", "message": "(mysql.connector.errors.DatabaseError) 1265 (01000): Data truncated for column 'status' at row 1\n[SQL: \n                CALL create_property(\n                    %(tax_id)s, %(property_address)s, %(status)s, %(price)s, %(lot_size)s, %(year_built)s, %(zoning)s, %(property_tax)s,\n                    %(property_type)s, %(bedrooms)s, %(bathrooms)s, %(r_type)s, %(square_feet)s, %(garage_spaces)s, %(has_basement)s,\n                    %(has_pool)s, %(commercial_sqft)s, %(industry)s, %(c_type)s, %(num_units)s, %(parking_spaces)s, %(zoning_type)s,\n                    @property_id\n                )\n            ]\n[parameters: {'tax_id': 'TAX576571', 'property_address': '23434', 'status': 'For Sale', 'price': 234234.0, 'lot_size': 234.0, 'year_built': 2000, 'zoning': 'Unknown', 'property_tax': 234.0, 'property_type': 'RESIDENTIAL', 'bedrooms': 32, 'bathrooms': 23.0, 'r_type': 'Single Family', 'square_feet': 0.0, 'garage_spaces': 0, 'has_basement': False, 'has_pool': False, 'commercial_sqft': 0.0, 'industry': 'General', 'c_type': 'Office', 'num_units': 0, 'parking_spaces': 0, 'zoning_type': 'General'}]\n(Background on this error at: https://sqlalche.me/e/20/4xp6)", "traceback": "Traceback (most recent call last):\n  File \"/home/tygilman/School/CS3200/real-estate-htmx-fastapi/.venv/lib/python3.12/site-packages/mysql/connector/connection_cext.py\", line 706, in cmd_query\n    self._cmysql.query(\n_mysql_connector.MySQLInterfaceError: Data truncated for column 'status' at row 1\n\nThe above exception was the direct cause of the following exception:\n\nTraceback (most recent call last):\n  File \"/home/tygilman/School/CS3200/real-estate-htmx-fastapi/.venv/lib/python3.12/site-packages/sqlalchemy/engine/base.py\", line 1969, in _exec_single_context\n    self.dialect.do_execute(\n  File \"/home/tygilman/School/CS3200/real-estate-htmx-fastapi/.venv/lib/python3.12/site-packages/sqlalchemy/engine/default.py\", line 922, in do_execute\n    cursor.execute(statement, parameters)\n  File \"/home/tygilman/School/CS3200/real-estate-htmx-fastapi/.venv/lib/python3.12/site-packages/mysql/connector/cursor_cext.py\", line 357, in execute\n    result = self._connection.cmd_query(\n             ^^^^^^^^^^^^^^^^^^^^^^^^^^^\n  File \"/home/tygilman/School/CS3200/real-estate-htmx-fastapi/.venv/lib/python3.12/site-packages/mysql/connector/opentelemetry/context_propagation.py\", line 97, in wrapper\n    return method(cnx, *args, **kwargs)\n           ^^^^^^^^^^^^^^^^^^^^^^^^^^^^\n  File \"/home/tygilman/School/CS3200/real-estate-htmx-fastapi/.venv/lib/python3.12/site-packages/mysql/connector/connection_cext.py\", line 714, in cmd_query\n    raise get_mysql_exception(\nmysql.connector.errors.DatabaseError: 1265 (01000): Data truncated for column 'status' at row 1\n\nThe above exception was the direct cause of the following exception:\n\nTraceback (most recent call last):\n  File \"/home/tygilman/School/CS3200/real-estate-htmx-fastapi/app/routes/admin.py\", line 263, in create_property\n    result = db.execute(\n             ^^^^^^^^^^^\n  File \"/home/tygilman/School/CS3200/real-estate-htmx-fastapi/.venv/lib/python3.12/site-packages/sqlalchemy/orm/session.py\", line 2308, in execute\n    return self._execute_internal(\n           ^^^^^^^^^^^^^^^^^^^^^^^\n  File \"/home/tygilman/School/CS3200/real-estate-htmx-fastapi/.venv/lib/python3.12/site-packages/sqlalchemy/orm/session.py\", line 2199, in _execute_internal\n    result = conn.execute(\n             ^^^^^^^^^^^^^\n  File \"/home/tygilman/School/CS3200/real-estate-htmx-fastapi/.venv/lib/python3.12/site-packages/sqlalchemy/engine/base.py\", line 1416, in execute\n    return meth(\n           ^^^^^\n  File \"/home/tygilman/School/CS3200/real-estate-htmx-fastapi/.venv/lib/python3.12/site-packages/sqlalchemy/sql/elements.py\", line 516, in _execute_on_connection\n    return connection._execute_clauseelement(\n           ^^^^^^^^^^^^^^^^^^^^^^^^^^^^^^^^^^\n  File \"/home/tygilman/School/CS3200/real-estate-htmx-fastapi/.venv/lib/python3.12/site-packages/sqlalchemy/engine/base.py\", line 1639, in _execute_clauseelement\n    ret = self._execute_context(\n          ^^^^^^^^^^^^^^^^^^^^^^\n  File \"/home/tygilman/School/CS3200/real-estate-htmx-fastapi/.venv/lib/python3.12/site-packages/sqlalchemy/engine/base.py\", line 1848, in _execute_context\n    return self._exec_single_context(\n           ^^^^^^^^^^^^^^^^^^^^^^^^^^\n  File \"/home/tygilman/School/CS3200/real-estate-htmx-fastapi/.venv/lib/python3.12/site-packages/sqlalchemy/engine/base.py\", line 1988, in _exec_single_context\n    self._handle_dbapi_exception(\n  File \"/home/tygilman/School/CS3200/real-estate-htmx-fastapi/.venv/lib/python3.12/site-packages/sqlalchemy/engine/base.py\", line 2343, in _handle_dbapi_exception\n    raise sqlalchemy_exception.with_traceback(exc_info[2]) from e\n  File \"/home/tygilman/School/CS3200/real-estate-htmx-fastapi/.venv/lib/python3.12/site-packages/sqlalchemy/engine/base.py\", line 1969, in _exec_single_context\n    self.dialect.do_execute(\n  File \"/home/tygilman/School/CS3200/real-estate-htmx-fastapi/.venv/lib/python3.12/site-packages/sqlalchemy/engine/default.py\", line 922, in do_execute\n    cursor.execute(statement, parameters)\n  File \"/home/tygilman/School/CS3200/real-estate-htmx-fastapi/.venv/lib/python3.12/site-packages/mysql/connector/cursor_cext.py\", line 357, in execute\n    result = self._connection.cmd_query(\n             ^^^^^^^^^^^^^^^^^^^^^^^^^^^\n  File \"/home/tygilman/School/CS3200/real-estate-htmx-fastapi/.venv/lib/python3.12/site-packages/mysql/connector/opentelemetry/context_propagation.py\", line 97, in wrapper\n    return method(cnx, *args, **kwargs)\n           ^^^^^^^^^^^^^^^^^^^^^^^^^^^^\n  File \"/home/tygilman/School/CS3200/real-estate-htmx-fastapi/.venv/lib/python3.12/site-packages/mysql/connector/connection_cext.py\", line 714, in cmd_query\n    raise get_mysql_exception(\nsqlalchemy.exc.DatabaseError: (mysql.connector.errors.DatabaseError) 1265 (01000): Data truncated for column 'status' at row 1\n[SQL: \n                CALL create_property(\n                    %(tax_id)s, %(property_address)s, %(status)s, %(price)s, %(lot_size)s, %(year_built)s, %(zoning)s, %(property_tax)s,\n                    %(property_type)s, %(bedrooms)s, %(bathrooms)s, %(r_type)s, %(square_feet)s, %(garage_spaces)s, %(has_basement)s,\n                    %(has_pool)s, %(commercial_sqft)s, %(industry)s, %(c_type)s, %(num_units)s, %(parking_spaces)s, %(zoning_type)s,\n                    @property_id\n                )\n            ]\n[parameters: {'tax_id': 'TAX576571', 'property_address': '23434', 'status': 'For Sale', 'price': 234234.0, 'lot_size': 234.0, 'year_built': 2000, 'zoning': 'Unknown', 'property_tax': 234.0, 'property_type': 'RESIDENTIAL', 'bedrooms': 32, 'bathrooms': 23.0, 'r_type': 'Single Family', 'square_feet': 0.0, 'garage_spaces': 0, 'has_basement': False, 'has_pool': False, 'commercial_sqft': 0.0, 'industry': 'General', 'c_type': 'Office', 'num_units': 0, 'parking_spaces': 0, 'zoning_type': 'General'}]\n(Background on this error at: https://sqlalche.me/e/20/4xp6)"}}
{"timestamp": "2024-11-27T03:15:07.462065", "level": "ERROR", "message": "Error creating property: (mysql.connector.errors.DatabaseError) 1265 (01000): Data truncated for column 'status' at row 1\n[SQL: \n                CALL create_property(\n                    %(tax_id)s, %(property_address)s, %(status)s, %(price)s, %(lot_size)s, %(year_built)s, %(zoning)s, %(property_tax)s,\n                    %(property_type)s, %(bedrooms)s, %(bathrooms)s, %(r_type)s, %(square_feet)s, %(garage_spaces)s, %(has_basement)s,\n                    %(has_pool)s, %(commercial_sqft)s, %(industry)s, %(c_type)s, %(num_units)s, %(parking_spaces)s, %(zoning_type)s,\n                    @property_id\n                )\n            ]\n[parameters: {'tax_id': 'TAX444751', 'property_address': '23434', 'status': 'For Sale', 'price': 234234.0, 'lot_size': 234.0, 'year_built': 2000, 'zoning': 'Unknown', 'property_tax': 234.0, 'property_type': 'RESIDENTIAL', 'bedrooms': 32, 'bathrooms': 23.0, 'r_type': 'Single Family', 'square_feet': 0.0, 'garage_spaces': 0, 'has_basement': False, 'has_pool': False, 'commercial_sqft': 0.0, 'industry': 'General', 'c_type': 'Office', 'num_units': 0, 'parking_spaces': 0, 'zoning_type': 'General'}]\n(Background on this error at: https://sqlalche.me/e/20/4xp6)", "module": "admin", "function": "create_property", "line": 339, "thread_id": 131418836424512, "exception": {"type": "DatabaseError", "message": "(mysql.connector.errors.DatabaseError) 1265 (01000): Data truncated for column 'status' at row 1\n[SQL: \n                CALL create_property(\n                    %(tax_id)s, %(property_address)s, %(status)s, %(price)s, %(lot_size)s, %(year_built)s, %(zoning)s, %(property_tax)s,\n                    %(property_type)s, %(bedrooms)s, %(bathrooms)s, %(r_type)s, %(square_feet)s, %(garage_spaces)s, %(has_basement)s,\n                    %(has_pool)s, %(commercial_sqft)s, %(industry)s, %(c_type)s, %(num_units)s, %(parking_spaces)s, %(zoning_type)s,\n                    @property_id\n                )\n            ]\n[parameters: {'tax_id': 'TAX444751', 'property_address': '23434', 'status': 'For Sale', 'price': 234234.0, 'lot_size': 234.0, 'year_built': 2000, 'zoning': 'Unknown', 'property_tax': 234.0, 'property_type': 'RESIDENTIAL', 'bedrooms': 32, 'bathrooms': 23.0, 'r_type': 'Single Family', 'square_feet': 0.0, 'garage_spaces': 0, 'has_basement': False, 'has_pool': False, 'commercial_sqft': 0.0, 'industry': 'General', 'c_type': 'Office', 'num_units': 0, 'parking_spaces': 0, 'zoning_type': 'General'}]\n(Background on this error at: https://sqlalche.me/e/20/4xp6)", "traceback": "Traceback (most recent call last):\n  File \"/home/tygilman/School/CS3200/real-estate-htmx-fastapi/.venv/lib/python3.12/site-packages/mysql/connector/connection_cext.py\", line 706, in cmd_query\n    self._cmysql.query(\n_mysql_connector.MySQLInterfaceError: Data truncated for column 'status' at row 1\n\nThe above exception was the direct cause of the following exception:\n\nTraceback (most recent call last):\n  File \"/home/tygilman/School/CS3200/real-estate-htmx-fastapi/.venv/lib/python3.12/site-packages/sqlalchemy/engine/base.py\", line 1969, in _exec_single_context\n    self.dialect.do_execute(\n  File \"/home/tygilman/School/CS3200/real-estate-htmx-fastapi/.venv/lib/python3.12/site-packages/sqlalchemy/engine/default.py\", line 922, in do_execute\n    cursor.execute(statement, parameters)\n  File \"/home/tygilman/School/CS3200/real-estate-htmx-fastapi/.venv/lib/python3.12/site-packages/mysql/connector/cursor_cext.py\", line 357, in execute\n    result = self._connection.cmd_query(\n             ^^^^^^^^^^^^^^^^^^^^^^^^^^^\n  File \"/home/tygilman/School/CS3200/real-estate-htmx-fastapi/.venv/lib/python3.12/site-packages/mysql/connector/opentelemetry/context_propagation.py\", line 97, in wrapper\n    return method(cnx, *args, **kwargs)\n           ^^^^^^^^^^^^^^^^^^^^^^^^^^^^\n  File \"/home/tygilman/School/CS3200/real-estate-htmx-fastapi/.venv/lib/python3.12/site-packages/mysql/connector/connection_cext.py\", line 714, in cmd_query\n    raise get_mysql_exception(\nmysql.connector.errors.DatabaseError: 1265 (01000): Data truncated for column 'status' at row 1\n\nThe above exception was the direct cause of the following exception:\n\nTraceback (most recent call last):\n  File \"/home/tygilman/School/CS3200/real-estate-htmx-fastapi/app/routes/admin.py\", line 263, in create_property\n    result = db.execute(\n             ^^^^^^^^^^^\n  File \"/home/tygilman/School/CS3200/real-estate-htmx-fastapi/.venv/lib/python3.12/site-packages/sqlalchemy/orm/session.py\", line 2308, in execute\n    return self._execute_internal(\n           ^^^^^^^^^^^^^^^^^^^^^^^\n  File \"/home/tygilman/School/CS3200/real-estate-htmx-fastapi/.venv/lib/python3.12/site-packages/sqlalchemy/orm/session.py\", line 2199, in _execute_internal\n    result = conn.execute(\n             ^^^^^^^^^^^^^\n  File \"/home/tygilman/School/CS3200/real-estate-htmx-fastapi/.venv/lib/python3.12/site-packages/sqlalchemy/engine/base.py\", line 1416, in execute\n    return meth(\n           ^^^^^\n  File \"/home/tygilman/School/CS3200/real-estate-htmx-fastapi/.venv/lib/python3.12/site-packages/sqlalchemy/sql/elements.py\", line 516, in _execute_on_connection\n    return connection._execute_clauseelement(\n           ^^^^^^^^^^^^^^^^^^^^^^^^^^^^^^^^^^\n  File \"/home/tygilman/School/CS3200/real-estate-htmx-fastapi/.venv/lib/python3.12/site-packages/sqlalchemy/engine/base.py\", line 1639, in _execute_clauseelement\n    ret = self._execute_context(\n          ^^^^^^^^^^^^^^^^^^^^^^\n  File \"/home/tygilman/School/CS3200/real-estate-htmx-fastapi/.venv/lib/python3.12/site-packages/sqlalchemy/engine/base.py\", line 1848, in _execute_context\n    return self._exec_single_context(\n           ^^^^^^^^^^^^^^^^^^^^^^^^^^\n  File \"/home/tygilman/School/CS3200/real-estate-htmx-fastapi/.venv/lib/python3.12/site-packages/sqlalchemy/engine/base.py\", line 1988, in _exec_single_context\n    self._handle_dbapi_exception(\n  File \"/home/tygilman/School/CS3200/real-estate-htmx-fastapi/.venv/lib/python3.12/site-packages/sqlalchemy/engine/base.py\", line 2343, in _handle_dbapi_exception\n    raise sqlalchemy_exception.with_traceback(exc_info[2]) from e\n  File \"/home/tygilman/School/CS3200/real-estate-htmx-fastapi/.venv/lib/python3.12/site-packages/sqlalchemy/engine/base.py\", line 1969, in _exec_single_context\n    self.dialect.do_execute(\n  File \"/home/tygilman/School/CS3200/real-estate-htmx-fastapi/.venv/lib/python3.12/site-packages/sqlalchemy/engine/default.py\", line 922, in do_execute\n    cursor.execute(statement, parameters)\n  File \"/home/tygilman/School/CS3200/real-estate-htmx-fastapi/.venv/lib/python3.12/site-packages/mysql/connector/cursor_cext.py\", line 357, in execute\n    result = self._connection.cmd_query(\n             ^^^^^^^^^^^^^^^^^^^^^^^^^^^\n  File \"/home/tygilman/School/CS3200/real-estate-htmx-fastapi/.venv/lib/python3.12/site-packages/mysql/connector/opentelemetry/context_propagation.py\", line 97, in wrapper\n    return method(cnx, *args, **kwargs)\n           ^^^^^^^^^^^^^^^^^^^^^^^^^^^^\n  File \"/home/tygilman/School/CS3200/real-estate-htmx-fastapi/.venv/lib/python3.12/site-packages/mysql/connector/connection_cext.py\", line 714, in cmd_query\n    raise get_mysql_exception(\nsqlalchemy.exc.DatabaseError: (mysql.connector.errors.DatabaseError) 1265 (01000): Data truncated for column 'status' at row 1\n[SQL: \n                CALL create_property(\n                    %(tax_id)s, %(property_address)s, %(status)s, %(price)s, %(lot_size)s, %(year_built)s, %(zoning)s, %(property_tax)s,\n                    %(property_type)s, %(bedrooms)s, %(bathrooms)s, %(r_type)s, %(square_feet)s, %(garage_spaces)s, %(has_basement)s,\n                    %(has_pool)s, %(commercial_sqft)s, %(industry)s, %(c_type)s, %(num_units)s, %(parking_spaces)s, %(zoning_type)s,\n                    @property_id\n                )\n            ]\n[parameters: {'tax_id': 'TAX444751', 'property_address': '23434', 'status': 'For Sale', 'price': 234234.0, 'lot_size': 234.0, 'year_built': 2000, 'zoning': 'Unknown', 'property_tax': 234.0, 'property_type': 'RESIDENTIAL', 'bedrooms': 32, 'bathrooms': 23.0, 'r_type': 'Single Family', 'square_feet': 0.0, 'garage_spaces': 0, 'has_basement': False, 'has_pool': False, 'commercial_sqft': 0.0, 'industry': 'General', 'c_type': 'Office', 'num_units': 0, 'parking_spaces': 0, 'zoning_type': 'General'}]\n(Background on this error at: https://sqlalche.me/e/20/4xp6)"}}
{"timestamp": "2024-11-27T03:15:38.823338", "level": "ERROR", "message": "Error creating property: (mysql.connector.errors.DatabaseError) 1265 (01000): Data truncated for column 'status' at row 1\n[SQL: \n                CALL create_property(\n                    %(tax_id)s, %(property_address)s, %(status)s, %(price)s, %(lot_size)s, %(year_built)s, %(zoning)s, %(property_tax)s,\n                    %(property_type)s, %(bedrooms)s, %(bathrooms)s, %(r_type)s, %(square_feet)s, %(garage_spaces)s, %(has_basement)s,\n                    %(has_pool)s, %(commercial_sqft)s, %(industry)s, %(c_type)s, %(num_units)s, %(parking_spaces)s, %(zoning_type)s,\n                    @property_id\n                )\n            ]\n[parameters: {'tax_id': 'TAX237319', 'property_address': '324234234', 'status': 'For Sale', 'price': 234234.0, 'lot_size': 234234.0, 'year_built': 2000, 'zoning': 'Unknown', 'property_tax': 234.0, 'property_type': 'COMMERCIAL', 'bedrooms': 0, 'bathrooms': 0.0, 'r_type': 'Single Family', 'square_feet': 0.0, 'garage_spaces': 0, 'has_basement': False, 'has_pool': False, 'commercial_sqft': 0.0, 'industry': 'Office', 'c_type': 'Retail Space', 'num_units': 0, 'parking_spaces': 0, 'zoning_type': 'General'}]\n(Background on this error at: https://sqlalche.me/e/20/4xp6)", "module": "admin", "function": "create_property", "line": 339, "thread_id": 131418836424512, "exception": {"type": "DatabaseError", "message": "(mysql.connector.errors.DatabaseError) 1265 (01000): Data truncated for column 'status' at row 1\n[SQL: \n                CALL create_property(\n                    %(tax_id)s, %(property_address)s, %(status)s, %(price)s, %(lot_size)s, %(year_built)s, %(zoning)s, %(property_tax)s,\n                    %(property_type)s, %(bedrooms)s, %(bathrooms)s, %(r_type)s, %(square_feet)s, %(garage_spaces)s, %(has_basement)s,\n                    %(has_pool)s, %(commercial_sqft)s, %(industry)s, %(c_type)s, %(num_units)s, %(parking_spaces)s, %(zoning_type)s,\n                    @property_id\n                )\n            ]\n[parameters: {'tax_id': 'TAX237319', 'property_address': '324234234', 'status': 'For Sale', 'price': 234234.0, 'lot_size': 234234.0, 'year_built': 2000, 'zoning': 'Unknown', 'property_tax': 234.0, 'property_type': 'COMMERCIAL', 'bedrooms': 0, 'bathrooms': 0.0, 'r_type': 'Single Family', 'square_feet': 0.0, 'garage_spaces': 0, 'has_basement': False, 'has_pool': False, 'commercial_sqft': 0.0, 'industry': 'Office', 'c_type': 'Retail Space', 'num_units': 0, 'parking_spaces': 0, 'zoning_type': 'General'}]\n(Background on this error at: https://sqlalche.me/e/20/4xp6)", "traceback": "Traceback (most recent call last):\n  File \"/home/tygilman/School/CS3200/real-estate-htmx-fastapi/.venv/lib/python3.12/site-packages/mysql/connector/connection_cext.py\", line 706, in cmd_query\n    self._cmysql.query(\n_mysql_connector.MySQLInterfaceError: Data truncated for column 'status' at row 1\n\nThe above exception was the direct cause of the following exception:\n\nTraceback (most recent call last):\n  File \"/home/tygilman/School/CS3200/real-estate-htmx-fastapi/.venv/lib/python3.12/site-packages/sqlalchemy/engine/base.py\", line 1969, in _exec_single_context\n    self.dialect.do_execute(\n  File \"/home/tygilman/School/CS3200/real-estate-htmx-fastapi/.venv/lib/python3.12/site-packages/sqlalchemy/engine/default.py\", line 922, in do_execute\n    cursor.execute(statement, parameters)\n  File \"/home/tygilman/School/CS3200/real-estate-htmx-fastapi/.venv/lib/python3.12/site-packages/mysql/connector/cursor_cext.py\", line 357, in execute\n    result = self._connection.cmd_query(\n             ^^^^^^^^^^^^^^^^^^^^^^^^^^^\n  File \"/home/tygilman/School/CS3200/real-estate-htmx-fastapi/.venv/lib/python3.12/site-packages/mysql/connector/opentelemetry/context_propagation.py\", line 97, in wrapper\n    return method(cnx, *args, **kwargs)\n           ^^^^^^^^^^^^^^^^^^^^^^^^^^^^\n  File \"/home/tygilman/School/CS3200/real-estate-htmx-fastapi/.venv/lib/python3.12/site-packages/mysql/connector/connection_cext.py\", line 714, in cmd_query\n    raise get_mysql_exception(\nmysql.connector.errors.DatabaseError: 1265 (01000): Data truncated for column 'status' at row 1\n\nThe above exception was the direct cause of the following exception:\n\nTraceback (most recent call last):\n  File \"/home/tygilman/School/CS3200/real-estate-htmx-fastapi/app/routes/admin.py\", line 263, in create_property\n    result = db.execute(\n             ^^^^^^^^^^^\n  File \"/home/tygilman/School/CS3200/real-estate-htmx-fastapi/.venv/lib/python3.12/site-packages/sqlalchemy/orm/session.py\", line 2308, in execute\n    return self._execute_internal(\n           ^^^^^^^^^^^^^^^^^^^^^^^\n  File \"/home/tygilman/School/CS3200/real-estate-htmx-fastapi/.venv/lib/python3.12/site-packages/sqlalchemy/orm/session.py\", line 2199, in _execute_internal\n    result = conn.execute(\n             ^^^^^^^^^^^^^\n  File \"/home/tygilman/School/CS3200/real-estate-htmx-fastapi/.venv/lib/python3.12/site-packages/sqlalchemy/engine/base.py\", line 1416, in execute\n    return meth(\n           ^^^^^\n  File \"/home/tygilman/School/CS3200/real-estate-htmx-fastapi/.venv/lib/python3.12/site-packages/sqlalchemy/sql/elements.py\", line 516, in _execute_on_connection\n    return connection._execute_clauseelement(\n           ^^^^^^^^^^^^^^^^^^^^^^^^^^^^^^^^^^\n  File \"/home/tygilman/School/CS3200/real-estate-htmx-fastapi/.venv/lib/python3.12/site-packages/sqlalchemy/engine/base.py\", line 1639, in _execute_clauseelement\n    ret = self._execute_context(\n          ^^^^^^^^^^^^^^^^^^^^^^\n  File \"/home/tygilman/School/CS3200/real-estate-htmx-fastapi/.venv/lib/python3.12/site-packages/sqlalchemy/engine/base.py\", line 1848, in _execute_context\n    return self._exec_single_context(\n           ^^^^^^^^^^^^^^^^^^^^^^^^^^\n  File \"/home/tygilman/School/CS3200/real-estate-htmx-fastapi/.venv/lib/python3.12/site-packages/sqlalchemy/engine/base.py\", line 1988, in _exec_single_context\n    self._handle_dbapi_exception(\n  File \"/home/tygilman/School/CS3200/real-estate-htmx-fastapi/.venv/lib/python3.12/site-packages/sqlalchemy/engine/base.py\", line 2343, in _handle_dbapi_exception\n    raise sqlalchemy_exception.with_traceback(exc_info[2]) from e\n  File \"/home/tygilman/School/CS3200/real-estate-htmx-fastapi/.venv/lib/python3.12/site-packages/sqlalchemy/engine/base.py\", line 1969, in _exec_single_context\n    self.dialect.do_execute(\n  File \"/home/tygilman/School/CS3200/real-estate-htmx-fastapi/.venv/lib/python3.12/site-packages/sqlalchemy/engine/default.py\", line 922, in do_execute\n    cursor.execute(statement, parameters)\n  File \"/home/tygilman/School/CS3200/real-estate-htmx-fastapi/.venv/lib/python3.12/site-packages/mysql/connector/cursor_cext.py\", line 357, in execute\n    result = self._connection.cmd_query(\n             ^^^^^^^^^^^^^^^^^^^^^^^^^^^\n  File \"/home/tygilman/School/CS3200/real-estate-htmx-fastapi/.venv/lib/python3.12/site-packages/mysql/connector/opentelemetry/context_propagation.py\", line 97, in wrapper\n    return method(cnx, *args, **kwargs)\n           ^^^^^^^^^^^^^^^^^^^^^^^^^^^^\n  File \"/home/tygilman/School/CS3200/real-estate-htmx-fastapi/.venv/lib/python3.12/site-packages/mysql/connector/connection_cext.py\", line 714, in cmd_query\n    raise get_mysql_exception(\nsqlalchemy.exc.DatabaseError: (mysql.connector.errors.DatabaseError) 1265 (01000): Data truncated for column 'status' at row 1\n[SQL: \n                CALL create_property(\n                    %(tax_id)s, %(property_address)s, %(status)s, %(price)s, %(lot_size)s, %(year_built)s, %(zoning)s, %(property_tax)s,\n                    %(property_type)s, %(bedrooms)s, %(bathrooms)s, %(r_type)s, %(square_feet)s, %(garage_spaces)s, %(has_basement)s,\n                    %(has_pool)s, %(commercial_sqft)s, %(industry)s, %(c_type)s, %(num_units)s, %(parking_spaces)s, %(zoning_type)s,\n                    @property_id\n                )\n            ]\n[parameters: {'tax_id': 'TAX237319', 'property_address': '324234234', 'status': 'For Sale', 'price': 234234.0, 'lot_size': 234234.0, 'year_built': 2000, 'zoning': 'Unknown', 'property_tax': 234.0, 'property_type': 'COMMERCIAL', 'bedrooms': 0, 'bathrooms': 0.0, 'r_type': 'Single Family', 'square_feet': 0.0, 'garage_spaces': 0, 'has_basement': False, 'has_pool': False, 'commercial_sqft': 0.0, 'industry': 'Office', 'c_type': 'Retail Space', 'num_units': 0, 'parking_spaces': 0, 'zoning_type': 'General'}]\n(Background on this error at: https://sqlalche.me/e/20/4xp6)"}}
{"timestamp": "2024-11-27T03:27:31.901286", "level": "ERROR", "message": "Error creating property: (mysql.connector.errors.DatabaseError) 1265 (01000): Data truncated for column 'p_status' at row 1\n[SQL: \n                CALL create_property(\n                    %(tax_id)s, %(property_address)s, %(status)s, %(price)s, %(lot_size)s, %(year_built)s, %(zoning)s, %(property_tax)s,\n                    %(property_type)s, %(bedrooms)s, %(bathrooms)s, %(r_type)s, %(square_feet)s, %(garage_spaces)s, %(has_basement)s,\n                    %(has_pool)s, %(commercial_sqft)s, %(industry)s, %(c_type)s, %(num_units)s, %(parking_spaces)s, %(zoning_type)s,\n                    @property_id\n                )\n            ]\n[parameters: {'tax_id': 'TAX167595', 'property_address': '23423', 'status': 'FOR_SALE', 'price': 2342234.0, 'lot_size': 324.0, 'year_built': 2000, 'zoning': 'Unknown', 'property_tax': 4234.0, 'property_type': 'RESIDENTIAL', 'bedrooms': 23, 'bathrooms': 32.0, 'r_type': 'Single Family', 'square_feet': 0.0, 'garage_spaces': 0, 'has_basement': False, 'has_pool': False, 'commercial_sqft': 0.0, 'industry': 'General', 'c_type': 'Office', 'num_units': 0, 'parking_spaces': 0, 'zoning_type': 'General'}]\n(Background on this error at: https://sqlalche.me/e/20/4xp6)", "module": "admin", "function": "create_property", "line": 352, "thread_id": 123936164067136, "exception": {"type": "DatabaseError", "message": "(mysql.connector.errors.DatabaseError) 1265 (01000): Data truncated for column 'p_status' at row 1\n[SQL: \n                CALL create_property(\n                    %(tax_id)s, %(property_address)s, %(status)s, %(price)s, %(lot_size)s, %(year_built)s, %(zoning)s, %(property_tax)s,\n                    %(property_type)s, %(bedrooms)s, %(bathrooms)s, %(r_type)s, %(square_feet)s, %(garage_spaces)s, %(has_basement)s,\n                    %(has_pool)s, %(commercial_sqft)s, %(industry)s, %(c_type)s, %(num_units)s, %(parking_spaces)s, %(zoning_type)s,\n                    @property_id\n                )\n            ]\n[parameters: {'tax_id': 'TAX167595', 'property_address': '23423', 'status': 'FOR_SALE', 'price': 2342234.0, 'lot_size': 324.0, 'year_built': 2000, 'zoning': 'Unknown', 'property_tax': 4234.0, 'property_type': 'RESIDENTIAL', 'bedrooms': 23, 'bathrooms': 32.0, 'r_type': 'Single Family', 'square_feet': 0.0, 'garage_spaces': 0, 'has_basement': False, 'has_pool': False, 'commercial_sqft': 0.0, 'industry': 'General', 'c_type': 'Office', 'num_units': 0, 'parking_spaces': 0, 'zoning_type': 'General'}]\n(Background on this error at: https://sqlalche.me/e/20/4xp6)", "traceback": "Traceback (most recent call last):\n  File \"/home/tygilman/School/CS3200/real-estate-htmx-fastapi/.venv/lib/python3.12/site-packages/mysql/connector/connection_cext.py\", line 706, in cmd_query\n    self._cmysql.query(\n_mysql_connector.MySQLInterfaceError: Data truncated for column 'p_status' at row 1\n\nThe above exception was the direct cause of the following exception:\n\nTraceback (most recent call last):\n  File \"/home/tygilman/School/CS3200/real-estate-htmx-fastapi/.venv/lib/python3.12/site-packages/sqlalchemy/engine/base.py\", line 1969, in _exec_single_context\n    self.dialect.do_execute(\n  File \"/home/tygilman/School/CS3200/real-estate-htmx-fastapi/.venv/lib/python3.12/site-packages/sqlalchemy/engine/default.py\", line 922, in do_execute\n    cursor.execute(statement, parameters)\n  File \"/home/tygilman/School/CS3200/real-estate-htmx-fastapi/.venv/lib/python3.12/site-packages/mysql/connector/cursor_cext.py\", line 357, in execute\n    result = self._connection.cmd_query(\n             ^^^^^^^^^^^^^^^^^^^^^^^^^^^\n  File \"/home/tygilman/School/CS3200/real-estate-htmx-fastapi/.venv/lib/python3.12/site-packages/mysql/connector/opentelemetry/context_propagation.py\", line 97, in wrapper\n    return method(cnx, *args, **kwargs)\n           ^^^^^^^^^^^^^^^^^^^^^^^^^^^^\n  File \"/home/tygilman/School/CS3200/real-estate-htmx-fastapi/.venv/lib/python3.12/site-packages/mysql/connector/connection_cext.py\", line 714, in cmd_query\n    raise get_mysql_exception(\nmysql.connector.errors.DatabaseError: 1265 (01000): Data truncated for column 'p_status' at row 1\n\nThe above exception was the direct cause of the following exception:\n\nTraceback (most recent call last):\n  File \"/home/tygilman/School/CS3200/real-estate-htmx-fastapi/app/routes/admin.py\", line 279, in create_property\n    property_id = db.execute(\n                  ^^^^^^^^^^^\n  File \"/home/tygilman/School/CS3200/real-estate-htmx-fastapi/.venv/lib/python3.12/site-packages/sqlalchemy/orm/session.py\", line 2308, in execute\n    return self._execute_internal(\n           ^^^^^^^^^^^^^^^^^^^^^^^\n  File \"/home/tygilman/School/CS3200/real-estate-htmx-fastapi/.venv/lib/python3.12/site-packages/sqlalchemy/orm/session.py\", line 2199, in _execute_internal\n    result = conn.execute(\n             ^^^^^^^^^^^^^\n  File \"/home/tygilman/School/CS3200/real-estate-htmx-fastapi/.venv/lib/python3.12/site-packages/sqlalchemy/engine/base.py\", line 1416, in execute\n    return meth(\n           ^^^^^\n  File \"/home/tygilman/School/CS3200/real-estate-htmx-fastapi/.venv/lib/python3.12/site-packages/sqlalchemy/sql/elements.py\", line 516, in _execute_on_connection\n    return connection._execute_clauseelement(\n           ^^^^^^^^^^^^^^^^^^^^^^^^^^^^^^^^^^\n  File \"/home/tygilman/School/CS3200/real-estate-htmx-fastapi/.venv/lib/python3.12/site-packages/sqlalchemy/engine/base.py\", line 1639, in _execute_clauseelement\n    ret = self._execute_context(\n          ^^^^^^^^^^^^^^^^^^^^^^\n  File \"/home/tygilman/School/CS3200/real-estate-htmx-fastapi/.venv/lib/python3.12/site-packages/sqlalchemy/engine/base.py\", line 1848, in _execute_context\n    return self._exec_single_context(\n           ^^^^^^^^^^^^^^^^^^^^^^^^^^\n  File \"/home/tygilman/School/CS3200/real-estate-htmx-fastapi/.venv/lib/python3.12/site-packages/sqlalchemy/engine/base.py\", line 1988, in _exec_single_context\n    self._handle_dbapi_exception(\n  File \"/home/tygilman/School/CS3200/real-estate-htmx-fastapi/.venv/lib/python3.12/site-packages/sqlalchemy/engine/base.py\", line 2343, in _handle_dbapi_exception\n    raise sqlalchemy_exception.with_traceback(exc_info[2]) from e\n  File \"/home/tygilman/School/CS3200/real-estate-htmx-fastapi/.venv/lib/python3.12/site-packages/sqlalchemy/engine/base.py\", line 1969, in _exec_single_context\n    self.dialect.do_execute(\n  File \"/home/tygilman/School/CS3200/real-estate-htmx-fastapi/.venv/lib/python3.12/site-packages/sqlalchemy/engine/default.py\", line 922, in do_execute\n    cursor.execute(statement, parameters)\n  File \"/home/tygilman/School/CS3200/real-estate-htmx-fastapi/.venv/lib/python3.12/site-packages/mysql/connector/cursor_cext.py\", line 357, in execute\n    result = self._connection.cmd_query(\n             ^^^^^^^^^^^^^^^^^^^^^^^^^^^\n  File \"/home/tygilman/School/CS3200/real-estate-htmx-fastapi/.venv/lib/python3.12/site-packages/mysql/connector/opentelemetry/context_propagation.py\", line 97, in wrapper\n    return method(cnx, *args, **kwargs)\n           ^^^^^^^^^^^^^^^^^^^^^^^^^^^^\n  File \"/home/tygilman/School/CS3200/real-estate-htmx-fastapi/.venv/lib/python3.12/site-packages/mysql/connector/connection_cext.py\", line 714, in cmd_query\n    raise get_mysql_exception(\nsqlalchemy.exc.DatabaseError: (mysql.connector.errors.DatabaseError) 1265 (01000): Data truncated for column 'p_status' at row 1\n[SQL: \n                CALL create_property(\n                    %(tax_id)s, %(property_address)s, %(status)s, %(price)s, %(lot_size)s, %(year_built)s, %(zoning)s, %(property_tax)s,\n                    %(property_type)s, %(bedrooms)s, %(bathrooms)s, %(r_type)s, %(square_feet)s, %(garage_spaces)s, %(has_basement)s,\n                    %(has_pool)s, %(commercial_sqft)s, %(industry)s, %(c_type)s, %(num_units)s, %(parking_spaces)s, %(zoning_type)s,\n                    @property_id\n                )\n            ]\n[parameters: {'tax_id': 'TAX167595', 'property_address': '23423', 'status': 'FOR_SALE', 'price': 2342234.0, 'lot_size': 324.0, 'year_built': 2000, 'zoning': 'Unknown', 'property_tax': 4234.0, 'property_type': 'RESIDENTIAL', 'bedrooms': 23, 'bathrooms': 32.0, 'r_type': 'Single Family', 'square_feet': 0.0, 'garage_spaces': 0, 'has_basement': False, 'has_pool': False, 'commercial_sqft': 0.0, 'industry': 'General', 'c_type': 'Office', 'num_units': 0, 'parking_spaces': 0, 'zoning_type': 'General'}]\n(Background on this error at: https://sqlalche.me/e/20/4xp6)"}}
{"timestamp": "2024-11-27T03:28:44.571960", "level": "ERROR", "message": "Error creating property: (mysql.connector.errors.DatabaseError) 1265 (01000): Data truncated for column 'p_status' at row 1\n[SQL: \n                CALL create_property(\n                    %(tax_id)s, %(property_address)s, %(status)s, %(price)s, %(lot_size)s, %(year_built)s, %(zoning)s, %(property_tax)s,\n                    %(property_type)s, 0, 0.0, NULL, 0.0, 0, FALSE, FALSE, 0.0, NULL, NULL, 0, 0, NULL, @property_id\n                )\n            ]\n[parameters: {'tax_id': 'TAX764184', 'property_address': '234', 'status': 'FOR_SALE', 'price': 3.0, 'lot_size': 2342.0, 'year_built': 2000, 'zoning': 'Unknown', 'property_tax': 23424.0, 'property_type': 'RESIDENTIAL'}]\n(Background on this error at: https://sqlalche.me/e/20/4xp6)", "module": "admin", "function": "create_property", "line": 287, "thread_id": 136287124981568, "exception": {"type": "DatabaseError", "message": "(mysql.connector.errors.DatabaseError) 1265 (01000): Data truncated for column 'p_status' at row 1\n[SQL: \n                CALL create_property(\n                    %(tax_id)s, %(property_address)s, %(status)s, %(price)s, %(lot_size)s, %(year_built)s, %(zoning)s, %(property_tax)s,\n                    %(property_type)s, 0, 0.0, NULL, 0.0, 0, FALSE, FALSE, 0.0, NULL, NULL, 0, 0, NULL, @property_id\n                )\n            ]\n[parameters: {'tax_id': 'TAX764184', 'property_address': '234', 'status': 'FOR_SALE', 'price': 3.0, 'lot_size': 2342.0, 'year_built': 2000, 'zoning': 'Unknown', 'property_tax': 23424.0, 'property_type': 'RESIDENTIAL'}]\n(Background on this error at: https://sqlalche.me/e/20/4xp6)", "traceback": "Traceback (most recent call last):\n  File \"/home/tygilman/School/CS3200/real-estate-htmx-fastapi/.venv/lib/python3.12/site-packages/mysql/connector/connection_cext.py\", line 706, in cmd_query\n    self._cmysql.query(\n_mysql_connector.MySQLInterfaceError: Data truncated for column 'p_status' at row 1\n\nThe above exception was the direct cause of the following exception:\n\nTraceback (most recent call last):\n  File \"/home/tygilman/School/CS3200/real-estate-htmx-fastapi/.venv/lib/python3.12/site-packages/sqlalchemy/engine/base.py\", line 1969, in _exec_single_context\n    self.dialect.do_execute(\n  File \"/home/tygilman/School/CS3200/real-estate-htmx-fastapi/.venv/lib/python3.12/site-packages/sqlalchemy/engine/default.py\", line 922, in do_execute\n    cursor.execute(statement, parameters)\n  File \"/home/tygilman/School/CS3200/real-estate-htmx-fastapi/.venv/lib/python3.12/site-packages/mysql/connector/cursor_cext.py\", line 357, in execute\n    result = self._connection.cmd_query(\n             ^^^^^^^^^^^^^^^^^^^^^^^^^^^\n  File \"/home/tygilman/School/CS3200/real-estate-htmx-fastapi/.venv/lib/python3.12/site-packages/mysql/connector/opentelemetry/context_propagation.py\", line 97, in wrapper\n    return method(cnx, *args, **kwargs)\n           ^^^^^^^^^^^^^^^^^^^^^^^^^^^^\n  File \"/home/tygilman/School/CS3200/real-estate-htmx-fastapi/.venv/lib/python3.12/site-packages/mysql/connector/connection_cext.py\", line 714, in cmd_query\n    raise get_mysql_exception(\nmysql.connector.errors.DatabaseError: 1265 (01000): Data truncated for column 'p_status' at row 1\n\nThe above exception was the direct cause of the following exception:\n\nTraceback (most recent call last):\n  File \"/home/tygilman/School/CS3200/real-estate-htmx-fastapi/app/routes/admin.py\", line 252, in create_property\n    db.execute(\n  File \"/home/tygilman/School/CS3200/real-estate-htmx-fastapi/.venv/lib/python3.12/site-packages/sqlalchemy/orm/session.py\", line 2308, in execute\n    return self._execute_internal(\n           ^^^^^^^^^^^^^^^^^^^^^^^\n  File \"/home/tygilman/School/CS3200/real-estate-htmx-fastapi/.venv/lib/python3.12/site-packages/sqlalchemy/orm/session.py\", line 2199, in _execute_internal\n    result = conn.execute(\n             ^^^^^^^^^^^^^\n  File \"/home/tygilman/School/CS3200/real-estate-htmx-fastapi/.venv/lib/python3.12/site-packages/sqlalchemy/engine/base.py\", line 1416, in execute\n    return meth(\n           ^^^^^\n  File \"/home/tygilman/School/CS3200/real-estate-htmx-fastapi/.venv/lib/python3.12/site-packages/sqlalchemy/sql/elements.py\", line 516, in _execute_on_connection\n    return connection._execute_clauseelement(\n           ^^^^^^^^^^^^^^^^^^^^^^^^^^^^^^^^^^\n  File \"/home/tygilman/School/CS3200/real-estate-htmx-fastapi/.venv/lib/python3.12/site-packages/sqlalchemy/engine/base.py\", line 1639, in _execute_clauseelement\n    ret = self._execute_context(\n          ^^^^^^^^^^^^^^^^^^^^^^\n  File \"/home/tygilman/School/CS3200/real-estate-htmx-fastapi/.venv/lib/python3.12/site-packages/sqlalchemy/engine/base.py\", line 1848, in _execute_context\n    return self._exec_single_context(\n           ^^^^^^^^^^^^^^^^^^^^^^^^^^\n  File \"/home/tygilman/School/CS3200/real-estate-htmx-fastapi/.venv/lib/python3.12/site-packages/sqlalchemy/engine/base.py\", line 1988, in _exec_single_context\n    self._handle_dbapi_exception(\n  File \"/home/tygilman/School/CS3200/real-estate-htmx-fastapi/.venv/lib/python3.12/site-packages/sqlalchemy/engine/base.py\", line 2343, in _handle_dbapi_exception\n    raise sqlalchemy_exception.with_traceback(exc_info[2]) from e\n  File \"/home/tygilman/School/CS3200/real-estate-htmx-fastapi/.venv/lib/python3.12/site-packages/sqlalchemy/engine/base.py\", line 1969, in _exec_single_context\n    self.dialect.do_execute(\n  File \"/home/tygilman/School/CS3200/real-estate-htmx-fastapi/.venv/lib/python3.12/site-packages/sqlalchemy/engine/default.py\", line 922, in do_execute\n    cursor.execute(statement, parameters)\n  File \"/home/tygilman/School/CS3200/real-estate-htmx-fastapi/.venv/lib/python3.12/site-packages/mysql/connector/cursor_cext.py\", line 357, in execute\n    result = self._connection.cmd_query(\n             ^^^^^^^^^^^^^^^^^^^^^^^^^^^\n  File \"/home/tygilman/School/CS3200/real-estate-htmx-fastapi/.venv/lib/python3.12/site-packages/mysql/connector/opentelemetry/context_propagation.py\", line 97, in wrapper\n    return method(cnx, *args, **kwargs)\n           ^^^^^^^^^^^^^^^^^^^^^^^^^^^^\n  File \"/home/tygilman/School/CS3200/real-estate-htmx-fastapi/.venv/lib/python3.12/site-packages/mysql/connector/connection_cext.py\", line 714, in cmd_query\n    raise get_mysql_exception(\nsqlalchemy.exc.DatabaseError: (mysql.connector.errors.DatabaseError) 1265 (01000): Data truncated for column 'p_status' at row 1\n[SQL: \n                CALL create_property(\n                    %(tax_id)s, %(property_address)s, %(status)s, %(price)s, %(lot_size)s, %(year_built)s, %(zoning)s, %(property_tax)s,\n                    %(property_type)s, 0, 0.0, NULL, 0.0, 0, FALSE, FALSE, 0.0, NULL, NULL, 0, 0, NULL, @property_id\n                )\n            ]\n[parameters: {'tax_id': 'TAX764184', 'property_address': '234', 'status': 'FOR_SALE', 'price': 3.0, 'lot_size': 2342.0, 'year_built': 2000, 'zoning': 'Unknown', 'property_tax': 23424.0, 'property_type': 'RESIDENTIAL'}]\n(Background on this error at: https://sqlalche.me/e/20/4xp6)"}}
{"timestamp": "2024-11-27T03:37:08.474851", "level": "ERROR", "message": "Error in create_property: (mysql.connector.errors.DataError) 1264 (22003): Out of range value for column 'bathrooms' at row 1\n[SQL: INSERT INTO `ResidentialProperty` (property_id, bedrooms, bathrooms, r_type, square_feet, garage_spaces, has_basement, has_pool, created_at) VALUES (%(property_id)s, %(bedrooms)s, %(bathrooms)s, %(r_type)s, %(square_feet)s, %(garage_spaces)s, %(has_basement)s, %(has_pool)s, now())]\n[parameters: {'property_id': 11, 'bedrooms': 234, 'bathrooms': 323.5, 'r_type': 'Single Family', 'square_feet': None, 'garage_spaces': None, 'has_basement': 0, 'has_pool': 0}]\n(Background on this error at: https://sqlalche.me/e/20/9h9h)", "module": "admin", "function": "create_property", "line": 340, "thread_id": 138330508015424, "exception": {"type": "DataError", "message": "(mysql.connector.errors.DataError) 1264 (22003): Out of range value for column 'bathrooms' at row 1\n[SQL: INSERT INTO `ResidentialProperty` (property_id, bedrooms, bathrooms, r_type, square_feet, garage_spaces, has_basement, has_pool, created_at) VALUES (%(property_id)s, %(bedrooms)s, %(bathrooms)s, %(r_type)s, %(square_feet)s, %(garage_spaces)s, %(has_basement)s, %(has_pool)s, now())]\n[parameters: {'property_id': 11, 'bedrooms': 234, 'bathrooms': 323.5, 'r_type': 'Single Family', 'square_feet': None, 'garage_spaces': None, 'has_basement': 0, 'has_pool': 0}]\n(Background on this error at: https://sqlalche.me/e/20/9h9h)", "traceback": "Traceback (most recent call last):\n  File \"/home/tygilman/School/CS3200/real-estate-htmx-fastapi/.venv/lib/python3.12/site-packages/mysql/connector/connection_cext.py\", line 706, in cmd_query\n    self._cmysql.query(\n_mysql_connector.MySQLInterfaceError: Out of range value for column 'bathrooms' at row 1\n\nThe above exception was the direct cause of the following exception:\n\nTraceback (most recent call last):\n  File \"/home/tygilman/School/CS3200/real-estate-htmx-fastapi/.venv/lib/python3.12/site-packages/sqlalchemy/engine/base.py\", line 1969, in _exec_single_context\n    self.dialect.do_execute(\n  File \"/home/tygilman/School/CS3200/real-estate-htmx-fastapi/.venv/lib/python3.12/site-packages/sqlalchemy/engine/default.py\", line 922, in do_execute\n    cursor.execute(statement, parameters)\n  File \"/home/tygilman/School/CS3200/real-estate-htmx-fastapi/.venv/lib/python3.12/site-packages/mysql/connector/cursor_cext.py\", line 357, in execute\n    result = self._connection.cmd_query(\n             ^^^^^^^^^^^^^^^^^^^^^^^^^^^\n  File \"/home/tygilman/School/CS3200/real-estate-htmx-fastapi/.venv/lib/python3.12/site-packages/mysql/connector/opentelemetry/context_propagation.py\", line 97, in wrapper\n    return method(cnx, *args, **kwargs)\n           ^^^^^^^^^^^^^^^^^^^^^^^^^^^^\n  File \"/home/tygilman/School/CS3200/real-estate-htmx-fastapi/.venv/lib/python3.12/site-packages/mysql/connector/connection_cext.py\", line 714, in cmd_query\n    raise get_mysql_exception(\nmysql.connector.errors.DataError: 1264 (22003): Out of range value for column 'bathrooms' at row 1\n\nThe above exception was the direct cause of the following exception:\n\nTraceback (most recent call last):\n  File \"/home/tygilman/School/CS3200/real-estate-htmx-fastapi/app/routes/admin.py\", line 326, in create_property\n    db.commit()\n  File \"/home/tygilman/School/CS3200/real-estate-htmx-fastapi/.venv/lib/python3.12/site-packages/sqlalchemy/orm/session.py\", line 1969, in commit\n    trans.commit(_to_root=True)\n  File \"<string>\", line 2, in commit\n  File \"/home/tygilman/School/CS3200/real-estate-htmx-fastapi/.venv/lib/python3.12/site-packages/sqlalchemy/orm/state_changes.py\", line 139, in _go\n    ret_value = fn(self, *arg, **kw)\n                ^^^^^^^^^^^^^^^^^^^^\n  File \"/home/tygilman/School/CS3200/real-estate-htmx-fastapi/.venv/lib/python3.12/site-packages/sqlalchemy/orm/session.py\", line 1256, in commit\n    self._prepare_impl()\n  File \"<string>\", line 2, in _prepare_impl\n  File \"/home/tygilman/School/CS3200/real-estate-htmx-fastapi/.venv/lib/python3.12/site-packages/sqlalchemy/orm/state_changes.py\", line 139, in _go\n    ret_value = fn(self, *arg, **kw)\n                ^^^^^^^^^^^^^^^^^^^^\n  File \"/home/tygilman/School/CS3200/real-estate-htmx-fastapi/.venv/lib/python3.12/site-packages/sqlalchemy/orm/session.py\", line 1231, in _prepare_impl\n    self.session.flush()\n  File \"/home/tygilman/School/CS3200/real-estate-htmx-fastapi/.venv/lib/python3.12/site-packages/sqlalchemy/orm/session.py\", line 4312, in flush\n    self._flush(objects)\n  File \"/home/tygilman/School/CS3200/real-estate-htmx-fastapi/.venv/lib/python3.12/site-packages/sqlalchemy/orm/session.py\", line 4447, in _flush\n    with util.safe_reraise():\n  File \"/home/tygilman/School/CS3200/real-estate-htmx-fastapi/.venv/lib/python3.12/site-packages/sqlalchemy/util/langhelpers.py\", line 146, in __exit__\n    raise exc_value.with_traceback(exc_tb)\n  File \"/home/tygilman/School/CS3200/real-estate-htmx-fastapi/.venv/lib/python3.12/site-packages/sqlalchemy/orm/session.py\", line 4408, in _flush\n    flush_context.execute()\n  File \"/home/tygilman/School/CS3200/real-estate-htmx-fastapi/.venv/lib/python3.12/site-packages/sqlalchemy/orm/unitofwork.py\", line 466, in execute\n    rec.execute(self)\n  File \"/home/tygilman/School/CS3200/real-estate-htmx-fastapi/.venv/lib/python3.12/site-packages/sqlalchemy/orm/unitofwork.py\", line 642, in execute\n    util.preloaded.orm_persistence.save_obj(\n  File \"/home/tygilman/School/CS3200/real-estate-htmx-fastapi/.venv/lib/python3.12/site-packages/sqlalchemy/orm/persistence.py\", line 93, in save_obj\n    _emit_insert_statements(\n  File \"/home/tygilman/School/CS3200/real-estate-htmx-fastapi/.venv/lib/python3.12/site-packages/sqlalchemy/orm/persistence.py\", line 1043, in _emit_insert_statements\n    result = connection.execute(\n             ^^^^^^^^^^^^^^^^^^^\n  File \"/home/tygilman/School/CS3200/real-estate-htmx-fastapi/.venv/lib/python3.12/site-packages/sqlalchemy/engine/base.py\", line 1416, in execute\n    return meth(\n           ^^^^^\n  File \"/home/tygilman/School/CS3200/real-estate-htmx-fastapi/.venv/lib/python3.12/site-packages/sqlalchemy/sql/elements.py\", line 516, in _execute_on_connection\n    return connection._execute_clauseelement(\n           ^^^^^^^^^^^^^^^^^^^^^^^^^^^^^^^^^^\n  File \"/home/tygilman/School/CS3200/real-estate-htmx-fastapi/.venv/lib/python3.12/site-packages/sqlalchemy/engine/base.py\", line 1639, in _execute_clauseelement\n    ret = self._execute_context(\n          ^^^^^^^^^^^^^^^^^^^^^^\n  File \"/home/tygilman/School/CS3200/real-estate-htmx-fastapi/.venv/lib/python3.12/site-packages/sqlalchemy/engine/base.py\", line 1848, in _execute_context\n    return self._exec_single_context(\n           ^^^^^^^^^^^^^^^^^^^^^^^^^^\n  File \"/home/tygilman/School/CS3200/real-estate-htmx-fastapi/.venv/lib/python3.12/site-packages/sqlalchemy/engine/base.py\", line 1988, in _exec_single_context\n    self._handle_dbapi_exception(\n  File \"/home/tygilman/School/CS3200/real-estate-htmx-fastapi/.venv/lib/python3.12/site-packages/sqlalchemy/engine/base.py\", line 2343, in _handle_dbapi_exception\n    raise sqlalchemy_exception.with_traceback(exc_info[2]) from e\n  File \"/home/tygilman/School/CS3200/real-estate-htmx-fastapi/.venv/lib/python3.12/site-packages/sqlalchemy/engine/base.py\", line 1969, in _exec_single_context\n    self.dialect.do_execute(\n  File \"/home/tygilman/School/CS3200/real-estate-htmx-fastapi/.venv/lib/python3.12/site-packages/sqlalchemy/engine/default.py\", line 922, in do_execute\n    cursor.execute(statement, parameters)\n  File \"/home/tygilman/School/CS3200/real-estate-htmx-fastapi/.venv/lib/python3.12/site-packages/mysql/connector/cursor_cext.py\", line 357, in execute\n    result = self._connection.cmd_query(\n             ^^^^^^^^^^^^^^^^^^^^^^^^^^^\n  File \"/home/tygilman/School/CS3200/real-estate-htmx-fastapi/.venv/lib/python3.12/site-packages/mysql/connector/opentelemetry/context_propagation.py\", line 97, in wrapper\n    return method(cnx, *args, **kwargs)\n           ^^^^^^^^^^^^^^^^^^^^^^^^^^^^\n  File \"/home/tygilman/School/CS3200/real-estate-htmx-fastapi/.venv/lib/python3.12/site-packages/mysql/connector/connection_cext.py\", line 714, in cmd_query\n    raise get_mysql_exception(\nsqlalchemy.exc.DataError: (mysql.connector.errors.DataError) 1264 (22003): Out of range value for column 'bathrooms' at row 1\n[SQL: INSERT INTO `ResidentialProperty` (property_id, bedrooms, bathrooms, r_type, square_feet, garage_spaces, has_basement, has_pool, created_at) VALUES (%(property_id)s, %(bedrooms)s, %(bathrooms)s, %(r_type)s, %(square_feet)s, %(garage_spaces)s, %(has_basement)s, %(has_pool)s, now())]\n[parameters: {'property_id': 11, 'bedrooms': 234, 'bathrooms': 323.5, 'r_type': 'Single Family', 'square_feet': None, 'garage_spaces': None, 'has_basement': 0, 'has_pool': 0}]\n(Background on this error at: https://sqlalche.me/e/20/9h9h)"}}
